Workbook

Sheet CHIS
A1: Don {not in Banner} | B1: Mismatching {not in Banner} | C1: Dept/Prog Admin {not in Banner} | D1: Mona {not in Banner} | E1: Karen {not in Banner} | F1: DONE {not in Banner} | G1: Notes {not in Banner} | H1: CRN sorted {not in Banner} | I1: CRN | J1: Attribute {not in Banner} | K1: Subject | L1: Course Number {Crse Num} | M1: Course Section {Seq Crse Num} | N1: Program {not in Banner} | O1: Catalog Title | P1: Section Title | Q1: Crosslist Details {not in Banner} | R1: X Lst | S1: Campus {Ssasect Campus} | T1: Campus Restriction {Camp Restr CC} | U1: Schedule Type {not in Banner} | V1: Instruction Method {Inst Method} | W1: Level {Level SC} | X1: Part-Of-Term | Y1: Credit Catalog {Cat Crs} | Z1: Credits {Sect Crs} | AA1: Faculty Load / Contract Credits {not in Banner} | AB1: Enrollment Cap {Max Enrl} | AC1: Meeting Type | AD1: Semester Start Date {Soaterm Start Date} | AE1: Pre-work Start Date {not in Banner} | AF1: Pre-work End Date {not in Banner} | AG1: pre-work # of weeks {not in Banner} | AH1: pre-work hours/week {not in Banner} | AI1: pre-work hours/period {not in Banner} | AJ1: Intensive Period Start Date {Meet Start Date} | AK1: Intensive Period End Date {Meet End Date} | AL1: intensive # of weeks {not in Banner} | AM1: intensive hours/week {not in Banner} | AN1: intensive hours/period {not in Banner} | AO1: Post-work Start Date {not in Banner} | AP1: Post-work End Date {not in Banner} | AQ1: post-work # of weeks {not in Banner} | AR1: post-work hours/week {not in Banner} | AS1: post-work hours/period {not in Banner} | AT1: sum of weeks (for check) {not in Banner} | AU1: total contract hours {not in Banner} | AV1: Semester End Date {Soaterm End Date} | AW1: Course Beginning Time {Meet Beg Time} | AX1: Course Ending Time {Meet End Time} | AY1: SUN | AZ1: MON | BA1: TUE | BB1: WED | BC1: THU | BD1: FRI | BE1: SAT | BF1: Weeks | BG1: Fiscal Year {not in Banner} | BH1: Semester {not in Banner} | BI1: Room {Meet Room} | BJ1: Building {Meet Bldg} | BK1: Instructor Name {Instr Name} | BL1: Instructor Email {Instr Email} | BM1: Instructor ID {Instr ID} | BN1: Remote Employee {not in Banner} | BO1: % Responsibility | BP1: load/contract {not in Banner} | BQ1: Reason for Contract {not in Banner} | BR1: costs per credit {not in Banner} | BS1: total costs {not in Banner} | BT1: dept budget {not in Banner} | BU1: account to be charged {not in Banner} | BV1: SEM Department {Scacrse Dept} | BW1: dean email | BX1: VP finance email | BY1: HR email | BZ1: Fee Amount {Fees Amt} | CA1: Fee Code {Detl Code} | CB1: Fee Type | CC1: Fee Level | CD1: Fee Ind | CE1: Fee Term | CF1: Activity Date | CG1: Status | CH1: Bill Hrs | CI1: Sect Sch Type | CJ1: Prerequisites {Preq Areas} | CK1: Link Ind | CL1: Integration Code | CM1: Link Conn | CN1: Crs Attr | CO1: Comments | CP1: Major Restr | CQ1: Scacrse College | CR1: Enrolled | CS1: Waitlist Capacity | CT1: Primary Ind | CU1: Override | CV1: 1st Date Reg Opens | CW1: Last Date Reg Opens | CX1: OL Range From Date | CY1: OL Range To Date | CZ1: OL Numb Units | DA1: OL Duration Code | DB1: Grade Mode | DC1: Gradable Ind | DD1: Tuit Waiver | DE1: Course Override {Meet Override} | DF1: Lvl Res Ind | DG1: Cmp Res Ind | DH1: Rate Code | DI1: Cohort Code | DJ1: St Attr Code | DK1: Coll SC | DL1: DegC SC | DM1: Prog SC | DN1: FOS Type | DO1: Special Approval {Special Apvl} | DP1: Term Code | DQ1: Camp SC

Sheet DSLE
A1: Don {not in Banner} | B1: Mismatching {not in Banner} | C1: Dept/Prog Admin {not in Banner} | D1: Mona {not in Banner} | E1: Karen {not in Banner} | F1: DONE {not in Banner} | G1: Notes {not in Banner} | H1: CRN sorted {not in Banner} | I1: CRN | J1: Attribute {not in Banner} | K1: Subject | L1: Course Number {Crse Num} | M1: Course Section {Seq Crse Num} | N1: Program {not in Banner} | O1: Catalog Title | P1: Section Title | Q1: Crosslist Details {not in Banner} | R1: X Lst | S1: Campus {Ssasect Campus} | T1: Campus Restriction {Camp Restr CC} | U1: Schedule Type {not in Banner} | V1: Instruction Method {Inst Method} | W1: Level {Level SC} | X1: Part-Of-Term | Y1: Credit Catalog {Cat Crs} | Z1: Credits {Sect Crs} | AA1: Faculty Load / Contract Credits {not in Banner} | AB1: Enrollment Cap {Max Enrl} | AC1: Meeting Type | AD1: Semester Start Date {Soaterm Start Date} | AE1: Pre-work Start Date {not in Banner} | AF1: Pre-work End Date {not in Banner} | AG1: pre-work # of weeks {not in Banner} | AH1: pre-work hours/week {not in Banner} | AI1: pre-work hours/period {not in Banner} | AJ1: Intensive Period Start Date {Meet Start Date} | AK1: Intensive Period End Date {Meet End Date} | AL1: intensive # of weeks {not in Banner} | AM1: intensive hours/week {not in Banner} | AN1: intensive hours/period {not in Banner} | AO1: Post-work Start Date {not in Banner} | AP1: Post-work End Date {not in Banner} | AQ1: post-work # of weeks {not in Banner} | AR1: post-work hours/week {not in Banner} | AS1: post-work hours/period {not in Banner} | AT1: sum of weeks (for check) {not in Banner} | AU1: total contract hours {not in Banner} | AV1: Semester End Date {Soaterm End Date} | AW1: Course Beginning Time {Meet Beg Time} | AX1: Course Ending Time {Meet End Time} | AY1: SUN | AZ1: MON | BA1: TUE | BB1: WED | BC1: THU | BD1: FRI | BE1: SAT | BF1: Weeks | BG1: Fiscal Year {not in Banner} | BH1: Semester {not in Banner} | BI1: Room {Meet Room} | BJ1: Building {Meet Bldg} | BK1: Instructor Name {Instr Name} | BL1: Instructor Email {Instr Email} | BM1: Instructor ID {Instr ID} | BN1: Remote Employee {not in Banner} | BO1: % Responsibility | BP1: load/contract {not in Banner} | BQ1: Reason for Contract {not in Banner} | BR1: costs per credit {not in Banner} | BS1: total costs {not in Banner} | BT1: dept budget {not in Banner} | BU1: account to be charged {not in Banner} | BV1: SEM Department {Scacrse Dept} | BW1: dean email | BX1: VP finance email | BY1: HR email | BZ1: Fee Amount {Fees Amt} | CA1: Fee Code {Detl Code} | CB1: Fee Type | CC1: Fee Level | CD1: Fee Ind | CE1: Fee Term | CF1: Activity Date | CG1: Status | CH1: Bill Hrs | CI1: Sect Sch Type | CJ1: Prerequisites {Preq Areas} | CK1: Link Ind | CL1: Integration Code | CM1: Link Conn | CN1: Crs Attr | CO1: Comments | CP1: Major Restr | CQ1: Scacrse College | CR1: Enrolled | CS1: Waitlist Capacity | CT1: Primary Ind | CU1: Override | CV1: 1st Date Reg Opens | CW1: Last Date Reg Opens | CX1: OL Range From Date | CY1: OL Range To Date | CZ1: OL Numb Units | DA1: OL Duration Code | DB1: Grade Mode | DC1: Gradable Ind | DD1: Tuit Waiver | DE1: Course Override {Meet Override} | DF1: Lvl Res Ind | DG1: Cmp Res Ind | DH1: Rate Code | DI1: Cohort Code | DJ1: St Attr Code | DK1: Coll SC | DL1: DegC SC | DM1: Prog SC | DN1: FOS Type | DO1: Special Approval {Special Apvl} | DP1: Term Code | DQ1: Camp SC

Sheet GSEM
A1: Don {not in Banner} | B1: Mismatching {not in Banner} | C1: Dept/Prog Admin {not in Banner} | D1: Mona {not in Banner} | E1: Karen {not in Banner} | F1: DONE {not in Banner} | G1: Notes {not in Banner} | H1: CRN sorted {not in Banner} | I1: CRN | J1: Attribute {not in Banner} | K1: Subject | L1: Course Number {Crse Num} | M1: Course Section {Seq Crse Num} | N1: Program {not in Banner} | O1: Catalog Title | P1: Section Title | Q1: Crosslist Details {not in Banner} | R1: X Lst | S1: Campus {Ssasect Campus} | T1: Campus Restriction {Camp Restr CC} | U1: Schedule Type {not in Banner} | V1: Instruction Method {Inst Method} | W1: Level {Level SC} | X1: Part-Of-Term | Y1: Credit Catalog {Cat Crs} | Z1: Credits {Sect Crs} | AA1: Faculty Load / Contract Credits {not in Banner} | AB1: Enrollment Cap {Max Enrl} | AC1: Meeting Type | AD1: Semester Start Date {Soaterm Start Date} | AE1: Pre-work Start Date {not in Banner} | AF1: Pre-work End Date {not in Banner} | AG1: pre-work # of weeks {not in Banner} | AH1: pre-work hours/week {not in Banner} | AI1: pre-work hours/period {not in Banner} | AJ1: Intensive Period Start Date {Meet Start Date} | AK1: Intensive Period End Date {Meet End Date} | AL1: intensive # of weeks {not in Banner} | AM1: intensive hours/week {not in Banner} | AN1: intensive hours/period {not in Banner} | AO1: Post-work Start Date {not in Banner} | AP1: Post-work End Date {not in Banner} | AQ1: post-work # of weeks {not in Banner} | AR1: post-work hours/week {not in Banner} | AS1: post-work hours/period {not in Banner} | AT1: sum of weeks (for check) {not in Banner} | AU1: total contract hours {not in Banner} | AV1: Semester End Date {Soaterm End Date} | AW1: Course Beginning Time {Meet Beg Time} | AX1: Course Ending Time {Meet End Time} | AY1: SUN | AZ1: MON | BA1: TUE | BB1: WED | BC1: THU | BD1: FRI | BE1: SAT | BF1: Weeks | BG1: Fiscal Year {not in Banner} | BH1: Semester {not in Banner} | BI1: Room {Meet Room} | BJ1: Building {Meet Bldg} | BK1: Instructor Name {Instr Name} | BL1: Instructor Email {Instr Email} | BM1: Instructor ID {Instr ID} | BN1: Remote Employee {not in Banner} | BO1: % Responsibility | BP1: load/contract {not in Banner} | BQ1: Reason for Contract {not in Banner} | BR1: costs per credit {not in Banner} | BS1: total costs {not in Banner} | BT1: dept budget {not in Banner} | BU1: account to be charged {not in Banner} | BV1: SEM Department {Scacrse Dept} | BW1: dean email | BX1: VP finance email | BY1: HR email | BZ1: Fee Amount {Fees Amt} | CA1: Fee Code {Detl Code} | CB1: Fee Type | CC1: Fee Level | CD1: Fee Ind | CE1: Fee Term | CF1: Activity Date | CG1: Status | CH1: Bill Hrs | CI1: Sect Sch Type | CJ1: Prerequisites {Preq Areas} | CK1: Link Ind | CL1: Integration Code | CM1: Link Conn | CN1: Crs Attr | CO1: Comments | CP1: Major Restr | CQ1: Scacrse College | CR1: Enrolled | CS1: Waitlist Capacity | CT1: Primary Ind | CU1: Override | CV1: 1st Date Reg Opens | CW1: Last Date Reg Opens | CX1: OL Range From Date | CY1: OL Range To Date | CZ1: OL Numb Units | DA1: OL Duration Code | DB1: Grade Mode | DC1: Gradable Ind | DD1: Tuit Waiver | DE1: Course Override {Meet Override} | DF1: Lvl Res Ind | DG1: Cmp Res Ind | DH1: Rate Code | DI1: Cohort Code | DJ1: St Attr Code | DK1: Coll SC | DL1: DegC SC | DM1: Prog SC | DN1: FOS Type | DO1: Special Approval {Special Apvl} | DP1: Term Code | DQ1: Camp SC

Sheet MSSN
A1: Don {not in Banner} | B1: Mismatching {not in Banner} | C1: Dept/Prog Admin {not in Banner} | D1: Mona {not in Banner} | E1: Karen {not in Banner} | F1: DONE {not in Banner} | G1: Notes {not in Banner} | H1: CRN sorted {not in Banner} | I1: CRN | J1: Attribute {not in Banner} | K1: Subject | L1: Course Number {Crse Num} | M1: Course Section {Seq Crse Num} | N1: Program {not in Banner} | O1: Catalog Title | P1: Section Title | Q1: Crosslist Details {not in Banner} | R1: X Lst | S1: Campus {Ssasect Campus} | T1: Campus Restriction {Camp Restr CC} | U1: Schedule Type {not in Banner} | V1: Instruction Method {Inst Method} | W1: Level {Level SC} | X1: Part-Of-Term | Y1: Credit Catalog {Cat Crs} | Z1: Credits {Sect Crs} | AA1: Faculty Load / Contract Credits {not in Banner} | AB1: Enrollment Cap {Max Enrl} | AC1: Meeting Type | AD1: Semester Start Date {Soaterm Start Date} | AE1: Pre-work Start Date {not in Banner} | AF1: Pre-work End Date {not in Banner} | AG1: pre-work # of weeks {not in Banner} | AH1: pre-work hours/week {not in Banner} | AI1: pre-work hours/period {not in Banner} | AJ1: Intensive Period Start Date {Meet Start Date} | AK1: Intensive Period End Date {Meet End Date} | AL1: intensive # of weeks {not in Banner} | AM1: intensive hours/week {not in Banner} | AN1: intensive hours/period {not in Banner} | AO1: Post-work Start Date {not in Banner} | AP1: Post-work End Date {not in Banner} | AQ1: post-work # of weeks {not in Banner} | AR1: post-work hours/week {not in Banner} | AS1: post-work hours/period {not in Banner} | AT1: sum of weeks (for check) {not in Banner} | AU1: total contract hours {not in Banner} | AV1: Semester End Date {Soaterm End Date} | AW1: Course Beginning Time {Meet Beg Time} | AX1: Course Ending Time {Meet End Time} | AY1: SUN | AZ1: MON | BA1: TUE | BB1: WED | BC1: THU | BD1: FRI | BE1: SAT | BF1: Weeks | BG1: Fiscal Year {not in Banner} | BH1: Semester {not in Banner} | BI1: Room {Meet Room} | BJ1: Building {Meet Bldg} | BK1: Instructor Name {Instr Name} | BL1: Instructor Email {Instr Email} | BM1: Instructor ID {Instr ID} | BN1: Remote Employee {not in Banner} | BO1: % Responsibility | BP1: load/contract {not in Banner} | BQ1: Reason for Contract {not in Banner} | BR1: costs per credit {not in Banner} | BS1: total costs {not in Banner} | BT1: dept budget {not in Banner} | BU1: account to be charged {not in Banner} | BV1: SEM Department {Scacrse Dept} | BW1: dean email | BX1: VP finance email | BY1: HR email | BZ1: Fee Amount {Fees Amt} | CA1: Fee Code {Detl Code} | CB1: Fee Type | CC1: Fee Level | CD1: Fee Ind | CE1: Fee Term | CF1: Activity Date | CG1: Status | CH1: Bill Hrs | CI1: Sect Sch Type | CJ1: Prerequisites {Preq Areas} | CK1: Link Ind | CL1: Integration Code | CM1: Link Conn | CN1: Crs Attr | CO1: Comments | CP1: Major Restr | CQ1: Scacrse College | CR1: Enrolled | CS1: Waitlist Capacity | CT1: Primary Ind | CU1: Override | CV1: 1st Date Reg Opens | CW1: Last Date Reg Opens | CX1: OL Range From Date | CY1: OL Range To Date | CZ1: OL Numb Units | DA1: OL Duration Code | DB1: Grade Mode | DC1: Gradable Ind | DD1: Tuit Waiver | DE1: Course Override {Meet Override} | DF1: Lvl Res Ind | DG1: Cmp Res Ind | DH1: Rate Code | DI1: Cohort Code | DJ1: St Attr Code | DK1: Coll SC | DL1: DegC SC | DM1: Prog SC | DN1: FOS Type | DO1: Special Approval {Special Apvl} | DP1: Term Code | DQ1: Camp SC
BK2: =IF($BJ2="","",IFERROR(INDEX(InstructorMap!$B:$B, MATCH($BJ2, InstructorMap!$A:$A, 0)),"")) | BL2: =IF($BJ2="","",IFERROR(INDEX(InstructorMap!$C:$C, MATCH($BJ2, InstructorMap!$A:$A, 0)),""))
BK3: =IF($BJ3="","",IFERROR(INDEX(InstructorMap!$B:$B, MATCH($BJ3, InstructorMap!$A:$A, 0)),"")) | BL3: =IF($BJ3="","",IFERROR(INDEX(InstructorMap!$C:$C, MATCH($BJ3, InstructorMap!$A:$A, 0)),""))
BK4: =IF($BJ4="","",IFERROR(INDEX(InstructorMap!$B:$B, MATCH($BJ4, InstructorMap!$A:$A, 0)),"")) | BL4: =IF($BJ4="","",IFERROR(INDEX(InstructorMap!$C:$C, MATCH($BJ4, InstructorMap!$A:$A, 0)),""))
BK5: =IF($BJ5="","",IFERROR(INDEX(InstructorMap!$B:$B, MATCH($BJ5, InstructorMap!$A:$A, 0)),"")) | BL5: =IF($BJ5="","",IFERROR(INDEX(InstructorMap!$C:$C, MATCH($BJ5, InstructorMap!$A:$A, 0)),""))

Sheet NTST
A1: Don {not in Banner} | B1: Mismatching {not in Banner} | C1: Dept/Prog Admin {not in Banner} | D1: Mona {not in Banner} | E1: Karen {not in Banner} | F1: DONE {not in Banner} | G1: Notes {not in Banner} | H1: CRN sorted {not in Banner} | I1: CRN | J1: Attribute {not in Banner} | K1: Subject | L1: Course Number {Crse Num} | M1: Course Section {Seq Crse Num} | N1: Program {not in Banner} | O1: Catalog Title | P1: Section Title | Q1: Crosslist Details {not in Banner} | R1: X Lst | S1: Campus {Ssasect Campus} | T1: Campus Restriction {Camp Restr CC} | U1: Schedule Type {not in Banner} | V1: Instruction Method {Inst Method} | W1: Level {Level SC} | X1: Part-Of-Term | Y1: Credit Catalog {Cat Crs} | Z1: Credits {Sect Crs} | AA1: Faculty Load / Contract Credits {not in Banner} | AB1: Enrollment Cap {Max Enrl} | AC1: Meeting Type | AD1: Semester Start Date {Soaterm Start Date} | AE1: Pre-work Start Date {not in Banner} | AF1: Pre-work End Date {not in Banner} | AG1: pre-work # of weeks {not in Banner} | AH1: pre-work hours/week {not in Banner} | AI1: pre-work hours/period {not in Banner} | AJ1: Intensive Period Start Date {Meet Start Date} | AK1: Intensive Period End Date {Meet End Date} | AL1: intensive # of weeks {not in Banner} | AM1: intensive hours/week {not in Banner} | AN1: intensive hours/period {not in Banner} | AO1: Post-work Start Date {not in Banner} | AP1: Post-work End Date {not in Banner} | AQ1: post-work # of weeks {not in Banner} | AR1: post-work hours/week {not in Banner} | AS1: post-work hours/period {not in Banner} | AT1: sum of weeks (for check) {not in Banner} | AU1: total contract hours {not in Banner} | AV1: Semester End Date {Soaterm End Date} | AW1: Course Beginning Time {Meet Beg Time} | AX1: Course Ending Time {Meet End Time} | AY1: SUN | AZ1: MON | BA1: TUE | BB1: WED | BC1: THU | BD1: FRI | BE1: SAT | BF1: Weeks | BG1: Fiscal Year {not in Banner} | BH1: Semester {not in Banner} | BI1: Room {Meet Room} | BJ1: Building {Meet Bldg} | BK1: Instructor Name {Instr Name} | BL1: Instructor Email {Instr Email} | BM1: Instructor ID {Instr ID} | BN1: Remote Employee {not in Banner} | BO1: % Responsibility | BP1: load/contract {not in Banner} | BQ1: Reason for Contract {not in Banner} | BR1: costs per credit {not in Banner} | BS1: total costs {not in Banner} | BT1: dept budget {not in Banner} | BU1: account to be charged {not in Banner} | BV1: SEM Department {Scacrse Dept} | BW1: dean email | BX1: VP finance email | BY1: HR email | BZ1: Fee Amount {Fees Amt} | CA1: Fee Code {Detl Code} | CB1: Fee Type | CC1: Fee Level | CD1: Fee Ind | CE1: Fee Term | CF1: Activity Date | CG1: Status | CH1: Bill Hrs | CI1: Sect Sch Type | CJ1: Prerequisites {Preq Areas} | CK1: Link Ind | CL1: Integration Code | CM1: Link Conn | CN1: Crs Attr | CO1: Comments | CP1: Major Restr | CQ1: Scacrse College | CR1: Enrolled | CS1: Waitlist Capacity | CT1: Primary Ind | CU1: Override | CV1: 1st Date Reg Opens | CW1: Last Date Reg Opens | CX1: OL Range From Date | CY1: OL Range To Date | CZ1: OL Numb Units | DA1: OL Duration Code | DB1: Grade Mode | DC1: Gradable Ind | DD1: Tuit Waiver | DE1: Course Override {Meet Override} | DF1: Lvl Res Ind | DG1: Cmp Res Ind | DH1: Rate Code | DI1: Cohort Code | DJ1: St Attr Code | DK1: Coll SC | DL1: DegC SC | DM1: Prog SC | DN1: FOS Type | DO1: Special Approval {Special Apvl} | DP1: Term Code | DQ1: Camp SC

Sheet OTST
A1: Don {not in Banner} | B1: Mismatching {not in Banner} | C1: Dept/Prog Admin {not in Banner} | D1: Mona {not in Banner} | E1: Karen {not in Banner} | F1: DONE {not in Banner} | G1: Notes {not in Banner} | H1: CRN sorted {not in Banner} | I1: CRN | J1: Attribute {not in Banner} | K1: Subject | L1: Course Number {Crse Num} | M1: Course Section {Seq Crse Num} | N1: Program {not in Banner} | O1: Catalog Title | P1: Section Title | Q1: Crosslist Details {not in Banner} | R1: X Lst | S1: Campus {Ssasect Campus} | T1: Campus Restriction {Camp Restr CC} | U1: Schedule Type {not in Banner} | V1: Instruction Method {Inst Method} | W1: Level {Level SC} | X1: Part-Of-Term | Y1: Credit Catalog {Cat Crs} | Z1: Credits {Sect Crs} | AA1: Faculty Load / Contract Credits {not in Banner} | AB1: Enrollment Cap {Max Enrl} | AC1: Meeting Type | AD1: Semester Start Date {Soaterm Start Date} | AE1: Pre-work Start Date {not in Banner} | AF1: Pre-work End Date {not in Banner} | AG1: pre-work # of weeks {not in Banner} | AH1: pre-work hours/week {not in Banner} | AI1: pre-work hours/period {not in Banner} | AJ1: Intensive Period Start Date {Meet Start Date} | AK1: Intensive Period End Date {Meet End Date} | AL1: intensive # of weeks {not in Banner} | AM1: intensive hours/week {not in Banner} | AN1: intensive hours/period {not in Banner} | AO1: Post-work Start Date {not in Banner} | AP1: Post-work End Date {not in Banner} | AQ1: post-work # of weeks {not in Banner} | AR1: post-work hours/week {not in Banner} | AS1: post-work hours/period {not in Banner} | AT1: sum of weeks (for check) {not in Banner} | AU1: total contract hours {not in Banner} | AV1: Semester End Date {Soaterm End Date} | AW1: Course Beginning Time {Meet Beg Time} | AX1: Course Ending Time {Meet End Time} | AY1: SUN | AZ1: MON | BA1: TUE | BB1: WED | BC1: THU | BD1: FRI | BE1: SAT | BF1: Weeks | BG1: Fiscal Year {not in Banner} | BH1: Semester {not in Banner} | BI1: Room {Meet Room} | BJ1: Building {Meet Bldg} | BK1: Instructor Name {Instr Name} | BL1: Instructor Email {Instr Email} | BM1: Instructor ID {Instr ID} | BN1: Remote Employee {not in Banner} | BO1: % Responsibility | BP1: load/contract {not in Banner} | BQ1: Reason for Contract {not in Banner} | BR1: costs per credit {not in Banner} | BS1: total costs {not in Banner} | BT1: dept budget {not in Banner} | BU1: account to be charged {not in Banner} | BV1: SEM Department {Scacrse Dept} | BW1: dean email | BX1: VP finance email | BY1: HR email | BZ1: Fee Amount {Fees Amt} | CA1: Fee Code {Detl Code} | CB1: Fee Type | CC1: Fee Level | CD1: Fee Ind | CE1: Fee Term | CF1: Activity Date | CG1: Status | CH1: Bill Hrs | CI1: Sect Sch Type | CJ1: Prerequisites {Preq Areas} | CK1: Link Ind | CL1: Integration Code | CM1: Link Conn | CN1: Crs Attr | CO1: Comments | CP1: Major Restr | CQ1: Scacrse College | CR1: Enrolled | CS1: Waitlist Capacity | CT1: Primary Ind | CU1: Override | CV1: 1st Date Reg Opens | CW1: Last Date Reg Opens | CX1: OL Range From Date | CY1: OL Range To Date | CZ1: OL Numb Units | DA1: OL Duration Code | DB1: Grade Mode | DC1: Gradable Ind | DD1: Tuit Waiver | DE1: Course Override {Meet Override} | DF1: Lvl Res Ind | DG1: Cmp Res Ind | DH1: Rate Code | DI1: Cohort Code | DJ1: St Attr Code | DK1: Coll SC | DL1: DegC SC | DM1: Prog SC | DN1: FOS Type | DO1: Special Approval {Special Apvl} | DP1: Term Code | DQ1: Camp SC

Sheet PATH
A1: Don {not in Banner} | B1: Mismatching {not in Banner} | C1: Dept/Prog Admin {not in Banner} | D1: Mona {not in Banner} | E1: Karen {not in Banner} | F1: DONE {not in Banner} | G1: Notes {not in Banner} | H1: CRN sorted {not in Banner} | I1: CRN | J1: Attribute {not in Banner} | K1: Subject | L1: Course Number {Crse Num} | M1: Course Section {Seq Crse Num} | N1: Program {not in Banner} | O1: Catalog Title | P1: Section Title | Q1: Crosslist Details {not in Banner} | R1: X Lst | S1: Campus {Ssasect Campus} | T1: Campus Restriction {Camp Restr CC} | U1: Schedule Type {not in Banner} | V1: Instruction Method {Inst Method} | W1: Level {Level SC} | X1: Part-Of-Term | Y1: Credit Catalog {Cat Crs} | Z1: Credits {Sect Crs} | AA1: Faculty Load / Contract Credits {not in Banner} | AB1: Enrollment Cap {Max Enrl} | AC1: Meeting Type | AD1: Semester Start Date {Soaterm Start Date} | AE1: Pre-work Start Date {not in Banner} | AF1: Pre-work End Date {not in Banner} | AG1: pre-work # of weeks {not in Banner} | AH1: pre-work hours/week {not in Banner} | AI1: pre-work hours/period {not in Banner} | AJ1: Intensive Period Start Date {Meet Start Date} | AK1: Intensive Period End Date {Meet End Date} | AL1: intensive # of weeks {not in Banner} | AM1: intensive hours/week {not in Banner} | AN1: intensive hours/period {not in Banner} | AO1: Post-work Start Date {not in Banner} | AP1: Post-work End Date {not in Banner} | AQ1: post-work # of weeks {not in Banner} | AR1: post-work hours/week {not in Banner} | AS1: post-work hours/period {not in Banner} | AT1: sum of weeks (for check) {not in Banner} | AU1: total contract hours {not in Banner} | AV1: Semester End Date {Soaterm End Date} | AW1: Course Beginning Time {Meet Beg Time} | AX1: Course Ending Time {Meet End Time} | AY1: SUN | AZ1: MON | BA1: TUE | BB1: WED | BC1: THU | BD1: FRI | BE1: SAT | BF1: Weeks | BG1: Fiscal Year {not in Banner} | BH1: Semester {not in Banner} | BI1: Room {Meet Room} | BJ1: Building {Meet Bldg} | BK1: Instructor Name {Instr Name} | BL1: Instructor Email {Instr Email} | BM1: Instructor ID {Instr ID} | BN1: Remote Employee {not in Banner} | BO1: % Responsibility | BP1: load/contract {not in Banner} | BQ1: Reason for Contract {not in Banner} | BR1: costs per credit {not in Banner} | BS1: total costs {not in Banner} | BT1: dept budget {not in Banner} | BU1: account to be charged {not in Banner} | BV1: SEM Department {Scacrse Dept} | BW1: dean email | BX1: VP finance email | BY1: HR email | BZ1: Fee Amount {Fees Amt} | CA1: Fee Code {Detl Code} | CB1: Fee Type | CC1: Fee Level | CD1: Fee Ind | CE1: Fee Term | CF1: Activity Date | CG1: Status | CH1: Bill Hrs | CI1: Sect Sch Type | CJ1: Prerequisites {Preq Areas} | CK1: Link Ind | CL1: Integration Code | CM1: Link Conn | CN1: Crs Attr | CO1: Comments | CP1: Major Restr | CQ1: Scacrse College | CR1: Enrolled | CS1: Waitlist Capacity | CT1: Primary Ind | CU1: Override | CV1: 1st Date Reg Opens | CW1: Last Date Reg Opens | CX1: OL Range From Date | CY1: OL Range To Date | CZ1: OL Numb Units | DA1: OL Duration Code | DB1: Grade Mode | DC1: Gradable Ind | DD1: Tuit Waiver | DE1: Course Override {Meet Override} | DF1: Lvl Res Ind | DG1: Cmp Res Ind | DH1: Rate Code | DI1: Cohort Code | DJ1: St Attr Code | DK1: Coll SC | DL1: DegC SC | DM1: Prog SC | DN1: FOS Type | DO1: Special Approval {Special Apvl} | DP1: Term Code | DQ1: Camp SC

Sheet THST
A1: Don {not in Banner} | B1: Mismatching {not in Banner} | C1: Dept/Prog Admin {not in Banner} | D1: Mona {not in Banner} | E1: Karen {not in Banner} | F1: DONE {not in Banner} | G1: Notes {not in Banner} | H1: CRN sorted {not in Banner} | I1: CRN | J1: Attribute {not in Banner} | K1: Subject | L1: Course Number {Crse Num} | M1: Course Section {Seq Crse Num} | N1: Program {not in Banner} | O1: Catalog Title | P1: Section Title | Q1: Crosslist Details {not in Banner} | R1: X Lst | S1: Campus {Ssasect Campus} | T1: Campus Restriction {Camp Restr CC} | U1: Schedule Type {not in Banner} | V1: Instruction Method {Inst Method} | W1: Level {Level SC} | X1: Part-Of-Term | Y1: Credit Catalog {Cat Crs} | Z1: Credits {Sect Crs} | AA1: Faculty Load / Contract Credits {not in Banner} | AB1: Enrollment Cap {Max Enrl} | AC1: Meeting Type | AD1: Semester Start Date {Soaterm Start Date} | AE1: Pre-work Start Date {not in Banner} | AF1: Pre-work End Date {not in Banner} | AG1: pre-work # of weeks {not in Banner} | AH1: pre-work hours/week {not in Banner} | AI1: pre-work hours/period {not in Banner} | AJ1: Intensive Period Start Date {Meet Start Date} | AK1: Intensive Period End Date {Meet End Date} | AL1: intensive # of weeks {not in Banner} | AM1: intensive hours/week {not in Banner} | AN1: intensive hours/period {not in Banner} | AO1: Post-work Start Date {not in Banner} | AP1: Post-work End Date {not in Banner} | AQ1: post-work # of weeks {not in Banner} | AR1: post-work hours/week {not in Banner} | AS1: post-work hours/period {not in Banner} | AT1: sum of weeks (for check) {not in Banner} | AU1: total contract hours {not in Banner} | AV1: Semester End Date {Soaterm End Date} | AW1: Course Beginning Time {Meet Beg Time} | AX1: Course Ending Time {Meet End Time} | AY1: SUN | AZ1: MON | BA1: TUE | BB1: WED | BC1: THU | BD1: FRI | BE1: SAT | BF1: Weeks | BG1: Fiscal Year {not in Banner} | BH1: Semester {not in Banner} | BI1: Room {Meet Room} | BJ1: Building {Meet Bldg} | BK1: Instructor Name {Instr Name} | BL1: Instructor Email {Instr Email} | BM1: Instructor ID {Instr ID} | BN1: Remote Employee {not in Banner} | BO1: % Responsibility | BP1: load/contract {not in Banner} | BQ1: Reason for Contract {not in Banner} | BR1: costs per credit {not in Banner} | BS1: total costs {not in Banner} | BT1: dept budget {not in Banner} | BU1: account to be charged {not in Banner} | BV1: SEM Department {Scacrse Dept} | BW1: dean email | BX1: VP finance email | BY1: HR email | BZ1: Fee Amount {Fees Amt} | CA1: Fee Code {Detl Code} | CB1: Fee Type | CC1: Fee Level | CD1: Fee Ind | CE1: Fee Term | CF1: Activity Date | CG1: Status | CH1: Bill Hrs | CI1: Sect Sch Type | CJ1: Prerequisites {Preq Areas} | CK1: Link Ind | CL1: Integration Code | CM1: Link Conn | CN1: Crs Attr | CO1: Comments | CP1: Major Restr | CQ1: Scacrse College | CR1: Enrolled | CS1: Waitlist Capacity | CT1: Primary Ind | CU1: Override | CV1: 1st Date Reg Opens | CW1: Last Date Reg Opens | CX1: OL Range From Date | CY1: OL Range To Date | CZ1: OL Numb Units | DA1: OL Duration Code | DB1: Grade Mode | DC1: Gradable Ind | DD1: Tuit Waiver | DE1: Course Override {Meet Override} | DF1: Lvl Res Ind | DG1: Cmp Res Ind | DH1: Rate Code | DI1: Cohort Code | DJ1: St Attr Code | DK1: Coll SC | DL1: DegC SC | DM1: Prog SC | DN1: FOS Type | DO1: Special Approval {Special Apvl} | DP1: Term Code | DQ1: Camp SC
BK2: =IF($BJ2="","",IFERROR(INDEX(InstructorMap!$B:$B, MATCH($BJ2, InstructorMap!$A:$A, 0)),"")) | BL2: =IF($BJ2="","",IFERROR(INDEX(InstructorMap!$C:$C, MATCH($BJ2, InstructorMap!$A:$A, 0)),""))
BK3: =IF($BJ3="","",IFERROR(INDEX(InstructorMap!$B:$B, MATCH($BJ3, InstructorMap!$A:$A, 0)),"")) | BL3: =IF($BJ3="","",IFERROR(INDEX(InstructorMap!$C:$C, MATCH($BJ3, InstructorMap!$A:$A, 0)),""))
BK4: =IF($BJ4="","",IFERROR(INDEX(InstructorMap!$B:$B, MATCH($BJ4, InstructorMap!$A:$A, 0)),"")) | BL4: =IF($BJ4="","",IFERROR(INDEX(InstructorMap!$C:$C, MATCH($BJ4, InstructorMap!$A:$A, 0)),""))
BK5: =IF($BJ5="","",IFERROR(INDEX(InstructorMap!$B:$B, MATCH($BJ5, InstructorMap!$A:$A, 0)),"")) | BL5: =IF($BJ5="","",IFERROR(INDEX(InstructorMap!$C:$C, MATCH($BJ5, InstructorMap!$A:$A, 0)),""))
BK6: =IF($BJ6="","",IFERROR(INDEX(InstructorMap!$B:$B, MATCH($BJ6, InstructorMap!$A:$A, 0)),"")) | BL6: =IF($BJ6="","",IFERROR(INDEX(InstructorMap!$C:$C, MATCH($BJ6, InstructorMap!$A:$A, 0)),""))
BK7: =IF($BJ7="","",IFERROR(INDEX(InstructorMap!$B:$B, MATCH($BJ7, InstructorMap!$A:$A, 0)),"")) | BL7: =IF($BJ7="","",IFERROR(INDEX(InstructorMap!$C:$C, MATCH($BJ7, InstructorMap!$A:$A, 0)),""))

Sheet MDivHISP_MAPmENGL_MAPmHISP
A1: Don {not in Banner} | B1: Mismatching {not in Banner} | C1: Dept/Prog Admin {not in Banner} | D1: Mona {not in Banner} | E1: Karen {not in Banner} | F1: DONE {not in Banner} | G1: Notes {not in Banner} | H1: CRN sorted {not in Banner} | I1: CRN | J1: Attribute {not in Banner} | K1: Subject | L1: Course Number {Crse Num} | M1: Course Section {Seq Crse Num} | N1: Program {not in Banner} | O1: Catalog Title | P1: Section Title | Q1: Crosslist Details {not in Banner} | R1: X Lst | S1: Campus {Ssasect Campus} | T1: Campus Restriction {Camp Restr CC} | U1: Schedule Type {not in Banner} | V1: Instruction Method {Inst Method} | W1: Level {Level SC} | X1: Part-Of-Term | Y1: Credit Catalog {Cat Crs} | Z1: Credits {Sect Crs} | AA1: Faculty Load / Contract Credits {not in Banner} | AB1: Enrollment Cap {Max Enrl} | AC1: Meeting Type | AD1: Semester Start Date {Soaterm Start Date} | AE1: Pre-work Start Date {not in Banner} | AF1: Pre-work End Date {not in Banner} | AG1: pre-work # of weeks {not in Banner} | AH1: pre-work hours/week {not in Banner} | AI1: pre-work hours/period {not in Banner} | AJ1: Intensive Period Start Date {Meet Start Date} | AK1: Intensive Period End Date {Meet End Date} | AL1: intensive # of weeks {not in Banner} | AM1: intensive hours/week {not in Banner} | AN1: intensive hours/period {not in Banner} | AO1: Post-work Start Date {not in Banner} | AP1: Post-work End Date {not in Banner} | AQ1: post-work # of weeks {not in Banner} | AR1: post-work hours/week {not in Banner} | AS1: post-work hours/period {not in Banner} | AT1: sum of weeks (for check) {not in Banner} | AU1: total contract hours {not in Banner} | AV1: Semester End Date {Soaterm End Date} | AW1: Course Beginning Time {Meet Beg Time} | AX1: Course Ending Time {Meet End Time} | AY1: SUN | AZ1: MON | BA1: TUE | BB1: WED | BC1: THU | BD1: FRI | BE1: SAT | BF1: Weeks | BG1: Fiscal Year {not in Banner} | BH1: Semester {not in Banner} | BI1: Room {Meet Room} | BJ1: Building {Meet Bldg} | BK1: Instructor Name {Instr Name} | BL1: Instructor Email {Instr Email} | BM1: Instructor ID {Instr ID} | BN1: Remote Employee {not in Banner} | BO1: % Responsibility | BP1: load/contract {not in Banner} | BQ1: Reason for Contract {not in Banner} | BR1: costs per credit {not in Banner} | BS1: total costs {not in Banner} | BT1: dept budget {not in Banner} | BU1: account to be charged {not in Banner} | BV1: SEM Department {Scacrse Dept} | BW1: dean email | BX1: VP finance email | BY1: HR email | BZ1: Fee Amount {Fees Amt} | CA1: Fee Code {Detl Code} | CB1: Fee Type | CC1: Fee Level | CD1: Fee Ind | CE1: Fee Term | CF1: Activity Date | CG1: Status | CH1: Bill Hrs | CI1: Sect Sch Type | CJ1: Prerequisites {Preq Areas} | CK1: Link Ind | CL1: Integration Code | CM1: Link Conn | CN1: Crs Attr | CO1: Comments | CP1: Major Restr | CQ1: Scacrse College | CR1: Enrolled | CS1: Waitlist Capacity | CT1: Primary Ind | CU1: Override | CV1: 1st Date Reg Opens | CW1: Last Date Reg Opens | CX1: OL Range From Date | CY1: OL Range To Date | CZ1: OL Numb Units | DA1: OL Duration Code | DB1: Grade Mode | DC1: Gradable Ind | DD1: Tuit Waiver | DE1: Course Override {Meet Override} | DF1: Lvl Res Ind | DG1: Cmp Res Ind | DH1: Rate Code | DI1: Cohort Code | DJ1: St Attr Code | DK1: Coll SC | DL1: DegC SC | DM1: Prog SC | DN1: FOS Type | DO1: Special Approval {Special Apvl} | DP1: Term Code | DQ1: Camp SC
BK2: =IF($BJ2="","",IFERROR(INDEX(InstructorMap!$B:$B, MATCH($BJ2, InstructorMap!$A:$A, 0)),"")) | BL2: =IF($BJ2="","",IFERROR(INDEX(InstructorMap!$C:$C, MATCH($BJ2, InstructorMap!$A:$A, 0)),""))
BK3: =IF($BJ3="","",IFERROR(INDEX(InstructorMap!$B:$B, MATCH($BJ3, InstructorMap!$A:$A, 0)),"")) | BL3: =IF($BJ3="","",IFERROR(INDEX(InstructorMap!$C:$C, MATCH($BJ3, InstructorMap!$A:$A, 0)),""))
BK4: =IF($BJ4="","",IFERROR(INDEX(InstructorMap!$B:$B, MATCH($BJ4, InstructorMap!$A:$A, 0)),"")) | BL4: =IF($BJ4="","",IFERROR(INDEX(InstructorMap!$C:$C, MATCH($BJ4, InstructorMap!$A:$A, 0)),""))
BK5: =IF($BJ5="","",IFERROR(INDEX(InstructorMap!$B:$B, MATCH($BJ5, InstructorMap!$A:$A, 0)),"")) | BL5: =IF($BJ5="","",IFERROR(INDEX(InstructorMap!$C:$C, MATCH($BJ5, InstructorMap!$A:$A, 0)),""))
BK6: =IF($BJ6="","",IFERROR(INDEX(InstructorMap!$B:$B, MATCH($BJ6, InstructorMap!$A:$A, 0)),"")) | BL6: =IF($BJ6="","",IFERROR(INDEX(InstructorMap!$C:$C, MATCH($BJ6, InstructorMap!$A:$A, 0)),""))
BK7: =IF($BJ7="","",IFERROR(INDEX(InstructorMap!$B:$B, MATCH($BJ7, InstructorMap!$A:$A, 0)),"")) | BL7: =IF($BJ7="","",IFERROR(INDEX(InstructorMap!$C:$C, MATCH($BJ7, InstructorMap!$A:$A, 0)),""))
BK8: =IF($BJ8="","",IFERROR(INDEX(InstructorMap!$B:$B, MATCH($BJ8, InstructorMap!$A:$A, 0)),"")) | BL8: =IF($BJ8="","",IFERROR(INDEX(InstructorMap!$C:$C, MATCH($BJ8, InstructorMap!$A:$A, 0)),""))
BK9: =IF($BJ9="","",IFERROR(INDEX(InstructorMap!$B:$B, MATCH($BJ9, InstructorMap!$A:$A, 0)),"")) | BL9: =IF($BJ9="","",IFERROR(INDEX(InstructorMap!$C:$C, MATCH($BJ9, InstructorMap!$A:$A, 0)),""))
BK10: =IF($BJ10="","",IFERROR(INDEX(InstructorMap!$B:$B, MATCH($BJ10, InstructorMap!$A:$A, 0)),"")) | BL10: =IF($BJ10="","",IFERROR(INDEX(InstructorMap!$C:$C, MATCH($BJ10, InstructorMap!$A:$A, 0)),""))
BK11: =IF($BJ11="","",IFERROR(INDEX(InstructorMap!$B:$B, MATCH($BJ11, InstructorMap!$A:$A, 0)),"")) | BL11: =IF($BJ11="","",IFERROR(INDEX(InstructorMap!$C:$C, MATCH($BJ11, InstructorMap!$A:$A, 0)),""))
BK12: =IF($BJ12="","",IFERROR(INDEX(InstructorMap!$B:$B, MATCH($BJ12, InstructorMap!$A:$A, 0)),"")) | BL12: =IF($BJ12="","",IFERROR(INDEX(InstructorMap!$C:$C, MATCH($BJ12, InstructorMap!$A:$A, 0)),""))
BK13: =IF($BJ13="","",IFERROR(INDEX(InstructorMap!$B:$B, MATCH($BJ13, InstructorMap!$A:$A, 0)),"")) | BL13: =IF($BJ13="","",IFERROR(INDEX(InstructorMap!$C:$C, MATCH($BJ13, InstructorMap!$A:$A, 0)),""))
... BK40: =IF($BJ40="","",IFERROR(INDEX(InstructorMap!$B:$B, MATCH($BJ40, InstructorMap!$A:$A, 0)),"")) | BL40: =IF($BJ40="","",IFERROR(INDEX(InstructorMap!$C:$C, MATCH($BJ40, InstructorMap!$A:$A, 0)),""))

Sheet MA_Religion
A1: Don {not in Banner} | B1: Mismatching {not in Banner} | C1: Dept/Prog Admin {not in Banner} | D1: Mona {not in Banner} | E1: Karen {not in Banner} | F1: DONE {not in Banner} | G1: Notes {not in Banner} | H1: CRN sorted {not in Banner} | I1: CRN | J1: Attribute {not in Banner} | K1: Subject | L1: Course Number {Crse Num} | M1: Course Section {Seq Crse Num} | N1: Program {not in Banner} | O1: Catalog Title | P1: Section Title | Q1: Crosslist Details {not in Banner} | R1: X Lst | S1: Campus {Ssasect Campus} | T1: Campus Restriction {Camp Restr CC} | U1: Schedule Type {not in Banner} | V1: Instruction Method {Inst Method} | W1: Level {Level SC} | X1: Part-Of-Term | Y1: Credit Catalog {Cat Crs} | Z1: Credits {Sect Crs} | AA1: Faculty Load / Contract Credits {not in Banner} | AB1: Enrollment Cap {Max Enrl} | AC1: Meeting Type | AD1: Semester Start Date {Soaterm Start Date} | AE1: Pre-work Start Date {not in Banner} | AF1: Pre-work End Date {not in Banner} | AG1: pre-work # of weeks {not in Banner} | AH1: pre-work hours/week {not in Banner} | AI1: pre-work hours/period {not in Banner} | AJ1: Intensive Period Start Date {Meet Start Date} | AK1: Intensive Period End Date {Meet End Date} | AL1: intensive # of weeks {not in Banner} | AM1: intensive hours/week {not in Banner} | AN1: intensive hours/period {not in Banner} | AO1: Post-work Start Date {not in Banner} | AP1: Post-work End Date {not in Banner} | AQ1: post-work # of weeks {not in Banner} | AR1: post-work hours/week {not in Banner} | AS1: post-work hours/period {not in Banner} | AT1: sum of weeks (for check) {not in Banner} | AU1: total contract hours {not in Banner} | AV1: Semester End Date {Soaterm End Date} | AW1: Course Beginning Time {Meet Beg Time} | AX1: Course Ending Time {Meet End Time} | AY1: SUN | AZ1: MON | BA1: TUE | BB1: WED | BC1: THU | BD1: FRI | BE1: SAT | BF1: Weeks | BG1: Fiscal Year {not in Banner} | BH1: Semester {not in Banner} | BI1: Room {Meet Room} | BJ1: Building {Meet Bldg} | BK1: Instructor Name {Instr Name} | BL1: Instructor Email {Instr Email} | BM1: Instructor ID {Instr ID} | BN1: Remote Employee {not in Banner} | BO1: % Responsibility | BP1: load/contract {not in Banner} | BQ1: Reason for Contract {not in Banner} | BR1: costs per credit {not in Banner} | BS1: total costs {not in Banner} | BT1: dept budget {not in Banner} | BU1: account to be charged {not in Banner} | BV1: SEM Department {Scacrse Dept} | BW1: dean email | BX1: VP finance email | BY1: HR email | BZ1: Fee Amount {Fees Amt} | CA1: Fee Code {Detl Code} | CB1: Fee Type | CC1: Fee Level | CD1: Fee Ind | CE1: Fee Term | CF1: Activity Date | CG1: Status | CH1: Bill Hrs | CI1: Sect Sch Type | CJ1: Prerequisites {Preq Areas} | CK1: Link Ind | CL1: Integration Code | CM1: Link Conn | CN1: Crs Attr | CO1: Comments | CP1: Major Restr | CQ1: Scacrse College | CR1: Enrolled | CS1: Waitlist Capacity | CT1: Primary Ind | CU1: Override | CV1: 1st Date Reg Opens | CW1: Last Date Reg Opens | CX1: OL Range From Date | CY1: OL Range To Date | CZ1: OL Numb Units | DA1: OL Duration Code | DB1: Grade Mode | DC1: Gradable Ind | DD1: Tuit Waiver | DE1: Course Override {Meet Override} | DF1: Lvl Res Ind | DG1: Cmp Res Ind | DH1: Rate Code | DI1: Cohort Code | DJ1: St Attr Code | DK1: Coll SC | DL1: DegC SC | DM1: Prog SC | DN1: FOS Type | DO1: Special Approval {Special Apvl} | DP1: Term Code | DQ1: Camp SC
BK2: =IF($BJ2="","",IFERROR(INDEX(InstructorMap!$B:$B, MATCH($BJ2, InstructorMap!$A:$A, 0)),"")) | BL2: =IF($BJ2="","",IFERROR(INDEX(InstructorMap!$C:$C, MATCH($BJ2, InstructorMap!$A:$A, 0)),""))
BK3: =IF($BJ3="","",IFERROR(INDEX(InstructorMap!$B:$B, MATCH($BJ3, InstructorMap!$A:$A, 0)),"")) | BL3: =IF($BJ3="","",IFERROR(INDEX(InstructorMap!$C:$C, MATCH($BJ3, InstructorMap!$A:$A, 0)),""))
BK4: =IF($BJ4="","",IFERROR(INDEX(InstructorMap!$B:$B, MATCH($BJ4, InstructorMap!$A:$A, 0)),"")) | BL4: =IF($BJ4="","",IFERROR(INDEX(InstructorMap!$C:$C, MATCH($BJ4, InstructorMap!$A:$A, 0)),""))
BK5: =IF($BJ5="","",IFERROR(INDEX(InstructorMap!$B:$B, MATCH($BJ5, InstructorMap!$A:$A, 0)),"")) | BL5: =IF($BJ5="","",IFERROR(INDEX(InstructorMap!$C:$C, MATCH($BJ5, InstructorMap!$A:$A, 0)),""))
BK6: =IF($BJ6="","",IFERROR(INDEX(InstructorMap!$B:$B, MATCH($BJ6, InstructorMap!$A:$A, 0)),"")) | BL6: =IF($BJ6="","",IFERROR(INDEX(InstructorMap!$C:$C, MATCH($BJ6, InstructorMap!$A:$A, 0)),""))
BK7: =IF($BJ7="","",IFERROR(INDEX(InstructorMap!$B:$B, MATCH($BJ7, InstructorMap!$A:$A, 0)),"")) | BL7: =IF($BJ7="","",IFERROR(INDEX(InstructorMap!$C:$C, MATCH($BJ7, InstructorMap!$A:$A, 0)),""))
BK8: =IF($BJ8="","",IFERROR(INDEX(InstructorMap!$B:$B, MATCH($BJ8, InstructorMap!$A:$A, 0)),"")) | BL8: =IF($BJ8="","",IFERROR(INDEX(InstructorMap!$C:$C, MATCH($BJ8, InstructorMap!$A:$A, 0)),""))
BK9: =IF($BJ9="","",IFERROR(INDEX(InstructorMap!$B:$B, MATCH($BJ9, InstructorMap!$A:$A, 0)),"")) | BL9: =IF($BJ9="","",IFERROR(INDEX(InstructorMap!$C:$C, MATCH($BJ9, InstructorMap!$A:$A, 0)),""))
BK10: =IF($BJ10="","",IFERROR(INDEX(InstructorMap!$B:$B, MATCH($BJ10, InstructorMap!$A:$A, 0)),"")) | BL10: =IF($BJ10="","",IFERROR(INDEX(InstructorMap!$C:$C, MATCH($BJ10, InstructorMap!$A:$A, 0)),""))
BK11: =IF($BJ11="","",IFERROR(INDEX(InstructorMap!$B:$B, MATCH($BJ11, InstructorMap!$A:$A, 0)),"")) | BL11: =IF($BJ11="","",IFERROR(INDEX(InstructorMap!$C:$C, MATCH($BJ11, InstructorMap!$A:$A, 0)),""))
BK12: =IF($BJ12="","",IFERROR(INDEX(InstructorMap!$B:$B, MATCH($BJ12, InstructorMap!$A:$A, 0)),"")) | BL12: =IF($BJ12="","",IFERROR(INDEX(InstructorMap!$C:$C, MATCH($BJ12, InstructorMap!$A:$A, 0)),""))
BK13: =IF($BJ13="","",IFERROR(INDEX(InstructorMap!$B:$B, MATCH($BJ13, InstructorMap!$A:$A, 0)),"")) | BL13: =IF($BJ13="","",IFERROR(INDEX(InstructorMap!$C:$C, MATCH($BJ13, InstructorMap!$A:$A, 0)),""))
... BK40: =IF($BJ40="","",IFERROR(INDEX(InstructorMap!$B:$B, MATCH($BJ40, InstructorMap!$A:$A, 0)),"")) | BL40: =IF($BJ40="","",IFERROR(INDEX(InstructorMap!$C:$C, MATCH($BJ40, InstructorMap!$A:$A, 0)),""))

Sheet DMIN
A1: Don {not in Banner} | B1: Mismatching {not in Banner} | C1: Dept/Prog Admin {not in Banner} | D1: Mona {not in Banner} | E1: Karen {not in Banner} | F1: DONE {not in Banner} | G1: Notes {not in Banner} | H1: CRN sorted {not in Banner} | I1: CRN | J1: Attribute {not in Banner} | K1: Subject | L1: Course Number {Crse Num} | M1: Course Section {Seq Crse Num} | N1: Program {not in Banner} | O1: Catalog Title | P1: Section Title | Q1: Crosslist Details {not in Banner} | R1: X Lst | S1: Campus {Ssasect Campus} | T1: Campus Restriction {Camp Restr CC} | U1: Schedule Type {not in Banner} | V1: Instruction Method {Inst Method} | W1: Level {Level SC} | X1: Part-Of-Term | Y1: Credit Catalog {Cat Crs} | Z1: Credits {Sect Crs} | AA1: Faculty Load / Contract Credits {not in Banner} | AB1: Enrollment Cap {Max Enrl} | AC1: Meeting Type | AD1: Semester Start Date {Soaterm Start Date} | AE1: Pre-work Start Date {not in Banner} | AF1: Pre-work End Date {not in Banner} | AG1: pre-work # of weeks {not in Banner} | AH1: pre-work hours/week {not in Banner} | AI1: pre-work hours/period {not in Banner} | AJ1: Intensive Period Start Date {Meet Start Date} | AK1: Intensive Period End Date {Meet End Date} | AL1: intensive # of weeks {not in Banner} | AM1: intensive hours/week {not in Banner} | AN1: intensive hours/period {not in Banner} | AO1: Post-work Start Date {not in Banner} | AP1: Post-work End Date {not in Banner} | AQ1: post-work # of weeks {not in Banner} | AR1: post-work hours/week {not in Banner} | AS1: post-work hours/period {not in Banner} | AT1: sum of weeks (for check) {not in Banner} | AU1: total contract hours {not in Banner} | AV1: Semester End Date {Soaterm End Date} | AW1: Course Beginning Time {Meet Beg Time} | AX1: Course Ending Time {Meet End Time} | AY1: SUN | AZ1: MON | BA1: TUE | BB1: WED | BC1: THU | BD1: FRI | BE1: SAT | BF1: Weeks | BG1: Fiscal Year {not in Banner} | BH1: Semester {not in Banner} | BI1: Room {Meet Room} | BJ1: Building {Meet Bldg} | BK1: Instructor Name {Instr Name} | BL1: Instructor Email {Instr Email} | BM1: Instructor ID {Instr ID} | BN1: Remote Employee {not in Banner} | BO1: % Responsibility | BP1: load/contract {not in Banner} | BQ1: Reason for Contract {not in Banner} | BR1: costs per credit {not in Banner} | BS1: total costs {not in Banner} | BT1: dept budget {not in Banner} | BU1: account to be charged {not in Banner} | BV1: SEM Department {Scacrse Dept} | BW1: dean email | BX1: VP finance email | BY1: HR email | BZ1: Fee Amount {Fees Amt} | CA1: Fee Code {Detl Code} | CB1: Fee Type | CC1: Fee Level | CD1: Fee Ind | CE1: Fee Term | CF1: Activity Date | CG1: Status | CH1: Bill Hrs | CI1: Sect Sch Type | CJ1: Prerequisites {Preq Areas} | CK1: Link Ind | CL1: Integration Code | CM1: Link Conn | CN1: Crs Attr | CO1: Comments | CP1: Major Restr | CQ1: Scacrse College | CR1: Enrolled | CS1: Waitlist Capacity | CT1: Primary Ind | CU1: Override | CV1: 1st Date Reg Opens | CW1: Last Date Reg Opens | CX1: OL Range From Date | CY1: OL Range To Date | CZ1: OL Numb Units | DA1: OL Duration Code | DB1: Grade Mode | DC1: Gradable Ind | DD1: Tuit Waiver | DE1: Course Override {Meet Override} | DF1: Lvl Res Ind | DG1: Cmp Res Ind | DH1: Rate Code | DI1: Cohort Code | DJ1: St Attr Code | DK1: Coll SC | DL1: DegC SC | DM1: Prog SC | DN1: FOS Type | DO1: Special Approval {Special Apvl} | DP1: Term Code | DQ1: Camp SC

Sheet InstructorMap
A1: Instructor Name {Instr Name} | B1: Instructor Email {Instr Email} | C1: Instructor ID {Instr ID}
A2: Abar, Emmanuel M. | B2: abar@andrews.edu | C2: 000114991
A3: Antic, Radisa | B3: radisa@andrews.edu | C3: 000042516
A4: Augsburger, Daniel E. | B4: augsburg@andrews.edu | C4: 000003539
A5: Barbosa, Rodrigo d. | B5: degaliza@andrews.edu | C5: 000141959
A6: Barna, Jan | B6: barna@andrews.edu | C6: 000107673
A7: Burton, Kevin M. | B7: burtonk@andrews.edu | C7: 000148286
A8: Chow, Christie Chui-Shan | B8: christiechu@andrews.edu | C8: 000232177
A9: Damsteegt, P Gerard | B9: damsteeg@andrews.edu | C9: 000009168
A10: Figueroa, Victor F. | B10: figuerov@andrews.edu | C10: 000055527
A11: Gameti, Yvonne Y. | B11: gameti@andrews.edu | C11: 000239625
A12: Garcia Zarate, Heber E. | B12: heber@andrews.edu | C12: 000147941
... A75: Reeve, Teresa L. | B75: tlreeve@andrews.edu | C75: 000050236
A76: Richards, W Larry | C76: 000008252
A77: Stefanovic, Ranko | B77: ranko@andrews.edu | C77: 000057767
A78: Vine, Cedric E. | B78: cvine@andrews.edu | C78: 000093509
A79: Baez Garcia, Enrique | B79: baezgarc@andrews.edu | C79: 000118530
A80: Baker, Leslie S. | B80: lsbakerjr@andrews.edu | C80: 000067622
A81: Bates, Robert D. | B81: bates@andrews.edu | C81: 000095796
A82: Beaulieu, Stephane A. | B82: beaulies@andrews.edu | C82: 000132272
A83: Bediako, Daniel K. | C83: 000246964
A84: Breja, Alexandru | B84: brejaal@andrews.edu | C84: 000068116
A85: Broy, Trisha E. | B85: trisha@andrews.edu | C85: 000088405
A86: Doukhan, Jacques B. | B86: doukhanj@andrews.edu | C86: 000027289
A87: Emswiler, Elizabeth | B87: emswiler@andrews.edu | C87: 000205980
A88: Gane, Constance E. | B88: cgane@andrews.edu | C88: 000074605
A89: Glanz, Oliver | B89: glanz@andrews.edu | C89: 000162826
A90: Gordan, Daniel M. | B90: danielgordan@andrews.edu | C90: 000155573
A91: Gregor, Paul Z. | B91: pgregor@andrews.edu | C91: 000052867
A92: Groda, Johnny | B92: johnny@andrews.edu | C92: 000102157
A93: Hudon, Jeffrey P. | B93: hudon@andrews.edu | C93: 000133678
A94: Ionescu, Laurentiu Gabriel | B94: laurentiuga@andrews.edu | C94: 000190055
A95: Jankovic, Slavisa | B95: jankovic@andrews.edu | C95: 000138176
... A98: Morrow, Laura K. | B98: morrowl@andrews.edu | C98: 000112615
A99: Nam, Daegeuk | C99: 000032749
A100: Ngo, Kim Chai | B100: kimchai@andrews.edu | C100: 000212413
A101: Olariu, Daniel | B101: olariu@andrews.edu | C101: 000163538
A102: Prestes Neto, Flavio | B102: neto@andrews.edu | C102: 000136415
A103: Rivas Santini, Abelardo J. | B103: abelardo@andrews.edu | C103: 000133197
A104: Rojas, Ronald | B104: rojasr@andrews.edu | C104: 000124643
...

Sheet DropDownMenu
A1: Notes {not in Banner} | B1: CRN sorted {not in Banner} | C1: CRN | D1: Subject | E1: Course Number {Crse Num} | F1: Course Section {Seq Crse Num} | G1: Program {not in Banner} | H1: Catalog Title | I1: Section Title | J1: X Lst | K1: Campus {Ssasect Campus} | L1: Campus Restriction {Camp Restr CC} | M1: Schedule Type {not in Banner} | N1: Instruction Method {Inst Method} | O1: Level {Level SC} | P1: Part-Of-Term | Q1: Credit Catalog {Cat Crs} | R1: Credits {Sect Crs} | S1: Faculty Load / Contract Credits {not in Banner} | T1: Enrollment Cap {Max Enrl} | U1: Meeting Type | V1: Semester Start Date {Soaterm Start Date} | W1: pre-work # of weeks {not in Banner} | X1: pre-work hours/week {not in Banner} | Y1: pre-work hours/period {not in Banner} | Z1: Intensive Period Start Date {Meet Start Date} | AA1: Intensive Period End Date {Meet End Date} | AB1: intensive # of weeks {not in Banner} | AC1: intensive hours/week {not in Banner} | AD1: intensive hours/period {not in Banner} | AE1: post-work # of weeks {not in Banner} | AF1: post-work hours/week {not in Banner} | AG1: post-work hours/period {not in Banner} | AH1: sum of weeks (for check) {not in Banner} | AI1: total contract hours {not in Banner} | AJ1: Semester End Date {Soaterm End Date} | AK1: Course Beginning Time {Meet Beg Time} | AL1: Course Ending Time {Meet End Time} | AM1: SUN | AN1: MON | AO1: TUE | AP1: WED | AQ1: THU | AR1: Weeks | AS1: Fiscal Year {not in Banner} | AT1: Semester {not in Banner} | AU1: Room {Meet Room} | AV1: Building {Meet Bldg} | AW1: Instructor Name {Instr Name} | AX1: Instructor Email {Instr Email} | AY1: Instructor ID {Instr ID} | AZ1: Remote Employee {not in Banner} | BA1: % Responsibility | BB1: load/contract {not in Banner} | BC1: Reason for Contract {not in Banner} | BD1: costs per credit {not in Banner} | BE1: dept budget {not in Banner} | BF1: account to be charged {not in Banner} | BG1: SEM Department {Scacrse Dept} | BH1: dean email | BI1: VP finance email | BJ1: HR email | BK1: Fee Amount {Fees Amt} | BL1: Fee Code {Detl Code} | BM1: Fee Type | BN1: Fee Level | BO1: Fee Term | BP1: Activity Date | BQ1: Status | BR1: Bill Hrs | BS1: Sect Sch Type | BT1: Prerequisites {Preq Areas} | BU1: Link Ind | BV1: Integration Code | BW1: Crs Attr | BX1: Scacrse College | BY1: Enrolled | BZ1: Waitlist Capacity | CA1: Primary Ind | CB1: Override | CC1: 1st Date Reg Opens | CD1: Last Date Reg Opens | CE1: OL Range From Date | CF1: OL Range To Date | CG1: OL Numb Units | CH1: OL Duration Code | CI1: Grade Mode | CJ1: Gradable Ind | CK1: Tuit Waiver | CL1: Course Override {Meet Override} | CM1: Coll SC | CN1: DegC SC | CO1: FOS Type | CP1: Special Approval {Special Apvl} | CQ1: Camp SC
A2: New Class | B2: 1043-01 | C2: 1043 | D2: ANEA | E2: 500 | F2: 0 | G2: MDIV | H2: A History of Preaching | I2: Idp Stdy:Mssn Cltrl&RlgsCntxt | J2: 009 | K2: 0 | L2: 0 | M2: Blended Learning | N2: ASYNC | O2: DO | P2: 1 | Q2: 0 | R2: 0 | S2: 1 | T2: 0 | U2: CLAS | V2: 04-MAY-25 | W2: 1 | X2: 1 | Y2: 1 | Z2: 01-JUN-25 | AA2: 01-AUG-25 | AB2: 1 | AC2: 40 | AD2: 1 | AE2: 1 | AF2: 1 | AG2: 1 | AH2: 1 | AI2: 109 | AJ2: 01-AUG-25 | AK2: 0800 | AL2: 1020 | AM2: S | AN2: M | AO2: T | AP2: W | AQ2: R | AR2: 12 | AS2: 2015 | AT2: Spring | AU2: 118 | AV2: Bell Hall [BH] | AW2: Abar, Emmanuel M. | AX2: abar@andrews.edu | AY2: 000114991 | AZ2: yes | BA2: 100 | BB2: load | BC2: Teacher loads are full | BD2: 1000 | BE2: yes | BF2: CHIS: 11-1100-9120-70 | BG2: CHIS | BH2: moskala@andrews.edu | BI2: valencia@andrews.edu | BJ2: employment@andrews.edu | BK2: -633 | BL2: EAB4 | BM2: BILL | BN2: DO | BO2: 202531 | BP2: 01-JUL-25 | BQ2: A | BR2: 0 | BS2: A | BT2: P-ANEA830 | BU2: A1 | BV2: MOODL | BW2: ADVN | BX2: 70 | BY2: 0 | BZ2: 0 | CA2: Y | CB2: O | CC2: 03-FEB-25 | CD2: 01-AUG-25 | CE2: 03-FEB-25 | CF2: 01-AUG-25 | CG2: 1 | CH2: DAYS | CI2: X | CJ2: Y | CK2: N | CL2: O | CM2: 70 | CN2: MSCID | CO2: MAJOR | CP2: I | CQ2: 0
A3: Delete Class | B3: 1044-01 | C3: 1044 | D3: CHIS | E3: 501 | F3: 001 | G3: MDIV-MA | H3: Adv Arch Field Work | I3: Adv Holistic Small Groups | J3: 028 | K3: 7 | L3: 7 | M3: Equivalency Assessment | N3: EXAM | O3: FP | P3: 2 | Q3: 0,2 | R3: 0,2 | S3: 2 | T3: 1 | U3: POST | V3: 07-JUL-25 | Z3: 02-JUL-25 | AA3: 01-JUL-25 | AJ3: 03-JUL-25 | AK3: 0830 | AL3: 1120 | AR3: 3 | AS3: 2016 | AT3: Summer | AU3: 120 | AV3: Buller Hall [BUL] | AW3: Antic, Radisa | AX3: radisa@andrews.edu | AY3: 000042516 | AZ3: no | BA3: 34 | BB3: contract | BC3: Teacher overload | BD3: 1050 | BE3: no | BF3: PATH: 11-1150-9120-70 | BG3: DSLE | BK3: -922 | BL3: EAR2 | BM3: FLAT | BN3: FP | BP3: 01-JUN-25 | BQ3: I | BR3: 1 | BS3: BL | BT3: P-CHIS624 | BU3: T1 | BW3: ADVN,THEO | BY3: 1 | CD3: 11-MAY-25 | CE3: 12-MAY-25 | CF3: 12-MAY-25 | CG3: 160 | CP3: IT | CQ3: 7
A4: Title | B4: 1045-01 | C4: 1045 | D4: DSLE | E4: 503 | F4: 002 | G4: MDIV-FL | H4: Adv Archaeology of NT Period | I4: Adv Scholarly & Prof Dev | J4: 044 | K4: 9OM | L4: 9 | M4: Independent | N4: INTEN | O4: MA | P4: 3 | Q4: 0,3 | R4: 0,3 | S4: 3 | T4: 10 | U4: PRE | V4: 09-JUN-25 | Z4: 02-JUN-25 | AA4: 01-JUN-25 | AJ4: 04-JUL-25 | AK4: 1330 | AL4: 1200 | AR4: 4 | AS4: 2017 | AT4: Fall | AU4: 153 | AV4: Chan Shun Hall [CSH] | AW4: Augsburger, Daniel E. | AX4: augsburg@andrews.edu | AY4: 000003539 | BA4: 50 | BB4: load x-list | BC4: Subject-matter expert | BF4: MSSN: 11-1200-9120-70 | BG4: GSEM | BK4: 1267 | BL4: ES12 | BN4: MA | BP4: 01-MAY-25 | BR4: 2 | BS4: EA | BT4: P-CHIS674 | BW4: ARHA,CLAS,JEWS,NTBG | BY4: 10 | CD4: 15-JUN-25 | CE4: 16-JUN-25 | CF4: 16-JUN-25 | CG4: 180 | CP4: RC
A5: Add X-List | B5: 1047-01 | C5: 1047 | D5: GSEM | E5: 504 | F5: 003 | G5: MAPM-HISP | H5: Adv Archaeology of Palestine | I5: Adv St Pauline Wrtg: Galatians | J5: 061 | K5: ZOM | L5: 9OM | M5: Int, Online | N5: SYNC | O5: FP/MA | P5: Q | Q5: 0-3 | R5: 0-3 | S5: 4 | T5: 15 | U5: TOUR | V5: 12-MAY-25 | Z5: 03-FEB-25 | AA5: 01-NOV-25 | AJ5: 06-JUN-25 | AK5: 1400 | AL5: 1220 | AR5: 8 | AS5: 2018 | AU5: N108 | AV5: Griggs Hall A [GHA] | AW5: Barbosa, Rodrigo d. | AX5: degaliza@andrews.edu | AY5: 000141959 | BB5: contract x-list | BF5: _DIS: 11-1200-9120-70-120011 | BG5: NTST | BK5: 130 | BL5: ES30 | BP5: 02-JUL-25 | BR5: 3 | BS5: I | BT5: P-NTST658 | BW5: CH1 | BY5: 11 | CD5: 18-MAY-25 | CE5: 19-MAY-25 | CF5: 19-MAY-25 | CG5: 290 | CP5: T
A6: Delete X-List | B6: 1050-01 | C6: 1050 | D6: MSSN | E6: 505 | F6: 004 | G6: MAPM-ENGL | H6: Adv Clin Pastoral Eductn | I6: Adv St Pauline Wrtg: Romans | J6: 086 | K6: ·­ | L6: Z | M6: Lecture | N6: TOUR | P6: W | Q6: 1 | R6: 1 | S6: 5 | T6: 18 | U6: WEB | V6: 14-JUL-25 | Z6: 03-JUL-25 | AA6: 02-DEC-25 | AJ6: 18-MAY-25 | AK6: 1430 | AL6: 1400 | AS6: 2019 | AU6: N110 | AV6: Griggs Hall B [GHB] | AW6: Barna, Jan | AX6: barna@andrews.edu | AY6: 000107673 | BB6: continuous | BF6: NTST: 11-1250-9120-70 | BG6: OTST | BK6: 1471 | BL6: ESCF | BP6: 02-JUN-25 | BR6: 4 | BS6: M | BT6: P-NTST668 | BW6: CH1,REFM | BY6: 12 | CD6: 21-JUN-25 | CE6: 22-JUN-25 | CF6: 26-JUN-25 | CG6: 90
A7: Sp. Approval | B7: 1050-02 | C7: 1120 | D7: NTST | E7: 506 | F7: 006 | G7: MAR-NAD | H7: Adv Fostering Spiritual Growth | I7: Adv St:Narrative Curriculum | J7: 087 | L7: ZOM | M7: Lecture/Lab | N7: WEB | Q7: 1-10 | R7: 1-10 | S7: 6 | T7: 20 | V7: 17-JUN-25 | Z7: 04-JUL-25 | AA7: 02-JUL-25 | AJ7: 24-JUN-25 | AL7: 1520 | AS7: 2020 | AU7: N150 | AV7: Horn Museum [HORN] | AW7: Burton, Kevin M. | AX7: burtonk@andrews.edu | AY7: 000148286 | BF7: OTST: 11-1300-9120-70 | BG7: PATH | BK7: 160 | BL7: ESM1 | BP7: 03-JUL-25 | BR7: 5 | BS7: N | BT7: P-OTST552 | BW7: CHAP,HITH,REFM | BY7: 13 | CD7: 25-MAY-25 | CE7: 26-MAY-25 | CF7: 26-MAY-25
A8: Campus 7 Restr. | B8: 1120-01 | C8: 1123 | D8: OTST | E8: 507 | F8: 031 | G8: MAR-INT | H8: Adv Greek Grammar & Syntax | I8: Adv St:Reachng the Seculr Mind | J8: 088 | M8: Music Organization | N8: INPERSON | Q8: 1-12 | R8: 1-12 | S8: 7 | T8: 25 | Z8: 04-MAY-25 | AA8: 03-DEC-25 | AJ8: 25-JUN-25 | AL8: 1620 | AS8: 2021 | AU8: N235 | AV8: James White Library [JWL] | AW8: Chow, Christie Chui-Shan | AX8: christiechu@andrews.edu | AY8: 000232177 | BF8: DSLE: 11-1320-9120-70 | BG8: THCP | BK8: 45 | BL8: ESM3 | BP8: 03-JUN-25 | BS8: P | BT8: P-OTST664 | BW8: CHAP,PACC,PACO | BY8: 14 | CD8: 26-JUN-25 | CE8: 27-JUN-25 | CF8: 27-JUN-25
A9: Remove C7 Restr. | B9: 1123-01 | C9: 1124 | D9: PATH | E9: 508 | F9: 038 | G9: MAYYAM | H9: Adv Holistic Small Groups | I9: Adv Stds Pauline Wrtg:1Thessal | J9: 089 | M9: Practicum | N9: EGW Cert | Q9: 1-13 | R9: 1-13 | S9: 8 | T9: 30 | Z9: 05-JUL-25 | AA9: 03-JUL-25 | AJ9: 31-JUL-25 | AL9: 1700 | AS9: 2022 | AU9: N310 | AV9: Johnson Gym [JGYM] | AW9: Damsteegt, P Gerard | AX9: damsteeg@andrews.edu | AY9: 000009168 | BF9: THST: 11-1350-9120-70 | BG9: WMIS | BK9: 929 | BL9: ESM4 | BP9: 03-OCT-25 | BS9: W | BT9: P-OTST940 | BW9: CHGE,CHPL,EVAN | BY9: 15
A10: Progr. Restr. | B10: 1123-02 | C10: 1148 | D10: THST | E10: 509 | F10: 040 | G10: TOUR | H10: Adv Ldshp Competencies | I10: Adv Stds Pauline Wrtg:1THS | J10: 093 | M10: Seminar | N10: MAPM_HISP | Q10: 1-3 | R10: 1-3 | T10: 35 | Z10: 05-JUN-25 | AA10: 04-JUL-25 | AL10: 1720 | AS10: 2023 | AU10: N335 | AV10: Nethery Hall [NH] | AW10: Figueroa, Victor F. | AX10: figuerov@andrews.edu | AY10: 000055527 | BF10: DMIN: 11-1170-9120-70-1170* | BL10: ESTD | BP10: 04-AUG-25 | BW10: CHGE,EVAN | BY10: 16
A11: Credits | B11: 1123-03 | C11: 1149 | E11: 510 | F11: 041 | G11: DIS | H11: Adv Ministerial Development | I11: Adv Stds:ChrstnFormtn&Dscplshp | J11: 104 | M11: Workshop | N11: MAPM_ENGL | Q11: 1-4 | R11: 1-4 | T11: 36 | Z11: 06-JUN-25 | AA11: 04-JUN-25 | AL11: 1730 | AS11: 2024 | AU11: S120 | AV11: Pioneer Memorial Church [PMC] | AW11: Gameti, Yvonne Y. | AX11: gameti@andrews.edu | AY11: 000239625 | BF11: TOUR | BL11: ESTM | BP11: 04-JUN-25 | BW11: CHGE,HLEV,HLMN,PACC | BY11: 17
A12: Cap | B12: 1124-01 | C12: 1150 | E12: 511 | F12: 042 | G12: DMIN | H12: Adv Pastoral Counseling | I12: Adv Stds:Dssrttn Ltrtr Review | J12: 126 | M12: ·­ | N12: MAR_INT | Q12: 1-5 | R12: 1-5 | T12: 40 | Z12: 07-JUL-25 | AA12: 05-JUN-25 | AS12: 2025 | AU12: S215 | AV12: Seminary Building / Lake Union [SEM] | AW12: Garcia Zarate, Heber E. | AX12: heber@andrews.edu | AY12: 000147941 | BP12: 04-MAY-25 | BW12: CHLP | BY12: 18
A13: Day | B13: 1124-02 | C13: 1151 | E13: 514 | F13: 043 | G13: PHD/THD | H13: Adv Resrch, Methd&Thry in Arch | I13: Adv Stds:Ethical Lead&Org Intg | J13: 128 | N13: MAR_NAD | Q13: 1-6 | R13: 1-6 | T13: 45 | Z13: 07-JUN-25 | AA13: 06-JUN-25 | AS13: 2026 | AU13: S340 | AV13: Wellness Center [ACW] | AW13: Kaiser, Angelika | AX13: angelika@andrews.edu | AY13: 000143159 | BP13: 05-MAY-25 | BW13: EVAN | BY13: 19
A14: Time | B14: 1124-03 | C14: 1154 | E14: 515 | F14: 044 | G14: PHD-RelEd | H14: Adv Scholarly & Prof Dev | I14: Adv Stds:Spiritual Formation | J14: 129 | Q14: 1-8 | R14: 1-8 | T14: 5 | Z14: 08-JUN-25 | AA14: 07-JUN-25 | AS14: 2027 | AV14: Advent Health University [OCFLAH] | AW14: Kaiser, Denis | AX14: denis@andrews.edu | AY14: 000134382 | BP14: 06-AUG-25 | BW14: EXEG | BY14: 2
A15: Room | B15: 1148-01 | C15: 1155 | E15: 516 | F15: 045 | G15: POSTDOC | H15: Adv Studies General Epistles: | I15: Adv Stds:Teaching Rlgn College | J15: 132 | Q15: 1-9 | R15: 1-9 | T15: 999 | Z15: 09-JUN-25 | AA15: 07-NOV-25 | AS15: 2028 | AV15: Thailand (Asia-Pacific Int Univ AIU) [OCTHA] | AW15: Louw, Eric A. | AX15: louw@andrews.edu | AY15: 000160504 | BP15: 06-JUL-25 | BW15: FT | BY15: 20
A16: Location | B16: 1149-01 | C16: 1159 | E16: 517 | F16: 055 | G16: EGW-Cert | H16: Adv Studies Gospels: | I16: Adv Stds:Thlgcal Fndtns Chrstn | J16: 133 | Q16: 1.5,2 | R16: 1.5,2 | Z16: 10-AUG-25 | AA16: 08-JUN-25 | AS16: 2029 | AV16: Canadian Union (Burman University) [OCCABU] | AW16: Park, Jungkyu | AX16: jungkyu@andrews.edu | AY16: 000122429 | BP16: 06-JUN-25 | BW16: HITH | BY16: 22
A17: Instructor | B17: 1150-01 | C17: 1160 | E17: 520 | F17: 065 | H17: Adv Studies Pauline Wrtg: | I17: Adv Stdy Pauline Wrtg: Romans | J17: 136 | Q17: 2 | R17: 2 | Z17: 10-JUN-25 | AA17: 09-AUG-25 | AS17: 2030 | AV17: Centro Univ Adv de Sao Paulo [OCBRA1] | AW17: Rodrigues, Gerson C. | AX17: gersoncr@andrews.edu | AY17: 000093682 | BP17: 06-MAY-25 | BW17: HT | BY17: 23
A18: Add Fee | B18: 1151-01 | C18: 1161 | E18: 521 | F18: 069 | H18: Adv Studies: | I18: Adv Stud Pauline Wrtg: Romans | J18: 137 | Q18: 2,3 | R18: 2,3 | Z18: 12-MAY-25 | AA18: 09-JUN-25 | AS18: 2031 | AV18: Florida Conference of SDA [OCFLFC] | AW18: Rosario, Antonio M. | AX18: arosario@andrews.edu | AY18: 000074158 | BP18: 07-AUG-25 | BW18: LLIT | BY18: 24
