Workbook

Sheet CHIS
A1: Don {not in Banner} | B1: Mismatching {not in Banner} | C1: Dept/Prog Admin {not in Banner} | D1: Mona {not in Banner} | E1: Karen {not in Banner} | F1: DONE {not in Banner} | G1: Notes {not in Banner} | H1: CRN sorted {not in Banner} | I1: CRN | J1: Attribute {not in Banner} | K1: Subject | L1: Course Number {Crse Num} | M1: Course Section {Seq Crse Num} | N1: Program {not in Banner} | O1: Catalog Title | P1: Section Title | Q1: Crosslist Details {not in Banner} | R1: X Lst | S1: Campus {Ssasect Campus} | T1: Campus Restriction {Camp Restr CC} | U1: Schedule Type {not in Banner} | V1: Instruction Method {Inst Method} | W1: Level {Level SC} | X1: Part-Of-Term | Y1: Credit Catalog {Cat Crs} | Z1: Credits {Sect Crs} | AA1: Faculty Load / Contract Credits {not in Banner} | AB1: Enrollment Cap {Max Enrl} | AC1: Meeting Type | AD1: Semester Start Date {Soaterm Start Date} | AE1: Pre-work Start Date {not in Banner} | AF1: Pre-work End Date {not in Banner} | AG1: pre-work # of weeks {not in Banner} | AH1: pre-work hours/week {not in Banner} | AI1: pre-work hours/period {not in Banner} | AJ1: Intensive Period Start Date {Meet Start Date} | AK1: Intensive Period End Date {Meet End Date} | AL1: intensive # of weeks {not in Banner} | AM1: intensive hours/week {not in Banner} | AN1: intensive hours/period {not in Banner} | AO1: Post-work Start Date {not in Banner} | AP1: Post-work End Date {not in Banner} | AQ1: post-work # of weeks {not in Banner} | AR1: post-work hours/week {not in Banner} | AS1: post-work hours/period {not in Banner} | AT1: sum of weeks (for check) {not in Banner} | AU1: total contract hours {not in Banner} | AV1: Semester End Date {Soaterm End Date} | AW1: Course Beginning Time {Meet Beg Time} | AX1: Course Ending Time {Meet End Time} | AY1: SUN | AZ1: MON | BA1: TUE | BB1: WED | BC1: THU | BD1: FRI | BE1: SAT | BF1: Weeks | BG1: Fiscal Year {not in Banner} | BH1: Semester {not in Banner} | BI1: Room {Meet Room} | BJ1: Building {Meet Bldg} | BK1: Instructor Name {Instr Name} | BL1: Instructor Email {Instr Email} | BM1: Instructor ID {Instr ID} | BN1: Remote Employee {not in Banner} | BO1: % Responsibility | BP1: load/contract {not in Banner} | BQ1: Reason for Contract {not in Banner} | BR1: costs per credit {not in Banner} | BS1: total costs {not in Banner} | BT1: dept budget {not in Banner} | BU1: account to be charged {not in Banner} | BV1: SEM Department {Scacrse Dept} | BW1: dean email | BX1: VP finance email | BY1: HR email | BZ1: Fee Amount {Fees Amt} | CA1: Fee Code {Detl Code} | CB1: Fee Type | CC1: Fee Level | CD1: Fee Ind | CE1: Fee Term | CF1: Activity Date | CG1: Status | CH1: Bill Hrs | CI1: Sect Sch Type | CJ1: Prerequisites {Preq Areas} | CK1: Link Ind | CL1: Integration Code | CM1: Link Conn | CN1: Crs Attr | CO1: Comments | CP1: Major Restr | CQ1: Scacrse College | CR1: Enrolled | CS1: Waitlist Capacity | CT1: Primary Ind | CU1: Override | CV1: 1st Date Reg Opens | CW1: Last Date Reg Opens | CX1: OL Range From Date | CY1: OL Range To Date | CZ1: OL Numb Units | DA1: OL Duration Code | DB1: Grade Mode | DC1: Gradable Ind | DD1: Tuit Waiver | DE1: Course Override {Meet Override} | DF1: Lvl Res Ind | DG1: Cmp Res Ind | DH1: Rate Code | DI1: Cohort Code | DJ1: St Attr Code | DK1: Coll SC | DL1: DegC SC | DM1: Prog SC | DN1: FOS Type | DO1: Special Approval {Special Apvl} | DP1: Term Code | DQ1: Camp SC
O2: =IFERROR(INDEX('_courses_lookup'!$C:$C,MATCH(K2&L2,'_courses_lookup'!$E:$E,0)),"") | P2: =IFERROR(INDEX('_courses_lookup'!$D:$D,MATCH(K2&L2,'_courses_lookup'!$E:$E,0)),"") | AG2: =IF(AND(AE2<>"",AF2<>""),ROUNDUP((AF2-AE2)/7,0),"") | AI2: =IFERROR(IF(AG2*AH2=0,"",AG2*AH2),"") | AL2: =IF(AND(AJ2<>"",AK2<>""),ROUNDUP((AK2-AJ2)/7,0),"") | AN2: =IFERROR(IF(AL2*AM2=0,"",AL2*AM2),"") | AQ2: =IF(AND(AO2<>"",AP2<>""),ROUNDUP((AP2-AO2)/7,0),"") | AR2: =IFERROR(IF((AU2-(AI2+AN2))/AQ2=0,"",ROUNDUP((AU2-(AI2+AN2))/AQ2,0)),"") | AS2: =IFERROR(IF((AU2-(AI2+AN2))=0,"",(AU2-(AI2+AN2))),"") | AT2: =IF(AND(AG2="",AQ2=""),AL2,IF(SUM(AG2,AL2,AQ2)=0,"",SUM(AG2,AL2,AQ2))) | BG2: =IF(AD2="","",YEAR(AD2)+IF(MONTH(AD2)>=5,1,0)) | BH2: =IF(AD2="","",IF(AND(MONTH(AD2)=8,DAY(AD2)>=15),"Fall",IF(MONTH(AD2)>8,"Fall",IF(MONTH(AD2)=5,"Summer",IF(MONTH(AD2)=1,"Spring",""))))) | BL2: =IFERROR(INDEX('_names_lookup'!$C:$C,MATCH(BK2,'_names_lookup'!$A:$A,0)),"") | BM2: =IFERROR(INDEX('_names_lookup'!$B:$B,MATCH(BK2,'_names_lookup'!$A:$A,0)),"") | BS2: =IFERROR(IF(BR2*AA2=0,"",BR2*AA2),"")
O3: =IFERROR(INDEX('_courses_lookup'!$C:$C,MATCH(K3&L3,'_courses_lookup'!$E:$E,0)),"") | P3: =IFERROR(INDEX('_courses_lookup'!$D:$D,MATCH(K3&L3,'_courses_lookup'!$E:$E,0)),"") | AG3: =IF(AND(AE3<>"",AF3<>""),ROUNDUP((AF3-AE3)/7,0),"") | AI3: =IFERROR(IF(AG3*AH3=0,"",AG3*AH3),"") | AL3: =IF(AND(AJ3<>"",AK3<>""),ROUNDUP((AK3-AJ3)/7,0),"") | AN3: =IFERROR(IF(AL3*AM3=0,"",AL3*AM3),"") | AQ3: =IF(AND(AO3<>"",AP3<>""),ROUNDUP((AP3-AO3)/7,0),"") | AR3: =IFERROR(IF((AU3-(AI3+AN3))/AQ3=0,"",ROUNDUP((AU3-(AI3+AN3))/AQ3,0)),"") | AS3: =IFERROR(IF((AU3-(AI3+AN3))=0,"",(AU3-(AI3+AN3))),"") | AT3: =IF(AND(AG3="",AQ3=""),AL3,IF(SUM(AG3,AL3,AQ3)=0,"",SUM(AG3,AL3,AQ3))) | BG3: =IF(AD3="","",YEAR(AD3)+IF(MONTH(AD3)>=5,1,0)) | BH3: =IF(AD3="","",IF(AND(MONTH(AD3)=8,DAY(AD3)>=15),"Fall",IF(MONTH(AD3)>8,"Fall",IF(MONTH(AD3)=5,"Summer",IF(MONTH(AD3)=1,"Spring",""))))) | BL3: =IFERROR(INDEX('_names_lookup'!$C:$C,MATCH(BK3,'_names_lookup'!$A:$A,0)),"") | BM3: =IFERROR(INDEX('_names_lookup'!$B:$B,MATCH(BK3,'_names_lookup'!$A:$A,0)),"") | BS3: =IFERROR(IF(BR3*AA3=0,"",BR3*AA3),"")
O4: =IFERROR(INDEX('_courses_lookup'!$C:$C,MATCH(K4&L4,'_courses_lookup'!$E:$E,0)),"") | P4: =IFERROR(INDEX('_courses_lookup'!$D:$D,MATCH(K4&L4,'_courses_lookup'!$E:$E,0)),"") | AG4: =IF(AND(AE4<>"",AF4<>""),ROUNDUP((AF4-AE4)/7,0),"") | AI4: =IFERROR(IF(AG4*AH4=0,"",AG4*AH4),"") | AL4: =IF(AND(AJ4<>"",AK4<>""),ROUNDUP((AK4-AJ4)/7,0),"") | AN4: =IFERROR(IF(AL4*AM4=0,"",AL4*AM4),"") | AQ4: =IF(AND(AO4<>"",AP4<>""),ROUNDUP((AP4-AO4)/7,0),"") | AR4: =IFERROR(IF((AU4-(AI4+AN4))/AQ4=0,"",ROUNDUP((AU4-(AI4+AN4))/AQ4,0)),"") | AS4: =IFERROR(IF((AU4-(AI4+AN4))=0,"",(AU4-(AI4+AN4))),"") | AT4: =IF(AND(AG4="",AQ4=""),AL4,IF(SUM(AG4,AL4,AQ4)=0,"",SUM(AG4,AL4,AQ4))) | BG4: =IF(AD4="","",YEAR(AD4)+IF(MONTH(AD4)>=5,1,0)) | BH4: =IF(AD4="","",IF(AND(MONTH(AD4)=8,DAY(AD4)>=15),"Fall",IF(MONTH(AD4)>8,"Fall",IF(MONTH(AD4)=5,"Summer",IF(MONTH(AD4)=1,"Spring",""))))) | BL4: =IFERROR(INDEX('_names_lookup'!$C:$C,MATCH(BK4,'_names_lookup'!$A:$A,0)),"") | BM4: =IFERROR(INDEX('_names_lookup'!$B:$B,MATCH(BK4,'_names_lookup'!$A:$A,0)),"") | BS4: =IFERROR(IF(BR4*AA4=0,"",BR4*AA4),"")
O5: =IFERROR(INDEX('_courses_lookup'!$C:$C,MATCH(K5&L5,'_courses_lookup'!$E:$E,0)),"") | P5: =IFERROR(INDEX('_courses_lookup'!$D:$D,MATCH(K5&L5,'_courses_lookup'!$E:$E,0)),"") | AG5: =IF(AND(AE5<>"",AF5<>""),ROUNDUP((AF5-AE5)/7,0),"") | AI5: =IFERROR(IF(AG5*AH5=0,"",AG5*AH5),"") | AL5: =IF(AND(AJ5<>"",AK5<>""),ROUNDUP((AK5-AJ5)/7,0),"") | AN5: =IFERROR(IF(AL5*AM5=0,"",AL5*AM5),"") | AQ5: =IF(AND(AO5<>"",AP5<>""),ROUNDUP((AP5-AO5)/7,0),"") | AR5: =IFERROR(IF((AU5-(AI5+AN5))/AQ5=0,"",ROUNDUP((AU5-(AI5+AN5))/AQ5,0)),"") | AS5: =IFERROR(IF((AU5-(AI5+AN5))=0,"",(AU5-(AI5+AN5))),"") | AT5: =IF(AND(AG5="",AQ5=""),AL5,IF(SUM(AG5,AL5,AQ5)=0,"",SUM(AG5,AL5,AQ5))) | BG5: =IF(AD5="","",YEAR(AD5)+IF(MONTH(AD5)>=5,1,0)) | BH5: =IF(AD5="","",IF(AND(MONTH(AD5)=8,DAY(AD5)>=15),"Fall",IF(MONTH(AD5)>8,"Fall",IF(MONTH(AD5)=5,"Summer",IF(MONTH(AD5)=1,"Spring",""))))) | BL5: =IFERROR(INDEX('_names_lookup'!$C:$C,MATCH(BK5,'_names_lookup'!$A:$A,0)),"") | BM5: =IFERROR(INDEX('_names_lookup'!$B:$B,MATCH(BK5,'_names_lookup'!$A:$A,0)),"") | BS5: =IFERROR(IF(BR5*AA5=0,"",BR5*AA5),"")
O6: =IFERROR(INDEX('_courses_lookup'!$C:$C,MATCH(K6&L6,'_courses_lookup'!$E:$E,0)),"") | P6: =IFERROR(INDEX('_courses_lookup'!$D:$D,MATCH(K6&L6,'_courses_lookup'!$E:$E,0)),"") | AG6: =IF(AND(AE6<>"",AF6<>""),ROUNDUP((AF6-AE6)/7,0),"") | AI6: =IFERROR(IF(AG6*AH6=0,"",AG6*AH6),"") | AL6: =IF(AND(AJ6<>"",AK6<>""),ROUNDUP((AK6-AJ6)/7,0),"") | AN6: =IFERROR(IF(AL6*AM6=0,"",AL6*AM6),"") | AQ6: =IF(AND(AO6<>"",AP6<>""),ROUNDUP((AP6-AO6)/7,0),"") | AR6: =IFERROR(IF((AU6-(AI6+AN6))/AQ6=0,"",ROUNDUP((AU6-(AI6+AN6))/AQ6,0)),"") | AS6: =IFERROR(IF((AU6-(AI6+AN6))=0,"",(AU6-(AI6+AN6))),"") | AT6: =IF(AND(AG6="",AQ6=""),AL6,IF(SUM(AG6,AL6,AQ6)=0,"",SUM(AG6,AL6,AQ6))) | BG6: =IF(AD6="","",YEAR(AD6)+IF(MONTH(AD6)>=5,1,0)) | BH6: =IF(AD6="","",IF(AND(MONTH(AD6)=8,DAY(AD6)>=15),"Fall",IF(MONTH(AD6)>8,"Fall",IF(MONTH(AD6)=5,"Summer",IF(MONTH(AD6)=1,"Spring",""))))) | BL6: =IFERROR(INDEX('_names_lookup'!$C:$C,MATCH(BK6,'_names_lookup'!$A:$A,0)),"") | BM6: =IFERROR(INDEX('_names_lookup'!$B:$B,MATCH(BK6,'_names_lookup'!$A:$A,0)),"") | BS6: =IFERROR(IF(BR6*AA6=0,"",BR6*AA6),"")
O7: =IFERROR(INDEX('_courses_lookup'!$C:$C,MATCH(K7&L7,'_courses_lookup'!$E:$E,0)),"") | P7: =IFERROR(INDEX('_courses_lookup'!$D:$D,MATCH(K7&L7,'_courses_lookup'!$E:$E,0)),"") | AG7: =IF(AND(AE7<>"",AF7<>""),ROUNDUP((AF7-AE7)/7,0),"") | AI7: =IFERROR(IF(AG7*AH7=0,"",AG7*AH7),"") | AL7: =IF(AND(AJ7<>"",AK7<>""),ROUNDUP((AK7-AJ7)/7,0),"") | AN7: =IFERROR(IF(AL7*AM7=0,"",AL7*AM7),"") | AQ7: =IF(AND(AO7<>"",AP7<>""),ROUNDUP((AP7-AO7)/7,0),"") | AR7: =IFERROR(IF((AU7-(AI7+AN7))/AQ7=0,"",ROUNDUP((AU7-(AI7+AN7))/AQ7,0)),"") | AS7: =IFERROR(IF((AU7-(AI7+AN7))=0,"",(AU7-(AI7+AN7))),"") | AT7: =IF(AND(AG7="",AQ7=""),AL7,IF(SUM(AG7,AL7,AQ7)=0,"",SUM(AG7,AL7,AQ7))) | BG7: =IF(AD7="","",YEAR(AD7)+IF(MONTH(AD7)>=5,1,0)) | BH7: =IF(AD7="","",IF(AND(MONTH(AD7)=8,DAY(AD7)>=15),"Fall",IF(MONTH(AD7)>8,"Fall",IF(MONTH(AD7)=5,"Summer",IF(MONTH(AD7)=1,"Spring",""))))) | BL7: =IFERROR(INDEX('_names_lookup'!$C:$C,MATCH(BK7,'_names_lookup'!$A:$A,0)),"") | BM7: =IFERROR(INDEX('_names_lookup'!$B:$B,MATCH(BK7,'_names_lookup'!$A:$A,0)),"") | BS7: =IFERROR(IF(BR7*AA7=0,"",BR7*AA7),"")
O8: =IFERROR(INDEX('_courses_lookup'!$C:$C,MATCH(K8&L8,'_courses_lookup'!$E:$E,0)),"") | P8: =IFERROR(INDEX('_courses_lookup'!$D:$D,MATCH(K8&L8,'_courses_lookup'!$E:$E,0)),"") | AG8: =IF(AND(AE8<>"",AF8<>""),ROUNDUP((AF8-AE8)/7,0),"") | AI8: =IFERROR(IF(AG8*AH8=0,"",AG8*AH8),"") | AL8: =IF(AND(AJ8<>"",AK8<>""),ROUNDUP((AK8-AJ8)/7,0),"") | AN8: =IFERROR(IF(AL8*AM8=0,"",AL8*AM8),"") | AQ8: =IF(AND(AO8<>"",AP8<>""),ROUNDUP((AP8-AO8)/7,0),"") | AR8: =IFERROR(IF((AU8-(AI8+AN8))/AQ8=0,"",ROUNDUP((AU8-(AI8+AN8))/AQ8,0)),"") | AS8: =IFERROR(IF((AU8-(AI8+AN8))=0,"",(AU8-(AI8+AN8))),"") | AT8: =IF(AND(AG8="",AQ8=""),AL8,IF(SUM(AG8,AL8,AQ8)=0,"",SUM(AG8,AL8,AQ8))) | BG8: =IF(AD8="","",YEAR(AD8)+IF(MONTH(AD8)>=5,1,0)) | BH8: =IF(AD8="","",IF(AND(MONTH(AD8)=8,DAY(AD8)>=15),"Fall",IF(MONTH(AD8)>8,"Fall",IF(MONTH(AD8)=5,"Summer",IF(MONTH(AD8)=1,"Spring",""))))) | BL8: =IFERROR(INDEX('_names_lookup'!$C:$C,MATCH(BK8,'_names_lookup'!$A:$A,0)),"") | BM8: =IFERROR(INDEX('_names_lookup'!$B:$B,MATCH(BK8,'_names_lookup'!$A:$A,0)),"") | BS8: =IFERROR(IF(BR8*AA8=0,"",BR8*AA8),"")
O9: =IFERROR(INDEX('_courses_lookup'!$C:$C,MATCH(K9&L9,'_courses_lookup'!$E:$E,0)),"") | P9: =IFERROR(INDEX('_courses_lookup'!$D:$D,MATCH(K9&L9,'_courses_lookup'!$E:$E,0)),"") | AG9: =IF(AND(AE9<>"",AF9<>""),ROUNDUP((AF9-AE9)/7,0),"") | AI9: =IFERROR(IF(AG9*AH9=0,"",AG9*AH9),"") | AL9: =IF(AND(AJ9<>"",AK9<>""),ROUNDUP((AK9-AJ9)/7,0),"") | AN9: =IFERROR(IF(AL9*AM9=0,"",AL9*AM9),"") | AQ9: =IF(AND(AO9<>"",AP9<>""),ROUNDUP((AP9-AO9)/7,0),"") | AR9: =IFERROR(IF((AU9-(AI9+AN9))/AQ9=0,"",ROUNDUP((AU9-(AI9+AN9))/AQ9,0)),"") | AS9: =IFERROR(IF((AU9-(AI9+AN9))=0,"",(AU9-(AI9+AN9))),"") | AT9: =IF(AND(AG9="",AQ9=""),AL9,IF(SUM(AG9,AL9,AQ9)=0,"",SUM(AG9,AL9,AQ9))) | BG9: =IF(AD9="","",YEAR(AD9)+IF(MONTH(AD9)>=5,1,0)) | BH9: =IF(AD9="","",IF(AND(MONTH(AD9)=8,DAY(AD9)>=15),"Fall",IF(MONTH(AD9)>8,"Fall",IF(MONTH(AD9)=5,"Summer",IF(MONTH(AD9)=1,"Spring",""))))) | BL9: =IFERROR(INDEX('_names_lookup'!$C:$C,MATCH(BK9,'_names_lookup'!$A:$A,0)),"") | BM9: =IFERROR(INDEX('_names_lookup'!$B:$B,MATCH(BK9,'_names_lookup'!$A:$A,0)),"") | BS9: =IFERROR(IF(BR9*AA9=0,"",BR9*AA9),"")
O10: =IFERROR(INDEX('_courses_lookup'!$C:$C,MATCH(K10&L10,'_courses_lookup'!$E:$E,0)),"") | P10: =IFERROR(INDEX('_courses_lookup'!$D:$D,MATCH(K10&L10,'_courses_lookup'!$E:$E,0)),"") | AG10: =IF(AND(AE10<>"",AF10<>""),ROUNDUP((AF10-AE10)/7,0),"") | AI10: =IFERROR(IF(AG10*AH10=0,"",AG10*AH10),"") | AL10: =IF(AND(AJ10<>"",AK10<>""),ROUNDUP((AK10-AJ10)/7,0),"") | AN10: =IFERROR(IF(AL10*AM10=0,"",AL10*AM10),"") | AQ10: =IF(AND(AO10<>"",AP10<>""),ROUNDUP((AP10-AO10)/7,0),"") | AR10: =IFERROR(IF((AU10-(AI10+AN10))/AQ10=0,"",ROUNDUP((AU10-(AI10+AN10))/AQ10,0)),"") | AS10: =IFERROR(IF((AU10-(AI10+AN10))=0,"",(AU10-(AI10+AN10))),"") | AT10: =IF(AND(AG10="",AQ10=""),AL10,IF(SUM(AG10,AL10,AQ10)=0,"",SUM(AG10,AL10,AQ10))) | BG10: =IF(AD10="","",YEAR(AD10)+IF(MONTH(AD10)>=5,1,0)) | BH10: =IF(AD10="","",IF(AND(MONTH(AD10)=8,DAY(AD10)>=15),"Fall",IF(MONTH(AD10)>8,"Fall",IF(MONTH(AD10)=5,"Summer",IF(MONTH(AD10)=1,"Spring",""))))) | BL10: =IFERROR(INDEX('_names_lookup'!$C:$C,MATCH(BK10,'_names_lookup'!$A:$A,0)),"") | BM10: =IFERROR(INDEX('_names_lookup'!$B:$B,MATCH(BK10,'_names_lookup'!$A:$A,0)),"") | BS10: =IFERROR(IF(BR10*AA10=0,"",BR10*AA10),"")
O11: =IFERROR(INDEX('_courses_lookup'!$C:$C,MATCH(K11&L11,'_courses_lookup'!$E:$E,0)),"") | P11: =IFERROR(INDEX('_courses_lookup'!$D:$D,MATCH(K11&L11,'_courses_lookup'!$E:$E,0)),"") | AG11: =IF(AND(AE11<>"",AF11<>""),ROUNDUP((AF11-AE11)/7,0),"") | AI11: =IFERROR(IF(AG11*AH11=0,"",AG11*AH11),"") | AL11: =IF(AND(AJ11<>"",AK11<>""),ROUNDUP((AK11-AJ11)/7,0),"") | AN11: =IFERROR(IF(AL11*AM11=0,"",AL11*AM11),"") | AQ11: =IF(AND(AO11<>"",AP11<>""),ROUNDUP((AP11-AO11)/7,0),"") | AR11: =IFERROR(IF((AU11-(AI11+AN11))/AQ11=0,"",ROUNDUP((AU11-(AI11+AN11))/AQ11,0)),"") | AS11: =IFERROR(IF((AU11-(AI11+AN11))=0,"",(AU11-(AI11+AN11))),"") | AT11: =IF(AND(AG11="",AQ11=""),AL11,IF(SUM(AG11,AL11,AQ11)=0,"",SUM(AG11,AL11,AQ11))) | BG11: =IF(AD11="","",YEAR(AD11)+IF(MONTH(AD11)>=5,1,0)) | BH11: =IF(AD11="","",IF(AND(MONTH(AD11)=8,DAY(AD11)>=15),"Fall",IF(MONTH(AD11)>8,"Fall",IF(MONTH(AD11)=5,"Summer",IF(MONTH(AD11)=1,"Spring",""))))) | BL11: =IFERROR(INDEX('_names_lookup'!$C:$C,MATCH(BK11,'_names_lookup'!$A:$A,0)),"") | BM11: =IFERROR(INDEX('_names_lookup'!$B:$B,MATCH(BK11,'_names_lookup'!$A:$A,0)),"") | BS11: =IFERROR(IF(BR11*AA11=0,"",BR11*AA11),"")
O12: =IFERROR(INDEX('_courses_lookup'!$C:$C,MATCH(K12&L12,'_courses_lookup'!$E:$E,0)),"") | P12: =IFERROR(INDEX('_courses_lookup'!$D:$D,MATCH(K12&L12,'_courses_lookup'!$E:$E,0)),"") | AG12: =IF(AND(AE12<>"",AF12<>""),ROUNDUP((AF12-AE12)/7,0),"") | AI12: =IFERROR(IF(AG12*AH12=0,"",AG12*AH12),"") | AL12: =IF(AND(AJ12<>"",AK12<>""),ROUNDUP((AK12-AJ12)/7,0),"") | AN12: =IFERROR(IF(AL12*AM12=0,"",AL12*AM12),"") | AQ12: =IF(AND(AO12<>"",AP12<>""),ROUNDUP((AP12-AO12)/7,0),"") | AR12: =IFERROR(IF((AU12-(AI12+AN12))/AQ12=0,"",ROUNDUP((AU12-(AI12+AN12))/AQ12,0)),"") | AS12: =IFERROR(IF((AU12-(AI12+AN12))=0,"",(AU12-(AI12+AN12))),"") | AT12: =IF(AND(AG12="",AQ12=""),AL12,IF(SUM(AG12,AL12,AQ12)=0,"",SUM(AG12,AL12,AQ12))) | BG12: =IF(AD12="","",YEAR(AD12)+IF(MONTH(AD12)>=5,1,0)) | BH12: =IF(AD12="","",IF(AND(MONTH(AD12)=8,DAY(AD12)>=15),"Fall",IF(MONTH(AD12)>8,"Fall",IF(MONTH(AD12)=5,"Summer",IF(MONTH(AD12)=1,"Spring",""))))) | BL12: =IFERROR(INDEX('_names_lookup'!$C:$C,MATCH(BK12,'_names_lookup'!$A:$A,0)),"") | BM12: =IFERROR(INDEX('_names_lookup'!$B:$B,MATCH(BK12,'_names_lookup'!$A:$A,0)),"") | BS12: =IFERROR(IF(BR12*AA12=0,"",BR12*AA12),"")
O13: =IFERROR(INDEX('_courses_lookup'!$C:$C,MATCH(K13&L13,'_courses_lookup'!$E:$E,0)),"") | P13: =IFERROR(INDEX('_courses_lookup'!$D:$D,MATCH(K13&L13,'_courses_lookup'!$E:$E,0)),"") | AG13: =IF(AND(AE13<>"",AF13<>""),ROUNDUP((AF13-AE13)/7,0),"") | AI13: =IFERROR(IF(AG13*AH13=0,"",AG13*AH13),"") | AL13: =IF(AND(AJ13<>"",AK13<>""),ROUNDUP((AK13-AJ13)/7,0),"") | AN13: =IFERROR(IF(AL13*AM13=0,"",AL13*AM13),"") | AQ13: =IF(AND(AO13<>"",AP13<>""),ROUNDUP((AP13-AO13)/7,0),"") | AR13: =IFERROR(IF((AU13-(AI13+AN13))/AQ13=0,"",ROUNDUP((AU13-(AI13+AN13))/AQ13,0)),"") | AS13: =IFERROR(IF((AU13-(AI13+AN13))=0,"",(AU13-(AI13+AN13))),"") | AT13: =IF(AND(AG13="",AQ13=""),AL13,IF(SUM(AG13,AL13,AQ13)=0,"",SUM(AG13,AL13,AQ13))) | BG13: =IF(AD13="","",YEAR(AD13)+IF(MONTH(AD13)>=5,1,0)) | BH13: =IF(AD13="","",IF(AND(MONTH(AD13)=8,DAY(AD13)>=15),"Fall",IF(MONTH(AD13)>8,"Fall",IF(MONTH(AD13)=5,"Summer",IF(MONTH(AD13)=1,"Spring",""))))) | BL13: =IFERROR(INDEX('_names_lookup'!$C:$C,MATCH(BK13,'_names_lookup'!$A:$A,0)),"") | BM13: =IFERROR(INDEX('_names_lookup'!$B:$B,MATCH(BK13,'_names_lookup'!$A:$A,0)),"") | BS13: =IFERROR(IF(BR13*AA13=0,"",BR13*AA13),"")
... O300: =IFERROR(INDEX('_courses_lookup'!$C:$C,MATCH(K300&L300,'_courses_lookup'!$E:$E,0)),"") | P300: =IFERROR(INDEX('_courses_lookup'!$D:$D,MATCH(K300&L300,'_courses_lookup'!$E:$E,0)),"") | AG300: =IF(AND(AE300<>"",AF300<>""),ROUNDUP((AF300-AE300)/7,0),"") | AI300: =IFERROR(IF(AG300*AH300=0,"",AG300*AH300),"") | AL300: =IF(AND(AJ300<>"",AK300<>""),ROUNDUP((AK300-AJ300)/7,0),"") | AN300: =IFERROR(IF(AL300*AM300=0,"",AL300*AM300),"") | AQ300: =IF(AND(AO300<>"",AP300<>""),ROUNDUP((AP300-AO300)/7,0),"") | AR300: =IFERROR(IF((AU300-(AI300+AN300))/AQ300=0,"",ROUNDUP((AU300-(AI300+AN300))/AQ300,0)),"") | AS300: =IFERROR(IF((AU300-(AI300+AN300))=0,"",(AU300-(AI300+AN300))),"") | AT300: =IF(AND(AG300="",AQ300=""),AL300,IF(SUM(AG300,AL300,AQ300)=0,"",SUM(AG300,AL300,AQ300))) | BG300: =IF(AD300="","",YEAR(AD300)+IF(MONTH(AD300)>=5,1,0)) | BH300: =IF(AD300="","",IF(AND(MONTH(AD300)=8,DAY(AD300)>=15),"Fall",IF(MONTH(AD300)>8,"Fall",IF(MONTH(AD300)=5,"Summer",IF(MONTH(AD300)=1,"Spring",""))))) | BL300: =IFERROR(INDEX('_names_lookup'!$C:$C,MATCH(BK300,'_names_lookup'!$A:$A,0)),"") | BM300: =IFERROR(INDEX('_names_lookup'!$B:$B,MATCH(BK300,'_names_lookup'!$A:$A,0)),"") | BS300: =IFERROR(IF(BR300*AA300=0,"",BR300*AA300),"")

Sheet DSLE
A1: Don {not in Banner} | B1: Mismatching {not in Banner} | C1: Dept/Prog Admin {not in Banner} | D1: Mona {not in Banner} | E1: Karen {not in Banner} | F1: DONE {not in Banner} | G1: Notes {not in Banner} | H1: CRN sorted {not in Banner} | I1: CRN | J1: Attribute {not in Banner} | K1: Subject | L1: Course Number {Crse Num} | M1: Course Section {Seq Crse Num} | N1: Program {not in Banner} | O1: Catalog Title | P1: Section Title | Q1: Crosslist Details {not in Banner} | R1: X Lst | S1: Campus {Ssasect Campus} | T1: Campus Restriction {Camp Restr CC} | U1: Schedule Type {not in Banner} | V1: Instruction Method {Inst Method} | W1: Level {Level SC} | X1: Part-Of-Term | Y1: Credit Catalog {Cat Crs} | Z1: Credits {Sect Crs} | AA1: Faculty Load / Contract Credits {not in Banner} | AB1: Enrollment Cap {Max Enrl} | AC1: Meeting Type | AD1: Semester Start Date {Soaterm Start Date} | AE1: Pre-work Start Date {not in Banner} | AF1: Pre-work End Date {not in Banner} | AG1: pre-work # of weeks {not in Banner} | AH1: pre-work hours/week {not in Banner} | AI1: pre-work hours/period {not in Banner} | AJ1: Intensive Period Start Date {Meet Start Date} | AK1: Intensive Period End Date {Meet End Date} | AL1: intensive # of weeks {not in Banner} | AM1: intensive hours/week {not in Banner} | AN1: intensive hours/period {not in Banner} | AO1: Post-work Start Date {not in Banner} | AP1: Post-work End Date {not in Banner} | AQ1: post-work # of weeks {not in Banner} | AR1: post-work hours/week {not in Banner} | AS1: post-work hours/period {not in Banner} | AT1: sum of weeks (for check) {not in Banner} | AU1: total contract hours {not in Banner} | AV1: Semester End Date {Soaterm End Date} | AW1: Course Beginning Time {Meet Beg Time} | AX1: Course Ending Time {Meet End Time} | AY1: SUN | AZ1: MON | BA1: TUE | BB1: WED | BC1: THU | BD1: FRI | BE1: SAT | BF1: Weeks | BG1: Fiscal Year {not in Banner} | BH1: Semester {not in Banner} | BI1: Room {Meet Room} | BJ1: Building {Meet Bldg} | BK1: Instructor Name {Instr Name} | BL1: Instructor Email {Instr Email} | BM1: Instructor ID {Instr ID} | BN1: Remote Employee {not in Banner} | BO1: % Responsibility | BP1: load/contract {not in Banner} | BQ1: Reason for Contract {not in Banner} | BR1: costs per credit {not in Banner} | BS1: total costs {not in Banner} | BT1: dept budget {not in Banner} | BU1: account to be charged {not in Banner} | BV1: SEM Department {Scacrse Dept} | BW1: dean email | BX1: VP finance email | BY1: HR email | BZ1: Fee Amount {Fees Amt} | CA1: Fee Code {Detl Code} | CB1: Fee Type | CC1: Fee Level | CD1: Fee Ind | CE1: Fee Term | CF1: Activity Date | CG1: Status | CH1: Bill Hrs | CI1: Sect Sch Type | CJ1: Prerequisites {Preq Areas} | CK1: Link Ind | CL1: Integration Code | CM1: Link Conn | CN1: Crs Attr | CO1: Comments | CP1: Major Restr | CQ1: Scacrse College | CR1: Enrolled | CS1: Waitlist Capacity | CT1: Primary Ind | CU1: Override | CV1: 1st Date Reg Opens | CW1: Last Date Reg Opens | CX1: OL Range From Date | CY1: OL Range To Date | CZ1: OL Numb Units | DA1: OL Duration Code | DB1: Grade Mode | DC1: Gradable Ind | DD1: Tuit Waiver | DE1: Course Override {Meet Override} | DF1: Lvl Res Ind | DG1: Cmp Res Ind | DH1: Rate Code | DI1: Cohort Code | DJ1: St Attr Code | DK1: Coll SC | DL1: DegC SC | DM1: Prog SC | DN1: FOS Type | DO1: Special Approval {Special Apvl} | DP1: Term Code | DQ1: Camp SC
O2: =IFERROR(INDEX('_courses_lookup'!$C:$C,MATCH(K2&L2,'_courses_lookup'!$E:$E,0)),"") | P2: =IFERROR(INDEX('_courses_lookup'!$D:$D,MATCH(K2&L2,'_courses_lookup'!$E:$E,0)),"") | AG2: =IF(AND(AE2<>"",AF2<>""),ROUNDUP((AF2-AE2)/7,0),"") | AI2: =IFERROR(IF(AG2*AH2=0,"",AG2*AH2),"") | AL2: =IF(AND(AJ2<>"",AK2<>""),ROUNDUP((AK2-AJ2)/7,0),"") | AN2: =IFERROR(IF(AL2*AM2=0,"",AL2*AM2),"") | AQ2: =IF(AND(AO2<>"",AP2<>""),ROUNDUP((AP2-AO2)/7,0),"") | AR2: =IFERROR(IF((AU2-(AI2+AN2))/AQ2=0,"",ROUNDUP((AU2-(AI2+AN2))/AQ2,0)),"") | AS2: =IFERROR(IF((AU2-(AI2+AN2))=0,"",(AU2-(AI2+AN2))),"") | AT2: =IF(AND(AG2="",AQ2=""),AL2,IF(SUM(AG2,AL2,AQ2)=0,"",SUM(AG2,AL2,AQ2))) | BG2: =IF(AD2="","",YEAR(AD2)+IF(MONTH(AD2)>=5,1,0)) | BH2: =IF(AD2="","",IF(AND(MONTH(AD2)=8,DAY(AD2)>=15),"Fall",IF(MONTH(AD2)>8,"Fall",IF(MONTH(AD2)=5,"Summer",IF(MONTH(AD2)=1,"Spring",""))))) | BL2: =IFERROR(INDEX('_names_lookup'!$C:$C,MATCH(BK2,'_names_lookup'!$A:$A,0)),"") | BM2: =IFERROR(INDEX('_names_lookup'!$B:$B,MATCH(BK2,'_names_lookup'!$A:$A,0)),"") | BS2: =IFERROR(IF(BR2*AA2=0,"",BR2*AA2),"")
O3: =IFERROR(INDEX('_courses_lookup'!$C:$C,MATCH(K3&L3,'_courses_lookup'!$E:$E,0)),"") | P3: =IFERROR(INDEX('_courses_lookup'!$D:$D,MATCH(K3&L3,'_courses_lookup'!$E:$E,0)),"") | AG3: =IF(AND(AE3<>"",AF3<>""),ROUNDUP((AF3-AE3)/7,0),"") | AI3: =IFERROR(IF(AG3*AH3=0,"",AG3*AH3),"") | AL3: =IF(AND(AJ3<>"",AK3<>""),ROUNDUP((AK3-AJ3)/7,0),"") | AN3: =IFERROR(IF(AL3*AM3=0,"",AL3*AM3),"") | AQ3: =IF(AND(AO3<>"",AP3<>""),ROUNDUP((AP3-AO3)/7,0),"") | AR3: =IFERROR(IF((AU3-(AI3+AN3))/AQ3=0,"",ROUNDUP((AU3-(AI3+AN3))/AQ3,0)),"") | AS3: =IFERROR(IF((AU3-(AI3+AN3))=0,"",(AU3-(AI3+AN3))),"") | AT3: =IF(AND(AG3="",AQ3=""),AL3,IF(SUM(AG3,AL3,AQ3)=0,"",SUM(AG3,AL3,AQ3))) | BG3: =IF(AD3="","",YEAR(AD3)+IF(MONTH(AD3)>=5,1,0)) | BH3: =IF(AD3="","",IF(AND(MONTH(AD3)=8,DAY(AD3)>=15),"Fall",IF(MONTH(AD3)>8,"Fall",IF(MONTH(AD3)=5,"Summer",IF(MONTH(AD3)=1,"Spring",""))))) | BL3: =IFERROR(INDEX('_names_lookup'!$C:$C,MATCH(BK3,'_names_lookup'!$A:$A,0)),"") | BM3: =IFERROR(INDEX('_names_lookup'!$B:$B,MATCH(BK3,'_names_lookup'!$A:$A,0)),"") | BS3: =IFERROR(IF(BR3*AA3=0,"",BR3*AA3),"")
O4: =IFERROR(INDEX('_courses_lookup'!$C:$C,MATCH(K4&L4,'_courses_lookup'!$E:$E,0)),"") | P4: =IFERROR(INDEX('_courses_lookup'!$D:$D,MATCH(K4&L4,'_courses_lookup'!$E:$E,0)),"") | AG4: =IF(AND(AE4<>"",AF4<>""),ROUNDUP((AF4-AE4)/7,0),"") | AI4: =IFERROR(IF(AG4*AH4=0,"",AG4*AH4),"") | AL4: =IF(AND(AJ4<>"",AK4<>""),ROUNDUP((AK4-AJ4)/7,0),"") | AN4: =IFERROR(IF(AL4*AM4=0,"",AL4*AM4),"") | AQ4: =IF(AND(AO4<>"",AP4<>""),ROUNDUP((AP4-AO4)/7,0),"") | AR4: =IFERROR(IF((AU4-(AI4+AN4))/AQ4=0,"",ROUNDUP((AU4-(AI4+AN4))/AQ4,0)),"") | AS4: =IFERROR(IF((AU4-(AI4+AN4))=0,"",(AU4-(AI4+AN4))),"") | AT4: =IF(AND(AG4="",AQ4=""),AL4,IF(SUM(AG4,AL4,AQ4)=0,"",SUM(AG4,AL4,AQ4))) | BG4: =IF(AD4="","",YEAR(AD4)+IF(MONTH(AD4)>=5,1,0)) | BH4: =IF(AD4="","",IF(AND(MONTH(AD4)=8,DAY(AD4)>=15),"Fall",IF(MONTH(AD4)>8,"Fall",IF(MONTH(AD4)=5,"Summer",IF(MONTH(AD4)=1,"Spring",""))))) | BL4: =IFERROR(INDEX('_names_lookup'!$C:$C,MATCH(BK4,'_names_lookup'!$A:$A,0)),"") | BM4: =IFERROR(INDEX('_names_lookup'!$B:$B,MATCH(BK4,'_names_lookup'!$A:$A,0)),"") | BS4: =IFERROR(IF(BR4*AA4=0,"",BR4*AA4),"")
O5: =IFERROR(INDEX('_courses_lookup'!$C:$C,MATCH(K5&L5,'_courses_lookup'!$E:$E,0)),"") | P5: =IFERROR(INDEX('_courses_lookup'!$D:$D,MATCH(K5&L5,'_courses_lookup'!$E:$E,0)),"") | AG5: =IF(AND(AE5<>"",AF5<>""),ROUNDUP((AF5-AE5)/7,0),"") | AI5: =IFERROR(IF(AG5*AH5=0,"",AG5*AH5),"") | AL5: =IF(AND(AJ5<>"",AK5<>""),ROUNDUP((AK5-AJ5)/7,0),"") | AN5: =IFERROR(IF(AL5*AM5=0,"",AL5*AM5),"") | AQ5: =IF(AND(AO5<>"",AP5<>""),ROUNDUP((AP5-AO5)/7,0),"") | AR5: =IFERROR(IF((AU5-(AI5+AN5))/AQ5=0,"",ROUNDUP((AU5-(AI5+AN5))/AQ5,0)),"") | AS5: =IFERROR(IF((AU5-(AI5+AN5))=0,"",(AU5-(AI5+AN5))),"") | AT5: =IF(AND(AG5="",AQ5=""),AL5,IF(SUM(AG5,AL5,AQ5)=0,"",SUM(AG5,AL5,AQ5))) | BG5: =IF(AD5="","",YEAR(AD5)+IF(MONTH(AD5)>=5,1,0)) | BH5: =IF(AD5="","",IF(AND(MONTH(AD5)=8,DAY(AD5)>=15),"Fall",IF(MONTH(AD5)>8,"Fall",IF(MONTH(AD5)=5,"Summer",IF(MONTH(AD5)=1,"Spring",""))))) | BL5: =IFERROR(INDEX('_names_lookup'!$C:$C,MATCH(BK5,'_names_lookup'!$A:$A,0)),"") | BM5: =IFERROR(INDEX('_names_lookup'!$B:$B,MATCH(BK5,'_names_lookup'!$A:$A,0)),"") | BS5: =IFERROR(IF(BR5*AA5=0,"",BR5*AA5),"")
O6: =IFERROR(INDEX('_courses_lookup'!$C:$C,MATCH(K6&L6,'_courses_lookup'!$E:$E,0)),"") | P6: =IFERROR(INDEX('_courses_lookup'!$D:$D,MATCH(K6&L6,'_courses_lookup'!$E:$E,0)),"") | AG6: =IF(AND(AE6<>"",AF6<>""),ROUNDUP((AF6-AE6)/7,0),"") | AI6: =IFERROR(IF(AG6*AH6=0,"",AG6*AH6),"") | AL6: =IF(AND(AJ6<>"",AK6<>""),ROUNDUP((AK6-AJ6)/7,0),"") | AN6: =IFERROR(IF(AL6*AM6=0,"",AL6*AM6),"") | AQ6: =IF(AND(AO6<>"",AP6<>""),ROUNDUP((AP6-AO6)/7,0),"") | AR6: =IFERROR(IF((AU6-(AI6+AN6))/AQ6=0,"",ROUNDUP((AU6-(AI6+AN6))/AQ6,0)),"") | AS6: =IFERROR(IF((AU6-(AI6+AN6))=0,"",(AU6-(AI6+AN6))),"") | AT6: =IF(AND(AG6="",AQ6=""),AL6,IF(SUM(AG6,AL6,AQ6)=0,"",SUM(AG6,AL6,AQ6))) | BG6: =IF(AD6="","",YEAR(AD6)+IF(MONTH(AD6)>=5,1,0)) | BH6: =IF(AD6="","",IF(AND(MONTH(AD6)=8,DAY(AD6)>=15),"Fall",IF(MONTH(AD6)>8,"Fall",IF(MONTH(AD6)=5,"Summer",IF(MONTH(AD6)=1,"Spring",""))))) | BL6: =IFERROR(INDEX('_names_lookup'!$C:$C,MATCH(BK6,'_names_lookup'!$A:$A,0)),"") | BM6: =IFERROR(INDEX('_names_lookup'!$B:$B,MATCH(BK6,'_names_lookup'!$A:$A,0)),"") | BS6: =IFERROR(IF(BR6*AA6=0,"",BR6*AA6),"")
O7: =IFERROR(INDEX('_courses_lookup'!$C:$C,MATCH(K7&L7,'_courses_lookup'!$E:$E,0)),"") | P7: =IFERROR(INDEX('_courses_lookup'!$D:$D,MATCH(K7&L7,'_courses_lookup'!$E:$E,0)),"") | AG7: =IF(AND(AE7<>"",AF7<>""),ROUNDUP((AF7-AE7)/7,0),"") | AI7: =IFERROR(IF(AG7*AH7=0,"",AG7*AH7),"") | AL7: =IF(AND(AJ7<>"",AK7<>""),ROUNDUP((AK7-AJ7)/7,0),"") | AN7: =IFERROR(IF(AL7*AM7=0,"",AL7*AM7),"") | AQ7: =IF(AND(AO7<>"",AP7<>""),ROUNDUP((AP7-AO7)/7,0),"") | AR7: =IFERROR(IF((AU7-(AI7+AN7))/AQ7=0,"",ROUNDUP((AU7-(AI7+AN7))/AQ7,0)),"") | AS7: =IFERROR(IF((AU7-(AI7+AN7))=0,"",(AU7-(AI7+AN7))),"") | AT7: =IF(AND(AG7="",AQ7=""),AL7,IF(SUM(AG7,AL7,AQ7)=0,"",SUM(AG7,AL7,AQ7))) | BG7: =IF(AD7="","",YEAR(AD7)+IF(MONTH(AD7)>=5,1,0)) | BH7: =IF(AD7="","",IF(AND(MONTH(AD7)=8,DAY(AD7)>=15),"Fall",IF(MONTH(AD7)>8,"Fall",IF(MONTH(AD7)=5,"Summer",IF(MONTH(AD7)=1,"Spring",""))))) | BL7: =IFERROR(INDEX('_names_lookup'!$C:$C,MATCH(BK7,'_names_lookup'!$A:$A,0)),"") | BM7: =IFERROR(INDEX('_names_lookup'!$B:$B,MATCH(BK7,'_names_lookup'!$A:$A,0)),"") | BS7: =IFERROR(IF(BR7*AA7=0,"",BR7*AA7),"")
O8: =IFERROR(INDEX('_courses_lookup'!$C:$C,MATCH(K8&L8,'_courses_lookup'!$E:$E,0)),"") | P8: =IFERROR(INDEX('_courses_lookup'!$D:$D,MATCH(K8&L8,'_courses_lookup'!$E:$E,0)),"") | AG8: =IF(AND(AE8<>"",AF8<>""),ROUNDUP((AF8-AE8)/7,0),"") | AI8: =IFERROR(IF(AG8*AH8=0,"",AG8*AH8),"") | AL8: =IF(AND(AJ8<>"",AK8<>""),ROUNDUP((AK8-AJ8)/7,0),"") | AN8: =IFERROR(IF(AL8*AM8=0,"",AL8*AM8),"") | AQ8: =IF(AND(AO8<>"",AP8<>""),ROUNDUP((AP8-AO8)/7,0),"") | AR8: =IFERROR(IF((AU8-(AI8+AN8))/AQ8=0,"",ROUNDUP((AU8-(AI8+AN8))/AQ8,0)),"") | AS8: =IFERROR(IF((AU8-(AI8+AN8))=0,"",(AU8-(AI8+AN8))),"") | AT8: =IF(AND(AG8="",AQ8=""),AL8,IF(SUM(AG8,AL8,AQ8)=0,"",SUM(AG8,AL8,AQ8))) | BG8: =IF(AD8="","",YEAR(AD8)+IF(MONTH(AD8)>=5,1,0)) | BH8: =IF(AD8="","",IF(AND(MONTH(AD8)=8,DAY(AD8)>=15),"Fall",IF(MONTH(AD8)>8,"Fall",IF(MONTH(AD8)=5,"Summer",IF(MONTH(AD8)=1,"Spring",""))))) | BL8: =IFERROR(INDEX('_names_lookup'!$C:$C,MATCH(BK8,'_names_lookup'!$A:$A,0)),"") | BM8: =IFERROR(INDEX('_names_lookup'!$B:$B,MATCH(BK8,'_names_lookup'!$A:$A,0)),"") | BS8: =IFERROR(IF(BR8*AA8=0,"",BR8*AA8),"")
O9: =IFERROR(INDEX('_courses_lookup'!$C:$C,MATCH(K9&L9,'_courses_lookup'!$E:$E,0)),"") | P9: =IFERROR(INDEX('_courses_lookup'!$D:$D,MATCH(K9&L9,'_courses_lookup'!$E:$E,0)),"") | AG9: =IF(AND(AE9<>"",AF9<>""),ROUNDUP((AF9-AE9)/7,0),"") | AI9: =IFERROR(IF(AG9*AH9=0,"",AG9*AH9),"") | AL9: =IF(AND(AJ9<>"",AK9<>""),ROUNDUP((AK9-AJ9)/7,0),"") | AN9: =IFERROR(IF(AL9*AM9=0,"",AL9*AM9),"") | AQ9: =IF(AND(AO9<>"",AP9<>""),ROUNDUP((AP9-AO9)/7,0),"") | AR9: =IFERROR(IF((AU9-(AI9+AN9))/AQ9=0,"",ROUNDUP((AU9-(AI9+AN9))/AQ9,0)),"") | AS9: =IFERROR(IF((AU9-(AI9+AN9))=0,"",(AU9-(AI9+AN9))),"") | AT9: =IF(AND(AG9="",AQ9=""),AL9,IF(SUM(AG9,AL9,AQ9)=0,"",SUM(AG9,AL9,AQ9))) | BG9: =IF(AD9="","",YEAR(AD9)+IF(MONTH(AD9)>=5,1,0)) | BH9: =IF(AD9="","",IF(AND(MONTH(AD9)=8,DAY(AD9)>=15),"Fall",IF(MONTH(AD9)>8,"Fall",IF(MONTH(AD9)=5,"Summer",IF(MONTH(AD9)=1,"Spring",""))))) | BL9: =IFERROR(INDEX('_names_lookup'!$C:$C,MATCH(BK9,'_names_lookup'!$A:$A,0)),"") | BM9: =IFERROR(INDEX('_names_lookup'!$B:$B,MATCH(BK9,'_names_lookup'!$A:$A,0)),"") | BS9: =IFERROR(IF(BR9*AA9=0,"",BR9*AA9),"")
O10: =IFERROR(INDEX('_courses_lookup'!$C:$C,MATCH(K10&L10,'_courses_lookup'!$E:$E,0)),"") | P10: =IFERROR(INDEX('_courses_lookup'!$D:$D,MATCH(K10&L10,'_courses_lookup'!$E:$E,0)),"") | AG10: =IF(AND(AE10<>"",AF10<>""),ROUNDUP((AF10-AE10)/7,0),"") | AI10: =IFERROR(IF(AG10*AH10=0,"",AG10*AH10),"") | AL10: =IF(AND(AJ10<>"",AK10<>""),ROUNDUP((AK10-AJ10)/7,0),"") | AN10: =IFERROR(IF(AL10*AM10=0,"",AL10*AM10),"") | AQ10: =IF(AND(AO10<>"",AP10<>""),ROUNDUP((AP10-AO10)/7,0),"") | AR10: =IFERROR(IF((AU10-(AI10+AN10))/AQ10=0,"",ROUNDUP((AU10-(AI10+AN10))/AQ10,0)),"") | AS10: =IFERROR(IF((AU10-(AI10+AN10))=0,"",(AU10-(AI10+AN10))),"") | AT10: =IF(AND(AG10="",AQ10=""),AL10,IF(SUM(AG10,AL10,AQ10)=0,"",SUM(AG10,AL10,AQ10))) | BG10: =IF(AD10="","",YEAR(AD10)+IF(MONTH(AD10)>=5,1,0)) | BH10: =IF(AD10="","",IF(AND(MONTH(AD10)=8,DAY(AD10)>=15),"Fall",IF(MONTH(AD10)>8,"Fall",IF(MONTH(AD10)=5,"Summer",IF(MONTH(AD10)=1,"Spring",""))))) | BL10: =IFERROR(INDEX('_names_lookup'!$C:$C,MATCH(BK10,'_names_lookup'!$A:$A,0)),"") | BM10: =IFERROR(INDEX('_names_lookup'!$B:$B,MATCH(BK10,'_names_lookup'!$A:$A,0)),"") | BS10: =IFERROR(IF(BR10*AA10=0,"",BR10*AA10),"")
O11: =IFERROR(INDEX('_courses_lookup'!$C:$C,MATCH(K11&L11,'_courses_lookup'!$E:$E,0)),"") | P11: =IFERROR(INDEX('_courses_lookup'!$D:$D,MATCH(K11&L11,'_courses_lookup'!$E:$E,0)),"") | AG11: =IF(AND(AE11<>"",AF11<>""),ROUNDUP((AF11-AE11)/7,0),"") | AI11: =IFERROR(IF(AG11*AH11=0,"",AG11*AH11),"") | AL11: =IF(AND(AJ11<>"",AK11<>""),ROUNDUP((AK11-AJ11)/7,0),"") | AN11: =IFERROR(IF(AL11*AM11=0,"",AL11*AM11),"") | AQ11: =IF(AND(AO11<>"",AP11<>""),ROUNDUP((AP11-AO11)/7,0),"") | AR11: =IFERROR(IF((AU11-(AI11+AN11))/AQ11=0,"",ROUNDUP((AU11-(AI11+AN11))/AQ11,0)),"") | AS11: =IFERROR(IF((AU11-(AI11+AN11))=0,"",(AU11-(AI11+AN11))),"") | AT11: =IF(AND(AG11="",AQ11=""),AL11,IF(SUM(AG11,AL11,AQ11)=0,"",SUM(AG11,AL11,AQ11))) | BG11: =IF(AD11="","",YEAR(AD11)+IF(MONTH(AD11)>=5,1,0)) | BH11: =IF(AD11="","",IF(AND(MONTH(AD11)=8,DAY(AD11)>=15),"Fall",IF(MONTH(AD11)>8,"Fall",IF(MONTH(AD11)=5,"Summer",IF(MONTH(AD11)=1,"Spring",""))))) | BL11: =IFERROR(INDEX('_names_lookup'!$C:$C,MATCH(BK11,'_names_lookup'!$A:$A,0)),"") | BM11: =IFERROR(INDEX('_names_lookup'!$B:$B,MATCH(BK11,'_names_lookup'!$A:$A,0)),"") | BS11: =IFERROR(IF(BR11*AA11=0,"",BR11*AA11),"")
O12: =IFERROR(INDEX('_courses_lookup'!$C:$C,MATCH(K12&L12,'_courses_lookup'!$E:$E,0)),"") | P12: =IFERROR(INDEX('_courses_lookup'!$D:$D,MATCH(K12&L12,'_courses_lookup'!$E:$E,0)),"") | AG12: =IF(AND(AE12<>"",AF12<>""),ROUNDUP((AF12-AE12)/7,0),"") | AI12: =IFERROR(IF(AG12*AH12=0,"",AG12*AH12),"") | AL12: =IF(AND(AJ12<>"",AK12<>""),ROUNDUP((AK12-AJ12)/7,0),"") | AN12: =IFERROR(IF(AL12*AM12=0,"",AL12*AM12),"") | AQ12: =IF(AND(AO12<>"",AP12<>""),ROUNDUP((AP12-AO12)/7,0),"") | AR12: =IFERROR(IF((AU12-(AI12+AN12))/AQ12=0,"",ROUNDUP((AU12-(AI12+AN12))/AQ12,0)),"") | AS12: =IFERROR(IF((AU12-(AI12+AN12))=0,"",(AU12-(AI12+AN12))),"") | AT12: =IF(AND(AG12="",AQ12=""),AL12,IF(SUM(AG12,AL12,AQ12)=0,"",SUM(AG12,AL12,AQ12))) | BG12: =IF(AD12="","",YEAR(AD12)+IF(MONTH(AD12)>=5,1,0)) | BH12: =IF(AD12="","",IF(AND(MONTH(AD12)=8,DAY(AD12)>=15),"Fall",IF(MONTH(AD12)>8,"Fall",IF(MONTH(AD12)=5,"Summer",IF(MONTH(AD12)=1,"Spring",""))))) | BL12: =IFERROR(INDEX('_names_lookup'!$C:$C,MATCH(BK12,'_names_lookup'!$A:$A,0)),"") | BM12: =IFERROR(INDEX('_names_lookup'!$B:$B,MATCH(BK12,'_names_lookup'!$A:$A,0)),"") | BS12: =IFERROR(IF(BR12*AA12=0,"",BR12*AA12),"")
O13: =IFERROR(INDEX('_courses_lookup'!$C:$C,MATCH(K13&L13,'_courses_lookup'!$E:$E,0)),"") | P13: =IFERROR(INDEX('_courses_lookup'!$D:$D,MATCH(K13&L13,'_courses_lookup'!$E:$E,0)),"") | AG13: =IF(AND(AE13<>"",AF13<>""),ROUNDUP((AF13-AE13)/7,0),"") | AI13: =IFERROR(IF(AG13*AH13=0,"",AG13*AH13),"") | AL13: =IF(AND(AJ13<>"",AK13<>""),ROUNDUP((AK13-AJ13)/7,0),"") | AN13: =IFERROR(IF(AL13*AM13=0,"",AL13*AM13),"") | AQ13: =IF(AND(AO13<>"",AP13<>""),ROUNDUP((AP13-AO13)/7,0),"") | AR13: =IFERROR(IF((AU13-(AI13+AN13))/AQ13=0,"",ROUNDUP((AU13-(AI13+AN13))/AQ13,0)),"") | AS13: =IFERROR(IF((AU13-(AI13+AN13))=0,"",(AU13-(AI13+AN13))),"") | AT13: =IF(AND(AG13="",AQ13=""),AL13,IF(SUM(AG13,AL13,AQ13)=0,"",SUM(AG13,AL13,AQ13))) | BG13: =IF(AD13="","",YEAR(AD13)+IF(MONTH(AD13)>=5,1,0)) | BH13: =IF(AD13="","",IF(AND(MONTH(AD13)=8,DAY(AD13)>=15),"Fall",IF(MONTH(AD13)>8,"Fall",IF(MONTH(AD13)=5,"Summer",IF(MONTH(AD13)=1,"Spring",""))))) | BL13: =IFERROR(INDEX('_names_lookup'!$C:$C,MATCH(BK13,'_names_lookup'!$A:$A,0)),"") | BM13: =IFERROR(INDEX('_names_lookup'!$B:$B,MATCH(BK13,'_names_lookup'!$A:$A,0)),"") | BS13: =IFERROR(IF(BR13*AA13=0,"",BR13*AA13),"")
... O300: =IFERROR(INDEX('_courses_lookup'!$C:$C,MATCH(K300&L300,'_courses_lookup'!$E:$E,0)),"") | P300: =IFERROR(INDEX('_courses_lookup'!$D:$D,MATCH(K300&L300,'_courses_lookup'!$E:$E,0)),"") | AG300: =IF(AND(AE300<>"",AF300<>""),ROUNDUP((AF300-AE300)/7,0),"") | AI300: =IFERROR(IF(AG300*AH300=0,"",AG300*AH300),"") | AL300: =IF(AND(AJ300<>"",AK300<>""),ROUNDUP((AK300-AJ300)/7,0),"") | AN300: =IFERROR(IF(AL300*AM300=0,"",AL300*AM300),"") | AQ300: =IF(AND(AO300<>"",AP300<>""),ROUNDUP((AP300-AO300)/7,0),"") | AR300: =IFERROR(IF((AU300-(AI300+AN300))/AQ300=0,"",ROUNDUP((AU300-(AI300+AN300))/AQ300,0)),"") | AS300: =IFERROR(IF((AU300-(AI300+AN300))=0,"",(AU300-(AI300+AN300))),"") | AT300: =IF(AND(AG300="",AQ300=""),AL300,IF(SUM(AG300,AL300,AQ300)=0,"",SUM(AG300,AL300,AQ300))) | BG300: =IF(AD300="","",YEAR(AD300)+IF(MONTH(AD300)>=5,1,0)) | BH300: =IF(AD300="","",IF(AND(MONTH(AD300)=8,DAY(AD300)>=15),"Fall",IF(MONTH(AD300)>8,"Fall",IF(MONTH(AD300)=5,"Summer",IF(MONTH(AD300)=1,"Spring",""))))) | BL300: =IFERROR(INDEX('_names_lookup'!$C:$C,MATCH(BK300,'_names_lookup'!$A:$A,0)),"") | BM300: =IFERROR(INDEX('_names_lookup'!$B:$B,MATCH(BK300,'_names_lookup'!$A:$A,0)),"") | BS300: =IFERROR(IF(BR300*AA300=0,"",BR300*AA300),"")

Sheet GSEM
A1: Don {not in Banner} | B1: Mismatching {not in Banner} | C1: Dept/Prog Admin {not in Banner} | D1: Mona {not in Banner} | E1: Karen {not in Banner} | F1: DONE {not in Banner} | G1: Notes {not in Banner} | H1: CRN sorted {not in Banner} | I1: CRN | J1: Attribute {not in Banner} | K1: Subject | L1: Course Number {Crse Num} | M1: Course Section {Seq Crse Num} | N1: Program {not in Banner} | O1: Catalog Title | P1: Section Title | Q1: Crosslist Details {not in Banner} | R1: X Lst | S1: Campus {Ssasect Campus} | T1: Campus Restriction {Camp Restr CC} | U1: Schedule Type {not in Banner} | V1: Instruction Method {Inst Method} | W1: Level {Level SC} | X1: Part-Of-Term | Y1: Credit Catalog {Cat Crs} | Z1: Credits {Sect Crs} | AA1: Faculty Load / Contract Credits {not in Banner} | AB1: Enrollment Cap {Max Enrl} | AC1: Meeting Type | AD1: Semester Start Date {Soaterm Start Date} | AE1: Pre-work Start Date {not in Banner} | AF1: Pre-work End Date {not in Banner} | AG1: pre-work # of weeks {not in Banner} | AH1: pre-work hours/week {not in Banner} | AI1: pre-work hours/period {not in Banner} | AJ1: Intensive Period Start Date {Meet Start Date} | AK1: Intensive Period End Date {Meet End Date} | AL1: intensive # of weeks {not in Banner} | AM1: intensive hours/week {not in Banner} | AN1: intensive hours/period {not in Banner} | AO1: Post-work Start Date {not in Banner} | AP1: Post-work End Date {not in Banner} | AQ1: post-work # of weeks {not in Banner} | AR1: post-work hours/week {not in Banner} | AS1: post-work hours/period {not in Banner} | AT1: sum of weeks (for check) {not in Banner} | AU1: total contract hours {not in Banner} | AV1: Semester End Date {Soaterm End Date} | AW1: Course Beginning Time {Meet Beg Time} | AX1: Course Ending Time {Meet End Time} | AY1: SUN | AZ1: MON | BA1: TUE | BB1: WED | BC1: THU | BD1: FRI | BE1: SAT | BF1: Weeks | BG1: Fiscal Year {not in Banner} | BH1: Semester {not in Banner} | BI1: Room {Meet Room} | BJ1: Building {Meet Bldg} | BK1: Instructor Name {Instr Name} | BL1: Instructor Email {Instr Email} | BM1: Instructor ID {Instr ID} | BN1: Remote Employee {not in Banner} | BO1: % Responsibility | BP1: load/contract {not in Banner} | BQ1: Reason for Contract {not in Banner} | BR1: costs per credit {not in Banner} | BS1: total costs {not in Banner} | BT1: dept budget {not in Banner} | BU1: account to be charged {not in Banner} | BV1: SEM Department {Scacrse Dept} | BW1: dean email | BX1: VP finance email | BY1: HR email | BZ1: Fee Amount {Fees Amt} | CA1: Fee Code {Detl Code} | CB1: Fee Type | CC1: Fee Level | CD1: Fee Ind | CE1: Fee Term | CF1: Activity Date | CG1: Status | CH1: Bill Hrs | CI1: Sect Sch Type | CJ1: Prerequisites {Preq Areas} | CK1: Link Ind | CL1: Integration Code | CM1: Link Conn | CN1: Crs Attr | CO1: Comments | CP1: Major Restr | CQ1: Scacrse College | CR1: Enrolled | CS1: Waitlist Capacity | CT1: Primary Ind | CU1: Override | CV1: 1st Date Reg Opens | CW1: Last Date Reg Opens | CX1: OL Range From Date | CY1: OL Range To Date | CZ1: OL Numb Units | DA1: OL Duration Code | DB1: Grade Mode | DC1: Gradable Ind | DD1: Tuit Waiver | DE1: Course Override {Meet Override} | DF1: Lvl Res Ind | DG1: Cmp Res Ind | DH1: Rate Code | DI1: Cohort Code | DJ1: St Attr Code | DK1: Coll SC | DL1: DegC SC | DM1: Prog SC | DN1: FOS Type | DO1: Special Approval {Special Apvl} | DP1: Term Code | DQ1: Camp SC
O2: =IFERROR(INDEX('_courses_lookup'!$C:$C,MATCH(K2&L2,'_courses_lookup'!$E:$E,0)),"") | P2: =IFERROR(INDEX('_courses_lookup'!$D:$D,MATCH(K2&L2,'_courses_lookup'!$E:$E,0)),"") | AG2: =IF(AND(AE2<>"",AF2<>""),ROUNDUP((AF2-AE2)/7,0),"") | AI2: =IFERROR(IF(AG2*AH2=0,"",AG2*AH2),"") | AL2: =IF(AND(AJ2<>"",AK2<>""),ROUNDUP((AK2-AJ2)/7,0),"") | AN2: =IFERROR(IF(AL2*AM2=0,"",AL2*AM2),"") | AQ2: =IF(AND(AO2<>"",AP2<>""),ROUNDUP((AP2-AO2)/7,0),"") | AR2: =IFERROR(IF((AU2-(AI2+AN2))/AQ2=0,"",ROUNDUP((AU2-(AI2+AN2))/AQ2,0)),"") | AS2: =IFERROR(IF((AU2-(AI2+AN2))=0,"",(AU2-(AI2+AN2))),"") | AT2: =IF(AND(AG2="",AQ2=""),AL2,IF(SUM(AG2,AL2,AQ2)=0,"",SUM(AG2,AL2,AQ2))) | BG2: =IF(AD2="","",YEAR(AD2)+IF(MONTH(AD2)>=5,1,0)) | BH2: =IF(AD2="","",IF(AND(MONTH(AD2)=8,DAY(AD2)>=15),"Fall",IF(MONTH(AD2)>8,"Fall",IF(MONTH(AD2)=5,"Summer",IF(MONTH(AD2)=1,"Spring",""))))) | BL2: =IFERROR(INDEX('_names_lookup'!$C:$C,MATCH(BK2,'_names_lookup'!$A:$A,0)),"") | BM2: =IFERROR(INDEX('_names_lookup'!$B:$B,MATCH(BK2,'_names_lookup'!$A:$A,0)),"") | BS2: =IFERROR(IF(BR2*AA2=0,"",BR2*AA2),"")
O3: =IFERROR(INDEX('_courses_lookup'!$C:$C,MATCH(K3&L3,'_courses_lookup'!$E:$E,0)),"") | P3: =IFERROR(INDEX('_courses_lookup'!$D:$D,MATCH(K3&L3,'_courses_lookup'!$E:$E,0)),"") | AG3: =IF(AND(AE3<>"",AF3<>""),ROUNDUP((AF3-AE3)/7,0),"") | AI3: =IFERROR(IF(AG3*AH3=0,"",AG3*AH3),"") | AL3: =IF(AND(AJ3<>"",AK3<>""),ROUNDUP((AK3-AJ3)/7,0),"") | AN3: =IFERROR(IF(AL3*AM3=0,"",AL3*AM3),"") | AQ3: =IF(AND(AO3<>"",AP3<>""),ROUNDUP((AP3-AO3)/7,0),"") | AR3: =IFERROR(IF((AU3-(AI3+AN3))/AQ3=0,"",ROUNDUP((AU3-(AI3+AN3))/AQ3,0)),"") | AS3: =IFERROR(IF((AU3-(AI3+AN3))=0,"",(AU3-(AI3+AN3))),"") | AT3: =IF(AND(AG3="",AQ3=""),AL3,IF(SUM(AG3,AL3,AQ3)=0,"",SUM(AG3,AL3,AQ3))) | BG3: =IF(AD3="","",YEAR(AD3)+IF(MONTH(AD3)>=5,1,0)) | BH3: =IF(AD3="","",IF(AND(MONTH(AD3)=8,DAY(AD3)>=15),"Fall",IF(MONTH(AD3)>8,"Fall",IF(MONTH(AD3)=5,"Summer",IF(MONTH(AD3)=1,"Spring",""))))) | BL3: =IFERROR(INDEX('_names_lookup'!$C:$C,MATCH(BK3,'_names_lookup'!$A:$A,0)),"") | BM3: =IFERROR(INDEX('_names_lookup'!$B:$B,MATCH(BK3,'_names_lookup'!$A:$A,0)),"") | BS3: =IFERROR(IF(BR3*AA3=0,"",BR3*AA3),"")
O4: =IFERROR(INDEX('_courses_lookup'!$C:$C,MATCH(K4&L4,'_courses_lookup'!$E:$E,0)),"") | P4: =IFERROR(INDEX('_courses_lookup'!$D:$D,MATCH(K4&L4,'_courses_lookup'!$E:$E,0)),"") | AG4: =IF(AND(AE4<>"",AF4<>""),ROUNDUP((AF4-AE4)/7,0),"") | AI4: =IFERROR(IF(AG4*AH4=0,"",AG4*AH4),"") | AL4: =IF(AND(AJ4<>"",AK4<>""),ROUNDUP((AK4-AJ4)/7,0),"") | AN4: =IFERROR(IF(AL4*AM4=0,"",AL4*AM4),"") | AQ4: =IF(AND(AO4<>"",AP4<>""),ROUNDUP((AP4-AO4)/7,0),"") | AR4: =IFERROR(IF((AU4-(AI4+AN4))/AQ4=0,"",ROUNDUP((AU4-(AI4+AN4))/AQ4,0)),"") | AS4: =IFERROR(IF((AU4-(AI4+AN4))=0,"",(AU4-(AI4+AN4))),"") | AT4: =IF(AND(AG4="",AQ4=""),AL4,IF(SUM(AG4,AL4,AQ4)=0,"",SUM(AG4,AL4,AQ4))) | BG4: =IF(AD4="","",YEAR(AD4)+IF(MONTH(AD4)>=5,1,0)) | BH4: =IF(AD4="","",IF(AND(MONTH(AD4)=8,DAY(AD4)>=15),"Fall",IF(MONTH(AD4)>8,"Fall",IF(MONTH(AD4)=5,"Summer",IF(MONTH(AD4)=1,"Spring",""))))) | BL4: =IFERROR(INDEX('_names_lookup'!$C:$C,MATCH(BK4,'_names_lookup'!$A:$A,0)),"") | BM4: =IFERROR(INDEX('_names_lookup'!$B:$B,MATCH(BK4,'_names_lookup'!$A:$A,0)),"") | BS4: =IFERROR(IF(BR4*AA4=0,"",BR4*AA4),"")
O5: =IFERROR(INDEX('_courses_lookup'!$C:$C,MATCH(K5&L5,'_courses_lookup'!$E:$E,0)),"") | P5: =IFERROR(INDEX('_courses_lookup'!$D:$D,MATCH(K5&L5,'_courses_lookup'!$E:$E,0)),"") | AG5: =IF(AND(AE5<>"",AF5<>""),ROUNDUP((AF5-AE5)/7,0),"") | AI5: =IFERROR(IF(AG5*AH5=0,"",AG5*AH5),"") | AL5: =IF(AND(AJ5<>"",AK5<>""),ROUNDUP((AK5-AJ5)/7,0),"") | AN5: =IFERROR(IF(AL5*AM5=0,"",AL5*AM5),"") | AQ5: =IF(AND(AO5<>"",AP5<>""),ROUNDUP((AP5-AO5)/7,0),"") | AR5: =IFERROR(IF((AU5-(AI5+AN5))/AQ5=0,"",ROUNDUP((AU5-(AI5+AN5))/AQ5,0)),"") | AS5: =IFERROR(IF((AU5-(AI5+AN5))=0,"",(AU5-(AI5+AN5))),"") | AT5: =IF(AND(AG5="",AQ5=""),AL5,IF(SUM(AG5,AL5,AQ5)=0,"",SUM(AG5,AL5,AQ5))) | BG5: =IF(AD5="","",YEAR(AD5)+IF(MONTH(AD5)>=5,1,0)) | BH5: =IF(AD5="","",IF(AND(MONTH(AD5)=8,DAY(AD5)>=15),"Fall",IF(MONTH(AD5)>8,"Fall",IF(MONTH(AD5)=5,"Summer",IF(MONTH(AD5)=1,"Spring",""))))) | BL5: =IFERROR(INDEX('_names_lookup'!$C:$C,MATCH(BK5,'_names_lookup'!$A:$A,0)),"") | BM5: =IFERROR(INDEX('_names_lookup'!$B:$B,MATCH(BK5,'_names_lookup'!$A:$A,0)),"") | BS5: =IFERROR(IF(BR5*AA5=0,"",BR5*AA5),"")
O6: =IFERROR(INDEX('_courses_lookup'!$C:$C,MATCH(K6&L6,'_courses_lookup'!$E:$E,0)),"") | P6: =IFERROR(INDEX('_courses_lookup'!$D:$D,MATCH(K6&L6,'_courses_lookup'!$E:$E,0)),"") | AG6: =IF(AND(AE6<>"",AF6<>""),ROUNDUP((AF6-AE6)/7,0),"") | AI6: =IFERROR(IF(AG6*AH6=0,"",AG6*AH6),"") | AL6: =IF(AND(AJ6<>"",AK6<>""),ROUNDUP((AK6-AJ6)/7,0),"") | AN6: =IFERROR(IF(AL6*AM6=0,"",AL6*AM6),"") | AQ6: =IF(AND(AO6<>"",AP6<>""),ROUNDUP((AP6-AO6)/7,0),"") | AR6: =IFERROR(IF((AU6-(AI6+AN6))/AQ6=0,"",ROUNDUP((AU6-(AI6+AN6))/AQ6,0)),"") | AS6: =IFERROR(IF((AU6-(AI6+AN6))=0,"",(AU6-(AI6+AN6))),"") | AT6: =IF(AND(AG6="",AQ6=""),AL6,IF(SUM(AG6,AL6,AQ6)=0,"",SUM(AG6,AL6,AQ6))) | BG6: =IF(AD6="","",YEAR(AD6)+IF(MONTH(AD6)>=5,1,0)) | BH6: =IF(AD6="","",IF(AND(MONTH(AD6)=8,DAY(AD6)>=15),"Fall",IF(MONTH(AD6)>8,"Fall",IF(MONTH(AD6)=5,"Summer",IF(MONTH(AD6)=1,"Spring",""))))) | BL6: =IFERROR(INDEX('_names_lookup'!$C:$C,MATCH(BK6,'_names_lookup'!$A:$A,0)),"") | BM6: =IFERROR(INDEX('_names_lookup'!$B:$B,MATCH(BK6,'_names_lookup'!$A:$A,0)),"") | BS6: =IFERROR(IF(BR6*AA6=0,"",BR6*AA6),"")
O7: =IFERROR(INDEX('_courses_lookup'!$C:$C,MATCH(K7&L7,'_courses_lookup'!$E:$E,0)),"") | P7: =IFERROR(INDEX('_courses_lookup'!$D:$D,MATCH(K7&L7,'_courses_lookup'!$E:$E,0)),"") | AG7: =IF(AND(AE7<>"",AF7<>""),ROUNDUP((AF7-AE7)/7,0),"") | AI7: =IFERROR(IF(AG7*AH7=0,"",AG7*AH7),"") | AL7: =IF(AND(AJ7<>"",AK7<>""),ROUNDUP((AK7-AJ7)/7,0),"") | AN7: =IFERROR(IF(AL7*AM7=0,"",AL7*AM7),"") | AQ7: =IF(AND(AO7<>"",AP7<>""),ROUNDUP((AP7-AO7)/7,0),"") | AR7: =IFERROR(IF((AU7-(AI7+AN7))/AQ7=0,"",ROUNDUP((AU7-(AI7+AN7))/AQ7,0)),"") | AS7: =IFERROR(IF((AU7-(AI7+AN7))=0,"",(AU7-(AI7+AN7))),"") | AT7: =IF(AND(AG7="",AQ7=""),AL7,IF(SUM(AG7,AL7,AQ7)=0,"",SUM(AG7,AL7,AQ7))) | BG7: =IF(AD7="","",YEAR(AD7)+IF(MONTH(AD7)>=5,1,0)) | BH7: =IF(AD7="","",IF(AND(MONTH(AD7)=8,DAY(AD7)>=15),"Fall",IF(MONTH(AD7)>8,"Fall",IF(MONTH(AD7)=5,"Summer",IF(MONTH(AD7)=1,"Spring",""))))) | BL7: =IFERROR(INDEX('_names_lookup'!$C:$C,MATCH(BK7,'_names_lookup'!$A:$A,0)),"") | BM7: =IFERROR(INDEX('_names_lookup'!$B:$B,MATCH(BK7,'_names_lookup'!$A:$A,0)),"") | BS7: =IFERROR(IF(BR7*AA7=0,"",BR7*AA7),"")
O8: =IFERROR(INDEX('_courses_lookup'!$C:$C,MATCH(K8&L8,'_courses_lookup'!$E:$E,0)),"") | P8: =IFERROR(INDEX('_courses_lookup'!$D:$D,MATCH(K8&L8,'_courses_lookup'!$E:$E,0)),"") | AG8: =IF(AND(AE8<>"",AF8<>""),ROUNDUP((AF8-AE8)/7,0),"") | AI8: =IFERROR(IF(AG8*AH8=0,"",AG8*AH8),"") | AL8: =IF(AND(AJ8<>"",AK8<>""),ROUNDUP((AK8-AJ8)/7,0),"") | AN8: =IFERROR(IF(AL8*AM8=0,"",AL8*AM8),"") | AQ8: =IF(AND(AO8<>"",AP8<>""),ROUNDUP((AP8-AO8)/7,0),"") | AR8: =IFERROR(IF((AU8-(AI8+AN8))/AQ8=0,"",ROUNDUP((AU8-(AI8+AN8))/AQ8,0)),"") | AS8: =IFERROR(IF((AU8-(AI8+AN8))=0,"",(AU8-(AI8+AN8))),"") | AT8: =IF(AND(AG8="",AQ8=""),AL8,IF(SUM(AG8,AL8,AQ8)=0,"",SUM(AG8,AL8,AQ8))) | BG8: =IF(AD8="","",YEAR(AD8)+IF(MONTH(AD8)>=5,1,0)) | BH8: =IF(AD8="","",IF(AND(MONTH(AD8)=8,DAY(AD8)>=15),"Fall",IF(MONTH(AD8)>8,"Fall",IF(MONTH(AD8)=5,"Summer",IF(MONTH(AD8)=1,"Spring",""))))) | BL8: =IFERROR(INDEX('_names_lookup'!$C:$C,MATCH(BK8,'_names_lookup'!$A:$A,0)),"") | BM8: =IFERROR(INDEX('_names_lookup'!$B:$B,MATCH(BK8,'_names_lookup'!$A:$A,0)),"") | BS8: =IFERROR(IF(BR8*AA8=0,"",BR8*AA8),"")
O9: =IFERROR(INDEX('_courses_lookup'!$C:$C,MATCH(K9&L9,'_courses_lookup'!$E:$E,0)),"") | P9: =IFERROR(INDEX('_courses_lookup'!$D:$D,MATCH(K9&L9,'_courses_lookup'!$E:$E,0)),"") | AG9: =IF(AND(AE9<>"",AF9<>""),ROUNDUP((AF9-AE9)/7,0),"") | AI9: =IFERROR(IF(AG9*AH9=0,"",AG9*AH9),"") | AL9: =IF(AND(AJ9<>"",AK9<>""),ROUNDUP((AK9-AJ9)/7,0),"") | AN9: =IFERROR(IF(AL9*AM9=0,"",AL9*AM9),"") | AQ9: =IF(AND(AO9<>"",AP9<>""),ROUNDUP((AP9-AO9)/7,0),"") | AR9: =IFERROR(IF((AU9-(AI9+AN9))/AQ9=0,"",ROUNDUP((AU9-(AI9+AN9))/AQ9,0)),"") | AS9: =IFERROR(IF((AU9-(AI9+AN9))=0,"",(AU9-(AI9+AN9))),"") | AT9: =IF(AND(AG9="",AQ9=""),AL9,IF(SUM(AG9,AL9,AQ9)=0,"",SUM(AG9,AL9,AQ9))) | BG9: =IF(AD9="","",YEAR(AD9)+IF(MONTH(AD9)>=5,1,0)) | BH9: =IF(AD9="","",IF(AND(MONTH(AD9)=8,DAY(AD9)>=15),"Fall",IF(MONTH(AD9)>8,"Fall",IF(MONTH(AD9)=5,"Summer",IF(MONTH(AD9)=1,"Spring",""))))) | BL9: =IFERROR(INDEX('_names_lookup'!$C:$C,MATCH(BK9,'_names_lookup'!$A:$A,0)),"") | BM9: =IFERROR(INDEX('_names_lookup'!$B:$B,MATCH(BK9,'_names_lookup'!$A:$A,0)),"") | BS9: =IFERROR(IF(BR9*AA9=0,"",BR9*AA9),"")
O10: =IFERROR(INDEX('_courses_lookup'!$C:$C,MATCH(K10&L10,'_courses_lookup'!$E:$E,0)),"") | P10: =IFERROR(INDEX('_courses_lookup'!$D:$D,MATCH(K10&L10,'_courses_lookup'!$E:$E,0)),"") | AG10: =IF(AND(AE10<>"",AF10<>""),ROUNDUP((AF10-AE10)/7,0),"") | AI10: =IFERROR(IF(AG10*AH10=0,"",AG10*AH10),"") | AL10: =IF(AND(AJ10<>"",AK10<>""),ROUNDUP((AK10-AJ10)/7,0),"") | AN10: =IFERROR(IF(AL10*AM10=0,"",AL10*AM10),"") | AQ10: =IF(AND(AO10<>"",AP10<>""),ROUNDUP((AP10-AO10)/7,0),"") | AR10: =IFERROR(IF((AU10-(AI10+AN10))/AQ10=0,"",ROUNDUP((AU10-(AI10+AN10))/AQ10,0)),"") | AS10: =IFERROR(IF((AU10-(AI10+AN10))=0,"",(AU10-(AI10+AN10))),"") | AT10: =IF(AND(AG10="",AQ10=""),AL10,IF(SUM(AG10,AL10,AQ10)=0,"",SUM(AG10,AL10,AQ10))) | BG10: =IF(AD10="","",YEAR(AD10)+IF(MONTH(AD10)>=5,1,0)) | BH10: =IF(AD10="","",IF(AND(MONTH(AD10)=8,DAY(AD10)>=15),"Fall",IF(MONTH(AD10)>8,"Fall",IF(MONTH(AD10)=5,"Summer",IF(MONTH(AD10)=1,"Spring",""))))) | BL10: =IFERROR(INDEX('_names_lookup'!$C:$C,MATCH(BK10,'_names_lookup'!$A:$A,0)),"") | BM10: =IFERROR(INDEX('_names_lookup'!$B:$B,MATCH(BK10,'_names_lookup'!$A:$A,0)),"") | BS10: =IFERROR(IF(BR10*AA10=0,"",BR10*AA10),"")
O11: =IFERROR(INDEX('_courses_lookup'!$C:$C,MATCH(K11&L11,'_courses_lookup'!$E:$E,0)),"") | P11: =IFERROR(INDEX('_courses_lookup'!$D:$D,MATCH(K11&L11,'_courses_lookup'!$E:$E,0)),"") | AG11: =IF(AND(AE11<>"",AF11<>""),ROUNDUP((AF11-AE11)/7,0),"") | AI11: =IFERROR(IF(AG11*AH11=0,"",AG11*AH11),"") | AL11: =IF(AND(AJ11<>"",AK11<>""),ROUNDUP((AK11-AJ11)/7,0),"") | AN11: =IFERROR(IF(AL11*AM11=0,"",AL11*AM11),"") | AQ11: =IF(AND(AO11<>"",AP11<>""),ROUNDUP((AP11-AO11)/7,0),"") | AR11: =IFERROR(IF((AU11-(AI11+AN11))/AQ11=0,"",ROUNDUP((AU11-(AI11+AN11))/AQ11,0)),"") | AS11: =IFERROR(IF((AU11-(AI11+AN11))=0,"",(AU11-(AI11+AN11))),"") | AT11: =IF(AND(AG11="",AQ11=""),AL11,IF(SUM(AG11,AL11,AQ11)=0,"",SUM(AG11,AL11,AQ11))) | BG11: =IF(AD11="","",YEAR(AD11)+IF(MONTH(AD11)>=5,1,0)) | BH11: =IF(AD11="","",IF(AND(MONTH(AD11)=8,DAY(AD11)>=15),"Fall",IF(MONTH(AD11)>8,"Fall",IF(MONTH(AD11)=5,"Summer",IF(MONTH(AD11)=1,"Spring",""))))) | BL11: =IFERROR(INDEX('_names_lookup'!$C:$C,MATCH(BK11,'_names_lookup'!$A:$A,0)),"") | BM11: =IFERROR(INDEX('_names_lookup'!$B:$B,MATCH(BK11,'_names_lookup'!$A:$A,0)),"") | BS11: =IFERROR(IF(BR11*AA11=0,"",BR11*AA11),"")
O12: =IFERROR(INDEX('_courses_lookup'!$C:$C,MATCH(K12&L12,'_courses_lookup'!$E:$E,0)),"") | P12: =IFERROR(INDEX('_courses_lookup'!$D:$D,MATCH(K12&L12,'_courses_lookup'!$E:$E,0)),"") | AG12: =IF(AND(AE12<>"",AF12<>""),ROUNDUP((AF12-AE12)/7,0),"") | AI12: =IFERROR(IF(AG12*AH12=0,"",AG12*AH12),"") | AL12: =IF(AND(AJ12<>"",AK12<>""),ROUNDUP((AK12-AJ12)/7,0),"") | AN12: =IFERROR(IF(AL12*AM12=0,"",AL12*AM12),"") | AQ12: =IF(AND(AO12<>"",AP12<>""),ROUNDUP((AP12-AO12)/7,0),"") | AR12: =IFERROR(IF((AU12-(AI12+AN12))/AQ12=0,"",ROUNDUP((AU12-(AI12+AN12))/AQ12,0)),"") | AS12: =IFERROR(IF((AU12-(AI12+AN12))=0,"",(AU12-(AI12+AN12))),"") | AT12: =IF(AND(AG12="",AQ12=""),AL12,IF(SUM(AG12,AL12,AQ12)=0,"",SUM(AG12,AL12,AQ12))) | BG12: =IF(AD12="","",YEAR(AD12)+IF(MONTH(AD12)>=5,1,0)) | BH12: =IF(AD12="","",IF(AND(MONTH(AD12)=8,DAY(AD12)>=15),"Fall",IF(MONTH(AD12)>8,"Fall",IF(MONTH(AD12)=5,"Summer",IF(MONTH(AD12)=1,"Spring",""))))) | BL12: =IFERROR(INDEX('_names_lookup'!$C:$C,MATCH(BK12,'_names_lookup'!$A:$A,0)),"") | BM12: =IFERROR(INDEX('_names_lookup'!$B:$B,MATCH(BK12,'_names_lookup'!$A:$A,0)),"") | BS12: =IFERROR(IF(BR12*AA12=0,"",BR12*AA12),"")
O13: =IFERROR(INDEX('_courses_lookup'!$C:$C,MATCH(K13&L13,'_courses_lookup'!$E:$E,0)),"") | P13: =IFERROR(INDEX('_courses_lookup'!$D:$D,MATCH(K13&L13,'_courses_lookup'!$E:$E,0)),"") | AG13: =IF(AND(AE13<>"",AF13<>""),ROUNDUP((AF13-AE13)/7,0),"") | AI13: =IFERROR(IF(AG13*AH13=0,"",AG13*AH13),"") | AL13: =IF(AND(AJ13<>"",AK13<>""),ROUNDUP((AK13-AJ13)/7,0),"") | AN13: =IFERROR(IF(AL13*AM13=0,"",AL13*AM13),"") | AQ13: =IF(AND(AO13<>"",AP13<>""),ROUNDUP((AP13-AO13)/7,0),"") | AR13: =IFERROR(IF((AU13-(AI13+AN13))/AQ13=0,"",ROUNDUP((AU13-(AI13+AN13))/AQ13,0)),"") | AS13: =IFERROR(IF((AU13-(AI13+AN13))=0,"",(AU13-(AI13+AN13))),"") | AT13: =IF(AND(AG13="",AQ13=""),AL13,IF(SUM(AG13,AL13,AQ13)=0,"",SUM(AG13,AL13,AQ13))) | BG13: =IF(AD13="","",YEAR(AD13)+IF(MONTH(AD13)>=5,1,0)) | BH13: =IF(AD13="","",IF(AND(MONTH(AD13)=8,DAY(AD13)>=15),"Fall",IF(MONTH(AD13)>8,"Fall",IF(MONTH(AD13)=5,"Summer",IF(MONTH(AD13)=1,"Spring",""))))) | BL13: =IFERROR(INDEX('_names_lookup'!$C:$C,MATCH(BK13,'_names_lookup'!$A:$A,0)),"") | BM13: =IFERROR(INDEX('_names_lookup'!$B:$B,MATCH(BK13,'_names_lookup'!$A:$A,0)),"") | BS13: =IFERROR(IF(BR13*AA13=0,"",BR13*AA13),"")
... O300: =IFERROR(INDEX('_courses_lookup'!$C:$C,MATCH(K300&L300,'_courses_lookup'!$E:$E,0)),"") | P300: =IFERROR(INDEX('_courses_lookup'!$D:$D,MATCH(K300&L300,'_courses_lookup'!$E:$E,0)),"") | AG300: =IF(AND(AE300<>"",AF300<>""),ROUNDUP((AF300-AE300)/7,0),"") | AI300: =IFERROR(IF(AG300*AH300=0,"",AG300*AH300),"") | AL300: =IF(AND(AJ300<>"",AK300<>""),ROUNDUP((AK300-AJ300)/7,0),"") | AN300: =IFERROR(IF(AL300*AM300=0,"",AL300*AM300),"") | AQ300: =IF(AND(AO300<>"",AP300<>""),ROUNDUP((AP300-AO300)/7,0),"") | AR300: =IFERROR(IF((AU300-(AI300+AN300))/AQ300=0,"",ROUNDUP((AU300-(AI300+AN300))/AQ300,0)),"") | AS300: =IFERROR(IF((AU300-(AI300+AN300))=0,"",(AU300-(AI300+AN300))),"") | AT300: =IF(AND(AG300="",AQ300=""),AL300,IF(SUM(AG300,AL300,AQ300)=0,"",SUM(AG300,AL300,AQ300))) | BG300: =IF(AD300="","",YEAR(AD300)+IF(MONTH(AD300)>=5,1,0)) | BH300: =IF(AD300="","",IF(AND(MONTH(AD300)=8,DAY(AD300)>=15),"Fall",IF(MONTH(AD300)>8,"Fall",IF(MONTH(AD300)=5,"Summer",IF(MONTH(AD300)=1,"Spring",""))))) | BL300: =IFERROR(INDEX('_names_lookup'!$C:$C,MATCH(BK300,'_names_lookup'!$A:$A,0)),"") | BM300: =IFERROR(INDEX('_names_lookup'!$B:$B,MATCH(BK300,'_names_lookup'!$A:$A,0)),"") | BS300: =IFERROR(IF(BR300*AA300=0,"",BR300*AA300),"")

Sheet MSSN
A1: Don {not in Banner} | B1: Mismatching {not in Banner} | C1: Dept/Prog Admin {not in Banner} | D1: Mona {not in Banner} | E1: Karen {not in Banner} | F1: DONE {not in Banner} | G1: Notes {not in Banner} | H1: CRN sorted {not in Banner} | I1: CRN | J1: Attribute {not in Banner} | K1: Subject | L1: Course Number {Crse Num} | M1: Course Section {Seq Crse Num} | N1: Program {not in Banner} | O1: Catalog Title | P1: Section Title | Q1: Crosslist Details {not in Banner} | R1: X Lst | S1: Campus {Ssasect Campus} | T1: Campus Restriction {Camp Restr CC} | U1: Schedule Type {not in Banner} | V1: Instruction Method {Inst Method} | W1: Level {Level SC} | X1: Part-Of-Term | Y1: Credit Catalog {Cat Crs} | Z1: Credits {Sect Crs} | AA1: Faculty Load / Contract Credits {not in Banner} | AB1: Enrollment Cap {Max Enrl} | AC1: Meeting Type | AD1: Semester Start Date {Soaterm Start Date} | AE1: Pre-work Start Date {not in Banner} | AF1: Pre-work End Date {not in Banner} | AG1: pre-work # of weeks {not in Banner} | AH1: pre-work hours/week {not in Banner} | AI1: pre-work hours/period {not in Banner} | AJ1: Intensive Period Start Date {Meet Start Date} | AK1: Intensive Period End Date {Meet End Date} | AL1: intensive # of weeks {not in Banner} | AM1: intensive hours/week {not in Banner} | AN1: intensive hours/period {not in Banner} | AO1: Post-work Start Date {not in Banner} | AP1: Post-work End Date {not in Banner} | AQ1: post-work # of weeks {not in Banner} | AR1: post-work hours/week {not in Banner} | AS1: post-work hours/period {not in Banner} | AT1: sum of weeks (for check) {not in Banner} | AU1: total contract hours {not in Banner} | AV1: Semester End Date {Soaterm End Date} | AW1: Course Beginning Time {Meet Beg Time} | AX1: Course Ending Time {Meet End Time} | AY1: SUN | AZ1: MON | BA1: TUE | BB1: WED | BC1: THU | BD1: FRI | BE1: SAT | BF1: Weeks | BG1: Fiscal Year {not in Banner} | BH1: Semester {not in Banner} | BI1: Room {Meet Room} | BJ1: Building {Meet Bldg} | BK1: Instructor Name {Instr Name} | BL1: Instructor Email {Instr Email} | BM1: Instructor ID {Instr ID} | BN1: Remote Employee {not in Banner} | BO1: % Responsibility | BP1: load/contract {not in Banner} | BQ1: Reason for Contract {not in Banner} | BR1: costs per credit {not in Banner} | BS1: total costs {not in Banner} | BT1: dept budget {not in Banner} | BU1: account to be charged {not in Banner} | BV1: SEM Department {Scacrse Dept} | BW1: dean email | BX1: VP finance email | BY1: HR email | BZ1: Fee Amount {Fees Amt} | CA1: Fee Code {Detl Code} | CB1: Fee Type | CC1: Fee Level | CD1: Fee Ind | CE1: Fee Term | CF1: Activity Date | CG1: Status | CH1: Bill Hrs | CI1: Sect Sch Type | CJ1: Prerequisites {Preq Areas} | CK1: Link Ind | CL1: Integration Code | CM1: Link Conn | CN1: Crs Attr | CO1: Comments | CP1: Major Restr | CQ1: Scacrse College | CR1: Enrolled | CS1: Waitlist Capacity | CT1: Primary Ind | CU1: Override | CV1: 1st Date Reg Opens | CW1: Last Date Reg Opens | CX1: OL Range From Date | CY1: OL Range To Date | CZ1: OL Numb Units | DA1: OL Duration Code | DB1: Grade Mode | DC1: Gradable Ind | DD1: Tuit Waiver | DE1: Course Override {Meet Override} | DF1: Lvl Res Ind | DG1: Cmp Res Ind | DH1: Rate Code | DI1: Cohort Code | DJ1: St Attr Code | DK1: Coll SC | DL1: DegC SC | DM1: Prog SC | DN1: FOS Type | DO1: Special Approval {Special Apvl} | DP1: Term Code | DQ1: Camp SC
O2: =IFERROR(INDEX('_courses_lookup'!$C:$C,MATCH(K2&L2,'_courses_lookup'!$E:$E,0)),"") | P2: =IFERROR(INDEX('_courses_lookup'!$D:$D,MATCH(K2&L2,'_courses_lookup'!$E:$E,0)),"") | AG2: =IF(AND(AE2<>"",AF2<>""),ROUNDUP((AF2-AE2)/7,0),"") | AI2: =IFERROR(IF(AG2*AH2=0,"",AG2*AH2),"") | AL2: =IF(AND(AJ2<>"",AK2<>""),ROUNDUP((AK2-AJ2)/7,0),"") | AN2: =IFERROR(IF(AL2*AM2=0,"",AL2*AM2),"") | AQ2: =IF(AND(AO2<>"",AP2<>""),ROUNDUP((AP2-AO2)/7,0),"") | AR2: =IFERROR(IF((AU2-(AI2+AN2))/AQ2=0,"",ROUNDUP((AU2-(AI2+AN2))/AQ2,0)),"") | AS2: =IFERROR(IF((AU2-(AI2+AN2))=0,"",(AU2-(AI2+AN2))),"") | AT2: =IF(AND(AG2="",AQ2=""),AL2,IF(SUM(AG2,AL2,AQ2)=0,"",SUM(AG2,AL2,AQ2))) | BG2: =IF(AD2="","",YEAR(AD2)+IF(MONTH(AD2)>=5,1,0)) | BH2: =IF(AD2="","",IF(AND(MONTH(AD2)=8,DAY(AD2)>=15),"Fall",IF(MONTH(AD2)>8,"Fall",IF(MONTH(AD2)=5,"Summer",IF(MONTH(AD2)=1,"Spring",""))))) | BK2: =IF($BJ2="","",IFERROR(INDEX(InstructorMap!$B:$B, MATCH($BJ2, InstructorMap!$A:$A, 0)),"")) | BL2: =IFERROR(INDEX('_names_lookup'!$C:$C,MATCH(BK2,'_names_lookup'!$A:$A,0)),"") | BM2: =IFERROR(INDEX('_names_lookup'!$B:$B,MATCH(BK2,'_names_lookup'!$A:$A,0)),"") | BS2: =IFERROR(IF(BR2*AA2=0,"",BR2*AA2),"")
O3: =IFERROR(INDEX('_courses_lookup'!$C:$C,MATCH(K3&L3,'_courses_lookup'!$E:$E,0)),"") | P3: =IFERROR(INDEX('_courses_lookup'!$D:$D,MATCH(K3&L3,'_courses_lookup'!$E:$E,0)),"") | AG3: =IF(AND(AE3<>"",AF3<>""),ROUNDUP((AF3-AE3)/7,0),"") | AI3: =IFERROR(IF(AG3*AH3=0,"",AG3*AH3),"") | AL3: =IF(AND(AJ3<>"",AK3<>""),ROUNDUP((AK3-AJ3)/7,0),"") | AN3: =IFERROR(IF(AL3*AM3=0,"",AL3*AM3),"") | AQ3: =IF(AND(AO3<>"",AP3<>""),ROUNDUP((AP3-AO3)/7,0),"") | AR3: =IFERROR(IF((AU3-(AI3+AN3))/AQ3=0,"",ROUNDUP((AU3-(AI3+AN3))/AQ3,0)),"") | AS3: =IFERROR(IF((AU3-(AI3+AN3))=0,"",(AU3-(AI3+AN3))),"") | AT3: =IF(AND(AG3="",AQ3=""),AL3,IF(SUM(AG3,AL3,AQ3)=0,"",SUM(AG3,AL3,AQ3))) | BG3: =IF(AD3="","",YEAR(AD3)+IF(MONTH(AD3)>=5,1,0)) | BH3: =IF(AD3="","",IF(AND(MONTH(AD3)=8,DAY(AD3)>=15),"Fall",IF(MONTH(AD3)>8,"Fall",IF(MONTH(AD3)=5,"Summer",IF(MONTH(AD3)=1,"Spring",""))))) | BK3: =IF($BJ3="","",IFERROR(INDEX(InstructorMap!$B:$B, MATCH($BJ3, InstructorMap!$A:$A, 0)),"")) | BL3: =IFERROR(INDEX('_names_lookup'!$C:$C,MATCH(BK3,'_names_lookup'!$A:$A,0)),"") | BM3: =IFERROR(INDEX('_names_lookup'!$B:$B,MATCH(BK3,'_names_lookup'!$A:$A,0)),"") | BS3: =IFERROR(IF(BR3*AA3=0,"",BR3*AA3),"")
