Workbook

Sheet contract-load_courses
A1: Faculty Name | B1: ID# | C1: email | D1: telephone | E1: status | F1: account to be charged | G1: Reason for Contract | H1: remote employee | I1: international | J1: Dept contact name | K1: Dept contact ID# | L1: Summer 2026 Course | M1: Course Section | N1: Catalog Title | O1: CRN | P1: Term 1 | Q1: Term 2 | R1: Term 3 | S1: Mode | T1: Program | U1: Location | V1: load/contract | W1: dept budget | X1: Cr. | Y1: rate per credit | Z1: total contract amount | AA1: Begin Date | AB1: End Date | AC1: pre-work period start | AD1: pre-work period end | AE1: pre-work # of weeks | AF1: pre-work hours/week | AG1: pre-work hours/period | AH1: intensive period start | AI1: intensive period end | AJ1: intensive # of weeks | AK1: intensive hours/week | AL1: intensive hours/period | AM1: post-work period start | AN1: post-work period end | AO1: post-work # of weeks | AP1: post-work hours/week | AQ1: post-work hours/period | AR1: sum of weeks (for check) | AS1: total contract hours | AT1: Fall 2026 Course | AU1: Course Section | AV1: Catalog Title | AW1: CRN | AX1: Mode | AY1: Program | AZ1: Location | BA1: load/contract | BB1: dept budget | BC1: Cr. | BD1: rate per credit | BE1: total contract amount | BF1: Begin Date | BG1: End Date | BH1: pre-work period start | BI1: pre-work period end | BJ1: pre-work # of weeks | BK1: pre-work hours/week | BL1: pre-work hours/period | BM1: intensive period start | BN1: intensive period end | BO1: intensive # of weeks | BP1: intensive hours/week | BQ1: intensive hours/period | BR1: post-work period start | BS1: post-work period end | BT1: post-work # of weeks | BU1: post-work hours/week | BV1: post-work hours/period | BW1: sum of weeks (for check) | BX1: total contract hours | BY1: Spring 2027 Course | BZ1: Course Section | CA1: Catalog Title | CB1: CRN | CC1: Mode | CD1: Program | CE1: Location | CF1: load/contract | CG1: dept budget | CH1: Cr. | CI1: rate per credit | CJ1: total contract amount | CK1: Begin Date | CL1: End Date | CM1: pre-work period start | CN1: pre-work period end | CO1: pre-work # of weeks | CP1: pre-work hours/week | CQ1: pre-work hours/period | CR1: intensive period start | CS1: intensive period end | CT1: intensive # of weeks | CU1: intensive hours/week | CV1: intensive hours/period | CW1: post-work period start | CX1: post-work period end | CY1: post-work # of weeks | CZ1: post-work hours/week | DA1: post-work hours/period | DB1: sum of weeks (for check) | DC1: total contract hours | DD1: Total Cr. | DE1: order
A2: Totals: Alain Coralie notes: | B2: ="Total Credits: " & IFERROR(IF(DD2=0,"",DD2),"") -> Total Credits: 16 | X2: =IF(SUM(X3:X11)=0, "", SUM(X3:X11)) -> 7 | BC2: =IF(SUM(BC3:BC11)=0, "", SUM(BC3:BC11)) -> 7 | CH2: =IF(SUM(CH3:CH11)=0, "", SUM(CH3:CH11)) -> 2 | DD2: =IF(SUM(L2:DC2)=0, "", SUM(L2:DC2)) -> 16 | DE2: 0
A3: Coralie, Alain | B3: =IF(_xlfn.XLOOKUP(A3, AutoFill_names!B:B, AutoFill_names!C:C,"")=0,"",_xlfn.XLOOKUP(A3, AutoFill_names!B:B, AutoFill_names!C:C,"")) | C3: =IF(_xlfn.XLOOKUP(A3, AutoFill_names!B:B, AutoFill_names!D:D,"")=0,"",_xlfn.XLOOKUP(A3, AutoFill_names!B:B, AutoFill_names!D:D,"")) | D3: =IF(_xlfn.XLOOKUP(A3, AutoFill_names!B:B, AutoFill_names!E:E,"")=0,"",_xlfn.XLOOKUP(A3, AutoFill_names!B:B, AutoFill_names!E:E,"")) | E3: =IF(_xlfn.XLOOKUP(A3, AutoFill_names!B:B, AutoFill_names!F:F,"")=0,"",_xlfn.XLOOKUP(A3, AutoFill_names!B:B, AutoFill_names!F:F,"")) | J3: =IF(_xlfn.XLOOKUP(A3, AutoFill_names!B:B, AutoFill_names!K:K,"")=0,"",_xlfn.XLOOKUP(A3, AutoFill_names!B:B, AutoFill_names!K:K,"")) | K3: =IF(_xlfn.XLOOKUP(A3, AutoFill_names!B:B, AutoFill_names!L:L,"")=0,"",_xlfn.XLOOKUP(A3, AutoFill_names!B:B, AutoFill_names!L:L,"")) | L3: PATH543 | N3: =IF(_xlfn.XLOOKUP(L3, AutoFill_classes!A:A, AutoFill_classes!B:B,"")=0,"",_xlfn.XLOOKUP(L3, AutoFill_classes!A:A, AutoFill_classes!B:B,"")) -> Christn Lead in a Chnging Wrld | S3: In-Person | T3: MDIV | U3: Main Campus - MC | V3: load | W3: yes | X3: 2 | Z3: =IF(X3*Y3=0,"",X3*Y3) | AE3: =IF(ROUNDUP((AD3-AC3)/7,0)=0,"",ROUNDUP((AD3-AC3)/7,0)) | AG3: =IFERROR(IF(AE3*AF3=0,"",AE3*AF3), "") | AJ3: =IF(ROUNDUP((AI3-AH3)/7,0)=0,"",ROUNDUP((AI3-AH3)/7,0)) | AL3: =IFERROR(IF(AJ3*AK3=0,"",AJ3*AK3), "") | AO3: =IF(ROUNDUP((AN3-AM3)/7,0)=0,"",ROUNDUP((AN3-AM3)/7,0)) | AP3: =IFERROR(IF((AS3-(AF3+AK3))/AO3=0,"",ROUNDUP((AS3-(AF3+AK3))/AO3,0)), "") | AQ3: =IFERROR(IF((AS3-(AG3+AL3))=0, "", (AS3-(AG3+AL3))), "") | AR3: =IFERROR(IF((AE3+AJ3+AO3)=0, "", (AE3+AJ3+AO3)), "") | AT3: PATH543 | AV3: =IF(_xlfn.XLOOKUP(AT3, AutoFill_classes!$A:$A, AutoFill_classes!$B:$B,"")=0,"",_xlfn.XLOOKUP(AT3, AutoFill_classes!$A:$A, AutoFill_classes!$B:$B,"")) -> Christn Lead in a Chnging Wrld | AX3: In-Person | AY3: MDIV | AZ3: Main Campus - MC | BA3: load | BB3: yes | BC3: 2 | BE3: =IF(BC3*BD3=0,"",BC3*BD3) | BJ3: =IF(ROUNDUP((BI3-BH3)/7,0)=0,"",ROUNDUP((BI3-BH3)/7,0)) | BL3: =IFERROR(IF(BJ3*BK3=0,"",BJ3*BK3), "") | BO3: =IF(ROUNDUP((BN3-BM3)/7,0)=0,"",ROUNDUP((BN3-BM3)/7,0)) | BQ3: =IFERROR(IF(BO3*BP3=0,"",BO3*BP3), "") | BT3: =IF(ROUNDUP((BS3-BR3)/7,0)=0,"",ROUNDUP((BS3-BR3)/7,0)) | BU3: =IFERROR(IF((BX3-(BK3+BP3))/BT3=0,"",ROUNDUP((BX3-(BK3+BP3))/BT3,0)), "") | BV3: =IFERROR(IF((BX3-(BL3+BQ3))=0, "", (BX3-(BL3+BQ3))), "") | BW3: =IFERROR(IF((BJ3+BO3+BT3)=0, "", (BJ3+BO3+BT3)), "") | BY3: PATH543 | CA3: =IF(_xlfn.XLOOKUP(BY3, AutoFill_classes!$A:$A, AutoFill_classes!$B:$B,"")=0,"",_xlfn.XLOOKUP(BY3, AutoFill_classes!$A:$A, AutoFill_classes!$B:$B,"")) -> Christn Lead in a Chnging Wrld | CC3: ASYNC | CD3: MDIV | CE3: Main Campus - MC | CF3: load | CG3: yes | CH3: 2 | CJ3: =IF(CH3*CI3=0,"",CH3*CI3) | CO3: =IF(ROUNDUP((CN3-CM3)/7,0)=0,"",ROUNDUP((CN3-CM3)/7,0)) | CQ3: =IFERROR(IF(CO3*CP3=0,"",CO3*CP3), "") | CT3: =IF(ROUNDUP((CS3-CR3)/7,0)=0,"",ROUNDUP((CS3-CR3)/7,0)) | CV3: =IFERROR(IF(CT3*CU3=0,"",CT3*CU3), "") | CY3: =IF(ROUNDUP((CX3-CW3)/7,0)=0,"",ROUNDUP((CX3-CW3)/7,0)) | CZ3: =IFERROR(IF((DC3-(CP3+CU3))/CY3=0,"",ROUNDUP((DC3-(CP3+CU3))/CY3,0)), "") | DA3: =IFERROR(IF((DC3-(CQ3+CV3))=0, "", (DC3-(CQ3+CV3))), "") | DB3: =IFERROR(IF((CO3+CT3+CY3)=0, "", (CO3+CT3+CY3)), "") | DE3: 1
A4: Coralie, Alain | B4: =IF(_xlfn.XLOOKUP(A4, AutoFill_names!B:B, AutoFill_names!C:C,"")=0,"",_xlfn.XLOOKUP(A4, AutoFill_names!B:B, AutoFill_names!C:C,"")) | C4: =IF(_xlfn.XLOOKUP(A4, AutoFill_names!B:B, AutoFill_names!D:D,"")=0,"",_xlfn.XLOOKUP(A4, AutoFill_names!B:B, AutoFill_names!D:D,"")) | D4: =IF(_xlfn.XLOOKUP(A4, AutoFill_names!B:B, AutoFill_names!E:E,"")=0,"",_xlfn.XLOOKUP(A4, AutoFill_names!B:B, AutoFill_names!E:E,"")) | E4: =IF(_xlfn.XLOOKUP(A4, AutoFill_names!B:B, AutoFill_names!F:F,"")=0,"",_xlfn.XLOOKUP(A4, AutoFill_names!B:B, AutoFill_names!F:F,"")) | J4: =IF(_xlfn.XLOOKUP(A4, AutoFill_names!B:B, AutoFill_names!K:K,"")=0,"",_xlfn.XLOOKUP(A4, AutoFill_names!B:B, AutoFill_names!K:K,"")) | K4: =IF(_xlfn.XLOOKUP(A4, AutoFill_names!B:B, AutoFill_names!L:L,"")=0,"",_xlfn.XLOOKUP(A4, AutoFill_names!B:B, AutoFill_names!L:L,"")) | L4: PATH543 | N4: =IF(_xlfn.XLOOKUP(L4, AutoFill_classes!A:A, AutoFill_classes!B:B,"")=0,"",_xlfn.XLOOKUP(L4, AutoFill_classes!A:A, AutoFill_classes!B:B,"")) -> Christn Lead in a Chnging Wrld | S4: ASYNC | T4: MDIV | U4: Main Campus - MC | V4: load | W4: yes | X4: 2 | Z4: =IF(X4*Y4=0,"",X4*Y4) | AE4: =IF(ROUNDUP((AD4-AC4)/7,0)=0,"",ROUNDUP((AD4-AC4)/7,0)) | AG4: =IFERROR(IF(AE4*AF4=0,"",AE4*AF4), "") | AJ4: =IF(ROUNDUP((AI4-AH4)/7,0)=0,"",ROUNDUP((AI4-AH4)/7,0)) | AL4: =IFERROR(IF(AJ4*AK4=0,"",AJ4*AK4), "") | AO4: =IF(ROUNDUP((AN4-AM4)/7,0)=0,"",ROUNDUP((AN4-AM4)/7,0)) | AP4: =IFERROR(IF((AS4-(AF4+AK4))/AO4=0,"",ROUNDUP((AS4-(AF4+AK4))/AO4,0)), "") | AQ4: =IFERROR(IF((AS4-(AG4+AL4))=0, "", (AS4-(AG4+AL4))), "") | AR4: =IFERROR(IF((AE4+AJ4+AO4)=0, "", (AE4+AJ4+AO4)), "") | AT4: PATH543 | AU4: 998 | AV4: =IF(_xlfn.XLOOKUP(AT4, AutoFill_classes!$A:$A, AutoFill_classes!$B:$B,"")=0,"",_xlfn.XLOOKUP(AT4, AutoFill_classes!$A:$A, AutoFill_classes!$B:$B,"")) -> Christn Lead in a Chnging Wrld | AX4: SYNC | AY4: MDIV | AZ4: Main Campus - MC | BA4: load | BB4: yes | BC4: 0 | BE4: =IF(BC4*BD4=0,"",BC4*BD4) | BJ4: =IF(ROUNDUP((BI4-BH4)/7,0)=0,"",ROUNDUP((BI4-BH4)/7,0)) | BL4: =IFERROR(IF(BJ4*BK4=0,"",BJ4*BK4), "") | BO4: =IF(ROUNDUP((BN4-BM4)/7,0)=0,"",ROUNDUP((BN4-BM4)/7,0)) | BQ4: =IFERROR(IF(BO4*BP4=0,"",BO4*BP4), "") | BT4: =IF(ROUNDUP((BS4-BR4)/7,0)=0,"",ROUNDUP((BS4-BR4)/7,0)) | BU4: =IFERROR(IF((BX4-(BK4+BP4))/BT4=0,"",ROUNDUP((BX4-(BK4+BP4))/BT4,0)), "") | BV4: =IFERROR(IF((BX4-(BL4+BQ4))=0, "", (BX4-(BL4+BQ4))), "") | BW4: =IFERROR(IF((BJ4+BO4+BT4)=0, "", (BJ4+BO4+BT4)), "") | CA4: =IF(_xlfn.XLOOKUP(BY4, AutoFill_classes!$A:$A, AutoFill_classes!$B:$B,"")=0,"",_xlfn.XLOOKUP(BY4, AutoFill_classes!$A:$A, AutoFill_classes!$B:$B,"")) | CJ4: =IF(CH4*CI4=0,"",CH4*CI4) | CO4: =IF(ROUNDUP((CN4-CM4)/7,0)=0,"",ROUNDUP((CN4-CM4)/7,0)) | CQ4: =IFERROR(IF(CO4*CP4=0,"",CO4*CP4), "") | CT4: =IF(ROUNDUP((CS4-CR4)/7,0)=0,"",ROUNDUP((CS4-CR4)/7,0)) | CV4: =IFERROR(IF(CT4*CU4=0,"",CT4*CU4), "") | CY4: =IF(ROUNDUP((CX4-CW4)/7,0)=0,"",ROUNDUP((CX4-CW4)/7,0)) | CZ4: =IFERROR(IF((DC4-(CP4+CU4))/CY4=0,"",ROUNDUP((DC4-(CP4+CU4))/CY4,0)), "") | DA4: =IFERROR(IF((DC4-(CQ4+CV4))=0, "", (DC4-(CQ4+CV4))), "") | DB4: =IFERROR(IF((CO4+CT4+CY4)=0, "", (CO4+CT4+CY4)), "") | DE4: 2
A5: Coralie, Alain | B5: =IF(_xlfn.XLOOKUP(A5, AutoFill_names!B:B, AutoFill_names!C:C,"")=0,"",_xlfn.XLOOKUP(A5, AutoFill_names!B:B, AutoFill_names!C:C,"")) | C5: =IF(_xlfn.XLOOKUP(A5, AutoFill_names!B:B, AutoFill_names!D:D,"")=0,"",_xlfn.XLOOKUP(A5, AutoFill_names!B:B, AutoFill_names!D:D,"")) | D5: =IF(_xlfn.XLOOKUP(A5, AutoFill_names!B:B, AutoFill_names!E:E,"")=0,"",_xlfn.XLOOKUP(A5, AutoFill_names!B:B, AutoFill_names!E:E,"")) | E5: =IF(_xlfn.XLOOKUP(A5, AutoFill_names!B:B, AutoFill_names!F:F,"")=0,"",_xlfn.XLOOKUP(A5, AutoFill_names!B:B, AutoFill_names!F:F,"")) | J5: =IF(_xlfn.XLOOKUP(A5, AutoFill_names!B:B, AutoFill_names!K:K,"")=0,"",_xlfn.XLOOKUP(A5, AutoFill_names!B:B, AutoFill_names!K:K,"")) | K5: =IF(_xlfn.XLOOKUP(A5, AutoFill_names!B:B, AutoFill_names!L:L,"")=0,"",_xlfn.XLOOKUP(A5, AutoFill_names!B:B, AutoFill_names!L:L,"")) | L5: PATH543 | N5: =IF(_xlfn.XLOOKUP(L5, AutoFill_classes!A:A, AutoFill_classes!B:B,"")=0,"",_xlfn.XLOOKUP(L5, AutoFill_classes!A:A, AutoFill_classes!B:B,"")) -> Christn Lead in a Chnging Wrld | S5: In-Person | T5: MAPM-ENGL | U5: Lake Union- LU | V5: load | W5: yes | X5: 3 | Z5: =IF(X5*Y5=0,"",X5*Y5) | AE5: =IF(ROUNDUP((AD5-AC5)/7,0)=0,"",ROUNDUP((AD5-AC5)/7,0)) | AG5: =IFERROR(IF(AE5*AF5=0,"",AE5*AF5), "") | AJ5: =IF(ROUNDUP((AI5-AH5)/7,0)=0,"",ROUNDUP((AI5-AH5)/7,0)) | AL5: =IFERROR(IF(AJ5*AK5=0,"",AJ5*AK5), "") | AO5: =IF(ROUNDUP((AN5-AM5)/7,0)=0,"",ROUNDUP((AN5-AM5)/7,0)) | AP5: =IFERROR(IF((AS5-(AF5+AK5))/AO5=0,"",ROUNDUP((AS5-(AF5+AK5))/AO5,0)), "") | AQ5: =IFERROR(IF((AS5-(AG5+AL5))=0, "", (AS5-(AG5+AL5))), "") | AR5: =IFERROR(IF((AE5+AJ5+AO5)=0, "", (AE5+AJ5+AO5)), "") | AT5: PATH543 | AV5: =IF(_xlfn.XLOOKUP(AT5, AutoFill_classes!$A:$A, AutoFill_classes!$B:$B,"")=0,"",_xlfn.XLOOKUP(AT5, AutoFill_classes!$A:$A, AutoFill_classes!$B:$B,"")) -> Christn Lead in a Chnging Wrld | AX5: In-Person | AY5: MAPM-ENGL | AZ5: Columbia Union - CU | BA5: load | BB5: yes | BC5: 3 | BE5: =IF(BC5*BD5=0,"",BC5*BD5) | BJ5: =IF(ROUNDUP((BI5-BH5)/7,0)=0,"",ROUNDUP((BI5-BH5)/7,0)) | BL5: =IFERROR(IF(BJ5*BK5=0,"",BJ5*BK5), "") | BO5: =IF(ROUNDUP((BN5-BM5)/7,0)=0,"",ROUNDUP((BN5-BM5)/7,0)) | BQ5: =IFERROR(IF(BO5*BP5=0,"",BO5*BP5), "") | BT5: =IF(ROUNDUP((BS5-BR5)/7,0)=0,"",ROUNDUP((BS5-BR5)/7,0)) | BU5: =IFERROR(IF((BX5-(BK5+BP5))/BT5=0,"",ROUNDUP((BX5-(BK5+BP5))/BT5,0)), "") | BV5: =IFERROR(IF((BX5-(BL5+BQ5))=0, "", (BX5-(BL5+BQ5))), "") | BW5: =IFERROR(IF((BJ5+BO5+BT5)=0, "", (BJ5+BO5+BT5)), "") | CA5: =IF(_xlfn.XLOOKUP(BY5, AutoFill_classes!$A:$A, AutoFill_classes!$B:$B,"")=0,"",_xlfn.XLOOKUP(BY5, AutoFill_classes!$A:$A, AutoFill_classes!$B:$B,"")) | CJ5: =IF(CH5*CI5=0,"",CH5*CI5) | CO5: =IF(ROUNDUP((CN5-CM5)/7,0)=0,"",ROUNDUP((CN5-CM5)/7,0)) | CQ5: =IFERROR(IF(CO5*CP5=0,"",CO5*CP5), "") | CT5: =IF(ROUNDUP((CS5-CR5)/7,0)=0,"",ROUNDUP((CS5-CR5)/7,0)) | CV5: =IFERROR(IF(CT5*CU5=0,"",CT5*CU5), "") | CY5: =IF(ROUNDUP((CX5-CW5)/7,0)=0,"",ROUNDUP((CX5-CW5)/7,0)) | CZ5: =IFERROR(IF((DC5-(CP5+CU5))/CY5=0,"",ROUNDUP((DC5-(CP5+CU5))/CY5,0)), "") | DA5: =IFERROR(IF((DC5-(CQ5+CV5))=0, "", (DC5-(CQ5+CV5))), "") | DB5: =IFERROR(IF((CO5+CT5+CY5)=0, "", (CO5+CT5+CY5)), "") | DE5: 3
A6: Coralie, Alain | B6: =IF(_xlfn.XLOOKUP(A6, AutoFill_names!B:B, AutoFill_names!C:C,"")=0,"",_xlfn.XLOOKUP(A6, AutoFill_names!B:B, AutoFill_names!C:C,"")) | C6: =IF(_xlfn.XLOOKUP(A6, AutoFill_names!B:B, AutoFill_names!D:D,"")=0,"",_xlfn.XLOOKUP(A6, AutoFill_names!B:B, AutoFill_names!D:D,"")) | D6: =IF(_xlfn.XLOOKUP(A6, AutoFill_names!B:B, AutoFill_names!E:E,"")=0,"",_xlfn.XLOOKUP(A6, AutoFill_names!B:B, AutoFill_names!E:E,"")) | E6: =IF(_xlfn.XLOOKUP(A6, AutoFill_names!B:B, AutoFill_names!F:F,"")=0,"",_xlfn.XLOOKUP(A6, AutoFill_names!B:B, AutoFill_names!F:F,"")) | J6: =IF(_xlfn.XLOOKUP(A6, AutoFill_names!B:B, AutoFill_names!K:K,"")=0,"",_xlfn.XLOOKUP(A6, AutoFill_names!B:B, AutoFill_names!K:K,"")) | K6: =IF(_xlfn.XLOOKUP(A6, AutoFill_names!B:B, AutoFill_names!L:L,"")=0,"",_xlfn.XLOOKUP(A6, AutoFill_names!B:B, AutoFill_names!L:L,"")) | N6: =IF(_xlfn.XLOOKUP(L6, AutoFill_classes!A:A, AutoFill_classes!B:B,"")=0,"",_xlfn.XLOOKUP(L6, AutoFill_classes!A:A, AutoFill_classes!B:B,"")) | Z6: =IF(X6*Y6=0,"",X6*Y6) | AE6: =IF(ROUNDUP((AD6-AC6)/7,0)=0,"",ROUNDUP((AD6-AC6)/7,0)) | AG6: =IFERROR(IF(AE6*AF6=0,"",AE6*AF6), "") | AJ6: =IF(ROUNDUP((AI6-AH6)/7,0)=0,"",ROUNDUP((AI6-AH6)/7,0)) | AL6: =IFERROR(IF(AJ6*AK6=0,"",AJ6*AK6), "") | AO6: =IF(ROUNDUP((AN6-AM6)/7,0)=0,"",ROUNDUP((AN6-AM6)/7,0)) | AP6: =IFERROR(IF((AS6-(AF6+AK6))/AO6=0,"",ROUNDUP((AS6-(AF6+AK6))/AO6,0)), "") | AQ6: =IFERROR(IF((AS6-(AG6+AL6))=0, "", (AS6-(AG6+AL6))), "") | AR6: =IFERROR(IF((AE6+AJ6+AO6)=0, "", (AE6+AJ6+AO6)), "") | AT6: PATH526 | AV6: =IF(_xlfn.XLOOKUP(AT6, AutoFill_classes!$A:$A, AutoFill_classes!$B:$B,"")=0,"",_xlfn.XLOOKUP(AT6, AutoFill_classes!$A:$A, AutoFill_classes!$B:$B,"")) -> Conflict Management | AX6: ASYNC | AY6: MDIV | AZ6: Main Campus - MC | BA6: load | BB6: yes | BC6: 2 | BE6: =IF(BC6*BD6=0,"",BC6*BD6) | BJ6: =IF(ROUNDUP((BI6-BH6)/7,0)=0,"",ROUNDUP((BI6-BH6)/7,0)) | BL6: =IFERROR(IF(BJ6*BK6=0,"",BJ6*BK6), "") | BO6: =IF(ROUNDUP((BN6-BM6)/7,0)=0,"",ROUNDUP((BN6-BM6)/7,0)) | BQ6: =IFERROR(IF(BO6*BP6=0,"",BO6*BP6), "") | BT6: =IF(ROUNDUP((BS6-BR6)/7,0)=0,"",ROUNDUP((BS6-BR6)/7,0)) | BU6: =IFERROR(IF((BX6-(BK6+BP6))/BT6=0,"",ROUNDUP((BX6-(BK6+BP6))/BT6,0)), "") | BV6: =IFERROR(IF((BX6-(BL6+BQ6))=0, "", (BX6-(BL6+BQ6))), "") | BW6: =IFERROR(IF((BJ6+BO6+BT6)=0, "", (BJ6+BO6+BT6)), "") | CA6: =IF(_xlfn.XLOOKUP(BY6, AutoFill_classes!$A:$A, AutoFill_classes!$B:$B,"")=0,"",_xlfn.XLOOKUP(BY6, AutoFill_classes!$A:$A, AutoFill_classes!$B:$B,"")) | CJ6: =IF(CH6*CI6=0,"",CH6*CI6) | CO6: =IF(ROUNDUP((CN6-CM6)/7,0)=0,"",ROUNDUP((CN6-CM6)/7,0)) | CQ6: =IFERROR(IF(CO6*CP6=0,"",CO6*CP6), "") | CT6: =IF(ROUNDUP((CS6-CR6)/7,0)=0,"",ROUNDUP((CS6-CR6)/7,0)) | CV6: =IFERROR(IF(CT6*CU6=0,"",CT6*CU6), "") | CY6: =IF(ROUNDUP((CX6-CW6)/7,0)=0,"",ROUNDUP((CX6-CW6)/7,0)) | CZ6: =IFERROR(IF((DC6-(CP6+CU6))/CY6=0,"",ROUNDUP((DC6-(CP6+CU6))/CY6,0)), "") | DA6: =IFERROR(IF((DC6-(CQ6+CV6))=0, "", (DC6-(CQ6+CV6))), "") | DB6: =IFERROR(IF((CO6+CT6+CY6)=0, "", (CO6+CT6+CY6)), "") | DE6: 4
B7: =IF(_xlfn.XLOOKUP(A7, AutoFill_names!B:B, AutoFill_names!C:C,"")=0,"",_xlfn.XLOOKUP(A7, AutoFill_names!B:B, AutoFill_names!C:C,"")) | C7: =IF(_xlfn.XLOOKUP(A7, AutoFill_names!B:B, AutoFill_names!D:D,"")=0,"",_xlfn.XLOOKUP(A7, AutoFill_names!B:B, AutoFill_names!D:D,"")) | D7: =IF(_xlfn.XLOOKUP(A7, AutoFill_names!B:B, AutoFill_names!E:E,"")=0,"",_xlfn.XLOOKUP(A7, AutoFill_names!B:B, AutoFill_names!E:E,"")) | E7: =IF(_xlfn.XLOOKUP(A7, AutoFill_names!B:B, AutoFill_names!F:F,"")=0,"",_xlfn.XLOOKUP(A7, AutoFill_names!B:B, AutoFill_names!F:F,"")) | J7: =IF(_xlfn.XLOOKUP(A7, AutoFill_names!B:B, AutoFill_names!K:K,"")=0,"",_xlfn.XLOOKUP(A7, AutoFill_names!B:B, AutoFill_names!K:K,"")) | K7: =IF(_xlfn.XLOOKUP(A7, AutoFill_names!B:B, AutoFill_names!L:L,"")=0,"",_xlfn.XLOOKUP(A7, AutoFill_names!B:B, AutoFill_names!L:L,"")) | N7: =IF(_xlfn.XLOOKUP(L7, AutoFill_classes!A:A, AutoFill_classes!B:B,"")=0,"",_xlfn.XLOOKUP(L7, AutoFill_classes!A:A, AutoFill_classes!B:B,"")) | Z7: =IF(X7*Y7=0,"",X7*Y7) | AE7: =IF(ROUNDUP((AD7-AC7)/7,0)=0,"",ROUNDUP((AD7-AC7)/7,0)) | AG7: =IFERROR(IF(AE7*AF7=0,"",AE7*AF7), "") | AJ7: =IF(ROUNDUP((AI7-AH7)/7,0)=0,"",ROUNDUP((AI7-AH7)/7,0)) | AL7: =IFERROR(IF(AJ7*AK7=0,"",AJ7*AK7), "") | AO7: =IF(ROUNDUP((AN7-AM7)/7,0)=0,"",ROUNDUP((AN7-AM7)/7,0)) | AP7: =IFERROR(IF((AS7-(AF7+AK7))/AO7=0,"",ROUNDUP((AS7-(AF7+AK7))/AO7,0)), "") | AQ7: =IFERROR(IF((AS7-(AG7+AL7))=0, "", (AS7-(AG7+AL7))), "") | AR7: =IFERROR(IF((AE7+AJ7+AO7)=0, "", (AE7+AJ7+AO7)), "") | AV7: =IF(_xlfn.XLOOKUP(AT7, AutoFill_classes!$A:$A, AutoFill_classes!$B:$B,"")=0,"",_xlfn.XLOOKUP(AT7, AutoFill_classes!$A:$A, AutoFill_classes!$B:$B,"")) | BE7: =IF(BC7*BD7=0,"",BC7*BD7) | BJ7: =IF(ROUNDUP((BI7-BH7)/7,0)=0,"",ROUNDUP((BI7-BH7)/7,0)) | BL7: =IFERROR(IF(BJ7*BK7=0,"",BJ7*BK7), "") | BO7: =IF(ROUNDUP((BN7-BM7)/7,0)=0,"",ROUNDUP((BN7-BM7)/7,0)) | BQ7: =IFERROR(IF(BO7*BP7=0,"",BO7*BP7), "") | BT7: =IF(ROUNDUP((BS7-BR7)/7,0)=0,"",ROUNDUP((BS7-BR7)/7,0)) | BU7: =IFERROR(IF((BX7-(BK7+BP7))/BT7=0,"",ROUNDUP((BX7-(BK7+BP7))/BT7,0)), "") | BV7: =IFERROR(IF((BX7-(BL7+BQ7))=0, "", (BX7-(BL7+BQ7))), "") | BW7: =IFERROR(IF((BJ7+BO7+BT7)=0, "", (BJ7+BO7+BT7)), "") | CA7: =IF(_xlfn.XLOOKUP(BY7, AutoFill_classes!$A:$A, AutoFill_classes!$B:$B,"")=0,"",_xlfn.XLOOKUP(BY7, AutoFill_classes!$A:$A, AutoFill_classes!$B:$B,"")) | CJ7: =IF(CH7*CI7=0,"",CH7*CI7) | CO7: =IF(ROUNDUP((CN7-CM7)/7,0)=0,"",ROUNDUP((CN7-CM7)/7,0)) | CQ7: =IFERROR(IF(CO7*CP7=0,"",CO7*CP7), "") | CT7: =IF(ROUNDUP((CS7-CR7)/7,0)=0,"",ROUNDUP((CS7-CR7)/7,0)) | CV7: =IFERROR(IF(CT7*CU7=0,"",CT7*CU7), "") | CY7: =IF(ROUNDUP((CX7-CW7)/7,0)=0,"",ROUNDUP((CX7-CW7)/7,0)) | CZ7: =IFERROR(IF((DC7-(CP7+CU7))/CY7=0,"",ROUNDUP((DC7-(CP7+CU7))/CY7,0)), "") | DA7: =IFERROR(IF((DC7-(CQ7+CV7))=0, "", (DC7-(CQ7+CV7))), "") | DB7: =IFERROR(IF((CO7+CT7+CY7)=0, "", (CO7+CT7+CY7)), "") | DE7: 5
B8: =IF(_xlfn.XLOOKUP(A8, AutoFill_names!B:B, AutoFill_names!C:C,"")=0,"",_xlfn.XLOOKUP(A8, AutoFill_names!B:B, AutoFill_names!C:C,"")) | C8: =IF(_xlfn.XLOOKUP(A8, AutoFill_names!B:B, AutoFill_names!D:D,"")=0,"",_xlfn.XLOOKUP(A8, AutoFill_names!B:B, AutoFill_names!D:D,"")) | D8: =IF(_xlfn.XLOOKUP(A8, AutoFill_names!B:B, AutoFill_names!E:E,"")=0,"",_xlfn.XLOOKUP(A8, AutoFill_names!B:B, AutoFill_names!E:E,"")) | E8: =IF(_xlfn.XLOOKUP(A8, AutoFill_names!B:B, AutoFill_names!F:F,"")=0,"",_xlfn.XLOOKUP(A8, AutoFill_names!B:B, AutoFill_names!F:F,"")) | J8: =IF(_xlfn.XLOOKUP(A8, AutoFill_names!B:B, AutoFill_names!K:K,"")=0,"",_xlfn.XLOOKUP(A8, AutoFill_names!B:B, AutoFill_names!K:K,"")) | K8: =IF(_xlfn.XLOOKUP(A8, AutoFill_names!B:B, AutoFill_names!L:L,"")=0,"",_xlfn.XLOOKUP(A8, AutoFill_names!B:B, AutoFill_names!L:L,"")) | N8: =IF(_xlfn.XLOOKUP(L8, AutoFill_classes!A:A, AutoFill_classes!B:B,"")=0,"",_xlfn.XLOOKUP(L8, AutoFill_classes!A:A, AutoFill_classes!B:B,"")) | Z8: =IF(X8*Y8=0,"",X8*Y8) | AE8: =IF(ROUNDUP((AD8-AC8)/7,0)=0,"",ROUNDUP((AD8-AC8)/7,0)) | AG8: =IFERROR(IF(AE8*AF8=0,"",AE8*AF8), "") | AJ8: =IF(ROUNDUP((AI8-AH8)/7,0)=0,"",ROUNDUP((AI8-AH8)/7,0)) | AL8: =IFERROR(IF(AJ8*AK8=0,"",AJ8*AK8), "") | AO8: =IF(ROUNDUP((AN8-AM8)/7,0)=0,"",ROUNDUP((AN8-AM8)/7,0)) | AP8: =IFERROR(IF((AS8-(AF8+AK8))/AO8=0,"",ROUNDUP((AS8-(AF8+AK8))/AO8,0)), "") | AQ8: =IFERROR(IF((AS8-(AG8+AL8))=0, "", (AS8-(AG8+AL8))), "") | AR8: =IFERROR(IF((AE8+AJ8+AO8)=0, "", (AE8+AJ8+AO8)), "") | AV8: =IF(_xlfn.XLOOKUP(AT8, AutoFill_classes!$A:$A, AutoFill_classes!$B:$B,"")=0,"",_xlfn.XLOOKUP(AT8, AutoFill_classes!$A:$A, AutoFill_classes!$B:$B,"")) | BE8: =IF(BC8*BD8=0,"",BC8*BD8) | BJ8: =IF(ROUNDUP((BI8-BH8)/7,0)=0,"",ROUNDUP((BI8-BH8)/7,0)) | BL8: =IFERROR(IF(BJ8*BK8=0,"",BJ8*BK8), "") | BO8: =IF(ROUNDUP((BN8-BM8)/7,0)=0,"",ROUNDUP((BN8-BM8)/7,0)) | BQ8: =IFERROR(IF(BO8*BP8=0,"",BO8*BP8), "") | BT8: =IF(ROUNDUP((BS8-BR8)/7,0)=0,"",ROUNDUP((BS8-BR8)/7,0)) | BU8: =IFERROR(IF((BX8-(BK8+BP8))/BT8=0,"",ROUNDUP((BX8-(BK8+BP8))/BT8,0)), "") | BV8: =IFERROR(IF((BX8-(BL8+BQ8))=0, "", (BX8-(BL8+BQ8))), "") | BW8: =IFERROR(IF((BJ8+BO8+BT8)=0, "", (BJ8+BO8+BT8)), "") | CA8: =IF(_xlfn.XLOOKUP(BY8, AutoFill_classes!$A:$A, AutoFill_classes!$B:$B,"")=0,"",_xlfn.XLOOKUP(BY8, AutoFill_classes!$A:$A, AutoFill_classes!$B:$B,"")) | CJ8: =IF(CH8*CI8=0,"",CH8*CI8) | CO8: =IF(ROUNDUP((CN8-CM8)/7,0)=0,"",ROUNDUP((CN8-CM8)/7,0)) | CQ8: =IFERROR(IF(CO8*CP8=0,"",CO8*CP8), "") | CT8: =IF(ROUNDUP((CS8-CR8)/7,0)=0,"",ROUNDUP((CS8-CR8)/7,0)) | CV8: =IFERROR(IF(CT8*CU8=0,"",CT8*CU8), "") | CY8: =IF(ROUNDUP((CX8-CW8)/7,0)=0,"",ROUNDUP((CX8-CW8)/7,0)) | CZ8: =IFERROR(IF((DC8-(CP8+CU8))/CY8=0,"",ROUNDUP((DC8-(CP8+CU8))/CY8,0)), "") | DA8: =IFERROR(IF((DC8-(CQ8+CV8))=0, "", (DC8-(CQ8+CV8))), "") | DB8: =IFERROR(IF((CO8+CT8+CY8)=0, "", (CO8+CT8+CY8)), "") | DE8: 6
B9: =IF(_xlfn.XLOOKUP(A9, AutoFill_names!B:B, AutoFill_names!C:C,"")=0,"",_xlfn.XLOOKUP(A9, AutoFill_names!B:B, AutoFill_names!C:C,"")) | C9: =IF(_xlfn.XLOOKUP(A9, AutoFill_names!B:B, AutoFill_names!D:D,"")=0,"",_xlfn.XLOOKUP(A9, AutoFill_names!B:B, AutoFill_names!D:D,"")) | D9: =IF(_xlfn.XLOOKUP(A9, AutoFill_names!B:B, AutoFill_names!E:E,"")=0,"",_xlfn.XLOOKUP(A9, AutoFill_names!B:B, AutoFill_names!E:E,"")) | E9: =IF(_xlfn.XLOOKUP(A9, AutoFill_names!B:B, AutoFill_names!F:F,"")=0,"",_xlfn.XLOOKUP(A9, AutoFill_names!B:B, AutoFill_names!F:F,"")) | J9: =IF(_xlfn.XLOOKUP(A9, AutoFill_names!B:B, AutoFill_names!K:K,"")=0,"",_xlfn.XLOOKUP(A9, AutoFill_names!B:B, AutoFill_names!K:K,"")) | K9: =IF(_xlfn.XLOOKUP(A9, AutoFill_names!B:B, AutoFill_names!L:L,"")=0,"",_xlfn.XLOOKUP(A9, AutoFill_names!B:B, AutoFill_names!L:L,"")) | N9: =IF(_xlfn.XLOOKUP(L9, AutoFill_classes!A:A, AutoFill_classes!B:B,"")=0,"",_xlfn.XLOOKUP(L9, AutoFill_classes!A:A, AutoFill_classes!B:B,"")) | Z9: =IF(X9*Y9=0,"",X9*Y9) | AE9: =IF(ROUNDUP((AD9-AC9)/7,0)=0,"",ROUNDUP((AD9-AC9)/7,0)) | AG9: =IFERROR(IF(AE9*AF9=0,"",AE9*AF9), "") | AJ9: =IF(ROUNDUP((AI9-AH9)/7,0)=0,"",ROUNDUP((AI9-AH9)/7,0)) | AL9: =IFERROR(IF(AJ9*AK9=0,"",AJ9*AK9), "") | AO9: =IF(ROUNDUP((AN9-AM9)/7,0)=0,"",ROUNDUP((AN9-AM9)/7,0)) | AP9: =IFERROR(IF((AS9-(AF9+AK9))/AO9=0,"",ROUNDUP((AS9-(AF9+AK9))/AO9,0)), "") | AQ9: =IFERROR(IF((AS9-(AG9+AL9))=0, "", (AS9-(AG9+AL9))), "") | AR9: =IFERROR(IF((AE9+AJ9+AO9)=0, "", (AE9+AJ9+AO9)), "") | AV9: =IF(_xlfn.XLOOKUP(AT9, AutoFill_classes!$A:$A, AutoFill_classes!$B:$B,"")=0,"",_xlfn.XLOOKUP(AT9, AutoFill_classes!$A:$A, AutoFill_classes!$B:$B,"")) | BE9: =IF(BC9*BD9=0,"",BC9*BD9) | BJ9: =IF(ROUNDUP((BI9-BH9)/7,0)=0,"",ROUNDUP((BI9-BH9)/7,0)) | BL9: =IFERROR(IF(BJ9*BK9=0,"",BJ9*BK9), "") | BO9: =IF(ROUNDUP((BN9-BM9)/7,0)=0,"",ROUNDUP((BN9-BM9)/7,0)) | BQ9: =IFERROR(IF(BO9*BP9=0,"",BO9*BP9), "") | BT9: =IF(ROUNDUP((BS9-BR9)/7,0)=0,"",ROUNDUP((BS9-BR9)/7,0)) | BU9: =IFERROR(IF((BX9-(BK9+BP9))/BT9=0,"",ROUNDUP((BX9-(BK9+BP9))/BT9,0)), "") | BV9: =IFERROR(IF((BX9-(BL9+BQ9))=0, "", (BX9-(BL9+BQ9))), "") | BW9: =IFERROR(IF((BJ9+BO9+BT9)=0, "", (BJ9+BO9+BT9)), "") | CA9: =IF(_xlfn.XLOOKUP(BY9, AutoFill_classes!$A:$A, AutoFill_classes!$B:$B,"")=0,"",_xlfn.XLOOKUP(BY9, AutoFill_classes!$A:$A, AutoFill_classes!$B:$B,"")) | CJ9: =IF(CH9*CI9=0,"",CH9*CI9) | CO9: =IF(ROUNDUP((CN9-CM9)/7,0)=0,"",ROUNDUP((CN9-CM9)/7,0)) | CQ9: =IFERROR(IF(CO9*CP9=0,"",CO9*CP9), "") | CT9: =IF(ROUNDUP((CS9-CR9)/7,0)=0,"",ROUNDUP((CS9-CR9)/7,0)) | CV9: =IFERROR(IF(CT9*CU9=0,"",CT9*CU9), "") | CY9: =IF(ROUNDUP((CX9-CW9)/7,0)=0,"",ROUNDUP((CX9-CW9)/7,0)) | CZ9: =IFERROR(IF((DC9-(CP9+CU9))/CY9=0,"",ROUNDUP((DC9-(CP9+CU9))/CY9,0)), "") | DA9: =IFERROR(IF((DC9-(CQ9+CV9))=0, "", (DC9-(CQ9+CV9))), "") | DB9: =IFERROR(IF((CO9+CT9+CY9)=0, "", (CO9+CT9+CY9)), "") | DE9: 7
B10: =IF(_xlfn.XLOOKUP(A10, AutoFill_names!B:B, AutoFill_names!C:C,"")=0,"",_xlfn.XLOOKUP(A10, AutoFill_names!B:B, AutoFill_names!C:C,"")) | C10: =IF(_xlfn.XLOOKUP(A10, AutoFill_names!B:B, AutoFill_names!D:D,"")=0,"",_xlfn.XLOOKUP(A10, AutoFill_names!B:B, AutoFill_names!D:D,"")) | D10: =IF(_xlfn.XLOOKUP(A10, AutoFill_names!B:B, AutoFill_names!E:E,"")=0,"",_xlfn.XLOOKUP(A10, AutoFill_names!B:B, AutoFill_names!E:E,"")) | E10: =IF(_xlfn.XLOOKUP(A10, AutoFill_names!B:B, AutoFill_names!F:F,"")=0,"",_xlfn.XLOOKUP(A10, AutoFill_names!B:B, AutoFill_names!F:F,"")) | J10: =IF(_xlfn.XLOOKUP(A10, AutoFill_names!B:B, AutoFill_names!K:K,"")=0,"",_xlfn.XLOOKUP(A10, AutoFill_names!B:B, AutoFill_names!K:K,"")) | K10: =IF(_xlfn.XLOOKUP(A10, AutoFill_names!B:B, AutoFill_names!L:L,"")=0,"",_xlfn.XLOOKUP(A10, AutoFill_names!B:B, AutoFill_names!L:L,"")) | N10: =IF(_xlfn.XLOOKUP(L10, AutoFill_classes!A:A, AutoFill_classes!B:B,"")=0,"",_xlfn.XLOOKUP(L10, AutoFill_classes!A:A, AutoFill_classes!B:B,"")) | Z10: =IF(X10*Y10=0,"",X10*Y10) | AE10: =IF(ROUNDUP((AD10-AC10)/7,0)=0,"",ROUNDUP((AD10-AC10)/7,0)) | AG10: =IFERROR(IF(AE10*AF10=0,"",AE10*AF10), "") | AJ10: =IF(ROUNDUP((AI10-AH10)/7,0)=0,"",ROUNDUP((AI10-AH10)/7,0)) | AL10: =IFERROR(IF(AJ10*AK10=0,"",AJ10*AK10), "") | AO10: =IF(ROUNDUP((AN10-AM10)/7,0)=0,"",ROUNDUP((AN10-AM10)/7,0)) | AP10: =IFERROR(IF((AS10-(AF10+AK10))/AO10=0,"",ROUNDUP((AS10-(AF10+AK10))/AO10,0)), "") | AQ10: =IFERROR(IF((AS10-(AG10+AL10))=0, "", (AS10-(AG10+AL10))), "") | AR10: =IFERROR(IF((AE10+AJ10+AO10)=0, "", (AE10+AJ10+AO10)), "") | AV10: =IF(_xlfn.XLOOKUP(AT10, AutoFill_classes!$A:$A, AutoFill_classes!$B:$B,"")=0,"",_xlfn.XLOOKUP(AT10, AutoFill_classes!$A:$A, AutoFill_classes!$B:$B,"")) | BE10: =IF(BC10*BD10=0,"",BC10*BD10) | BJ10: =IF(ROUNDUP((BI10-BH10)/7,0)=0,"",ROUNDUP((BI10-BH10)/7,0)) | BL10: =IFERROR(IF(BJ10*BK10=0,"",BJ10*BK10), "") | BO10: =IF(ROUNDUP((BN10-BM10)/7,0)=0,"",ROUNDUP((BN10-BM10)/7,0)) | BQ10: =IFERROR(IF(BO10*BP10=0,"",BO10*BP10), "") | BT10: =IF(ROUNDUP((BS10-BR10)/7,0)=0,"",ROUNDUP((BS10-BR10)/7,0)) | BU10: =IFERROR(IF((BX10-(BK10+BP10))/BT10=0,"",ROUNDUP((BX10-(BK10+BP10))/BT10,0)), "") | BV10: =IFERROR(IF((BX10-(BL10+BQ10))=0, "", (BX10-(BL10+BQ10))), "") | BW10: =IFERROR(IF((BJ10+BO10+BT10)=0, "", (BJ10+BO10+BT10)), "") | CA10: =IF(_xlfn.XLOOKUP(BY10, AutoFill_classes!$A:$A, AutoFill_classes!$B:$B,"")=0,"",_xlfn.XLOOKUP(BY10, AutoFill_classes!$A:$A, AutoFill_classes!$B:$B,"")) | CJ10: =IF(CH10*CI10=0,"",CH10*CI10) | CO10: =IF(ROUNDUP((CN10-CM10)/7,0)=0,"",ROUNDUP((CN10-CM10)/7,0)) | CQ10: =IFERROR(IF(CO10*CP10=0,"",CO10*CP10), "") | CT10: =IF(ROUNDUP((CS10-CR10)/7,0)=0,"",ROUNDUP((CS10-CR10)/7,0)) | CV10: =IFERROR(IF(CT10*CU10=0,"",CT10*CU10), "") | CY10: =IF(ROUNDUP((CX10-CW10)/7,0)=0,"",ROUNDUP((CX10-CW10)/7,0)) | CZ10: =IFERROR(IF((DC10-(CP10+CU10))/CY10=0,"",ROUNDUP((DC10-(CP10+CU10))/CY10,0)), "") | DA10: =IFERROR(IF((DC10-(CQ10+CV10))=0, "", (DC10-(CQ10+CV10))), "") | DB10: =IFERROR(IF((CO10+CT10+CY10)=0, "", (CO10+CT10+CY10)), "") | DE10: 8
B11: =IF(_xlfn.XLOOKUP(A11, AutoFill_names!B:B, AutoFill_names!C:C,"")=0,"",_xlfn.XLOOKUP(A11, AutoFill_names!B:B, AutoFill_names!C:C,"")) | C11: =IF(_xlfn.XLOOKUP(A11, AutoFill_names!B:B, AutoFill_names!D:D,"")=0,"",_xlfn.XLOOKUP(A11, AutoFill_names!B:B, AutoFill_names!D:D,"")) | D11: =IF(_xlfn.XLOOKUP(A11, AutoFill_names!B:B, AutoFill_names!E:E,"")=0,"",_xlfn.XLOOKUP(A11, AutoFill_names!B:B, AutoFill_names!E:E,"")) | E11: =IF(_xlfn.XLOOKUP(A11, AutoFill_names!B:B, AutoFill_names!F:F,"")=0,"",_xlfn.XLOOKUP(A11, AutoFill_names!B:B, AutoFill_names!F:F,"")) | J11: =IF(_xlfn.XLOOKUP(A11, AutoFill_names!B:B, AutoFill_names!K:K,"")=0,"",_xlfn.XLOOKUP(A11, AutoFill_names!B:B, AutoFill_names!K:K,"")) | K11: =IF(_xlfn.XLOOKUP(A11, AutoFill_names!B:B, AutoFill_names!L:L,"")=0,"",_xlfn.XLOOKUP(A11, AutoFill_names!B:B, AutoFill_names!L:L,"")) | N11: =IF(_xlfn.XLOOKUP(L11, AutoFill_classes!A:A, AutoFill_classes!B:B,"")=0,"",_xlfn.XLOOKUP(L11, AutoFill_classes!A:A, AutoFill_classes!B:B,"")) | Z11: =IF(X11*Y11=0,"",X11*Y11) | AE11: =IF(ROUNDUP((AD11-AC11)/7,0)=0,"",ROUNDUP((AD11-AC11)/7,0)) | AG11: =IFERROR(IF(AE11*AF11=0,"",AE11*AF11), "") | AJ11: =IF(ROUNDUP((AI11-AH11)/7,0)=0,"",ROUNDUP((AI11-AH11)/7,0)) | AL11: =IFERROR(IF(AJ11*AK11=0,"",AJ11*AK11), "") | AO11: =IF(ROUNDUP((AN11-AM11)/7,0)=0,"",ROUNDUP((AN11-AM11)/7,0)) | AP11: =IFERROR(IF((AS11-(AF11+AK11))/AO11=0,"",ROUNDUP((AS11-(AF11+AK11))/AO11,0)), "") | AQ11: =IFERROR(IF((AS11-(AG11+AL11))=0, "", (AS11-(AG11+AL11))), "") | AR11: =IFERROR(IF((AE11+AJ11+AO11)=0, "", (AE11+AJ11+AO11)), "") | AV11: =IF(_xlfn.XLOOKUP(AT11, AutoFill_classes!$A:$A, AutoFill_classes!$B:$B,"")=0,"",_xlfn.XLOOKUP(AT11, AutoFill_classes!$A:$A, AutoFill_classes!$B:$B,"")) | BE11: =IF(BC11*BD11=0,"",BC11*BD11) | BJ11: =IF(ROUNDUP((BI11-BH11)/7,0)=0,"",ROUNDUP((BI11-BH11)/7,0)) | BL11: =IFERROR(IF(BJ11*BK11=0,"",BJ11*BK11), "") | BO11: =IF(ROUNDUP((BN11-BM11)/7,0)=0,"",ROUNDUP((BN11-BM11)/7,0)) | BQ11: =IFERROR(IF(BO11*BP11=0,"",BO11*BP11), "") | BT11: =IF(ROUNDUP((BS11-BR11)/7,0)=0,"",ROUNDUP((BS11-BR11)/7,0)) | BU11: =IFERROR(IF((BX11-(BK11+BP11))/BT11=0,"",ROUNDUP((BX11-(BK11+BP11))/BT11,0)), "") | BV11: =IFERROR(IF((BX11-(BL11+BQ11))=0, "", (BX11-(BL11+BQ11))), "") | BW11: =IFERROR(IF((BJ11+BO11+BT11)=0, "", (BJ11+BO11+BT11)), "") | CA11: =IF(_xlfn.XLOOKUP(BY11, AutoFill_classes!$A:$A, AutoFill_classes!$B:$B,"")=0,"",_xlfn.XLOOKUP(BY11, AutoFill_classes!$A:$A, AutoFill_classes!$B:$B,"")) | CJ11: =IF(CH11*CI11=0,"",CH11*CI11) | CO11: =IF(ROUNDUP((CN11-CM11)/7,0)=0,"",ROUNDUP((CN11-CM11)/7,0)) | CQ11: =IFERROR(IF(CO11*CP11=0,"",CO11*CP11), "") | CT11: =IF(ROUNDUP((CS11-CR11)/7,0)=0,"",ROUNDUP((CS11-CR11)/7,0)) | CV11: =IFERROR(IF(CT11*CU11=0,"",CT11*CU11), "") | CY11: =IF(ROUNDUP((CX11-CW11)/7,0)=0,"",ROUNDUP((CX11-CW11)/7,0)) | CZ11: =IFERROR(IF((DC11-(CP11+CU11))/CY11=0,"",ROUNDUP((DC11-(CP11+CU11))/CY11,0)), "") | DA11: =IFERROR(IF((DC11-(CQ11+CV11))=0, "", (DC11-(CQ11+CV11))), "") | DB11: =IFERROR(IF((CO11+CT11+CY11)=0, "", (CO11+CT11+CY11)), "") | DE11: 9
A12: Totals: Natasha Richards notes: team teaching for CPE; Caplaincy center; 25% load reduction | B12: ="Total Credits: " & IFERROR(IF(DD12=0,"",DD12),"") -> Total Credits: 18 | X12: =IF(SUM(X13:X21)=0,"", SUM(X13:X21)) -> 6 | BC12: =IF(SUM(BC13:BC21)=0, "", SUM(BC13:BC21)) -> 6 | CH12: =IF(SUM(CH13:CH21)=0, "", SUM(CH13:CH21)) -> 6 | DD12: =IF(SUM(L12:DC12)=0, "", SUM(L12:DC12)) -> 18 | DE12: 10
A13: Richards, Natasha | B13: =IF(_xlfn.XLOOKUP(A13, AutoFill_names!B:B, AutoFill_names!C:C,"")=0,"",_xlfn.XLOOKUP(A13, AutoFill_names!B:B, AutoFill_names!C:C,"")) | C13: =IF(_xlfn.XLOOKUP(A13, AutoFill_names!B:B, AutoFill_names!D:D,"")=0,"",_xlfn.XLOOKUP(A13, AutoFill_names!B:B, AutoFill_names!D:D,"")) | D13: =IF(_xlfn.XLOOKUP(A13, AutoFill_names!B:B, AutoFill_names!E:E,"")=0,"",_xlfn.XLOOKUP(A13, AutoFill_names!B:B, AutoFill_names!E:E,"")) | E13: =IF(_xlfn.XLOOKUP(A13, AutoFill_names!B:B, AutoFill_names!F:F,"")=0,"",_xlfn.XLOOKUP(A13, AutoFill_names!B:B, AutoFill_names!F:F,"")) | J13: =IF(_xlfn.XLOOKUP(A13, AutoFill_names!B:B, AutoFill_names!K:K,"")=0,"",_xlfn.XLOOKUP(A13, AutoFill_names!B:B, AutoFill_names!K:K,"")) | K13: =IF(_xlfn.XLOOKUP(A13, AutoFill_names!B:B, AutoFill_names!L:L,"")=0,"",_xlfn.XLOOKUP(A13, AutoFill_names!B:B, AutoFill_names!L:L,"")) | L13: PATH554 | N13: =IF(_xlfn.XLOOKUP(L13, AutoFill_classes!A:A, AutoFill_classes!B:B,"")=0,"",_xlfn.XLOOKUP(L13, AutoFill_classes!A:A, AutoFill_classes!B:B,"")) | P13: x | S13: In-Person | T13: MDIV | U13: Main Campus - MC | V13: load | W13: yes | X13: 3 | Z13: =IF(X13*Y13=0,"",X13*Y13) | AE13: =IF(ROUNDUP((AD13-AC13)/7,0)=0,"",ROUNDUP((AD13-AC13)/7,0)) | AG13: =IFERROR(IF(AE13*AF13=0,"",AE13*AF13), "") | AJ13: =IF(ROUNDUP((AI13-AH13)/7,0)=0,"",ROUNDUP((AI13-AH13)/7,0)) | AL13: =IFERROR(IF(AJ13*AK13=0,"",AJ13*AK13), "") | AO13: =IF(ROUNDUP((AN13-AM13)/7,0)=0,"",ROUNDUP((AN13-AM13)/7,0)) | AP13: =IFERROR(IF((AS13-(AF13+AK13))/AO13=0,"",ROUNDUP((AS13-(AF13+AK13))/AO13,0)), "") | AQ13: =IFERROR(IF((AS13-(AG13+AL13))=0, "", (AS13-(AG13+AL13))), "") | AR13: =IFERROR(IF((AE13+AJ13+AO13)=0, "", (AE13+AJ13+AO13)), "") | AT13: PATH554 | AU13: CPE | AV13: =IF(_xlfn.XLOOKUP(AT13, AutoFill_classes!$A:$A, AutoFill_classes!$B:$B,"")=0,"",_xlfn.XLOOKUP(AT13, AutoFill_classes!$A:$A, AutoFill_classes!$B:$B,"")) | AX13: In-Person | AY13: MDIV | AZ13: Main Campus - MC | BA13: load | BB13: yes | BC13: 6 | BE13: =IF(BC13*BD13=0,"",BC13*BD13) | BJ13: =IF(ROUNDUP((BI13-BH13)/7,0)=0,"",ROUNDUP((BI13-BH13)/7,0)) | BL13: =IFERROR(IF(BJ13*BK13=0,"",BJ13*BK13), "") | BO13: =IF(ROUNDUP((BN13-BM13)/7,0)=0,"",ROUNDUP((BN13-BM13)/7,0)) | BQ13: =IFERROR(IF(BO13*BP13=0,"",BO13*BP13), "") | BT13: =IF(ROUNDUP((BS13-BR13)/7,0)=0,"",ROUNDUP((BS13-BR13)/7,0)) | BU13: =IFERROR(IF((BX13-(BK13+BP13))/BT13=0,"",ROUNDUP((BX13-(BK13+BP13))/BT13,0)), "") | BV13: =IFERROR(IF((BX13-(BL13+BQ13))=0, "", (BX13-(BL13+BQ13))), "") | BW13: =IFERROR(IF((BJ13+BO13+BT13)=0, "", (BJ13+BO13+BT13)), "") | BY13: PATH554 | BZ13: CPE | CA13: =IF(_xlfn.XLOOKUP(BY13, AutoFill_classes!$A:$A, AutoFill_classes!$B:$B,"")=0,"",_xlfn.XLOOKUP(BY13, AutoFill_classes!$A:$A, AutoFill_classes!$B:$B,"")) | CC13: In-Person | CD13: MDIV | CE13: Main Campus - MC | CF13: load | CG13: yes | CH13: 6 | CJ13: =IF(CH13*CI13=0,"",CH13*CI13) | CO13: =IF(ROUNDUP((CN13-CM13)/7,0)=0,"",ROUNDUP((CN13-CM13)/7,0)) | CQ13: =IFERROR(IF(CO13*CP13=0,"",CO13*CP13), "") | CT13: =IF(ROUNDUP((CS13-CR13)/7,0)=0,"",ROUNDUP((CS13-CR13)/7,0)) | CV13: =IFERROR(IF(CT13*CU13=0,"",CT13*CU13), "") | CY13: =IF(ROUNDUP((CX13-CW13)/7,0)=0,"",ROUNDUP((CX13-CW13)/7,0)) | CZ13: =IFERROR(IF((DC13-(CP13+CU13))/CY13=0,"",ROUNDUP((DC13-(CP13+CU13))/CY13,0)), "") | DA13: =IFERROR(IF((DC13-(CQ13+CV13))=0, "", (DC13-(CQ13+CV13))), "") | DB13: =IFERROR(IF((CO13+CT13+CY13)=0, "", (CO13+CT13+CY13)), "") | DE13: 11
A14: Richards, Natasha | B14: =IF(_xlfn.XLOOKUP(A14, AutoFill_names!B:B, AutoFill_names!C:C,"")=0,"",_xlfn.XLOOKUP(A14, AutoFill_names!B:B, AutoFill_names!C:C,"")) | C14: =IF(_xlfn.XLOOKUP(A14, AutoFill_names!B:B, AutoFill_names!D:D,"")=0,"",_xlfn.XLOOKUP(A14, AutoFill_names!B:B, AutoFill_names!D:D,"")) | D14: =IF(_xlfn.XLOOKUP(A14, AutoFill_names!B:B, AutoFill_names!E:E,"")=0,"",_xlfn.XLOOKUP(A14, AutoFill_names!B:B, AutoFill_names!E:E,"")) | E14: =IF(_xlfn.XLOOKUP(A14, AutoFill_names!B:B, AutoFill_names!F:F,"")=0,"",_xlfn.XLOOKUP(A14, AutoFill_names!B:B, AutoFill_names!F:F,"")) | J14: =IF(_xlfn.XLOOKUP(A14, AutoFill_names!B:B, AutoFill_names!K:K,"")=0,"",_xlfn.XLOOKUP(A14, AutoFill_names!B:B, AutoFill_names!K:K,"")) | K14: =IF(_xlfn.XLOOKUP(A14, AutoFill_names!B:B, AutoFill_names!L:L,"")=0,"",_xlfn.XLOOKUP(A14, AutoFill_names!B:B, AutoFill_names!L:L,"")) | L14: PATH554 | M14: faculty | N14: =IF(_xlfn.XLOOKUP(L14, AutoFill_classes!A:A, AutoFill_classes!B:B,"")=0,"",_xlfn.XLOOKUP(L14, AutoFill_classes!A:A, AutoFill_classes!B:B,"")) | Q14: x | S14: In-Person | T14: MAR-INT | U14: Main Campus - MC | V14: load | W14: yes | X14: 3 | Z14: =IF(X14*Y14=0,"",X14*Y14) | AE14: =IF(ROUNDUP((AD14-AC14)/7,0)=0,"",ROUNDUP((AD14-AC14)/7,0)) | AG14: =IFERROR(IF(AE14*AF14=0,"",AE14*AF14), "") | AJ14: =IF(ROUNDUP((AI14-AH14)/7,0)=0,"",ROUNDUP((AI14-AH14)/7,0)) | AL14: =IFERROR(IF(AJ14*AK14=0,"",AJ14*AK14), "") | AO14: =IF(ROUNDUP((AN14-AM14)/7,0)=0,"",ROUNDUP((AN14-AM14)/7,0)) | AP14: =IFERROR(IF((AS14-(AF14+AK14))/AO14=0,"",ROUNDUP((AS14-(AF14+AK14))/AO14,0)), "") | AQ14: =IFERROR(IF((AS14-(AG14+AL14))=0, "", (AS14-(AG14+AL14))), "") | AR14: =IFERROR(IF((AE14+AJ14+AO14)=0, "", (AE14+AJ14+AO14)), "") | AV14: =IF(_xlfn.XLOOKUP(AT14, AutoFill_classes!$A:$A, AutoFill_classes!$B:$B,"")=0,"",_xlfn.XLOOKUP(AT14, AutoFill_classes!$A:$A, AutoFill_classes!$B:$B,"")) | BE14: =IF(BC14*BD14=0,"",BC14*BD14) | BJ14: =IF(ROUNDUP((BI14-BH14)/7,0)=0,"",ROUNDUP((BI14-BH14)/7,0)) | BL14: =IFERROR(IF(BJ14*BK14=0,"",BJ14*BK14), "") | BO14: =IF(ROUNDUP((BN14-BM14)/7,0)=0,"",ROUNDUP((BN14-BM14)/7,0)) | BQ14: =IFERROR(IF(BO14*BP14=0,"",BO14*BP14), "") | BT14: =IF(ROUNDUP((BS14-BR14)/7,0)=0,"",ROUNDUP((BS14-BR14)/7,0)) | BU14: =IFERROR(IF((BX14-(BK14+BP14))/BT14=0,"",ROUNDUP((BX14-(BK14+BP14))/BT14,0)), "") | BV14: =IFERROR(IF((BX14-(BL14+BQ14))=0, "", (BX14-(BL14+BQ14))), "") | BW14: =IFERROR(IF((BJ14+BO14+BT14)=0, "", (BJ14+BO14+BT14)), "") | CA14: =IF(_xlfn.XLOOKUP(BY14, AutoFill_classes!$A:$A, AutoFill_classes!$B:$B,"")=0,"",_xlfn.XLOOKUP(BY14, AutoFill_classes!$A:$A, AutoFill_classes!$B:$B,"")) | CJ14: =IF(CH14*CI14=0,"",CH14*CI14) | CO14: =IF(ROUNDUP((CN14-CM14)/7,0)=0,"",ROUNDUP((CN14-CM14)/7,0)) | CQ14: =IFERROR(IF(CO14*CP14=0,"",CO14*CP14), "") | CT14: =IF(ROUNDUP((CS14-CR14)/7,0)=0,"",ROUNDUP((CS14-CR14)/7,0)) | CV14: =IFERROR(IF(CT14*CU14=0,"",CT14*CU14), "") | CY14: =IF(ROUNDUP((CX14-CW14)/7,0)=0,"",ROUNDUP((CX14-CW14)/7,0)) | CZ14: =IFERROR(IF((DC14-(CP14+CU14))/CY14=0,"",ROUNDUP((DC14-(CP14+CU14))/CY14,0)), "") | DA14: =IFERROR(IF((DC14-(CQ14+CV14))=0, "", (DC14-(CQ14+CV14))), "") | DB14: =IFERROR(IF((CO14+CT14+CY14)=0, "", (CO14+CT14+CY14)), "") | DE14: 12
B15: =IF(_xlfn.XLOOKUP(A15, AutoFill_names!B:B, AutoFill_names!C:C,"")=0,"",_xlfn.XLOOKUP(A15, AutoFill_names!B:B, AutoFill_names!C:C,"")) | C15: =IF(_xlfn.XLOOKUP(A15, AutoFill_names!B:B, AutoFill_names!D:D,"")=0,"",_xlfn.XLOOKUP(A15, AutoFill_names!B:B, AutoFill_names!D:D,"")) | D15: =IF(_xlfn.XLOOKUP(A15, AutoFill_names!B:B, AutoFill_names!E:E,"")=0,"",_xlfn.XLOOKUP(A15, AutoFill_names!B:B, AutoFill_names!E:E,"")) | E15: =IF(_xlfn.XLOOKUP(A15, AutoFill_names!B:B, AutoFill_names!F:F,"")=0,"",_xlfn.XLOOKUP(A15, AutoFill_names!B:B, AutoFill_names!F:F,"")) | J15: =IF(_xlfn.XLOOKUP(A15, AutoFill_names!B:B, AutoFill_names!K:K,"")=0,"",_xlfn.XLOOKUP(A15, AutoFill_names!B:B, AutoFill_names!K:K,"")) | K15: =IF(_xlfn.XLOOKUP(A15, AutoFill_names!B:B, AutoFill_names!L:L,"")=0,"",_xlfn.XLOOKUP(A15, AutoFill_names!B:B, AutoFill_names!L:L,"")) | N15: =IF(_xlfn.XLOOKUP(L15, AutoFill_classes!A:A, AutoFill_classes!B:B,"")=0,"",_xlfn.XLOOKUP(L15, AutoFill_classes!A:A, AutoFill_classes!B:B,"")) | Z15: =IF(X15*Y15=0,"",X15*Y15) | AE15: =IF(ROUNDUP((AD15-AC15)/7,0)=0,"",ROUNDUP((AD15-AC15)/7,0)) | AG15: =IFERROR(IF(AE15*AF15=0,"",AE15*AF15), "") | AJ15: =IF(ROUNDUP((AI15-AH15)/7,0)=0,"",ROUNDUP((AI15-AH15)/7,0)) | AL15: =IFERROR(IF(AJ15*AK15=0,"",AJ15*AK15), "") | AO15: =IF(ROUNDUP((AN15-AM15)/7,0)=0,"",ROUNDUP((AN15-AM15)/7,0)) | AP15: =IFERROR(IF((AS15-(AF15+AK15))/AO15=0,"",ROUNDUP((AS15-(AF15+AK15))/AO15,0)), "") | AQ15: =IFERROR(IF((AS15-(AG15+AL15))=0, "", (AS15-(AG15+AL15))), "") | AR15: =IFERROR(IF((AE15+AJ15+AO15)=0, "", (AE15+AJ15+AO15)), "") | AV15: =IF(_xlfn.XLOOKUP(AT15, AutoFill_classes!$A:$A, AutoFill_classes!$B:$B,"")=0,"",_xlfn.XLOOKUP(AT15, AutoFill_classes!$A:$A, AutoFill_classes!$B:$B,"")) | BE15: =IF(BC15*BD15=0,"",BC15*BD15) | BJ15: =IF(ROUNDUP((BI15-BH15)/7,0)=0,"",ROUNDUP((BI15-BH15)/7,0)) | BL15: =IFERROR(IF(BJ15*BK15=0,"",BJ15*BK15), "") | BO15: =IF(ROUNDUP((BN15-BM15)/7,0)=0,"",ROUNDUP((BN15-BM15)/7,0)) | BQ15: =IFERROR(IF(BO15*BP15=0,"",BO15*BP15), "") | BT15: =IF(ROUNDUP((BS15-BR15)/7,0)=0,"",ROUNDUP((BS15-BR15)/7,0)) | BU15: =IFERROR(IF((BX15-(BK15+BP15))/BT15=0,"",ROUNDUP((BX15-(BK15+BP15))/BT15,0)), "") | BV15: =IFERROR(IF((BX15-(BL15+BQ15))=0, "", (BX15-(BL15+BQ15))), "") | BW15: =IFERROR(IF((BJ15+BO15+BT15)=0, "", (BJ15+BO15+BT15)), "") | CA15: =IF(_xlfn.XLOOKUP(BY15, AutoFill_classes!$A:$A, AutoFill_classes!$B:$B,"")=0,"",_xlfn.XLOOKUP(BY15, AutoFill_classes!$A:$A, AutoFill_classes!$B:$B,"")) | CJ15: =IF(CH15*CI15=0,"",CH15*CI15) | CO15: =IF(ROUNDUP((CN15-CM15)/7,0)=0,"",ROUNDUP((CN15-CM15)/7,0)) | CQ15: =IFERROR(IF(CO15*CP15=0,"",CO15*CP15), "") | CT15: =IF(ROUNDUP((CS15-CR15)/7,0)=0,"",ROUNDUP((CS15-CR15)/7,0)) | CV15: =IFERROR(IF(CT15*CU15=0,"",CT15*CU15), "") | CY15: =IF(ROUNDUP((CX15-CW15)/7,0)=0,"",ROUNDUP((CX15-CW15)/7,0)) | CZ15: =IFERROR(IF((DC15-(CP15+CU15))/CY15=0,"",ROUNDUP((DC15-(CP15+CU15))/CY15,0)), "") | DA15: =IFERROR(IF((DC15-(CQ15+CV15))=0, "", (DC15-(CQ15+CV15))), "") | DB15: =IFERROR(IF((CO15+CT15+CY15)=0, "", (CO15+CT15+CY15)), "") | DE15: 13
B16: =IF(_xlfn.XLOOKUP(A16, AutoFill_names!B:B, AutoFill_names!C:C,"")=0,"",_xlfn.XLOOKUP(A16, AutoFill_names!B:B, AutoFill_names!C:C,"")) | C16: =IF(_xlfn.XLOOKUP(A16, AutoFill_names!B:B, AutoFill_names!D:D,"")=0,"",_xlfn.XLOOKUP(A16, AutoFill_names!B:B, AutoFill_names!D:D,"")) | D16: =IF(_xlfn.XLOOKUP(A16, AutoFill_names!B:B, AutoFill_names!E:E,"")=0,"",_xlfn.XLOOKUP(A16, AutoFill_names!B:B, AutoFill_names!E:E,"")) | E16: =IF(_xlfn.XLOOKUP(A16, AutoFill_names!B:B, AutoFill_names!F:F,"")=0,"",_xlfn.XLOOKUP(A16, AutoFill_names!B:B, AutoFill_names!F:F,"")) | J16: =IF(_xlfn.XLOOKUP(A16, AutoFill_names!B:B, AutoFill_names!K:K,"")=0,"",_xlfn.XLOOKUP(A16, AutoFill_names!B:B, AutoFill_names!K:K,"")) | K16: =IF(_xlfn.XLOOKUP(A16, AutoFill_names!B:B, AutoFill_names!L:L,"")=0,"",_xlfn.XLOOKUP(A16, AutoFill_names!B:B, AutoFill_names!L:L,"")) | N16: =IF(_xlfn.XLOOKUP(L16, AutoFill_classes!A:A, AutoFill_classes!B:B,"")=0,"",_xlfn.XLOOKUP(L16, AutoFill_classes!A:A, AutoFill_classes!B:B,"")) | Z16: =IF(X16*Y16=0,"",X16*Y16) | AE16: =IF(ROUNDUP((AD16-AC16)/7,0)=0,"",ROUNDUP((AD16-AC16)/7,0)) | AG16: =IFERROR(IF(AE16*AF16=0,"",AE16*AF16), "") | AJ16: =IF(ROUNDUP((AI16-AH16)/7,0)=0,"",ROUNDUP((AI16-AH16)/7,0)) | AL16: =IFERROR(IF(AJ16*AK16=0,"",AJ16*AK16), "") | AO16: =IF(ROUNDUP((AN16-AM16)/7,0)=0,"",ROUNDUP((AN16-AM16)/7,0)) | AP16: =IFERROR(IF((AS16-(AF16+AK16))/AO16=0,"",ROUNDUP((AS16-(AF16+AK16))/AO16,0)), "") | AQ16: =IFERROR(IF((AS16-(AG16+AL16))=0, "", (AS16-(AG16+AL16))), "") | AR16: =IFERROR(IF((AE16+AJ16+AO16)=0, "", (AE16+AJ16+AO16)), "") | AV16: =IF(_xlfn.XLOOKUP(AT16, AutoFill_classes!$A:$A, AutoFill_classes!$B:$B,"")=0,"",_xlfn.XLOOKUP(AT16, AutoFill_classes!$A:$A, AutoFill_classes!$B:$B,"")) | BE16: =IF(BC16*BD16=0,"",BC16*BD16) | BJ16: =IF(ROUNDUP((BI16-BH16)/7,0)=0,"",ROUNDUP((BI16-BH16)/7,0)) | BL16: =IFERROR(IF(BJ16*BK16=0,"",BJ16*BK16), "") | BO16: =IF(ROUNDUP((BN16-BM16)/7,0)=0,"",ROUNDUP((BN16-BM16)/7,0)) | BQ16: =IFERROR(IF(BO16*BP16=0,"",BO16*BP16), "") | BT16: =IF(ROUNDUP((BS16-BR16)/7,0)=0,"",ROUNDUP((BS16-BR16)/7,0)) | BU16: =IFERROR(IF((BX16-(BK16+BP16))/BT16=0,"",ROUNDUP((BX16-(BK16+BP16))/BT16,0)), "") | BV16: =IFERROR(IF((BX16-(BL16+BQ16))=0, "", (BX16-(BL16+BQ16))), "") | BW16: =IFERROR(IF((BJ16+BO16+BT16)=0, "", (BJ16+BO16+BT16)), "") | CA16: =IF(_xlfn.XLOOKUP(BY16, AutoFill_classes!$A:$A, AutoFill_classes!$B:$B,"")=0,"",_xlfn.XLOOKUP(BY16, AutoFill_classes!$A:$A, AutoFill_classes!$B:$B,"")) | CJ16: =IF(CH16*CI16=0,"",CH16*CI16) | CO16: =IF(ROUNDUP((CN16-CM16)/7,0)=0,"",ROUNDUP((CN16-CM16)/7,0)) | CQ16: =IFERROR(IF(CO16*CP16=0,"",CO16*CP16), "") | CT16: =IF(ROUNDUP((CS16-CR16)/7,0)=0,"",ROUNDUP((CS16-CR16)/7,0)) | CV16: =IFERROR(IF(CT16*CU16=0,"",CT16*CU16), "") | CY16: =IF(ROUNDUP((CX16-CW16)/7,0)=0,"",ROUNDUP((CX16-CW16)/7,0)) | CZ16: =IFERROR(IF((DC16-(CP16+CU16))/CY16=0,"",ROUNDUP((DC16-(CP16+CU16))/CY16,0)), "") | DA16: =IFERROR(IF((DC16-(CQ16+CV16))=0, "", (DC16-(CQ16+CV16))), "") | DB16: =IFERROR(IF((CO16+CT16+CY16)=0, "", (CO16+CT16+CY16)), "") | DE16: 14
B17: =IF(_xlfn.XLOOKUP(A17, AutoFill_names!B:B, AutoFill_names!C:C,"")=0,"",_xlfn.XLOOKUP(A17, AutoFill_names!B:B, AutoFill_names!C:C,"")) | C17: =IF(_xlfn.XLOOKUP(A17, AutoFill_names!B:B, AutoFill_names!D:D,"")=0,"",_xlfn.XLOOKUP(A17, AutoFill_names!B:B, AutoFill_names!D:D,"")) | D17: =IF(_xlfn.XLOOKUP(A17, AutoFill_names!B:B, AutoFill_names!E:E,"")=0,"",_xlfn.XLOOKUP(A17, AutoFill_names!B:B, AutoFill_names!E:E,"")) | E17: =IF(_xlfn.XLOOKUP(A17, AutoFill_names!B:B, AutoFill_names!F:F,"")=0,"",_xlfn.XLOOKUP(A17, AutoFill_names!B:B, AutoFill_names!F:F,"")) | J17: =IF(_xlfn.XLOOKUP(A17, AutoFill_names!B:B, AutoFill_names!K:K,"")=0,"",_xlfn.XLOOKUP(A17, AutoFill_names!B:B, AutoFill_names!K:K,"")) | K17: =IF(_xlfn.XLOOKUP(A17, AutoFill_names!B:B, AutoFill_names!L:L,"")=0,"",_xlfn.XLOOKUP(A17, AutoFill_names!B:B, AutoFill_names!L:L,"")) | N17: =IF(_xlfn.XLOOKUP(L17, AutoFill_classes!A:A, AutoFill_classes!B:B,"")=0,"",_xlfn.XLOOKUP(L17, AutoFill_classes!A:A, AutoFill_classes!B:B,"")) | Z17: =IF(X17*Y17=0,"",X17*Y17) | AE17: =IF(ROUNDUP((AD17-AC17)/7,0)=0,"",ROUNDUP((AD17-AC17)/7,0)) | AG17: =IFERROR(IF(AE17*AF17=0,"",AE17*AF17), "") | AJ17: =IF(ROUNDUP((AI17-AH17)/7,0)=0,"",ROUNDUP((AI17-AH17)/7,0)) | AL17: =IFERROR(IF(AJ17*AK17=0,"",AJ17*AK17), "") | AO17: =IF(ROUNDUP((AN17-AM17)/7,0)=0,"",ROUNDUP((AN17-AM17)/7,0)) | AP17: =IFERROR(IF((AS17-(AF17+AK17))/AO17=0,"",ROUNDUP((AS17-(AF17+AK17))/AO17,0)), "") | AQ17: =IFERROR(IF((AS17-(AG17+AL17))=0, "", (AS17-(AG17+AL17))), "") | AR17: =IFERROR(IF((AE17+AJ17+AO17)=0, "", (AE17+AJ17+AO17)), "") | AV17: =IF(_xlfn.XLOOKUP(AT17, AutoFill_classes!$A:$A, AutoFill_classes!$B:$B,"")=0,"",_xlfn.XLOOKUP(AT17, AutoFill_classes!$A:$A, AutoFill_classes!$B:$B,"")) | BE17: =IF(BC17*BD17=0,"",BC17*BD17) | BJ17: =IF(ROUNDUP((BI17-BH17)/7,0)=0,"",ROUNDUP((BI17-BH17)/7,0)) | BL17: =IFERROR(IF(BJ17*BK17=0,"",BJ17*BK17), "") | BO17: =IF(ROUNDUP((BN17-BM17)/7,0)=0,"",ROUNDUP((BN17-BM17)/7,0)) | BQ17: =IFERROR(IF(BO17*BP17=0,"",BO17*BP17), "") | BT17: =IF(ROUNDUP((BS17-BR17)/7,0)=0,"",ROUNDUP((BS17-BR17)/7,0)) | BU17: =IFERROR(IF((BX17-(BK17+BP17))/BT17=0,"",ROUNDUP((BX17-(BK17+BP17))/BT17,0)), "") | BV17: =IFERROR(IF((BX17-(BL17+BQ17))=0, "", (BX17-(BL17+BQ17))), "") | BW17: =IFERROR(IF((BJ17+BO17+BT17)=0, "", (BJ17+BO17+BT17)), "") | CA17: =IF(_xlfn.XLOOKUP(BY17, AutoFill_classes!$A:$A, AutoFill_classes!$B:$B,"")=0,"",_xlfn.XLOOKUP(BY17, AutoFill_classes!$A:$A, AutoFill_classes!$B:$B,"")) | CJ17: =IF(CH17*CI17=0,"",CH17*CI17) | CO17: =IF(ROUNDUP((CN17-CM17)/7,0)=0,"",ROUNDUP((CN17-CM17)/7,0)) | CQ17: =IFERROR(IF(CO17*CP17=0,"",CO17*CP17), "") | CT17: =IF(ROUNDUP((CS17-CR17)/7,0)=0,"",ROUNDUP((CS17-CR17)/7,0)) | CV17: =IFERROR(IF(CT17*CU17=0,"",CT17*CU17), "") | CY17: =IF(ROUNDUP((CX17-CW17)/7,0)=0,"",ROUNDUP((CX17-CW17)/7,0)) | CZ17: =IFERROR(IF((DC17-(CP17+CU17))/CY17=0,"",ROUNDUP((DC17-(CP17+CU17))/CY17,0)), "") | DA17: =IFERROR(IF((DC17-(CQ17+CV17))=0, "", (DC17-(CQ17+CV17))), "") | DB17: =IFERROR(IF((CO17+CT17+CY17)=0, "", (CO17+CT17+CY17)), "") | DE17: 15
B18: =IF(_xlfn.XLOOKUP(A18, AutoFill_names!B:B, AutoFill_names!C:C,"")=0,"",_xlfn.XLOOKUP(A18, AutoFill_names!B:B, AutoFill_names!C:C,"")) | C18: =IF(_xlfn.XLOOKUP(A18, AutoFill_names!B:B, AutoFill_names!D:D,"")=0,"",_xlfn.XLOOKUP(A18, AutoFill_names!B:B, AutoFill_names!D:D,"")) | D18: =IF(_xlfn.XLOOKUP(A18, AutoFill_names!B:B, AutoFill_names!E:E,"")=0,"",_xlfn.XLOOKUP(A18, AutoFill_names!B:B, AutoFill_names!E:E,"")) | E18: =IF(_xlfn.XLOOKUP(A18, AutoFill_names!B:B, AutoFill_names!F:F,"")=0,"",_xlfn.XLOOKUP(A18, AutoFill_names!B:B, AutoFill_names!F:F,"")) | J18: =IF(_xlfn.XLOOKUP(A18, AutoFill_names!B:B, AutoFill_names!K:K,"")=0,"",_xlfn.XLOOKUP(A18, AutoFill_names!B:B, AutoFill_names!K:K,"")) | K18: =IF(_xlfn.XLOOKUP(A18, AutoFill_names!B:B, AutoFill_names!L:L,"")=0,"",_xlfn.XLOOKUP(A18, AutoFill_names!B:B, AutoFill_names!L:L,"")) | N18: =IF(_xlfn.XLOOKUP(L18, AutoFill_classes!A:A, AutoFill_classes!B:B,"")=0,"",_xlfn.XLOOKUP(L18, AutoFill_classes!A:A, AutoFill_classes!B:B,"")) | Z18: =IF(X18*Y18=0,"",X18*Y18) | AE18: =IF(ROUNDUP((AD18-AC18)/7,0)=0,"",ROUNDUP((AD18-AC18)/7,0)) | AG18: =IFERROR(IF(AE18*AF18=0,"",AE18*AF18), "") | AJ18: =IF(ROUNDUP((AI18-AH18)/7,0)=0,"",ROUNDUP((AI18-AH18)/7,0)) | AL18: =IFERROR(IF(AJ18*AK18=0,"",AJ18*AK18), "") | AO18: =IF(ROUNDUP((AN18-AM18)/7,0)=0,"",ROUNDUP((AN18-AM18)/7,0)) | AP18: =IFERROR(IF((AS18-(AF18+AK18))/AO18=0,"",ROUNDUP((AS18-(AF18+AK18))/AO18,0)), "") | AQ18: =IFERROR(IF((AS18-(AG18+AL18))=0, "", (AS18-(AG18+AL18))), "") | AR18: =IFERROR(IF((AE18+AJ18+AO18)=0, "", (AE18+AJ18+AO18)), "") | AV18: =IF(_xlfn.XLOOKUP(AT18, AutoFill_classes!$A:$A, AutoFill_classes!$B:$B,"")=0,"",_xlfn.XLOOKUP(AT18, AutoFill_classes!$A:$A, AutoFill_classes!$B:$B,"")) | BE18: =IF(BC18*BD18=0,"",BC18*BD18) | BJ18: =IF(ROUNDUP((BI18-BH18)/7,0)=0,"",ROUNDUP((BI18-BH18)/7,0)) | BL18: =IFERROR(IF(BJ18*BK18=0,"",BJ18*BK18), "") | BO18: =IF(ROUNDUP((BN18-BM18)/7,0)=0,"",ROUNDUP((BN18-BM18)/7,0)) | BQ18: =IFERROR(IF(BO18*BP18=0,"",BO18*BP18), "") | BT18: =IF(ROUNDUP((BS18-BR18)/7,0)=0,"",ROUNDUP((BS18-BR18)/7,0)) | BU18: =IFERROR(IF((BX18-(BK18+BP18))/BT18=0,"",ROUNDUP((BX18-(BK18+BP18))/BT18,0)), "") | BV18: =IFERROR(IF((BX18-(BL18+BQ18))=0, "", (BX18-(BL18+BQ18))), "") | BW18: =IFERROR(IF((BJ18+BO18+BT18)=0, "", (BJ18+BO18+BT18)), "") | CA18: =IF(_xlfn.XLOOKUP(BY18, AutoFill_classes!$A:$A, AutoFill_classes!$B:$B,"")=0,"",_xlfn.XLOOKUP(BY18, AutoFill_classes!$A:$A, AutoFill_classes!$B:$B,"")) | CJ18: =IF(CH18*CI18=0,"",CH18*CI18) | CO18: =IF(ROUNDUP((CN18-CM18)/7,0)=0,"",ROUNDUP((CN18-CM18)/7,0)) | CQ18: =IFERROR(IF(CO18*CP18=0,"",CO18*CP18), "") | CT18: =IF(ROUNDUP((CS18-CR18)/7,0)=0,"",ROUNDUP((CS18-CR18)/7,0)) | CV18: =IFERROR(IF(CT18*CU18=0,"",CT18*CU18), "") | CY18: =IF(ROUNDUP((CX18-CW18)/7,0)=0,"",ROUNDUP((CX18-CW18)/7,0)) | CZ18: =IFERROR(IF((DC18-(CP18+CU18))/CY18=0,"",ROUNDUP((DC18-(CP18+CU18))/CY18,0)), "") | DA18: =IFERROR(IF((DC18-(CQ18+CV18))=0, "", (DC18-(CQ18+CV18))), "") | DB18: =IFERROR(IF((CO18+CT18+CY18)=0, "", (CO18+CT18+CY18)), "") | DE18: 16
B19: =IF(_xlfn.XLOOKUP(A19, AutoFill_names!B:B, AutoFill_names!C:C,"")=0,"",_xlfn.XLOOKUP(A19, AutoFill_names!B:B, AutoFill_names!C:C,"")) | C19: =IF(_xlfn.XLOOKUP(A19, AutoFill_names!B:B, AutoFill_names!D:D,"")=0,"",_xlfn.XLOOKUP(A19, AutoFill_names!B:B, AutoFill_names!D:D,"")) | D19: =IF(_xlfn.XLOOKUP(A19, AutoFill_names!B:B, AutoFill_names!E:E,"")=0,"",_xlfn.XLOOKUP(A19, AutoFill_names!B:B, AutoFill_names!E:E,"")) | E19: =IF(_xlfn.XLOOKUP(A19, AutoFill_names!B:B, AutoFill_names!F:F,"")=0,"",_xlfn.XLOOKUP(A19, AutoFill_names!B:B, AutoFill_names!F:F,"")) | J19: =IF(_xlfn.XLOOKUP(A19, AutoFill_names!B:B, AutoFill_names!K:K,"")=0,"",_xlfn.XLOOKUP(A19, AutoFill_names!B:B, AutoFill_names!K:K,"")) | K19: =IF(_xlfn.XLOOKUP(A19, AutoFill_names!B:B, AutoFill_names!L:L,"")=0,"",_xlfn.XLOOKUP(A19, AutoFill_names!B:B, AutoFill_names!L:L,"")) | N19: =IF(_xlfn.XLOOKUP(L19, AutoFill_classes!A:A, AutoFill_classes!B:B,"")=0,"",_xlfn.XLOOKUP(L19, AutoFill_classes!A:A, AutoFill_classes!B:B,"")) | Z19: =IF(X19*Y19=0,"",X19*Y19) | AE19: =IF(ROUNDUP((AD19-AC19)/7,0)=0,"",ROUNDUP((AD19-AC19)/7,0)) | AG19: =IFERROR(IF(AE19*AF19=0,"",AE19*AF19), "") | AJ19: =IF(ROUNDUP((AI19-AH19)/7,0)=0,"",ROUNDUP((AI19-AH19)/7,0)) | AL19: =IFERROR(IF(AJ19*AK19=0,"",AJ19*AK19), "") | AO19: =IF(ROUNDUP((AN19-AM19)/7,0)=0,"",ROUNDUP((AN19-AM19)/7,0)) | AP19: =IFERROR(IF((AS19-(AF19+AK19))/AO19=0,"",ROUNDUP((AS19-(AF19+AK19))/AO19,0)), "") | AQ19: =IFERROR(IF((AS19-(AG19+AL19))=0, "", (AS19-(AG19+AL19))), "") | AR19: =IFERROR(IF((AE19+AJ19+AO19)=0, "", (AE19+AJ19+AO19)), "") | AV19: =IF(_xlfn.XLOOKUP(AT19, AutoFill_classes!$A:$A, AutoFill_classes!$B:$B,"")=0,"",_xlfn.XLOOKUP(AT19, AutoFill_classes!$A:$A, AutoFill_classes!$B:$B,"")) | BE19: =IF(BC19*BD19=0,"",BC19*BD19) | BJ19: =IF(ROUNDUP((BI19-BH19)/7,0)=0,"",ROUNDUP((BI19-BH19)/7,0)) | BL19: =IFERROR(IF(BJ19*BK19=0,"",BJ19*BK19), "") | BO19: =IF(ROUNDUP((BN19-BM19)/7,0)=0,"",ROUNDUP((BN19-BM19)/7,0)) | BQ19: =IFERROR(IF(BO19*BP19=0,"",BO19*BP19), "") | BT19: =IF(ROUNDUP((BS19-BR19)/7,0)=0,"",ROUNDUP((BS19-BR19)/7,0)) | BU19: =IFERROR(IF((BX19-(BK19+BP19))/BT19=0,"",ROUNDUP((BX19-(BK19+BP19))/BT19,0)), "") | BV19: =IFERROR(IF((BX19-(BL19+BQ19))=0, "", (BX19-(BL19+BQ19))), "") | BW19: =IFERROR(IF((BJ19+BO19+BT19)=0, "", (BJ19+BO19+BT19)), "") | CA19: =IF(_xlfn.XLOOKUP(BY19, AutoFill_classes!$A:$A, AutoFill_classes!$B:$B,"")=0,"",_xlfn.XLOOKUP(BY19, AutoFill_classes!$A:$A, AutoFill_classes!$B:$B,"")) | CJ19: =IF(CH19*CI19=0,"",CH19*CI19) | CO19: =IF(ROUNDUP((CN19-CM19)/7,0)=0,"",ROUNDUP((CN19-CM19)/7,0)) | CQ19: =IFERROR(IF(CO19*CP19=0,"",CO19*CP19), "") | CT19: =IF(ROUNDUP((CS19-CR19)/7,0)=0,"",ROUNDUP((CS19-CR19)/7,0)) | CV19: =IFERROR(IF(CT19*CU19=0,"",CT19*CU19), "") | CY19: =IF(ROUNDUP((CX19-CW19)/7,0)=0,"",ROUNDUP((CX19-CW19)/7,0)) | CZ19: =IFERROR(IF((DC19-(CP19+CU19))/CY19=0,"",ROUNDUP((DC19-(CP19+CU19))/CY19,0)), "") | DA19: =IFERROR(IF((DC19-(CQ19+CV19))=0, "", (DC19-(CQ19+CV19))), "") | DB19: =IFERROR(IF((CO19+CT19+CY19)=0, "", (CO19+CT19+CY19)), "") | DE19: 17
B20: =IF(_xlfn.XLOOKUP(A20, AutoFill_names!B:B, AutoFill_names!C:C,"")=0,"",_xlfn.XLOOKUP(A20, AutoFill_names!B:B, AutoFill_names!C:C,"")) | C20: =IF(_xlfn.XLOOKUP(A20, AutoFill_names!B:B, AutoFill_names!D:D,"")=0,"",_xlfn.XLOOKUP(A20, AutoFill_names!B:B, AutoFill_names!D:D,"")) | D20: =IF(_xlfn.XLOOKUP(A20, AutoFill_names!B:B, AutoFill_names!E:E,"")=0,"",_xlfn.XLOOKUP(A20, AutoFill_names!B:B, AutoFill_names!E:E,"")) | E20: =IF(_xlfn.XLOOKUP(A20, AutoFill_names!B:B, AutoFill_names!F:F,"")=0,"",_xlfn.XLOOKUP(A20, AutoFill_names!B:B, AutoFill_names!F:F,"")) | J20: =IF(_xlfn.XLOOKUP(A20, AutoFill_names!B:B, AutoFill_names!K:K,"")=0,"",_xlfn.XLOOKUP(A20, AutoFill_names!B:B, AutoFill_names!K:K,"")) | K20: =IF(_xlfn.XLOOKUP(A20, AutoFill_names!B:B, AutoFill_names!L:L,"")=0,"",_xlfn.XLOOKUP(A20, AutoFill_names!B:B, AutoFill_names!L:L,"")) | N20: =IF(_xlfn.XLOOKUP(L20, AutoFill_classes!A:A, AutoFill_classes!B:B,"")=0,"",_xlfn.XLOOKUP(L20, AutoFill_classes!A:A, AutoFill_classes!B:B,"")) | Z20: =IF(X20*Y20=0,"",X20*Y20) | AE20: =IF(ROUNDUP((AD20-AC20)/7,0)=0,"",ROUNDUP((AD20-AC20)/7,0)) | AG20: =IFERROR(IF(AE20*AF20=0,"",AE20*AF20), "") | AJ20: =IF(ROUNDUP((AI20-AH20)/7,0)=0,"",ROUNDUP((AI20-AH20)/7,0)) | AL20: =IFERROR(IF(AJ20*AK20=0,"",AJ20*AK20), "") | AO20: =IF(ROUNDUP((AN20-AM20)/7,0)=0,"",ROUNDUP((AN20-AM20)/7,0)) | AP20: =IFERROR(IF((AS20-(AF20+AK20))/AO20=0,"",ROUNDUP((AS20-(AF20+AK20))/AO20,0)), "") | AQ20: =IFERROR(IF((AS20-(AG20+AL20))=0, "", (AS20-(AG20+AL20))), "") | AR20: =IFERROR(IF((AE20+AJ20+AO20)=0, "", (AE20+AJ20+AO20)), "") | AV20: =IF(_xlfn.XLOOKUP(AT20, AutoFill_classes!$A:$A, AutoFill_classes!$B:$B,"")=0,"",_xlfn.XLOOKUP(AT20, AutoFill_classes!$A:$A, AutoFill_classes!$B:$B,"")) | BE20: =IF(BC20*BD20=0,"",BC20*BD20) | BJ20: =IF(ROUNDUP((BI20-BH20)/7,0)=0,"",ROUNDUP((BI20-BH20)/7,0)) | BL20: =IFERROR(IF(BJ20*BK20=0,"",BJ20*BK20), "") | BO20: =IF(ROUNDUP((BN20-BM20)/7,0)=0,"",ROUNDUP((BN20-BM20)/7,0)) | BQ20: =IFERROR(IF(BO20*BP20=0,"",BO20*BP20), "") | BT20: =IF(ROUNDUP((BS20-BR20)/7,0)=0,"",ROUNDUP((BS20-BR20)/7,0)) | BU20: =IFERROR(IF((BX20-(BK20+BP20))/BT20=0,"",ROUNDUP((BX20-(BK20+BP20))/BT20,0)), "") | BV20: =IFERROR(IF((BX20-(BL20+BQ20))=0, "", (BX20-(BL20+BQ20))), "") | BW20: =IFERROR(IF((BJ20+BO20+BT20)=0, "", (BJ20+BO20+BT20)), "") | CA20: =IF(_xlfn.XLOOKUP(BY20, AutoFill_classes!$A:$A, AutoFill_classes!$B:$B,"")=0,"",_xlfn.XLOOKUP(BY20, AutoFill_classes!$A:$A, AutoFill_classes!$B:$B,"")) | CJ20: =IF(CH20*CI20=0,"",CH20*CI20) | CO20: =IF(ROUNDUP((CN20-CM20)/7,0)=0,"",ROUNDUP((CN20-CM20)/7,0)) | CQ20: =IFERROR(IF(CO20*CP20=0,"",CO20*CP20), "") | CT20: =IF(ROUNDUP((CS20-CR20)/7,0)=0,"",ROUNDUP((CS20-CR20)/7,0)) | CV20: =IFERROR(IF(CT20*CU20=0,"",CT20*CU20), "") | CY20: =IF(ROUNDUP((CX20-CW20)/7,0)=0,"",ROUNDUP((CX20-CW20)/7,0)) | CZ20: =IFERROR(IF((DC20-(CP20+CU20))/CY20=0,"",ROUNDUP((DC20-(CP20+CU20))/CY20,0)), "") | DA20: =IFERROR(IF((DC20-(CQ20+CV20))=0, "", (DC20-(CQ20+CV20))), "") | DB20: =IFERROR(IF((CO20+CT20+CY20)=0, "", (CO20+CT20+CY20)), "") | DE20: 18
B21: =IF(_xlfn.XLOOKUP(A21, AutoFill_names!B:B, AutoFill_names!C:C,"")=0,"",_xlfn.XLOOKUP(A21, AutoFill_names!B:B, AutoFill_names!C:C,"")) | C21: =IF(_xlfn.XLOOKUP(A21, AutoFill_names!B:B, AutoFill_names!D:D,"")=0,"",_xlfn.XLOOKUP(A21, AutoFill_names!B:B, AutoFill_names!D:D,"")) | D21: =IF(_xlfn.XLOOKUP(A21, AutoFill_names!B:B, AutoFill_names!E:E,"")=0,"",_xlfn.XLOOKUP(A21, AutoFill_names!B:B, AutoFill_names!E:E,"")) | E21: =IF(_xlfn.XLOOKUP(A21, AutoFill_names!B:B, AutoFill_names!F:F,"")=0,"",_xlfn.XLOOKUP(A21, AutoFill_names!B:B, AutoFill_names!F:F,"")) | J21: =IF(_xlfn.XLOOKUP(A21, AutoFill_names!B:B, AutoFill_names!K:K,"")=0,"",_xlfn.XLOOKUP(A21, AutoFill_names!B:B, AutoFill_names!K:K,"")) | K21: =IF(_xlfn.XLOOKUP(A21, AutoFill_names!B:B, AutoFill_names!L:L,"")=0,"",_xlfn.XLOOKUP(A21, AutoFill_names!B:B, AutoFill_names!L:L,"")) | N21: =IF(_xlfn.XLOOKUP(L21, AutoFill_classes!A:A, AutoFill_classes!B:B,"")=0,"",_xlfn.XLOOKUP(L21, AutoFill_classes!A:A, AutoFill_classes!B:B,"")) | Z21: =IF(X21*Y21=0,"",X21*Y21) | AE21: =IF(ROUNDUP((AD21-AC21)/7,0)=0,"",ROUNDUP((AD21-AC21)/7,0)) | AG21: =IFERROR(IF(AE21*AF21=0,"",AE21*AF21), "") | AJ21: =IF(ROUNDUP((AI21-AH21)/7,0)=0,"",ROUNDUP((AI21-AH21)/7,0)) | AL21: =IFERROR(IF(AJ21*AK21=0,"",AJ21*AK21), "") | AO21: =IF(ROUNDUP((AN21-AM21)/7,0)=0,"",ROUNDUP((AN21-AM21)/7,0)) | AP21: =IFERROR(IF((AS21-(AF21+AK21))/AO21=0,"",ROUNDUP((AS21-(AF21+AK21))/AO21,0)), "") | AQ21: =IFERROR(IF((AS21-(AG21+AL21))=0, "", (AS21-(AG21+AL21))), "") | AR21: =IFERROR(IF((AE21+AJ21+AO21)=0, "", (AE21+AJ21+AO21)), "") | AV21: =IF(_xlfn.XLOOKUP(AT21, AutoFill_classes!$A:$A, AutoFill_classes!$B:$B,"")=0,"",_xlfn.XLOOKUP(AT21, AutoFill_classes!$A:$A, AutoFill_classes!$B:$B,"")) | BE21: =IF(BC21*BD21=0,"",BC21*BD21) | BJ21: =IF(ROUNDUP((BI21-BH21)/7,0)=0,"",ROUNDUP((BI21-BH21)/7,0)) | BL21: =IFERROR(IF(BJ21*BK21=0,"",BJ21*BK21), "") | BO21: =IF(ROUNDUP((BN21-BM21)/7,0)=0,"",ROUNDUP((BN21-BM21)/7,0)) | BQ21: =IFERROR(IF(BO21*BP21=0,"",BO21*BP21), "") | BT21: =IF(ROUNDUP((BS21-BR21)/7,0)=0,"",ROUNDUP((BS21-BR21)/7,0)) | BU21: =IFERROR(IF((BX21-(BK21+BP21))/BT21=0,"",ROUNDUP((BX21-(BK21+BP21))/BT21,0)), "") | BV21: =IFERROR(IF((BX21-(BL21+BQ21))=0, "", (BX21-(BL21+BQ21))), "") | BW21: =IFERROR(IF((BJ21+BO21+BT21)=0, "", (BJ21+BO21+BT21)), "") | CA21: =IF(_xlfn.XLOOKUP(BY21, AutoFill_classes!$A:$A, AutoFill_classes!$B:$B,"")=0,"",_xlfn.XLOOKUP(BY21, AutoFill_classes!$A:$A, AutoFill_classes!$B:$B,"")) | CJ21: =IF(CH21*CI21=0,"",CH21*CI21) | CO21: =IF(ROUNDUP((CN21-CM21)/7,0)=0,"",ROUNDUP((CN21-CM21)/7,0)) | CQ21: =IFERROR(IF(CO21*CP21=0,"",CO21*CP21), "") | CT21: =IF(ROUNDUP((CS21-CR21)/7,0)=0,"",ROUNDUP((CS21-CR21)/7,0)) | CV21: =IFERROR(IF(CT21*CU21=0,"",CT21*CU21), "") | CY21: =IF(ROUNDUP((CX21-CW21)/7,0)=0,"",ROUNDUP((CX21-CW21)/7,0)) | CZ21: =IFERROR(IF((DC21-(CP21+CU21))/CY21=0,"",ROUNDUP((DC21-(CP21+CU21))/CY21,0)), "") | DA21: =IFERROR(IF((DC21-(CQ21+CV21))=0, "", (DC21-(CQ21+CV21))), "") | DB21: =IFERROR(IF((CO21+CT21+CY21)=0, "", (CO21+CT21+CY21)), "") | DE21: 19
A22: Totals: Roy Gaton notes: Pastoral Care; 25% load reduction | B22: ="Total Credits: " & IFERROR(IF(DD22=0,"",DD22),"") -> Total Credits: 13 | X22: =IF(SUM(X23:X31)=0, "", SUM(X23:X31)) -> 3 | BC22: =IF(SUM(BC23:BC31)=0, "", SUM(BC23:BC31)) -> 4 | CH22: =IF(SUM(CH23:CH31)=0, "", SUM(CH23:CH31)) -> 6 | DD22: =IF(SUM(L22:DC22)=0, "", SUM(L22:DC22)) -> 13 | DE22: 20
