Workbook

Sheet CHIS
A1: Don {not in Banner} | B1: Mismatching {not in Banner} | C1: Dept/Prog Admin {not in Banner} | D1: Mona {not in Banner} | E1: Karen {not in Banner} | F1: DONE {not in Banner} | G1: Notes {not in Banner} | H1: CRN sorted {not in Banner} | I1: CRN | J1: Subject | K1: Course Number {Crse Num} | L1: Course Section {Seq Crse Num} | M1: Program {not in Banner} | N1: Catalog Title | O1: Section Title | P1: Crosslist Details {not in Banner} | Q1: X Lst | R1: Campus {Ssasect Campus} | S1: Campus Restriction {Camp Restr CC} | T1: Schedule Type {not in Banner} | U1: Instruction Method {Inst Method} | V1: Level {Level SC} | W1: Credit Catalog {Cat Crs} | X1: Credits {Sect Crs} | Y1: Enrollment Cap {Max Enrl} | Z1: Meeting Type | AA1: Semester Start Date {Soaterm Start Date} | AB1: Pre-work Start Date {not in Banner} | AC1: Pre-work End Date {not in Banner} | AD1: Course Start Date {Meet Start Date} | AE1: Course End Date {Meet End Date} | AF1: Post-work Start Date {not in Banner} | AG1: Post-work End Date {not in Banner} | AH1: Semester End Date {Soaterm End Date} | AI1: Course Beginning Time {Meet Beg Time} | AJ1: Course Ending Time {Meet End Time} | AK1: SUN | AL1: MON | AM1: TUE | AN1: WED | AO1: THU | AP1: FRI | AQ1: SAT | AR1: Room {Meet Room} | AS1: Building {Meet Bldg} | AT1: Instructor Name {Instr Name} | AU1: Instructor Email {Instr Email} | AV1: Instructor ID {Instr ID} | AW1: % Responsibility | AX1: load/contract {not in Banner} | AY1: costs per credit {not in Banner} | AZ1: total costs {not in Banner} | BA1: account to be charged {not in Banner} | BB1: Fee Amount {Fees Amt} | BC1: Fee Code {Detl Code} | BD1: Fee Type | BE1: Fee Level | BF1: Fee Ind | BG1: Fee Term | BH1: SEM Department {Scacrse Dept} | BI1: Activity Date | BJ1: Status | BK1: Bill Hrs | BL1: Sect Sch Type | BM1: Prerequisites {Preq Areas} | BN1: Link Ind | BO1: Integration Code | BP1: Link Conn | BQ1: Crs Attr | BR1: Comments | BS1: Major Restr | BT1: Scacrse College | BU1: Enrolled | BV1: Waitlist Capacity | BW1: Primary Ind | BX1: Override | BY1: 1st Date Reg Opens | BZ1: Last Date Reg Opens | CA1: OL Range From Date | CB1: OL Range To Date | CC1: OL Numb Units | CD1: OL Duration Code | CE1: Grade Mode | CF1: Gradable Ind | CG1: Tuit Waiver | CH1: Course Override {Meet Override} | CI1: Lvl Res Ind | CJ1: Cmp Res Ind | CK1: Rate Code | CL1: Cohort Code | CM1: St Attr Code | CN1: Coll SC | CO1: DegC SC | CP1: Prog SC | CQ1: FOS Type | CR1: Special Approval {Special Apvl} | CS1: Weeks | CT1: Term Code | CU1: Part-Of-Term | CV1: Camp SC
A2: FALSE | B2: FALSE | C2: TRUE | D2: FALSE | E2: FALSE | F2: FALSE | G2: add FP Online Fee | H2: 3980-02 | I2: 3980 | J2: CHIS | K2: 506 | L2: 998 | N2: Church History to 1500 | Q2: 242 | R2: 7 | S2: 7 | T2: Int, Online | U2: SYNC | V2: FP | W2: 2,3 | Y2: 25 | Z2: WEB | AA2: 24-AUG-26 | AD2: 24-AUG-26 | AE2: 10-DEC-26 | AH2: 10-DEC-26 | AI2: 1430 | AJ2: 1720 | AL2: M | AT2: Reeve, John W. | AU2: =IF($AT2="","",IFERROR(INDEX(InstructorMap!$B:$B, MATCH($AT2, InstructorMap!$A:$A, 0)),"")) -> jreeve@andrews.edu | AV2: =IF($AT2="","",IFERROR(INDEX(InstructorMap!$C:$C, MATCH($AT2, InstructorMap!$A:$A, 0)),"")) -> 000049018 | AW2: 100 | AX2: load | BA2: CHIS: 11-1100-9120-70 | BH2: CHIS | BI2: 16-MAR-26 | BJ2: A | BL2: N | BO2: MOODL | BT2: 70 | BU2: 0 | BV2: 0 | BW2: Y | BX2: O | CF2: Y | CS2: 15 | CT2: 202641 | CU2: 1
A3: FALSE | B3: FALSE | C3: TRUE | D3: FALSE | E3: FALSE | F3: FALSE | H3: 538-02 | I3: 538 | J3: CHIS | K3: 506 | L3: 001 | N3: Church Hist to 1500 | Q3: 242 | R3: 0 | T3: Lecture | U3: INPERSON | V3: FP | W3: 2,3 | X3: 2,3 | Y3: 40 | Z3: CLAS | AA3: 24-AUG-26 | AD3: 24-AUG-26 | AE3: 10-DEC-26 | AH3: 10-DEC-26 | AI3: 1430 | AJ3: 1720 | AL3: M | AR3: N110 | AS3: Seminary Building [SEM] | AT3: Reeve, John W. | AU3: =IF($AT3="","",IFERROR(INDEX(InstructorMap!$B:$B, MATCH($AT3, InstructorMap!$A:$A, 0)),"")) -> jreeve@andrews.edu | AV3: =IF($AT3="","",IFERROR(INDEX(InstructorMap!$C:$C, MATCH($AT3, InstructorMap!$A:$A, 0)),"")) -> 000049018 | AW3: 100 | AX3: load | BA3: CHIS: 11-1100-9120-70 | BH3: CHIS | BI3: 16-MAR-26 | BJ3: A | BL3: A | BO3: MOODL | BT3: 70 | BU3: 0 | BV3: 99 | BW3: Y | BX3: O | CF3: Y | CH3: O | CS3: 16 | CT3: 202641 | CU3: 1
A4: FALSE | B4: FALSE | C4: TRUE | D4: FALSE | E4: FALSE | F4: FALSE | G4: add FP Online Fee | I4: #### | J4: CHIS | K4: 506 | L4: 999 | N4: Church History to 1500 | R4: 7 | T4: Int, Online | U4: ASYNC | V4: FP | W4: 2,3 | X4: 2 | Y4: 30 | Z4: WEB | AA4: 24-AUG-26 | AD4: 24-AUG-26 | AE4: 10-DEC-26 | AH4: 10-DEC-26 | AI4: #### | AJ4: #### | AT4: Reeve, John W. | AU4: =IF($AT4="","",IFERROR(INDEX(InstructorMap!$B:$B, MATCH($AT4, InstructorMap!$A:$A, 0)),"")) -> jreeve@andrews.edu | AV4: =IF($AT4="","",IFERROR(INDEX(InstructorMap!$C:$C, MATCH($AT4, InstructorMap!$A:$A, 0)),"")) -> 000049018 | AW4: 100 | AX4: load | BA4: CHIS: 11-1100-9120-70 | BH4: CHIS | CS4: #### | CT4: 202641
A5: FALSE | B5: FALSE | C5: TRUE | D5: FALSE | E5: FALSE | F5: FALSE | G5: Instructor, add FP Online Fee | H5: 1361-02 | I5: 1361 | J5: CHIS | K5: 570 | L5: 999 | N5: Hist of the SDA Church | R5: 7 | T5: Int, Online | U5: ASYNC | V5: FP | W5: 1.5,2 | X5: 1.5 | Y5: 25 | Z5: WEB | AA5: 24-AUG-26 | AD5: 24-AUG-26 | AE5: 10-DEC-26 | AH5: 10-DEC-26 | AI5: #### | AJ5: #### | AT5: Garcia Zarate, Heber E. | AU5: =IF($AT5="","",IFERROR(INDEX(InstructorMap!$B:$B, MATCH($AT5, InstructorMap!$A:$A, 0)),"")) -> heber@andrews.edu | AV5: =IF($AT5="","",IFERROR(INDEX(InstructorMap!$C:$C, MATCH($AT5, InstructorMap!$A:$A, 0)),"")) -> 000147941 | AW5: 100 | AX5: contract | AY5: 1000 | BA5: CHIS: 11-1100-9120-70 | BH5: CHIS | BI5: 16-MAR-26 | BJ5: A | BL5: N | BO5: MOODL | BT5: 70 | BU5: 0 | BV5: 0 | BW5: Y | CF5: Y | CS5: #### | CT5: 202641 | CU5: 1
A6: FALSE | B6: FALSE | C6: TRUE | D6: FALSE | E6: FALSE | F6: FALSE | G6: Instructor, add FP Online Fee | H6: 1362-02 | I6: 1362 | J6: CHIS | K6: 571 | L6: 999 | N6: Life & Wr. of EGW | R6: 7 | T6: Int, Online | U6: ASYNC | V6: FP | W6: 1.5,2 | X6: 1.5 | Y6: 25 | Z6: WEB | AA6: 24-AUG-26 | AD6: 24-AUG-26 | AE6: 10-DEC-26 | AH6: 10-DEC-26 | AI6: #### | AJ6: #### | AT6: Steger, Walter E. | AU6: =IF($AT6="","",IFERROR(INDEX(InstructorMap!$B:$B, MATCH($AT6, InstructorMap!$A:$A, 0)),"")) -> steger@andrews.edu | AV6: =IF($AT6="","",IFERROR(INDEX(InstructorMap!$C:$C, MATCH($AT6, InstructorMap!$A:$A, 0)),"")) -> 000064286 | AX6: contract | AY6: 1000 | BA6: CHIS: 11-1100-9120-70 | BH6: CHIS | BI6: 16-MAR-26 | BJ6: A | BL6: N | BO6: MOODL | BQ6: ADVN | BT6: 70 | BU6: 0 | BV6: 0 | CF6: Y | CS6: #### | CT6: 202641 | CU6: 1
A7: FALSE | B7: FALSE | C7: TRUE | D7: FALSE | E7: FALSE | F7: FALSE | H7: 3987-02 | I7: 3987 | J7: CHIS | K7: 612 | L7: 001 | N7: Intro to Ecc Latin | Q7: 249 | R7: 0 | T7: Lecture | U7: INPERSON | V7: FP | W7: 3 | X7: 3 | Y7: 12 | Z7: CLAS | AA7: 24-AUG-26 | AD7: 24-AUG-26 | AE7: 10-DEC-26 | AH7: 10-DEC-26 | AI7: 0830 | AJ7: 1020 | AL7: M | AN7: W | AR7: N108 | AS7: Seminary Building [SEM] | AT7: Kaiser, Angelika | AU7: =IF($AT7="","",IFERROR(INDEX(InstructorMap!$B:$B, MATCH($AT7, InstructorMap!$A:$A, 0)),"")) -> angelika@andrews.edu | AV7: =IF($AT7="","",IFERROR(INDEX(InstructorMap!$C:$C, MATCH($AT7, InstructorMap!$A:$A, 0)),"")) -> 000143159 | AX7: contract | AY7: 1050 | BA7: CHIS: 11-1100-9120-70 | BH7: CHIS | BI7: 16-MAR-26 | BJ7: A | BL7: A | BO7: MOODL | BQ7: LLIT | BT7: 70 | BU7: 0 | BV7: 0 | CF7: Y | CH7: O | CS7: 16 | CT7: 202641 | CU7: 1
A8: FALSE | B8: FALSE | C8: TRUE | D8: FALSE | E8: FALSE | F8: FALSE | H8: 3987-04 | I8: 3987 | J8: CHIS | K8: 612 | L8: 001 | N8: Intro to Ecc Latin | Q8: 249 | R8: 0 | T8: Lecture | U8: INPERSON | V8: FP | W8: 3 | X8: 3 | Y8: 12 | Z8: CLAS | AA8: 24-AUG-26 | AD8: 24-AUG-26 | AE8: 10-DEC-26 | AH8: 10-DEC-26 | AI8: 0830 | AJ8: 1020 | AL8: M | AN8: W | AR8: N108 | AS8: Seminary Building [SEM] | AT8: Kaiser, Angelika | AU8: =IF($AT8="","",IFERROR(INDEX(InstructorMap!$B:$B, MATCH($AT8, InstructorMap!$A:$A, 0)),"")) -> angelika@andrews.edu | AV8: =IF($AT8="","",IFERROR(INDEX(InstructorMap!$C:$C, MATCH($AT8, InstructorMap!$A:$A, 0)),"")) -> 000143159 | BH8: CHIS | BI8: 16-MAR-26 | BJ8: A | BL8: A | BO8: MOODL | BQ8: LLIT | BT8: 70 | BU8: 0 | BV8: 0 | CF8: Y | CH8: O | CS8: 16 | CT8: 202641 | CU8: 1
A9: FALSE | B9: FALSE | C9: TRUE | D9: FALSE | E9: FALSE | F9: FALSE | G9: add FP Online Fee | H9: 3988-02 | I9: 3988 | J9: CHIS | K9: 612 | L9: 998 | N9: Intro to Ecc Latin | Q9: 249 | R9: 7 | T9: Int, Online | U9: SYNC | V9: FP | W9: 3 | X9: 3 | Y9: 12 | Z9: WEB | AA9: 24-AUG-26 | AD9: 24-AUG-26 | AE9: 10-DEC-26 | AH9: 10-DEC-26 | AI9: 0830 | AJ9: 1020 | AL9: M | AN9: W | AT9: Kaiser, Angelika | AU9: =IF($AT9="","",IFERROR(INDEX(InstructorMap!$B:$B, MATCH($AT9, InstructorMap!$A:$A, 0)),"")) -> angelika@andrews.edu | AV9: =IF($AT9="","",IFERROR(INDEX(InstructorMap!$C:$C, MATCH($AT9, InstructorMap!$A:$A, 0)),"")) -> 000143159 | BH9: CHIS | BI9: 16-MAR-26 | BJ9: A | BL9: N | BO9: MOODL | BQ9: LLIT | BT9: 70 | BU9: 0 | BV9: 0 | CF9: Y | CS9: 16 | CT9: 202641 | CU9: 1
A10: FALSE | B10: FALSE | C10: TRUE | D10: FALSE | E10: FALSE | F10: FALSE | G10: add FP Online Fee | H10: 3988-04 | I10: 3988 | J10: CHIS | K10: 612 | L10: 998 | N10: Intro to Ecc Latin | Q10: 249 | R10: 7 | S10: 7 | T10: Int, Online | U10: SYNC | V10: FP | W10: 3 | X10: 3 | Y10: 12 | Z10: WEB | AA10: 24-AUG-26 | AD10: 24-AUG-26 | AE10: 10-DEC-26 | AH10: 10-DEC-26 | AI10: 0830 | AJ10: 1020 | AL10: M | AN10: W | AT10: Kaiser, Angelika | AU10: =IF($AT10="","",IFERROR(INDEX(InstructorMap!$B:$B, MATCH($AT10, InstructorMap!$A:$A, 0)),"")) -> angelika@andrews.edu | AV10: =IF($AT10="","",IFERROR(INDEX(InstructorMap!$C:$C, MATCH($AT10, InstructorMap!$A:$A, 0)),"")) -> 000143159 | BH10: CHIS | BI10: 16-MAR-26 | BJ10: A | BL10: N | BO10: MOODL | BQ10: LLIT | BT10: 70 | BU10: 0 | BV10: 0 | CF10: Y | CS10: 16 | CT10: 202641 | CU10: 1
A11: FALSE | B11: FALSE | C11: TRUE | D11: FALSE | E11: FALSE | F11: FALSE | G11: Instructor | H11: 463-02 | I11: 463 | J11: CHIS | K11: 624 | L11: 001 | N11: Issues in Ellen White Studies | P11: CHIS624-001/CHIS885-001 | Q11: 077 | R11: 0 | T11: Lecture | U11: INPERSON | V11: FP | W11: 2,3 | X11: 2 | Y11: 45 | Z11: CLAS | AA11: 24-AUG-26 | AD11: 24-AUG-26 | AE11: 10-DEC-26 | AH11: 10-DEC-26 | AI11: 1430 | AJ11: 1620 | AN11: W | AR11: N150 | AS11: Seminary Building [SEM] | AT11: Staff | AU11: =IF($AT11="","",IFERROR(INDEX(InstructorMap!$B:$B, MATCH($AT11, InstructorMap!$A:$A, 0)),"")) | AV11: =IF($AT11="","",IFERROR(INDEX(InstructorMap!$C:$C, MATCH($AT11, InstructorMap!$A:$A, 0)),"")) | AX11: load | BA11: CHIS: 11-1100-9120-70 | BH11: CHIS | BI11: 16-MAR-26 | BJ11: A | BL11: A | BM11: P-CHIS624 | BO11: MOODL | BQ11: THEO | BT11: 70 | BU11: 0 | BV11: 99 | BW11: Y | BX11: O | CF11: Y | CH11: O | CS11: 16 | CT11: 202641 | CU11: 1
A12: FALSE | B12: FALSE | C12: TRUE | D12: FALSE | E12: FALSE | F12: FALSE | I12: ### | J12: CHIS | K12: 645 | L12: 001 | N12: Seminar in Adv Studies | P12: CHIS645-001/CHIS944-101 | R12: 0 | T12: Lecture | U12: INPERSON | V12: FP | W12: 3 | X12: 3 | Y12: 5 | Z12: CLAS | AA12: 24-AUG-26 | AD12: 24-AUG-26 | AE12: 10-DEC-26 | AH12: 10-DEC-26 | AI12: 1430 | AJ12: 1720 | AN12: W | AR12: N108 | AS12: Seminary Building [SEM] | AT12: Rodrigues, Gerson C. | AU12: =IF($AT12="","",IFERROR(INDEX(InstructorMap!$B:$B, MATCH($AT12, InstructorMap!$A:$A, 0)),"")) -> gersoncr@andrews.edu | AV12: =IF($AT12="","",IFERROR(INDEX(InstructorMap!$C:$C, MATCH($AT12, InstructorMap!$A:$A, 0)),"")) -> 000093682 | AW12: 100 | AX12: load | BA12: CHIS: 11-1100-9120-70 | BH12: CHIS | CS12: 16 | CT12: 202641
A13: FALSE | B13: FALSE | C13: TRUE | D13: FALSE | E13: FALSE | F13: FALSE | H13: 3177-02 | I13: 3177 | J13: CHIS | K13: 660 | L13: 001 | N13: Hist of Religion in America | P13: CHIS660-001/CHIS660-002/CHIS880-001 | Q13: 164 | R13: 0 | T13: Lecture | U13: INPERSON | V13: FP | W13: 2,3 | X13: 2 | Y13: 25 | Z13: CLAS | AA13: 24-AUG-26 | AD13: 24-AUG-26 | AE13: 10-DEC-26 | AH13: 10-DEC-26 | AI13: 1430 | AJ13: 1720 | AM13: T | AR13: N235 | AS13: Seminary Building [SEM] | AT13: O'Reggio, Trevor E. | AU13: =IF($AT13="","",IFERROR(INDEX(InstructorMap!$B:$B, MATCH($AT13, InstructorMap!$A:$A, 0)),"")) -> toreggio@andrews.edu | AV13: =IF($AT13="","",IFERROR(INDEX(InstructorMap!$C:$C, MATCH($AT13, InstructorMap!$A:$A, 0)),"")) -> 000035762 | AW13: 100 | AX13: load | BA13: CHIS: 11-1100-9120-70 | BH13: CHIS | BI13: 16-MAR-26 | BJ13: A | BL13: A | BO13: MOODL | BQ13: ADVN,CH2,US1,US2 | BT13: 70 | BU13: 0 | BV13: 0 | BW13: Y | BX13: O | CF13: Y | CH13: O | CS13: 16 | CT13: 202641 | CU13: 1
A14: FALSE | B14: FALSE | C14: TRUE | D14: FALSE | E14: FALSE | F14: FALSE | I14: 4661 | J14: CHIS | K14: 660 | L14: 002 | N14: Hist of Religion in America | P14: CHIS660-001/CHIS660-002/CHIS880-001 | R14: 0 | T14: Lecture | U14: INPERSON | V14: FP | W14: 2,3 | X14: 3 | Y14: 10 | Z14: CLAS | AA14: 24-AUG-26 | AD14: 24-AUG-26 | AE14: 10-DEC-26 | AH14: 10-DEC-26 | AI14: 1430 | AJ14: 1720 | AM14: T | AR14: N235 | AS14: Seminary Building [SEM] | AT14: O'Reggio, Trevor E. | AU14: =IF($AT14="","",IFERROR(INDEX(InstructorMap!$B:$B, MATCH($AT14, InstructorMap!$A:$A, 0)),"")) -> toreggio@andrews.edu | AV14: =IF($AT14="","",IFERROR(INDEX(InstructorMap!$C:$C, MATCH($AT14, InstructorMap!$A:$A, 0)),"")) -> 000035762 | AW14: 100 | AX14: load | BA14: CHIS: 11-1100-9120-70 | BH14: CHIS | CS14: 16 | CT14: 202641
A15: FALSE | B15: FALSE | C15: TRUE | D15: FALSE | E15: FALSE | F15: FALSE | I15: ### | J15: CHIS | K15: 674 | L15: 002 | N15: Dev of SDA Theology | P15: CHIS674-001/CHIS674-002/CHIS885-002 | R15: 0 | T15: Lecture | U15: INPERSON | V15: FP | W15: 2,3 | X15: 3 | Y15: 30 | Z15: CLAS | AA15: 24-AUG-26 | AD15: 24-AUG-26 | AE15: 10-DEC-26 | AH15: 10-DEC-26 | AI15: 1430 | AJ15: 1720 | AO15: R | AR15: N110 | AS15: Seminary Building [SEM] | AT15: Staff | AU15: =IF($AT15="","",IFERROR(INDEX(InstructorMap!$B:$B, MATCH($AT15, InstructorMap!$A:$A, 0)),"")) | AV15: =IF($AT15="","",IFERROR(INDEX(InstructorMap!$C:$C, MATCH($AT15, InstructorMap!$A:$A, 0)),"")) | AX15: load | BA15: CHIS: 11-1100-9120-70 | BH15: CHIS | CS15: 16 | CT15: 202641
A16: FALSE | B16: FALSE | C16: TRUE | D16: FALSE | E16: FALSE | F16: FALSE | G16: Instructor | H16: 487-02 | I16: 487 | J16: CHIS | K16: 674 | L16: 001 | N16: Dev of SDA Theology | P16: CHIS674-001/CHIS674-002/CHIS885-002 | Q16: 288 | R16: 0 | T16: Lecture | U16: INPERSON | V16: FP | W16: 2,3 | X16: 2 | Y16: 15 | Z16: CLAS | AA16: 24-AUG-26 | AD16: 24-AUG-26 | AE16: 10-DEC-26 | AH16: 10-DEC-26 | AI16: 1430 | AJ16: 1720 | AO16: R | AR16: N110 | AS16: Seminary Building [SEM] | AT16: Staff | AU16: =IF($AT16="","",IFERROR(INDEX(InstructorMap!$B:$B, MATCH($AT16, InstructorMap!$A:$A, 0)),"")) | AV16: =IF($AT16="","",IFERROR(INDEX(InstructorMap!$C:$C, MATCH($AT16, InstructorMap!$A:$A, 0)),"")) | AX16: load | BA16: CHIS: 11-1100-9120-70 | BH16: CHIS | BI16: 16-MAR-26 | BJ16: A | BL16: A | BM16: P-CHIS674 | BO16: MOODL | BQ16: ADVN,THEO | BT16: 70 | BU16: 0 | BV16: 99 | BW16: Y | BX16: O | CF16: Y | CH16: O | CS16: 16 | CT16: 202641 | CU16: 1
A17: FALSE | B17: FALSE | C17: TRUE | D17: FALSE | E17: FALSE | F17: FALSE | I17: ### | J17: CHIS | K17: 645 | L17: 001 | N17: Seminar in Adventist Studies | P17: CHIS685-001/CHIS944-001 | R17: 0 | T17: Lecture | U17: INPERSON | V17: FP | W17: 3 | X17: 3 | Y17: 5 | Z17: CLAS | AA17: 24-AUG-26 | AD17: 24-AUG-26 | AE17: 10-DEC-26 | AH17: 10-DEC-26 | AI17: 1430 | AJ17: 1720 | AN17: W | AR17: N108 | AS17: Seminary Building [SEM] | AT17: Rodrigues, Gerson C. | AU17: =IF($AT17="","",IFERROR(INDEX(InstructorMap!$B:$B, MATCH($AT17, InstructorMap!$A:$A, 0)),"")) -> gersoncr@andrews.edu | AV17: =IF($AT17="","",IFERROR(INDEX(InstructorMap!$C:$C, MATCH($AT17, InstructorMap!$A:$A, 0)),"")) -> 000093682 | AW17: 100 | AX17: load | BA17: CHIS: 11-1100-9120-70 | BH17: CHIS | CS17: 16 | CT17: 202641
A18: FALSE | B18: FALSE | C18: TRUE | D18: FALSE | E18: FALSE | F18: FALSE | I18: ### | J18: CHIS | K18: 685 | L18: 002 | N18: Hist & Theo of Adv Worship | P18: CHIS685-002/CHIS685-003/PATH654-001 | R18: 0 | T18: Lecture | U18: INPERSON | V18: FP | W18: 2,3 | X18: 2 | Y18: 25 | Z18: CLAS | AA18: 24-AUG-26 | AD18: 24-AUG-26 | AE18: 10-DEC-26 | AH18: 10-DEC-26 | AI18: 0830 | AJ18: 1020 | AN18: W | AR18: S120 | AS18: Seminary Building [SEM] | AT18: Williams, David A. | AU18: =IF($AT18="","",IFERROR(INDEX(InstructorMap!$B:$B, MATCH($AT18, InstructorMap!$A:$A, 0)),"")) -> wdavid@andrews.edu | AV18: =IF($AT18="","",IFERROR(INDEX(InstructorMap!$C:$C, MATCH($AT18, InstructorMap!$A:$A, 0)),"")) -> 000124996 | AW18: 100 | AX18: load | BA18: CHIS: 11-1100-9120-70 | BH18: CHIS | CS18: 16 | CT18: 202641
A19: FALSE | B19: FALSE | C19: TRUE | D19: FALSE | E19: FALSE | F19: FALSE | I19: ### | J19: CHIS | K19: 685 | L19: 003 | N19: Hist & Theo of Adv Worship | P19: CHIS685-002/CHIS685-003/PATH654-001 | R19: 0 | T19: Lecture | U19: INPERSON | V19: FP | W19: 2,3 | X19: 3 | Y19: 25 | Z19: CLAS | AA19: 24-AUG-26 | AD19: 24-AUG-26 | AE19: 10-DEC-26 | AH19: 10-DEC-26 | AI19: 0830 | AJ19: 1020 | AN19: W | AR19: S120 | AS19: Seminary Building [SEM] | AT19: Williams, David A. | AU19: =IF($AT19="","",IFERROR(INDEX(InstructorMap!$B:$B, MATCH($AT19, InstructorMap!$A:$A, 0)),"")) -> wdavid@andrews.edu | AV19: =IF($AT19="","",IFERROR(INDEX(InstructorMap!$C:$C, MATCH($AT19, InstructorMap!$A:$A, 0)),"")) -> 000124996 | AW19: 100 | AX19: load | BA19: CHIS: 11-1100-9120-70 | BH19: CHIS | CS19: 16 | CT19: 202641
A20: FALSE | B20: FALSE | C20: TRUE | D20: FALSE | E20: FALSE | F20: FALSE | G20: add FP Online Fee | I20: ### | J20: CHIS | K20: 685 | L20: 998 | N20: Seminar in Church History | P20: CHIS685-998/CHIS940-998 | R20: 7 | S20: 7 | T20: Int, Online | U20: SYNC | V20: FP | W20: 3 | X20: 3 | Y20: 5 | Z20: WEB | AA20: 24-AUG-26 | AH20: 10-DEC-26 | AI20: 0830 | AJ20: 1120 | AL20: M | AT20: Staff | BH20: CHIS
A21: FALSE | B21: FALSE | C21: TRUE | D21: FALSE | E21: FALSE | F21: FALSE | I21: ### | J21: CHIS | K21: 940 | L21: 998 | N21: Seminar in Church History | P21: CHIS685-998/CHIS940-998 | R21: 7 | S21: 7 | T21: Int, Online | U21: SYNC | V21: DO | W21: 3 | X21: 3 | Y21: 25 | Z21: WEB | AA21: 24-AUG-26 | AH21: 10-DEC-26 | AI21: 0830 | AJ21: 1120 | AL21: M | AT21: Staff | BH21: CHIS
A22: FALSE | B22: FALSE | C22: TRUE | D22: FALSE | E22: FALSE | F22: FALSE | G22: Remove Title | H22: 881-02 | I22: 881 | J22: CHIS | K22: 690 | L22: 104 | N22: Ind St: | R22: 0 | T22: Independent | V22: FP | W22: 1-3 | X22: 1-3 | Y22: 999 | Z22: CLAS | AA22: 24-AUG-26 | AD22: 24-AUG-26 | AE22: 10-DEC-26 | AH22: 10-DEC-26 | AT22: Hernandez, Abner F. | AU22: =IF($AT22="","",IFERROR(INDEX(InstructorMap!$B:$B, MATCH($AT22, InstructorMap!$A:$A, 0)),"")) -> abnerh@andrews.edu | AV22: =IF($AT22="","",IFERROR(INDEX(InstructorMap!$C:$C, MATCH($AT22, InstructorMap!$A:$A, 0)),"")) -> 000149024 | AW22: 100 | BA22: CHIS: 11-1100-9120-70 | BH22: CHIS | BI22: 16-MAR-26 | BJ22: A | BK22: 2 | BL22: I | BO22: MOODL | BT22: 70 | BU22: 0 | BV22: 0 | BW22: Y | CF22: Y | CR22: I | CS22: 15 | CT22: 202641 | CU22: 1
A23: FALSE | B23: FALSE | C23: TRUE | D23: FALSE | E23: FALSE | F23: FALSE | G23: Remove Title | H23: 1012-02 | I23: 1012 | J23: CHIS | K23: 690 | L23: 102 | N23: Ind St: | R23: 0 | T23: Independent | V23: FP | W23: 1-3 | X23: 1-3 | Y23: 999 | Z23: CLAS | AA23: 24-AUG-26 | AD23: 24-AUG-26 | AE23: 10-DEC-26 | AH23: 10-DEC-26 | AT23: O'Reggio, Trevor E. | AU23: =IF($AT23="","",IFERROR(INDEX(InstructorMap!$B:$B, MATCH($AT23, InstructorMap!$A:$A, 0)),"")) -> toreggio@andrews.edu | AV23: =IF($AT23="","",IFERROR(INDEX(InstructorMap!$C:$C, MATCH($AT23, InstructorMap!$A:$A, 0)),"")) -> 000035762 | AW23: 100 | BA23: CHIS: 11-1100-9120-70 | BH23: CHIS | BI23: 16-MAR-26 | BJ23: A | BL23: I | BO23: MOODL | BT23: 70 | BU23: 0 | BV23: 0 | BW23: Y | CF23: Y | CR23: I | CS23: 15 | CT23: 202641 | CU23: 1
A24: FALSE | B24: FALSE | C24: TRUE | D24: FALSE | E24: FALSE | F24: FALSE | G24: Remove Title | H24: 1041-02 | I24: 1041 | J24: CHIS | K24: 690 | L24: 101 | N24: Ind St: | R24: 0 | T24: Independent | V24: FP | W24: 1-3 | X24: 1-3 | Y24: 999 | Z24: CLAS | AA24: 24-AUG-26 | AD24: 24-AUG-26 | AE24: 10-DEC-26 | AH24: 10-DEC-26 | AT24: Reeve, John W. | AU24: =IF($AT24="","",IFERROR(INDEX(InstructorMap!$B:$B, MATCH($AT24, InstructorMap!$A:$A, 0)),"")) -> jreeve@andrews.edu | AV24: =IF($AT24="","",IFERROR(INDEX(InstructorMap!$C:$C, MATCH($AT24, InstructorMap!$A:$A, 0)),"")) -> 000049018 | AW24: 100 | BA24: CHIS: 11-1100-9120-70 | BH24: CHIS | BI24: 16-MAR-26 | BJ24: A | BL24: I | BO24: MOODL | BT24: 70 | BU24: 0 | BV24: 0 | BW24: Y | CF24: Y | CR24: I | CS24: 15 | CT24: 202641 | CU24: 1
A25: FALSE | B25: FALSE | C25: TRUE | D25: FALSE | E25: FALSE | F25: FALSE | G25: Remove Title | H25: 2068-02 | I25: 2068 | J25: CHIS | K25: 690 | L25: 105 | N25: Ind St: | R25: 0 | T25: Independent | V25: FP | W25: 1-3 | X25: 1-3 | Y25: 999 | Z25: CLAS | AA25: 24-AUG-26 | AD25: 24-AUG-26 | AE25: 10-DEC-26 | AH25: 10-DEC-26 | AT25: Kaiser, Denis | AU25: =IF($AT25="","",IFERROR(INDEX(InstructorMap!$B:$B, MATCH($AT25, InstructorMap!$A:$A, 0)),"")) -> denis@andrews.edu | AV25: =IF($AT25="","",IFERROR(INDEX(InstructorMap!$C:$C, MATCH($AT25, InstructorMap!$A:$A, 0)),"")) -> 000134382 | AW25: 100 | BA25: CHIS: 11-1100-9120-70 | BH25: CHIS | BI25: 16-MAR-26 | BJ25: A | BL25: I | BO25: MOODL | BT25: 70 | BU25: 0 | BV25: 0 | BW25: Y | CF25: Y | CR25: I | CS25: 15 | CT25: 202641 | CU25: 1
A26: FALSE | B26: FALSE | C26: TRUE | D26: FALSE | E26: FALSE | F26: FALSE | G26: Add Title | H26: 535-02 | I26: 535 | J26: CHIS | K26: 880 | L26: 001 | N26: Topics in Church History: | O26: Hist of Religion in America | P26: CHIS660-001/CHIS660-002/CHIS880-001 | Q26: 164 | R26: 0 | T26: Lecture | U26: INPERSON | V26: DO | W26: 1-3 | X26: 1-3 | Y26: 5 | Z26: CLAS | AA26: 24-AUG-26 | AD26: 24-AUG-26 | AE26: 10-DEC-26 | AH26: 10-DEC-26 | AI26: 1430 | AJ26: 1720 | AM26: T | AR26: N235 | AS26: Seminary Building [SEM] | AT26: O'Reggio, Trevor E. | AU26: =IF($AT26="","",IFERROR(INDEX(InstructorMap!$B:$B, MATCH($AT26, InstructorMap!$A:$A, 0)),"")) -> toreggio@andrews.edu | AV26: =IF($AT26="","",IFERROR(INDEX(InstructorMap!$C:$C, MATCH($AT26, InstructorMap!$A:$A, 0)),"")) -> 000035762 | AW26: 100 | AX26: load | BA26: CHIS: 11-1100-9120-70 | BH26: CHIS | BI26: 16-MAR-26 | BJ26: A | BL26: A | BO26: MOODL | BT26: 70 | BU26: 0 | BV26: 0 | BW26: Y | BX26: O | CF26: Y | CH26: O | CS26: 16 | CT26: 202641 | CU26: 1
A27: FALSE | B27: FALSE | C27: TRUE | D27: FALSE | E27: FALSE | F27: FALSE | G27: Add Title | H27: 2071-02 | I27: 2071 | J27: CHIS | K27: 885 | L27: 001 | N27: Issues in Ellen White Studies | O27: Issues in Ellen White Studies | P27: CHIS624-001/CHIS885-001 | Q27: 077 | R27: 0 | T27: Lecture | U27: INPERSON | V27: DO | W27: 1-3 | X27: 1-3 | Y27: 5 | Z27: CLAS | AA27: 24-AUG-26 | AD27: 24-AUG-26 | AE27: 10-DEC-26 | AH27: 10-DEC-26 | AI27: 1430 | AJ27: 1620 | AN27: W | AR27: N150 | AS27: Seminary Building [SEM] | AT27: Rodrigues, Gerson C. | AU27: =IF($AT27="","",IFERROR(INDEX(InstructorMap!$B:$B, MATCH($AT27, InstructorMap!$A:$A, 0)),"")) -> gersoncr@andrews.edu | AV27: =IF($AT27="","",IFERROR(INDEX(InstructorMap!$C:$C, MATCH($AT27, InstructorMap!$A:$A, 0)),"")) -> 000093682 | AW27: 100 | AX27: load | BA27: CHIS: 11-1100-9120-70 | BH27: CHIS | BI27: 16-MAR-26 | BJ27: A | BL27: A | BO27: MOODL | BT27: 70 | BU27: 0 | BV27: 0 | BW27: Y | BX27: O | CF27: Y | CH27: O | CS27: 16 | CT27: 202641 | CU27: 1
A28: FALSE | B28: FALSE | C28: TRUE | D28: FALSE | E28: FALSE | F28: FALSE | G28: Add Title | H28: 4303-02 | I28: 4303 | J28: CHIS | K28: 885 | L28: 002 | N28: Topics in Adv St | O28: Dev of SDA Theology | P28: CHIS674-001/CHIS674-002/CHIS885-002 | Q28: 288 | R28: 0 | T28: Lecture | U28: INPERSON | V28: DO | W28: 1-3 | X28: 1-3 | Y28: 5 | Z28: CLAS | AA28: 24-AUG-26 | AD28: 24-AUG-26 | AE28: 10-DEC-26 | AH28: 10-DEC-26 | AI28: 1430 | AJ28: 1720 | AO28: R | AR28: N110 | AS28: Seminary Building [SEM] | AT28: Rodrigues, Gerson C. | AU28: =IF($AT28="","",IFERROR(INDEX(InstructorMap!$B:$B, MATCH($AT28, InstructorMap!$A:$A, 0)),"")) -> gersoncr@andrews.edu | AV28: =IF($AT28="","",IFERROR(INDEX(InstructorMap!$C:$C, MATCH($AT28, InstructorMap!$A:$A, 0)),"")) -> 000093682 | AW28: 100 | AX28: load | BA28: CHIS: 11-1100-9120-70 | BH28: CHIS | BI28: 16-MAR-26 | BJ28: A | BL28: A | BO28: MOODL | BT28: 70 | BU28: 0 | BV28: 0 | BW28: Y | BX28: O | CF28: Y | CH28: O | CS28: 16 | CT28: 202641 | CU28: 1
A29: FALSE | B29: FALSE | C29: TRUE | D29: FALSE | E29: FALSE | F29: FALSE | G29: Deactivate | H29: 4343-02 | I29: 4343 | J29: CHIS | K29: 885 | L29: 003 | N29: Topics in | O29: Topics Grt Cont, Cov, Law, Sab | Q29: 274 | R29: 0 | W29: 1-3 | Y29: 5 | Z29: CLAS | AA29: 24-AUG-26 | AD29: 24-AUG-26 | AE29: 10-DEC-26 | AH29: 10-DEC-26 | AI29: 1330 | AJ29: 1520 | AO29: R | AS29: Seminary Building [SEM] | AT29: Davidson, Richard M. | AU29: =IF($AT29="","",IFERROR(INDEX(InstructorMap!$B:$B, MATCH($AT29, InstructorMap!$A:$A, 0)),"")) -> davidson@andrews.edu | AV29: =IF($AT29="","",IFERROR(INDEX(InstructorMap!$C:$C, MATCH($AT29, InstructorMap!$A:$A, 0)),"")) -> 000012107 | AW29: 100 | BH29: CHIS | BI29: 16-MAR-26 | BJ29: A | BL29: A | BO29: MOODL | BT29: 70 | BU29: 0 | BV29: 0 | BW29: Y | BX29: O | CF29: Y | CH29: O | CS29: 15 | CT29: 202641 | CU29: 1
A30: FALSE | B30: FALSE | C30: TRUE | D30: FALSE | E30: FALSE | F30: FALSE | G30: Deactivate | H30: 4305-02 | I30: 4305 | J30: CHIS | K30: 885 | L30: 997 | N30: Topics in | O30: Top: Theological Ethics | Q30: 272 | R30: 7 | U30: SYNC | W30: 1-3 | Y30: 5 | Z30: WEB | AA30: 24-AUG-26 | AD30: 24-AUG-26 | AE30: 10-DEC-26 | AH30: 10-DEC-26 | AI30: 1430 | AJ30: 1720 | AN30: W | AT30: NAME NOT FOUND FOR PIDM: | AU30: =IF($AT30="","",IFERROR(INDEX(InstructorMap!$B:$B, MATCH($AT30, InstructorMap!$A:$A, 0)),"")) | AV30: =IF($AT30="","",IFERROR(INDEX(InstructorMap!$C:$C, MATCH($AT30, InstructorMap!$A:$A, 0)),"")) | BH30: CHIS | BI30: 16-MAR-26 | BJ30: A | BL30: N | BO30: MOODL | BT30: 70 | BU30: 0 | BV30: 0 | CF30: Y | CS30: 15 | CT30: 202641 | CU30: 1
A31: FALSE | B31: FALSE | C31: TRUE | D31: FALSE | E31: FALSE | F31: FALSE | H31: 3981-02 | I31: 3981 | J31: CHIS | K31: 890 | L31: 101 | N31: Directed Rdg in Church History | R31: 0 | T31: Independent | V31: DO | W31: 1-6 | X31: 1-6 | Y31: 5 | Z31: CLAS | AA31: 24-AUG-26 | AD31: 24-AUG-26 | AE31: 10-DEC-26 | AH31: 10-DEC-26 | AT31: Hernandez, Abner F. | AU31: =IF($AT31="","",IFERROR(INDEX(InstructorMap!$B:$B, MATCH($AT31, InstructorMap!$A:$A, 0)),"")) -> abnerh@andrews.edu | AV31: =IF($AT31="","",IFERROR(INDEX(InstructorMap!$C:$C, MATCH($AT31, InstructorMap!$A:$A, 0)),"")) -> 000149024 | AW31: 100 | BA31: CHIS: 11-1100-9120-70 | BH31: CHIS | BI31: 16-MAR-26 | BJ31: A | BL31: I | BO31: MOODL | BT31: 70 | BU31: 0 | BV31: 0 | BW31: Y | CF31: Y | CR31: T | CS31: 15 | CT31: 202641 | CU31: 1
A32: FALSE | B32: FALSE | C32: TRUE | D32: FALSE | E32: FALSE | F32: FALSE | H32: 3982-02 | I32: 3982 | J32: CHIS | K32: 890 | L32: 102 | N32: Directed Rdg in Church History | R32: 0 | T32: Independent | V32: DO | W32: 1-6 | X32: 1-6 | Y32: 5 | Z32: CLAS | AA32: 24-AUG-26 | AD32: 24-AUG-26 | AE32: 10-DEC-26 | AH32: 10-DEC-26 | AT32: O'Reggio, Trevor E. | AU32: =IF($AT32="","",IFERROR(INDEX(InstructorMap!$B:$B, MATCH($AT32, InstructorMap!$A:$A, 0)),"")) -> toreggio@andrews.edu | AV32: =IF($AT32="","",IFERROR(INDEX(InstructorMap!$C:$C, MATCH($AT32, InstructorMap!$A:$A, 0)),"")) -> 000035762 | AW32: 100 | BA32: CHIS: 11-1100-9120-70 | BH32: CHIS | BI32: 16-MAR-26 | BJ32: A | BL32: I | BO32: MOODL | BT32: 70 | BU32: 0 | BV32: 0 | BW32: Y | CF32: Y | CR32: T | CS32: 15 | CT32: 202641 | CU32: 1
A33: FALSE | B33: FALSE | C33: TRUE | D33: FALSE | E33: FALSE | F33: FALSE | G33: Remove Title | H33: 4300-02 | I33: 4300 | J33: CHIS | K33: 890 | L33: 105 | N33: Directed Rdg in Church History | R33: 0 | T33: Independent | V33: DO | W33: 1-6 | X33: 1-6 | Y33: 5 | Z33: CLAS | AA33: 24-AUG-26 | AD33: 24-AUG-26 | AE33: 10-DEC-26 | AH33: 10-DEC-26 | AT33: Reeve, John W. | AU33: =IF($AT33="","",IFERROR(INDEX(InstructorMap!$B:$B, MATCH($AT33, InstructorMap!$A:$A, 0)),"")) -> jreeve@andrews.edu | AV33: =IF($AT33="","",IFERROR(INDEX(InstructorMap!$C:$C, MATCH($AT33, InstructorMap!$A:$A, 0)),"")) -> 000049018 | AW33: 100 | BA33: CHIS: 11-1100-9120-70 | BH33: CHIS | BI33: 16-MAR-26 | BJ33: A | BL33: I | BO33: MOODL | BT33: 70 | BU33: 0 | BV33: 0 | BW33: Y | CF33: Y | CR33: I | CS33: 15 | CT33: 202641 | CU33: 1
A34: FALSE | B34: FALSE | C34: TRUE | D34: FALSE | E34: FALSE | F34: FALSE | G34: Remove Title | H34: 4301-02 | I34: 4301 | J34: CHIS | K34: 890 | L34: 103 | N34: Directed Rdg in Church History | R34: 0 | T34: Independent | V34: DO | W34: 1-6 | X34: 1-6 | Y34: 5 | Z34: CLAS | AA34: 24-AUG-26 | AD34: 24-AUG-26 | AE34: 10-DEC-26 | AH34: 10-DEC-26 | AT34: Reeve, John W. | AU34: =IF($AT34="","",IFERROR(INDEX(InstructorMap!$B:$B, MATCH($AT34, InstructorMap!$A:$A, 0)),"")) -> jreeve@andrews.edu | AV34: =IF($AT34="","",IFERROR(INDEX(InstructorMap!$C:$C, MATCH($AT34, InstructorMap!$A:$A, 0)),"")) -> 000049018 | AW34: 100 | BA34: CHIS: 11-1100-9120-70 | BH34: CHIS | BI34: 16-MAR-26 | BJ34: A | BL34: I | BO34: MOODL | BT34: 70 | BU34: 0 | BV34: 0 | BW34: Y | CF34: Y | CR34: I | CS34: 15 | CT34: 202641 | CU34: 1
A35: FALSE | B35: FALSE | C35: TRUE | D35: FALSE | E35: FALSE | F35: FALSE | G35: Remove Title | H35: 4302-02 | I35: 4302 | J35: CHIS | K35: 890 | L35: 104 | N35: Directed Rdg in Church History | R35: 0 | T35: Independent | V35: DO | W35: 1-6 | X35: 1-6 | Y35: 5 | Z35: CLAS | AA35: 24-AUG-26 | AD35: 24-AUG-26 | AE35: 10-DEC-26 | AH35: 10-DEC-26 | AT35: Hernandez, Abner F. | AU35: =IF($AT35="","",IFERROR(INDEX(InstructorMap!$B:$B, MATCH($AT35, InstructorMap!$A:$A, 0)),"")) -> abnerh@andrews.edu | AV35: =IF($AT35="","",IFERROR(INDEX(InstructorMap!$C:$C, MATCH($AT35, InstructorMap!$A:$A, 0)),"")) -> 000149024 | AW35: 100 | BA35: CHIS: 11-1100-9120-70 | BH35: CHIS | BI35: 16-MAR-26 | BJ35: A | BL35: I | BO35: MOODL | BT35: 70 | BU35: 0 | BV35: 0 | BW35: Y | CF35: Y | CR35: I | CS35: 15 | CT35: 202641 | CU35: 1
A36: FALSE | B36: FALSE | C36: TRUE | D36: FALSE | E36: FALSE | F36: FALSE | G36: Remove Title | H36: 4319-02 | I36: 4319 | J36: CHIS | K36: 890 | L36: 106 | N36: Directed Rdg in Church History | R36: 0 | T36: Independent | V36: DO | W36: 1-6 | X36: 1-6 | Y36: 5 | Z36: CLAS | AA36: 24-AUG-26 | AD36: 24-AUG-26 | AE36: 10-DEC-26 | AH36: 10-DEC-26 | AT36: Hernandez, Abner F. | AU36: =IF($AT36="","",IFERROR(INDEX(InstructorMap!$B:$B, MATCH($AT36, InstructorMap!$A:$A, 0)),"")) -> abnerh@andrews.edu | AV36: =IF($AT36="","",IFERROR(INDEX(InstructorMap!$C:$C, MATCH($AT36, InstructorMap!$A:$A, 0)),"")) -> 000149024 | AW36: 100 | BA36: CHIS: 11-1100-9120-70 | BH36: CHIS | BI36: 16-MAR-26 | BJ36: A | BL36: I | BO36: MOODL | BT36: 70 | BU36: 0 | BV36: 0 | BW36: Y | CF36: Y | CS36: 15 | CT36: 202641 | CU36: 1
A37: FALSE | B37: FALSE | C37: TRUE | D37: FALSE | E37: FALSE | F37: FALSE | G37: Remove Title | H37: 3581-02 | I37: 3581 | J37: CHIS | K37: 891 | L37: 102 | N37: Ind St: | R37: 0 | T37: Independent | V37: DO | W37: 1-3 | X37: 1-3 | Y37: 5 | Z37: CLAS | AA37: 24-AUG-26 | AD37: 24-AUG-26 | AE37: 10-DEC-26 | AH37: 10-DEC-26 | AT37: Reeve, John W. | AU37: =IF($AT37="","",IFERROR(INDEX(InstructorMap!$B:$B, MATCH($AT37, InstructorMap!$A:$A, 0)),"")) -> jreeve@andrews.edu | AV37: =IF($AT37="","",IFERROR(INDEX(InstructorMap!$C:$C, MATCH($AT37, InstructorMap!$A:$A, 0)),"")) -> 000049018 | AW37: 100 | BA37: CHIS: 11-1100-9120-70 | BH37: CHIS | BI37: 16-MAR-26 | BJ37: A | BL37: I | BO37: MOODL | BT37: 70 | BU37: 0 | BV37: 0 | BW37: Y | CF37: Y | CS37: 15 | CT37: 202641 | CU37: 1
A38: FALSE | B38: FALSE | C38: TRUE | D38: FALSE | E38: FALSE | F38: FALSE | G38: Remove Title | H38: 3983-02 | I38: 3983 | J38: CHIS | K38: 891 | L38: 103 | N38: Ind St: | R38: 0 | T38: Independent | V38: DO | W38: 1-3 | X38: 1-3 | Y38: 5 | Z38: CLAS | AA38: 24-AUG-26 | AD38: 24-AUG-26 | AE38: 10-DEC-26 | AH38: 10-DEC-26 | AT38: O'Reggio, Trevor E. | AU38: =IF($AT38="","",IFERROR(INDEX(InstructorMap!$B:$B, MATCH($AT38, InstructorMap!$A:$A, 0)),"")) -> toreggio@andrews.edu | AV38: =IF($AT38="","",IFERROR(INDEX(InstructorMap!$C:$C, MATCH($AT38, InstructorMap!$A:$A, 0)),"")) -> 000035762 | AW38: 100 | BA38: CHIS: 11-1100-9120-70 | BH38: CHIS | BI38: 16-MAR-26 | BJ38: A | BL38: I | BO38: MOODL | BT38: 70 | BU38: 0 | BV38: 0 | BW38: Y | CF38: Y | CS38: 15 | CT38: 202641 | CU38: 1
A39: FALSE | B39: FALSE | C39: TRUE | D39: FALSE | E39: FALSE | F39: FALSE | G39: Remove Title | H39: 4304-02 | I39: 4304 | J39: CHIS | K39: 891 | L39: 104 | N39: Ind St: | R39: 0 | T39: Independent | V39: DO | W39: 1-3 | X39: 1-3 | Y39: 5 | Z39: CLAS | AA39: 24-AUG-26 | AD39: 24-AUG-26 | AE39: 10-DEC-26 | AH39: 10-DEC-26 | AT39: Hernandez, Abner F. | AU39: =IF($AT39="","",IFERROR(INDEX(InstructorMap!$B:$B, MATCH($AT39, InstructorMap!$A:$A, 0)),"")) -> abnerh@andrews.edu | AV39: =IF($AT39="","",IFERROR(INDEX(InstructorMap!$C:$C, MATCH($AT39, InstructorMap!$A:$A, 0)),"")) -> 000149024 | AW39: 100 | BA39: CHIS: 11-1100-9120-70 | BH39: CHIS | BI39: 16-MAR-26 | BJ39: A | BL39: I | BO39: MOODL | BT39: 70 | BU39: 0 | BV39: 0 | BW39: Y | CF39: Y | CR39: I | CS39: 15 | CT39: 202641 | CU39: 1
A40: FALSE | B40: FALSE | C40: TRUE | D40: FALSE | E40: FALSE | F40: FALSE | G40: Remove Title | H40: 4320-02 | I40: 4320 | J40: CHIS | K40: 891 | L40: 105 | N40: Ind St: | R40: 0 | T40: Independent | V40: DO | W40: 1-3 | X40: 1-3 | Y40: 5 | Z40: CLAS | AA40: 24-AUG-26 | AD40: 24-AUG-26 | AE40: 10-DEC-26 | AH40: 10-DEC-26 | AT40: Hernandez, Abner F. | AU40: =IF($AT40="","",IFERROR(INDEX(InstructorMap!$B:$B, MATCH($AT40, InstructorMap!$A:$A, 0)),"")) -> abnerh@andrews.edu | AV40: =IF($AT40="","",IFERROR(INDEX(InstructorMap!$C:$C, MATCH($AT40, InstructorMap!$A:$A, 0)),"")) -> 000149024 | AW40: 100 | BA40: CHIS: 11-1100-9120-70 | BH40: CHIS | BI40: 16-MAR-26 | BJ40: A | BL40: I | BO40: MOODL | BT40: 70 | BU40: 0 | BV40: 0 | BW40: Y | CF40: Y | CS40: 15 | CT40: 202641 | CU40: 1
...

Sheet DSLE
A1: Don {not in Banner} | B1: Mismatching {not in Banner} | C1: Dept/Prog Admin {not in Banner} | D1: Mona {not in Banner} | E1: Karen {not in Banner} | F1: DONE {not in Banner} | G1: Notes {not in Banner} | H1: CRN sorted {not in Banner} | I1: CRN | J1: Subject | K1: Course Number {Crse Num} | L1: Course Section {Seq Crse Num} | M1: Program {not in Banner} | N1: Catalog Title | O1: Section Title | P1: Crosslist Details {not in Banner} | Q1: X Lst | R1: Campus {Ssasect Campus} | S1: Campus Restriction {Camp Restr CC} | T1: Schedule Type {not in Banner} | U1: Instruction Method {Inst Method} | V1: Level {Level SC} | W1: Credit Catalog {Cat Crs} | X1: Credits {Sect Crs} | Y1: Enrollment Cap {Max Enrl} | Z1: Meeting Type | AA1: Semester Start Date {Soaterm Start Date} | AB1: Pre-work Start Date {not in Banner} | AC1: Pre-work End Date {not in Banner} | AD1: Course Start Date {Meet Start Date} | AE1: Course End Date {Meet End Date} | AF1: Post-work Start Date {not in Banner} | AG1: Post-work End Date {not in Banner} | AH1: Semester End Date {Soaterm End Date} | AI1: Course Beginning Time {Meet Beg Time} | AJ1: Course Ending Time {Meet End Time} | AK1: SUN | AL1: MON | AM1: TUE | AN1: WED | AO1: THU | AP1: FRI | AQ1: SAT | AR1: Room {Meet Room} | AS1: Building {Meet Bldg} | AT1: Instructor Name {Instr Name} | AU1: Instructor Email {Instr Email} | AV1: Instructor ID {Instr ID} | AW1: % Responsibility | AX1: load/contract {not in Banner} | AY1: costs per credit {not in Banner} | AZ1: total costs {not in Banner} | BA1: account to be charged {not in Banner} | BB1: Fee Amount {Fees Amt} | BC1: Fee Code {Detl Code} | BD1: Fee Type | BE1: Fee Level | BF1: Fee Ind | BG1: Fee Term | BH1: SEM Department {Scacrse Dept} | BI1: Activity Date | BJ1: Status | BK1: Bill Hrs | BL1: Sect Sch Type | BM1: Prerequisites {Preq Areas} | BN1: Link Ind | BO1: Integration Code | BP1: Link Conn | BQ1: Crs Attr | BR1: Comments | BS1: Major Restr | BT1: Scacrse College | BU1: Enrolled | BV1: Waitlist Capacity | BW1: Primary Ind | BX1: Override | BY1: 1st Date Reg Opens | BZ1: Last Date Reg Opens | CA1: OL Range From Date | CB1: OL Range To Date | CC1: OL Numb Units | CD1: OL Duration Code | CE1: Grade Mode | CF1: Gradable Ind | CG1: Tuit Waiver | CH1: Course Override {Meet Override} | CI1: Lvl Res Ind | CJ1: Cmp Res Ind | CK1: Rate Code | CL1: Cohort Code | CM1: St Attr Code | CN1: Coll SC | CO1: DegC SC | CP1: Prog SC | CQ1: FOS Type | CR1: Special Approval {Special Apvl} | CS1: Weeks | CT1: Term Code | CU1: Part-Of-Term | CV1: Camp SC
A2: FALSE | B2: FALSE | C2: FALSE | D2: FALSE | E2: FALSE | F2: TRUE | H2: 492-02 | I2: 492 | J2: DSLE | K2: 503 | L2: 002 | N2: Marriage, Family & IPR | R2: 0 | U2: INPERSON | W2: 2,3 | X2: 2,3 | Y2: 35 | Z2: CLAS | AA2: 24-AUG-26 | AD2: 24-AUG-26 | AE2: 10-DEC-26 | AH2: 10-DEC-26 | AI2: 0830 | AJ2: 1020 | AO2: R | AR2: S340 | AS2: Seminary Building [SEM] | AT2: Fraser, Jasmine J. | AU2: =IF($AT2="","",IFERROR(INDEX(InstructorMap!$B:$B, MATCH($AT2, InstructorMap!$A:$A, 0)),"")) -> fraserj@andrews.edu | AV2: =IF($AT2="","",IFERROR(INDEX(InstructorMap!$C:$C, MATCH($AT2, InstructorMap!$A:$A, 0)),"")) -> 000129106 | AW2: 100 | AX2: load | BH2: DSLE | BI2: 16-MAR-26 | BJ2: A | BL2: A | BO2: MOODL | BT2: 70 | BU2: 0 | BV2: 99 | BW2: Y | CF2: Y | CH2: O | CS2: 16 | CT2: 202641 | CU2: 1
A3: FALSE | B3: FALSE | C3: FALSE | D3: FALSE | E3: FALSE | F3: TRUE | H3: 3978-02 | I3: 3978 | J3: DSLE | K3: 503 | L3: 001 | N3: Marriage, Family & IPR | P3: DSLE 503-001/503-999 | Q3: 198 | R3: 0 | U3: INPERSON | W3: 2,3 | X3: 2,3 | Y3: 35 | Z3: CLAS | AA3: 24-AUG-26 | AD3: 24-AUG-26 | AE3: 10-DEC-26 | AH3: 10-DEC-26 | AI3: 1830 | AJ3: 2020 | AM3: T | AR3: S120 | AS3: Seminary Building [SEM] | AT3: Joseph, Ainsworth E. | AU3: =IF($AT3="","",IFERROR(INDEX(InstructorMap!$B:$B, MATCH($AT3, InstructorMap!$A:$A, 0)),"")) -> ainsworj@andrews.edu | AV3: =IF($AT3="","",IFERROR(INDEX(InstructorMap!$C:$C, MATCH($AT3, InstructorMap!$A:$A, 0)),"")) -> 000079312 | AW3: 100 | AX3: load | BH3: DSLE | BI3: 16-MAR-26 | BJ3: A | BL3: A | BO3: MOODL | BT3: 70 | BU3: 0 | BV3: 0 | BW3: Y | CF3: Y | CS3: 16 | CT3: 202641 | CU3: 1
A4: FALSE | B4: FALSE | C4: FALSE | D4: FALSE | E4: FALSE | F4: FALSE | H4: 1408-02 | I4: 1408 | J4: DSLE | K4: 503 | L4: 999 | N4: Marriage, Family & IPR | P4: DSLE 503-001/503-999 | Q4: 198 | R4: 7 | U4: ASYNC | W4: 2,3 | X4: 2,3 | Y4: 25 | Z4: WEB | AA4: 24-AUG-26 | AD4: 24-AUG-26 | AE4: 10-DEC-26 | AH4: 10-DEC-26 | AT4: Joseph, Ainsworth E. | AU4: =IF($AT4="","",IFERROR(INDEX(InstructorMap!$B:$B, MATCH($AT4, InstructorMap!$A:$A, 0)),"")) -> ainsworj@andrews.edu | AV4: =IF($AT4="","",IFERROR(INDEX(InstructorMap!$C:$C, MATCH($AT4, InstructorMap!$A:$A, 0)),"")) -> 000079312 | AW4: 100 | AX4: X-list | BH4: DSLE | BI4: 16-MAR-26 | BJ4: A | BL4: N | BO4: MOODL | BT4: 70 | BU4: 0 | BV4: 0 | BW4: Y | CF4: Y | CS4: #### | CT4: 202641 | CU4: 1
A5: FALSE | B5: FALSE | C5: TRUE | D5: FALSE | E5: FALSE | F5: TRUE | G5: Campus Restriction, cap,online fee | H5: 482-02 | I5: 482 | J5: DSLE | K5: 503 | L5: 998 | N5: Marriage, Family & IPR | P5: DSLE 503-001/503-999 | Q5: 198 | R5: 7 | S5: 7 | U5: SYNC | W5: 2,3 | Y5: 5 | Z5: WEB | AA5: 24-AUG-26 | AD5: 24-AUG-26 | AE5: 10-DEC-26 | AH5: 10-DEC-26 | AI5: 1830 | AJ5: 2020 | AM5: T | AT5: Joseph, Ainsworth E. | AU5: =IF($AT5="","",IFERROR(INDEX(InstructorMap!$B:$B, MATCH($AT5, InstructorMap!$A:$A, 0)),"")) -> ainsworj@andrews.edu | AV5: =IF($AT5="","",IFERROR(INDEX(InstructorMap!$C:$C, MATCH($AT5, InstructorMap!$A:$A, 0)),"")) -> 000079312 | AW5: 100 | AX5: x-list | BC5: ES12 | BD5: BILL | BE5: FP | BH5: PTDI | BI5: 16-MAR-26 | BJ5: A | BL5: N | BO5: MOODL | BT5: 70 | BU5: 0 | BV5: 0 | BW5: Y | BX5: O | CF5: Y | CS5: 15 | CT5: 202641 | CU5: 1
A6: FALSE | B6: FALSE | C6: TRUE | D6: FALSE | E6: FALSE | F6: FALSE | G6: Remove x list | H6: 495-02 | I6: 495 | J6: DSLE | K6: 534 | L6: 001 | N6: Ministry to Y & YA | Q6: 100 | R6: 0 | U6: INPERSON | W6: 2,3 | X6: 2,3 | Y6: 40 | Z6: CLAS | AA6: 24-AUG-26 | AD6: 24-AUG-26 | AE6: 10-DEC-26 | AH6: 10-DEC-26 | AI6: 1030 | AJ6: 1220 | AN6: W | AR6: N235 | AS6: Seminary Building [SEM] | AT6: Paquini, Rogelio | AU6: =IF($AT6="","",IFERROR(INDEX(InstructorMap!$B:$B, MATCH($AT6, InstructorMap!$A:$A, 0)),"")) -> rpaquini@andrews.edu | AV6: =IF($AT6="","",IFERROR(INDEX(InstructorMap!$C:$C, MATCH($AT6, InstructorMap!$A:$A, 0)),"")) -> 000105171 | AW6: 100 | AX6: load | BH6: DSLE | BI6: 16-MAR-26 | BJ6: A | BL6: A | BO6: MOODL | BT6: 70 | BU6: 0 | BV6: 99 | BW6: Y | BX6: O | CF6: Y | CS6: 16 | CT6: 202641 | CU6: 1
A7: FALSE | B7: FALSE | C7: TRUE | D7: FALSE | E7: FALSE | F7: TRUE | H7: 555-02 | I7: 555 | J7: DSLE | K7: 534 | L7: 002 | N7: Ministry to Y & YA | R7: 0 | U7: INPERSON | W7: 2,3 | X7: 2,3 | Y7: 40 | Z7: CLAS | AA7: 24-AUG-26 | AD7: 24-AUG-26 | AE7: 10-DEC-26 | AH7: 10-DEC-26 | AI7: 1030 | AJ7: 1220 | AO7: R | AR7: N235 | AS7: Seminary Building [SEM] | AT7: Paquini, Rogelio | AU7: =IF($AT7="","",IFERROR(INDEX(InstructorMap!$B:$B, MATCH($AT7, InstructorMap!$A:$A, 0)),"")) -> rpaquini@andrews.edu | AV7: =IF($AT7="","",IFERROR(INDEX(InstructorMap!$C:$C, MATCH($AT7, InstructorMap!$A:$A, 0)),"")) -> 000105171 | AW7: 100 | AX7: load | BH7: DSLE | BI7: 16-MAR-26 | BJ7: A | BL7: A | BO7: MOODL | BT7: 70 | BU7: 0 | BV7: 0 | BW7: Y | CF7: Y | CH7: O | CS7: 16 | CT7: 202641 | CU7: 1
A8: FALSE | B8: FALSE | C8: TRUE | D8: FALSE | E8: FALSE | F8: TRUE | G8: Delete Section | H8: 2112-02 | I8: 2112 | J8: DSLE | K8: 534 | L8: 998 | N8: Ministry to Youth&Yng Adlt | Q8: 100 | R8: 7 | U8: SYNC | W8: 2,3 | Y8: 15 | Z8: WEB | AA8: 24-AUG-26 | AD8: 24-AUG-26 | AE8: 10-DEC-26 | AH8: 10-DEC-26 | AI8: 0930 | AJ8: 1120 | AM8: T | AT8: Paquini, Rogelio | AU8: =IF($AT8="","",IFERROR(INDEX(InstructorMap!$B:$B, MATCH($AT8, InstructorMap!$A:$A, 0)),"")) -> rpaquini@andrews.edu | AV8: =IF($AT8="","",IFERROR(INDEX(InstructorMap!$C:$C, MATCH($AT8, InstructorMap!$A:$A, 0)),"")) -> 000105171 | AW8: 100 | BH8: PTDI | BI8: 16-MAR-26 | BJ8: A | BL8: N | BO8: MOODL | BT8: 70 | BU8: 0 | BV8: 0 | BW8: Y | BX8: O | CF8: Y | CS8: 15 | CT8: 202641 | CU8: 1
A9: FALSE | B9: FALSE | C9: TRUE | D9: FALSE | E9: FALSE | F9: TRUE | G9: Delete Section | H9: 3989-02 | I9: 3989 | J9: DSLE | K9: 534 | L9: 999 | N9: Ministry to Youth&Yng Adlt | Q9: 100 | R9: 7 | U9: ASYNC | W9: 2,3 | Y9: 10 | Z9: WEB | AA9: 24-AUG-26 | AD9: 24-AUG-26 | AE9: 10-DEC-26 | AH9: 10-DEC-26 | AT9: Paquini, Rogelio | AU9: =IF($AT9="","",IFERROR(INDEX(InstructorMap!$B:$B, MATCH($AT9, InstructorMap!$A:$A, 0)),"")) -> rpaquini@andrews.edu | AV9: =IF($AT9="","",IFERROR(INDEX(InstructorMap!$C:$C, MATCH($AT9, InstructorMap!$A:$A, 0)),"")) -> 000105171 | AW9: 100 | BH9: PTDI | BI9: 16-MAR-26 | BJ9: A | BL9: N | BO9: MOODL | BT9: 70 | BU9: 0 | BV9: 99 | BW9: Y | CF9: Y | CS9: 15 | CT9: 202641 | CU9: 1
A10: FALSE | B10: FALSE | C10: TRUE | D10: FALSE | E10: FALSE | F10: TRUE | H10: 477-02 | I10: 477 | J10: DSLE | K10: 541 | L10: 002 | N10: Fdns of Biblical Spirituality | Q10: 243 | R10: 0 | U10: INPERSON | W10: 2,3 | X10: 3 | Y10: 25 | Z10: CLAS | AA10: 24-AUG-26 | AD10: 24-AUG-26 | AE10: 10-DEC-26 | AH10: 10-DEC-26 | AI10: 0930 | AJ10: 1220 | AL10: M | AR10: N150 | AS10: Seminary Building [SEM] | AT10: Kidder, S Joseph | AU10: =IF($AT10="","",IFERROR(INDEX(InstructorMap!$B:$B, MATCH($AT10, InstructorMap!$A:$A, 0)),"")) -> kiddersj@andrews.edu | AV10: =IF($AT10="","",IFERROR(INDEX(InstructorMap!$C:$C, MATCH($AT10, InstructorMap!$A:$A, 0)),"")) -> 000039170 | AW10: 100 | AX10: load | BH10: DSLE | BI10: 16-MAR-26 | BJ10: A | BK10: 3 | BL10: A | BO10: MOODL | BT10: 70 | BU10: 0 | BV10: 99 | BW10: Y | BX10: O | CF10: Y | CS10: 16 | CT10: 202641 | CU10: 1
A11: FALSE | B11: FALSE | C11: TRUE | D11: FALSE | E11: FALSE | F11: TRUE | H11: 533-02 | I11: 533 | J11: DSLE | K11: 541 | L11: 003 | N11: Fdns of Biblical Spirituality | R11: 0 | U11: INPERSON | W11: 2,3 | X11: 3 | Y11: 30 | Z11: CLAS | AA11: 24-AUG-26 | AD11: 24-AUG-26 | AE11: 10-DEC-26 | AH11: 10-DEC-26 | AI11: 1430 | AJ11: 1720 | AL11: M | AR11: N150 | AS11: Seminary Building [SEM] | AT11: Kidder, S Joseph | AU11: =IF($AT11="","",IFERROR(INDEX(InstructorMap!$B:$B, MATCH($AT11, InstructorMap!$A:$A, 0)),"")) -> kiddersj@andrews.edu | AV11: =IF($AT11="","",IFERROR(INDEX(InstructorMap!$C:$C, MATCH($AT11, InstructorMap!$A:$A, 0)),"")) -> 000039170 | AW11: 100 | AX11: load | BH11: DSLE | BI11: 16-MAR-26 | BJ11: A | BK11: 3 | BL11: A | BO11: MOODL | BT11: 70 | BU11: 0 | BV11: 0 | BW11: Y | BX11: O | CF11: Y | CH11: O | CS11: 16 | CT11: 202641 | CU11: 1
A12: FALSE | B12: FALSE | C12: TRUE | D12: FALSE | E12: FALSE | F12: TRUE | H12: 3382-02 | I12: 3382 | J12: DSLE | K12: 541 | L12: 001 | N12: Fdns of Biblical Spirituality | R12: 0 | U12: INPERSON | W12: 2,3 | X12: 3 | Y12: 30 | Z12: CLAS | AA12: 24-AUG-26 | AD12: 24-AUG-26 | AE12: 10-DEC-26 | AH12: 10-DEC-26 | AI12: 1430 | AJ12: 1720 | AL12: M | AR12: S120 | AS12: Seminary Building [SEM] | AT12: Ward, Scott R. | AU12: =IF($AT12="","",IFERROR(INDEX(InstructorMap!$B:$B, MATCH($AT12, InstructorMap!$A:$A, 0)),"")) -> sward@andrews.edu | AV12: =IF($AT12="","",IFERROR(INDEX(InstructorMap!$C:$C, MATCH($AT12, InstructorMap!$A:$A, 0)),"")) -> 000077973 | AW12: 100 | AX12: load | BH12: DSLE | BI12: 16-MAR-26 | BJ12: A | BK12: 3 | BL12: A | BO12: MOODL | BT12: 70 | BU12: 0 | BV12: 0 | BW12: Y | BX12: O | CF12: Y | CH12: O | CS12: 16 | CT12: 202641 | CU12: 1
A13: FALSE | B13: FALSE | C13: TRUE | D13: FALSE | E13: FALSE | F13: TRUE | G13: online fee | H13: 1366-02 | I13: 1366 | J13: DSLE | K13: 541 | L13: 999 | N13: Fndtns of Biblicl Spirituality | Q13: 243 | R13: 7 | U13: ASYNC | W13: 2,3 | X13: 3 | Y13: 30 | Z13: WEB | AA13: 24-AUG-26 | AD13: 24-AUG-26 | AE13: 10-DEC-26 | AH13: 10-DEC-26 | AT13: Kidder, S Joseph | AU13: =IF($AT13="","",IFERROR(INDEX(InstructorMap!$B:$B, MATCH($AT13, InstructorMap!$A:$A, 0)),"")) -> kiddersj@andrews.edu | AV13: =IF($AT13="","",IFERROR(INDEX(InstructorMap!$C:$C, MATCH($AT13, InstructorMap!$A:$A, 0)),"")) -> 000039170 | AW13: 100 | AX13: xlist | BC13: ES12 | BD13: BILL | BE13: FP | BH13: PTDI | BI13: 16-MAR-26 | BJ13: A | BK13: 3 | BL13: N | BO13: MOODL | BT13: 70 | BU13: 0 | BV13: 99 | BW13: Y | CF13: Y | CS13: 15 | CT13: 202641 | CU13: 1
A14: FALSE | B14: FALSE | C14: TRUE | D14: FALSE | E14: FALSE | F14: TRUE | G14: campus restriction, cap,online fee | H14: 4098-02 | I14: 4098 | J14: DSLE | K14: 541 | L14: 998 | N14: Fndtns of Biblicl Spirituality | Q14: 243 | R14: 7 | S14: 7 | U14: SYNC | W14: 2,3 | X14: 3 | Y14: 15 | Z14: WEB | AA14: 24-AUG-26 | AD14: 24-AUG-26 | AE14: 10-DEC-26 | AH14: 10-DEC-26 | AI14: 0930 | AJ14: 1220 | AL14: M | AT14: Kidder, S Joseph | AU14: =IF($AT14="","",IFERROR(INDEX(InstructorMap!$B:$B, MATCH($AT14, InstructorMap!$A:$A, 0)),"")) -> kiddersj@andrews.edu | AV14: =IF($AT14="","",IFERROR(INDEX(InstructorMap!$C:$C, MATCH($AT14, InstructorMap!$A:$A, 0)),"")) -> 000039170 | AW14: 100 | AX14: x-list | BC14: ES12 | BD14: BILL | BE14: FP | BH14: PTDI | BI14: 16-MAR-26 | BJ14: A | BK14: 3 | BL14: N | BO14: MOODL | BT14: 70 | BU14: 0 | BV14: 0 | BW14: Y | BX14: O | CF14: Y | CS14: 15 | CT14: 202641 | CU14: 1
A15: FALSE | B15: FALSE | C15: TRUE | D15: FALSE | E15: FALSE | F15: FALSE | G15: Remove Crosslist | H15: 496-02 | I15: 496 | J15: DSLE | K15: 615 | L15: 001 | N15: Collaborative Ministry | P15: Remove crosslist | Q15: 199 | R15: 0 | U15: INPERSON | W15: 2,3 | X15: 2,3 | Y15: 30 | Z15: CLAS | AA15: 24-AUG-26 | AD15: 24-AUG-26 | AE15: 10-DEC-26 | AH15: 10-DEC-26 | AI15: 0830 | AJ15: 1020 | AN15: W | AR15: S340 | AS15: Seminary Building [SEM] | AT15: Ward, Scott R. | AU15: =IF($AT15="","",IFERROR(INDEX(InstructorMap!$B:$B, MATCH($AT15, InstructorMap!$A:$A, 0)),"")) -> sward@andrews.edu | AV15: =IF($AT15="","",IFERROR(INDEX(InstructorMap!$C:$C, MATCH($AT15, InstructorMap!$A:$A, 0)),"")) -> 000077973 | AW15: 100 | AX15: load | BH15: DSLE | BI15: 16-MAR-26 | BJ15: A | BL15: A | BO15: MOODL | BT15: 70 | BU15: 0 | BV15: 99 | BW15: Y | BX15: O | CF15: Y | CH15: O | CS15: 16 | CT15: 202641 | CU15: 1
A16: FALSE | B16: FALSE | C16: TRUE | D16: FALSE | E16: FALSE | F16: TRUE | G16: Remove crosslist,online fee | H16: 501-02 | I16: 501 | J16: DSLE | K16: 615 | L16: 999 | N16: Collaboratv Min:Schl,Chrch,Com | P16: Remove crosslist | Q16: 199 | R16: 7 | U16: ASYNC | W16: 2,3 | Y16: 10 | Z16: WEB | AA16: 24-AUG-26 | AD16: 24-AUG-26 | AE16: 10-DEC-26 | AH16: 10-DEC-26 | AT16: Ward, Scott R. | AU16: =IF($AT16="","",IFERROR(INDEX(InstructorMap!$B:$B, MATCH($AT16, InstructorMap!$A:$A, 0)),"")) -> sward@andrews.edu | AV16: =IF($AT16="","",IFERROR(INDEX(InstructorMap!$C:$C, MATCH($AT16, InstructorMap!$A:$A, 0)),"")) -> 000077973 | AW16: 100 | AX16: load | BC16: ES12 | BD16: BILL | BE16: FP | BH16: PTDI | BI16: 16-MAR-26 | BJ16: A | BL16: N | BO16: MOODL | BT16: 70 | BU16: 0 | BV16: 99 | BW16: Y | CF16: Y | CS16: 15 | CT16: 202641 | CU16: 1
A17: FALSE | B17: FALSE | C17: TRUE | D17: FALSE | E17: FALSE | F17: TRUE | G17: Delete Section | H17: 3422-02 | I17: 3422 | J17: DSLE | K17: 615 | L17: 998 | N17: Collaboratv Min:Schl,Chrch,Com | Q17: 199 | R17: 7 | U17: SYNC | W17: 2,3 | Y17: 5 | Z17: WEB | AA17: 24-AUG-26 | AD17: 24-AUG-26 | AE17: 10-DEC-26 | AH17: 10-DEC-26 | AI17: 1330 | AJ17: 1520 | AM17: T | AT17: Ward, Scott R. | AU17: =IF($AT17="","",IFERROR(INDEX(InstructorMap!$B:$B, MATCH($AT17, InstructorMap!$A:$A, 0)),"")) -> sward@andrews.edu | AV17: =IF($AT17="","",IFERROR(INDEX(InstructorMap!$C:$C, MATCH($AT17, InstructorMap!$A:$A, 0)),"")) -> 000077973 | AW17: 100 | BH17: PTDI | BI17: 16-MAR-26 | BJ17: A | BL17: N | BO17: MOODL | BT17: 70 | BU17: 0 | BV17: 0 | BW17: Y | BX17: O | CF17: Y | CS17: 15 | CT17: 202641 | CU17: 1
A18: FALSE | B18: FALSE | C18: TRUE | D18: FALSE | E18: FALSE | F18: TRUE | H18: 1090-02 | I18: 1090 | J18: DSLE | K18: 620 | L18: 001 | N18: Scholarly & Prof. Development | R18: 0 | U18: INPERSON | W18: 0 | X18: 0 | Y18: 35 | Z18: CLAS | AA18: 24-AUG-26 | AD18: 24-AUG-26 | AE18: 10-DEC-26 | AH18: 10-DEC-26 | AT18: Fraser, Jasmine J. | AU18: =IF($AT18="","",IFERROR(INDEX(InstructorMap!$B:$B, MATCH($AT18, InstructorMap!$A:$A, 0)),"")) -> fraserj@andrews.edu | AV18: =IF($AT18="","",IFERROR(INDEX(InstructorMap!$C:$C, MATCH($AT18, InstructorMap!$A:$A, 0)),"")) -> 000129106 | AW18: 100 | AX18: Portfolio | BH18: DSLE | BI18: 16-MAR-26 | BJ18: A | BL18: I | BO18: MOODL | BT18: 70 | BU18: 0 | BV18: 0 | BW18: Y | CF18: Y | CS18: #### | CT18: 202641 | CU18: 1
A19: FALSE | B19: FALSE | C19: TRUE | D19: FALSE | E19: FALSE | F19: FALSE | G19: time change, instructor change | H19: 4085-02 | I19: 4085 | J19: DSLE | K19: 635 | L19: 001 | N19: Christian Perspectives on Prof. Ethics | Q19: 118 | R19: 0 | U19: INPERSON | W19: 2,3 | Y19: 15 | Z19: CLAS | AA19: 24-AUG-26 | AD19: 24-AUG-26 | AE19: 10-DEC-26 | AH19: 10-DEC-26 | AI19: 1630 | AJ19: 1820 | AL19: M | AR19: NH200 | AS19: Seminary Building [SEM] | AT19: Staff | AU19: =IF($AT19="","",IFERROR(INDEX(InstructorMap!$B:$B, MATCH($AT19, InstructorMap!$A:$A, 0)),"")) | AV19: =IF($AT19="","",IFERROR(INDEX(InstructorMap!$C:$C, MATCH($AT19, InstructorMap!$A:$A, 0)),"")) | AW19: 100 | AX19: SWK | BH19: DSLE | BI19: 16-MAR-26 | BJ19: A | BL19: A | BO19: MOODL | BT19: 70 | BU19: 0 | BV19: 0 | BW19: Y | CF19: Y | CS19: #### | CT19: 202641 | CU19: 1
A20: FALSE | B20: FALSE | C20: TRUE | D20: FALSE | E20: FALSE | F20: FALSE | G20: instructor | H20: 4086-02 | I20: 4086 | J20: DSLE | K20: 636 | L20: 001 | N20: Discipling Youth | Q20: 200 | R20: 0 | U20: INPERSON | W20: 2,3 | X20: 3 | Y20: 15 | Z20: CLAS | AA20: 24-AUG-26 | AD20: 24-AUG-26 | AE20: 10-DEC-26 | AH20: 10-DEC-26 | AI20: 0930 | AJ20: 1120 | AM20: T | AR20: N310 | AS20: Seminary Building [SEM] | AT20: Ward, Scott R. | AU20: =IF($AT20="","",IFERROR(INDEX(InstructorMap!$B:$B, MATCH($AT20, InstructorMap!$A:$A, 0)),"")) -> sward@andrews.edu | AV20: =IF($AT20="","",IFERROR(INDEX(InstructorMap!$C:$C, MATCH($AT20, InstructorMap!$A:$A, 0)),"")) -> 000077973 | AW20: 100 | AX20: load | BH20: DSLE | BI20: 16-MAR-26 | BJ20: A | BL20: A | BO20: MOODL | BT20: 70 | BU20: 0 | BV20: 0 | BW20: Y | BX20: O | CF20: Y | CS20: 16 | CT20: 202641 | CU20: 1
A21: FALSE | B21: FALSE | C21: TRUE | D21: FALSE | E21: FALSE | F21: TRUE | G21: online fee | H21: 1950-02 | I21: 1950 | J21: DSLE | K21: 636 | L21: 999 | N21: Discipling Youth | Q21: 200 | R21: 7 | U21: ASYNC | W21: 2,3 | Y21: 10 | Z21: WEB | AA21: 24-AUG-26 | AD21: 24-AUG-26 | AE21: 10-DEC-26 | AH21: 10-DEC-26 | AT21: Ward, Scott R. | AU21: =IF($AT21="","",IFERROR(INDEX(InstructorMap!$B:$B, MATCH($AT21, InstructorMap!$A:$A, 0)),"")) -> sward@andrews.edu | AV21: =IF($AT21="","",IFERROR(INDEX(InstructorMap!$C:$C, MATCH($AT21, InstructorMap!$A:$A, 0)),"")) -> 000077973 | AW21: 100 | AX21: x-list | BC21: ES12 | BD21: BILL | BE21: FP | BH21: DSLE | BI21: 16-MAR-26 | BJ21: A | BL21: N | BO21: MOODL | BT21: 70 | BU21: 0 | BV21: 0 | BW21: Y | CF21: Y | CS21: #### | CT21: 202641 | CU21: 1
A22: FALSE | B22: FALSE | C22: TRUE | D22: FALSE | E22: FALSE | F22: TRUE | G22: ,time and date,campus restrict,online fee | H22: 3418-02 | I22: 3418 | J22: DSLE | K22: 636 | L22: 998 | N22: Discipling Youth | Q22: 200 | R22: 7 | S22: 7 | U22: SYNC | W22: 2,3 | Y22: 10 | Z22: WEB | AA22: 24-AUG-26 | AD22: 24-AUG-26 | AE22: 10-DEC-26 | AH22: 10-DEC-26 | AI22: 0930 | AJ22: 1120 | AM22: T | AO22: R | AT22: Ward, Scott R. | AU22: =IF($AT22="","",IFERROR(INDEX(InstructorMap!$B:$B, MATCH($AT22, InstructorMap!$A:$A, 0)),"")) -> sward@andrews.edu | AV22: =IF($AT22="","",IFERROR(INDEX(InstructorMap!$C:$C, MATCH($AT22, InstructorMap!$A:$A, 0)),"")) -> 000077973 | AW22: 100 | AX22: x-list | BC22: ES12 | BD22: BILL | BE22: FP | BH22: PTDI | BI22: 16-MAR-26 | BJ22: A | BL22: N | BO22: MOODL | BT22: 70 | BU22: 0 | BV22: 0 | BW22: Y | CF22: Y | CS22: 15 | CT22: 202641 | CU22: 1
A23: FALSE | B23: FALSE | C23: TRUE | D23: FALSE | E23: FALSE | F23: TRUE | H23: 4087-02 | I23: 4087 | J23: DSLE | K23: 655 | L23: 001 | N23: Families in Society | Q23: 266 | R23: 0 | U23: INPERSON | W23: 3 | X23: 3 | Y23: 25 | Z23: CLAS | AA23: 24-AUG-26 | AD23: 24-AUG-26 | AE23: 10-DEC-26 | AH23: 10-DEC-26 | AI23: 1430 | AJ23: 1720 | AN23: W | AR23: N310 | AS23: Seminary Building [SEM] | AT23: Fraser, Jasmine J. | AU23: =IF($AT23="","",IFERROR(INDEX(InstructorMap!$B:$B, MATCH($AT23, InstructorMap!$A:$A, 0)),"")) -> fraserj@andrews.edu | AV23: =IF($AT23="","",IFERROR(INDEX(InstructorMap!$C:$C, MATCH($AT23, InstructorMap!$A:$A, 0)),"")) -> 000129106 | AW23: 100 | AX23: load | BH23: DSLE | BI23: 16-MAR-26 | BJ23: A | BL23: A | BO23: MOODL | BT23: 70 | BU23: 0 | BV23: 0 | BW23: Y | BX23: O | CF23: Y | CS23: 16 | CT23: 202641 | CU23: 1
A24: FALSE | B24: FALSE | C24: TRUE | D24: FALSE | E24: FALSE | F24: TRUE | G24: online fee | H24: 4089-02 | I24: 4089 | J24: DSLE | K24: 655 | L24: 999 | N24: Families in Society | Q24: 266 | R24: 7 | U24: ASYNC | W24: 3 | X24: 3 | Y24: 10 | Z24: WEB | AA24: 24-AUG-26 | AD24: 24-AUG-26 | AE24: 10-DEC-26 | AH24: 10-DEC-26 | AT24: Fraser, Jasmine J. | AU24: =IF($AT24="","",IFERROR(INDEX(InstructorMap!$B:$B, MATCH($AT24, InstructorMap!$A:$A, 0)),"")) -> fraserj@andrews.edu | AV24: =IF($AT24="","",IFERROR(INDEX(InstructorMap!$C:$C, MATCH($AT24, InstructorMap!$A:$A, 0)),"")) -> 000129106 | AW24: 100 | AX24: x-list | BC24: ES12 | BD24: BILL | BE24: FP | BH24: DSLE | BI24: 16-MAR-26 | BJ24: A | BL24: N | BO24: MOODL | BT24: 70 | BU24: 0 | BV24: 0 | BW24: Y | CF24: Y | CS24: #### | CT24: 202641 | CU24: 1
A25: FALSE | B25: FALSE | C25: TRUE | D25: FALSE | E25: FALSE | F25: TRUE | G25: Delete Section | H25: 4088-02 | I25: 4088 | J25: DSLE | K25: 655 | L25: 998 | N25: Families in Society | Q25: 266 | R25: 7 | U25: SYNC | W25: 3 | Y25: 10 | Z25: WEB | AA25: 24-AUG-26 | AD25: 24-AUG-26 | AE25: 10-DEC-26 | AH25: 10-DEC-26 | AI25: 1330 | AJ25: 1620 | AO25: R | AT25: Fraser, Jasmine J. | AU25: =IF($AT25="","",IFERROR(INDEX(InstructorMap!$B:$B, MATCH($AT25, InstructorMap!$A:$A, 0)),"")) -> fraserj@andrews.edu | AV25: =IF($AT25="","",IFERROR(INDEX(InstructorMap!$C:$C, MATCH($AT25, InstructorMap!$A:$A, 0)),"")) -> 000129106 | AW25: 100 | BH25: PTDI | BI25: 16-MAR-26 | BJ25: A | BL25: N | BO25: MOODL | BT25: 70 | BU25: 0 | BV25: 0 | BW25: Y | BX25: O | CF25: Y | CS25: 15 | CT25: 202641 | CU25: 1
A26: FALSE | B26: FALSE | C26: TRUE | D26: FALSE | E26: FALSE | F26: FALSE | G26: Times | H26: 3321-02 | I26: 3321 | J26: DSLE | K26: 656 | L26: 001 | N26: Counseling Youth & YA | Q26: 202 | R26: 0 | U26: INPERSON | W26: 2,3 | X26: 2,3 | Y26: 25 | Z26: CLAS | AA26: 24-AUG-26 | AD26: 24-AUG-26 | AE26: 10-DEC-26 | AH26: 10-DEC-26 | AI26: 0830 | AJ26: 1020 | AN26: W | AR26: N310 | AS26: Seminary Building [SEM] | AT26: Joseph, Ainsworth E. | AU26: =IF($AT26="","",IFERROR(INDEX(InstructorMap!$B:$B, MATCH($AT26, InstructorMap!$A:$A, 0)),"")) -> ainsworj@andrews.edu | AV26: =IF($AT26="","",IFERROR(INDEX(InstructorMap!$C:$C, MATCH($AT26, InstructorMap!$A:$A, 0)),"")) -> 000079312 | AW26: 100 | AX26: load | BH26: DSLE | BI26: 16-MAR-26 | BJ26: A | BL26: A | BO26: MOODL | BT26: 70 | BU26: 0 | BV26: 0 | BW26: Y | CF26: Y | CH26: O | CS26: 16 | CT26: 202641 | CU26: 1
A27: FALSE | B27: FALSE | C27: TRUE | D27: FALSE | E27: FALSE | F27: TRUE | G27: online fee | H27: 4090-02 | I27: 4090 | J27: DSLE | K27: 656 | L27: 999 | N27: Counseling Youth & YA | Q27: 202 | R27: 7 | U27: ASYNC | W27: 2,3 | X27: 2,3 | Y27: 10 | Z27: WEB | AA27: 24-AUG-26 | AD27: 24-AUG-26 | AE27: 10-DEC-26 | AH27: 10-DEC-26 | AT27: Joseph, Ainsworth E. | AU27: =IF($AT27="","",IFERROR(INDEX(InstructorMap!$B:$B, MATCH($AT27, InstructorMap!$A:$A, 0)),"")) -> ainsworj@andrews.edu | AV27: =IF($AT27="","",IFERROR(INDEX(InstructorMap!$C:$C, MATCH($AT27, InstructorMap!$A:$A, 0)),"")) -> 000079312 | AW27: 100 | AX27: x-list | BC27: ES12 | BD27: BILL | BE27: FP | BH27: DSLE | BI27: 16-MAR-26 | BJ27: A | BL27: N | BO27: MOODL | BT27: 70 | BU27: 0 | BV27: 0 | BW27: Y | CF27: Y | CS27: #### | CT27: 202641 | CU27: 1
A28: FALSE | B28: FALSE | C28: TRUE | D28: FALSE | E28: FALSE | F28: TRUE | G28: Cap & Times, campus restriction,online fee | H28: 3423-02 | I28: 3423 | J28: DSLE | K28: 656 | L28: 998 | N28: Counseling Youth & YA | Q28: 202 | R28: 7 | S28: 7 | U28: SYNC | W28: 2,3 | Y28: 5 | Z28: WEB | AA28: 24-AUG-26 | AD28: 24-AUG-26 | AE28: 10-DEC-26 | AH28: 10-DEC-26 | AI28: 0830 | AJ28: 1020 | AN28: W | AT28: Joseph, Ainsworth E. | AU28: =IF($AT28="","",IFERROR(INDEX(InstructorMap!$B:$B, MATCH($AT28, InstructorMap!$A:$A, 0)),"")) -> ainsworj@andrews.edu | AV28: =IF($AT28="","",IFERROR(INDEX(InstructorMap!$C:$C, MATCH($AT28, InstructorMap!$A:$A, 0)),"")) -> 000079312 | AW28: 100 | AX28: x-list | BC28: ES12 | BD28: BILL | BE28: FP | BH28: PTDI | BI28: 16-MAR-26 | BJ28: A | BL28: N | BO28: MOODL | BT28: 70 | BU28: 0 | BV28: 0 | BW28: Y | BX28: O | CF28: Y | CS28: 15 | CT28: 202641 | CU28: 1
A29: FALSE | B29: FALSE | C29: TRUE | D29: FALSE | E29: FALSE | F29: TRUE | I29: 1952 | J29: DSLE | K29: 660 | L29: 001 | N29: Field Practicum: MAYYAM | X29: 1-6 | AA29: 24-AUG-26 | AD29: 24-AUG-26 | AE29: 10-DEC-26 | AH29: 10-DEC-26 | AT29: Ward, Scott R. | AU29: =IF($AT29="","",IFERROR(INDEX(InstructorMap!$B:$B, MATCH($AT29, InstructorMap!$A:$A, 0)),"")) -> sward@andrews.edu | AV29: =IF($AT29="","",IFERROR(INDEX(InstructorMap!$C:$C, MATCH($AT29, InstructorMap!$A:$A, 0)),"")) -> 000077973 | BH29: DSLE | CS29: #### | CT29: 202641
