Workbook

Sheet CHIS
A1: Don {not in Banner} | B1: Mismatching {not in Banner} | C1: Dept/Prog Admin {not in Banner} | D1: Mona {not in Banner} | E1: Karen {not in Banner} | F1: DONE {not in Banner} | G1: Notes {not in Banner} | H1: CRN sorted {not in Banner} | I1: CRN | J1: Subject | K1: Course Number {Crse Num} | L1: Course Section {Seq Crse Num} | M1: Program {not in Banner} | N1: Catalog Title | O1: Section Title | P1: Crosslist Details {not in Banner} | Q1: X Lst | R1: Campus {Ssasect Campus} | S1: Campus Restriction {Camp Restr CC} | T1: Schedule Type {not in Banner} | U1: Instruction Method {Inst Method} | V1: Level {Level SC} | W1: Credit Catalog {Cat Crs} | X1: Credits {Sect Crs} | Y1: Enrollment Cap {Max Enrl} | Z1: Meeting Type | AA1: Semester Start Date {Soaterm Start Date} | AB1: Pre-work Start Date {not in Banner} | AC1: Pre-work End Date {not in Banner} | AD1: Course Start Date {Meet Start Date} | AE1: Course End Date {Meet End Date} | AF1: Post-work Start Date {not in Banner} | AG1: Post-work End Date {not in Banner} | AH1: Semester End Date {Soaterm End Date} | AI1: Course Beginning Time {Meet Beg Time} | AJ1: Course Ending Time {Meet End Time} | AK1: SUN | AL1: MON | AM1: TUE | AN1: WED | AO1: THU | AP1: FRI | AQ1: SAT | AR1: Room {Meet Room} | AS1: Building {Meet Bldg} | AT1: Instructor Name {Instr Name} | AU1: Instructor Email {Instr Email} | AV1: Instructor ID {Instr ID} | AW1: % Responsibility | AX1: load/contract {not in Banner} | AY1: costs per credit {not in Banner} | AZ1: total costs {not in Banner} | BA1: account to be charged {not in Banner} | BB1: Fee Amount {Fees Amt} | BC1: Fee Code {Detl Code} | BD1: Fee Type | BE1: Fee Level | BF1: Fee Ind | BG1: Fee Term | BH1: SEM Department {Scacrse Dept} | BI1: Activity Date | BJ1: Status | BK1: Bill Hrs | BL1: Sect Sch Type | BM1: Prerequisites {Preq Areas} | BN1: Link Ind | BO1: Integration Code | BP1: Link Conn | BQ1: Crs Attr | BR1: Comments | BS1: Major Restr | BT1: Scacrse College | BU1: Enrolled | BV1: Waitlist Capacity | BW1: Primary Ind | BX1: Override | BY1: 1st Date Reg Opens | BZ1: Last Date Reg Opens | CA1: OL Range From Date | CB1: OL Range To Date | CC1: OL Numb Units | CD1: OL Duration Code | CE1: Grade Mode | CF1: Gradable Ind | CG1: Tuit Waiver | CH1: Course Override {Meet Override} | CI1: Lvl Res Ind | CJ1: Cmp Res Ind | CK1: Rate Code | CL1: Cohort Code | CM1: St Attr Code | CN1: Coll SC | CO1: DegC SC | CP1: Prog SC | CQ1: FOS Type | CR1: Special Approval {Special Apvl} | CS1: Weeks | CT1: Term Code | CU1: Part-Of-Term | CV1: Camp SC
H2: 2221-02 | I2: 2221 | J2: CHIS | K2: 885 | L2: 040 | N2: Topics in | O2: Top in: Adventist Studies | R2: 0 | U2: TOUR | W2: 1-3 | Y2: 45 | Z2: POST | AA2: 07-JUL-25 | AD2: 28-JUL-25 | AE2: 01-AUG-25 | AH2: 01-AUG-25 | AT2: Burton, Kevin M. | AU2: =IF($AT2="","",IFERROR(INDEX(InstructorMap!$B:$B, MATCH($AT2, InstructorMap!$A:$A, 0)),"")) | AV2: =IF($AT2="","",IFERROR(INDEX(InstructorMap!$C:$C, MATCH($AT2, InstructorMap!$A:$A, 0)),"")) | AW2: 100 | BH2: CHIS | BI2: 27-MAR-25 | BJ2: A | BL2: A | BO2: MOODL | BT2: 70 | BU2: 0 | BV2: 0 | BW2: Y | CF2: Y | CS2: 4 | CT2: 202531 | CU2: Q
H3: 2221-04 | I3: 2221 | J3: CHIS | K3: 885 | L3: 040 | N3: Topics in | O3: Top in: Adventist Studies | R3: 0 | U3: TOUR | W3: 1-3 | Y3: 45 | Z3: PRE | AA3: 07-JUL-25 | AD3: 07-JUL-25 | AE3: 19-JUL-25 | AH3: 01-AUG-25 | AT3: Burton, Kevin M. | AU3: =IF($AT3="","",IFERROR(INDEX(InstructorMap!$B:$B, MATCH($AT3, InstructorMap!$A:$A, 0)),"")) | AV3: =IF($AT3="","",IFERROR(INDEX(InstructorMap!$C:$C, MATCH($AT3, InstructorMap!$A:$A, 0)),"")) | AW3: 100 | BH3: CHIS | BI3: 27-MAR-25 | BJ3: A | BL3: A | BO3: MOODL | BT3: 70 | BU3: 0 | BV3: 0 | BW3: Y | CF3: Y | CS3: 4 | CT3: 202531 | CU3: Q
H4: 2221-06 | I4: 2221 | J4: CHIS | K4: 885 | L4: 040 | N4: Topics in | O4: Top in: Adventist Studies | R4: 0 | U4: TOUR | W4: 1-3 | Y4: 45 | Z4: TOUR | AA4: 07-JUL-25 | AD4: 20-JUL-25 | AE4: 27-JUL-25 | AH4: 01-AUG-25 | AT4: Burton, Kevin M. | AU4: =IF($AT4="","",IFERROR(INDEX(InstructorMap!$B:$B, MATCH($AT4, InstructorMap!$A:$A, 0)),"")) | AV4: =IF($AT4="","",IFERROR(INDEX(InstructorMap!$C:$C, MATCH($AT4, InstructorMap!$A:$A, 0)),"")) | AW4: 100 | BH4: CHIS | BI4: 27-MAR-25 | BJ4: A | BL4: A | BO4: MOODL | BT4: 70 | BU4: 0 | BV4: 0 | BW4: Y | CF4: Y | CS4: 4 | CT4: 202531 | CU4: Q
H5: 2852-02 | I5: 2852 | J5: CHIS | K5: 890 | L5: 101 | N5: Directed Rdg in Church History | O5: DirRdg: | R5: 0 | W5: 1-6 | Y5: 999 | Z5: CLAS | AA5: 12-MAY-25 | AD5: 12-MAY-25 | AE5: 01-AUG-25 | AH5: 01-AUG-25 | AT5: Kaiser, Denis | AU5: =IF($AT5="","",IFERROR(INDEX(InstructorMap!$B:$B, MATCH($AT5, InstructorMap!$A:$A, 0)),"")) | AV5: =IF($AT5="","",IFERROR(INDEX(InstructorMap!$C:$C, MATCH($AT5, InstructorMap!$A:$A, 0)),"")) | AW5: 100 | BH5: CHIS | BI5: 27-MAR-25 | BJ5: A | BL5: I | BO5: MOODL | BT5: 70 | BU5: 0 | BV5: 0 | BW5: Y | CF5: Y | CR5: IT | CS5: 12 | CT5: 202531 | CU5: 1
H6: 2879-02 | I6: 2879 | J6: CHIS | K6: 890 | L6: 102 | N6: Directed Rdg in Church History | O6: DirRdg: | R6: 0 | W6: 1-6 | Y6: 999 | Z6: CLAS | AA6: 12-MAY-25 | AD6: 12-MAY-25 | AE6: 01-AUG-25 | AH6: 01-AUG-25 | AT6: O'Reggio, Trevor E. | AU6: =IF($AT6="","",IFERROR(INDEX(InstructorMap!$B:$B, MATCH($AT6, InstructorMap!$A:$A, 0)),"")) | AV6: =IF($AT6="","",IFERROR(INDEX(InstructorMap!$C:$C, MATCH($AT6, InstructorMap!$A:$A, 0)),"")) | AW6: 100 | BH6: CHIS | BI6: 27-MAR-25 | BJ6: A | BL6: I | BO6: MOODL | BT6: 70 | BU6: 0 | BV6: 0 | BW6: Y | CF6: Y | CR6: IT | CS6: 12 | CT6: 202531 | CU6: 1
H7: 2509-02 | I7: 2509 | J7: CHIS | K7: 891 | L7: 101 | N7: Ind St: | R7: 0 | W7: 1-3 | Y7: 999 | Z7: CLAS | AA7: 12-MAY-25 | AD7: 13-MAY-25 | AE7: 01-AUG-25 | AH7: 01-AUG-25 | AT7: Reeve, John W. | AU7: =IF($AT7="","",IFERROR(INDEX(InstructorMap!$B:$B, MATCH($AT7, InstructorMap!$A:$A, 0)),"")) | AV7: =IF($AT7="","",IFERROR(INDEX(InstructorMap!$C:$C, MATCH($AT7, InstructorMap!$A:$A, 0)),"")) | AW7: 100 | BH7: CHIS | BI7: 27-MAR-25 | BJ7: A | BL7: I | BO7: MOODL | BT7: 70 | BU7: 0 | BV7: 0 | BW7: Y | CF7: Y | CR7: IT | CS7: 12 | CT7: 202531 | CU7: 1
H8: 2580-02 | I8: 2580 | J8: CHIS | K8: 891 | L8: 102 | N8: Ind St: | O8: IndSt: | R8: 0 | W8: 1-3 | Y8: 999 | Z8: CLAS | AA8: 12-MAY-25 | AD8: 12-MAY-25 | AE8: 01-AUG-25 | AH8: 01-AUG-25 | AT8: Burton, Kevin M. | AU8: =IF($AT8="","",IFERROR(INDEX(InstructorMap!$B:$B, MATCH($AT8, InstructorMap!$A:$A, 0)),"")) | AV8: =IF($AT8="","",IFERROR(INDEX(InstructorMap!$C:$C, MATCH($AT8, InstructorMap!$A:$A, 0)),"")) | AW8: 100 | BH8: CHIS | BI8: 27-MAR-25 | BJ8: A | BL8: I | BO8: MOODL | BT8: 70 | BU8: 0 | BV8: 0 | BW8: Y | CF8: Y | CR8: IT | CS8: 12 | CT8: 202531 | CU8: 1
H9: 2612-02 | I9: 2612 | J9: CHIS | K9: 891 | L9: 103 | N9: Ind St: | R9: 0 | W9: 1-3 | Y9: 5 | Z9: CLAS | AA9: 12-MAY-25 | AD9: 12-MAY-25 | AE9: 01-AUG-25 | AH9: 01-AUG-25 | AT9: Burton, Kevin M. | AU9: =IF($AT9="","",IFERROR(INDEX(InstructorMap!$B:$B, MATCH($AT9, InstructorMap!$A:$A, 0)),"")) | AV9: =IF($AT9="","",IFERROR(INDEX(InstructorMap!$C:$C, MATCH($AT9, InstructorMap!$A:$A, 0)),"")) | AW9: 100 | BH9: CHIS | BI9: 27-MAR-25 | BJ9: A | BL9: I | BO9: MOODL | BT9: 70 | BU9: 0 | BV9: 0 | BW9: Y | CF9: Y | CR9: IT | CS9: 12 | CT9: 202531 | CU9: 1
H10: 2216-02 | I10: 2216 | J10: CHIS | K10: 892 | L10: 101 | N10: IndSty in Adv St: | R10: 0 | W10: 1-3 | Y10: 999 | Z10: CLAS | AA10: 12-MAY-25 | AD10: 12-MAY-25 | AE10: 01-AUG-25 | AH10: 01-AUG-25 | AT10: Kaiser, Denis | AU10: =IF($AT10="","",IFERROR(INDEX(InstructorMap!$B:$B, MATCH($AT10, InstructorMap!$A:$A, 0)),"")) | AV10: =IF($AT10="","",IFERROR(INDEX(InstructorMap!$C:$C, MATCH($AT10, InstructorMap!$A:$A, 0)),"")) | AW10: 100 | BH10: CHIS | BI10: 27-MAR-25 | BJ10: A | BL10: I | BO10: MOODL | BT10: 70 | BU10: 0 | BV10: 0 | BW10: Y | CF10: Y | CR10: IT | CS10: 12 | CT10: 202531 | CU10: 1
H11: 2217-02 | I11: 2217 | J11: CHIS | K11: 895 | L11: 102 | N11: Directed Rdg Adventist Studies | O11: DirRdg: | R11: 0 | W11: 1-6 | Y11: 999 | Z11: CLAS | AA11: 12-MAY-25 | AD11: 12-MAY-25 | AE11: 01-AUG-25 | AH11: 01-AUG-25 | AT11: Hernandez, Abner F. | AU11: =IF($AT11="","",IFERROR(INDEX(InstructorMap!$B:$B, MATCH($AT11, InstructorMap!$A:$A, 0)),"")) | AV11: =IF($AT11="","",IFERROR(INDEX(InstructorMap!$C:$C, MATCH($AT11, InstructorMap!$A:$A, 0)),"")) | AW11: 100 | BH11: CHIS | BI11: 27-MAR-25 | BJ11: A | BL11: I | BO11: MOODL | BQ11: ADVN | BT11: 70 | BU11: 0 | BV11: 0 | BW11: Y | CF11: Y | CR11: IT | CS11: 12 | CT11: 202531 | CU11: 1
H12: 3296-02 | I12: 3296 | J12: CHIS | K12: 891 | L12: 041 | N12: Ind St: | O12: IndSt:Apoclypt Wrtngs Early Ch | R12: 0 | U12: TOUR | W12: 1-3 | Y12: 999 | Z12: POST | AA12: 12-MAY-25 | AD12: 23-JUN-25 | AE12: 01-AUG-25 | AH12: 01-AUG-25 | AT12: Hernandez, Abner F. | AU12: =IF($AT12="","",IFERROR(INDEX(InstructorMap!$B:$B, MATCH($AT12, InstructorMap!$A:$A, 0)),"")) | AV12: =IF($AT12="","",IFERROR(INDEX(InstructorMap!$C:$C, MATCH($AT12, InstructorMap!$A:$A, 0)),"")) | AW12: 100 | BH12: CHIS | BI12: 17-APR-25 | BJ12: A | BL12: I | BO12: MOODL | BT12: 70 | BU12: 1 | BV12: 0 | BW12: Y | CF12: Y | CS12: 12 | CT12: 202531 | CU12: 1
H13: 3296-04 | I13: 3296 | J13: CHIS | K13: 891 | L13: 041 | N13: Ind St: | O13: IndSt:Apoclypt Wrtngs Early Ch | R13: 0 | U13: TOUR | W13: 1-3 | Y13: 999 | Z13: TOUR | AA13: 12-MAY-25 | AD13: 12-MAY-25 | AE13: 22-JUN-25 | AH13: 01-AUG-25 | AT13: Hernandez, Abner F. | AU13: =IF($AT13="","",IFERROR(INDEX(InstructorMap!$B:$B, MATCH($AT13, InstructorMap!$A:$A, 0)),"")) | AV13: =IF($AT13="","",IFERROR(INDEX(InstructorMap!$C:$C, MATCH($AT13, InstructorMap!$A:$A, 0)),"")) | AW13: 100 | BH13: CHIS | BI13: 17-APR-25 | BJ13: A | BL13: I | BO13: MOODL | BT13: 70 | BU13: 1 | BV13: 0 | BW13: Y | CF13: Y | CS13: 12 | CT13: 202531 | CU13: 1
H14: 3362-02 | I14: 3362 | J14: CHIS | K14: 880 | L14: 043 | N14: Topics in Church History: | O14: TopicsCHIS: Protest Theo Herit | Q14: 327 | R14: 0 | U14: TOUR | W14: 1-3 | X14: 3 | Y14: 25 | Z14: POST | AA14: 09-JUN-25 | AD14: 23-JUN-25 | AE14: 01-AUG-25 | AH14: 01-AUG-25 | AT14: Hernandez, Abner F. | AU14: =IF($AT14="","",IFERROR(INDEX(InstructorMap!$B:$B, MATCH($AT14, InstructorMap!$A:$A, 0)),"")) | AV14: =IF($AT14="","",IFERROR(INDEX(InstructorMap!$C:$C, MATCH($AT14, InstructorMap!$A:$A, 0)),"")) | AW14: 100 | BH14: CHIS | BI14: 18-APR-25 | BJ14: A | BK14: 3 | BL14: BL | BO14: MOODL | BT14: 70 | BU14: 1 | BV14: 0 | BW14: Y | CF14: Y | CS14: 8 | CT14: 202531 | CU14: W
H15: 3362-04 | I15: 3362 | J15: CHIS | K15: 880 | L15: 043 | N15: Topics in Church History: | O15: TopicsCHIS: Protest Theo Herit | Q15: 327 | R15: 0 | U15: TOUR | W15: 1-3 | X15: 3 | Y15: 25 | Z15: TOUR | AA15: 09-JUN-25 | AD15: 09-JUN-25 | AE15: 22-JUN-25 | AH15: 01-AUG-25 | AT15: Hernandez, Abner F. | AU15: =IF($AT15="","",IFERROR(INDEX(InstructorMap!$B:$B, MATCH($AT15, InstructorMap!$A:$A, 0)),"")) | AV15: =IF($AT15="","",IFERROR(INDEX(InstructorMap!$C:$C, MATCH($AT15, InstructorMap!$A:$A, 0)),"")) | AW15: 100 | BH15: CHIS | BI15: 18-APR-25 | BJ15: A | BK15: 3 | BL15: BL | BO15: MOODL | BT15: 70 | BU15: 1 | BV15: 0 | BW15: Y | CF15: Y | CS15: 8 | CT15: 202531 | CU15: W
H16: 2220-02 | I16: 2220 | J16: CHIS | K16: 685 | L16: 040 | N16: Studies in Church History | Q16: 321 | R16: 0 | U16: TOUR | W16: 2,3 | X16: 2 | Y16: 45 | Z16: POST | AA16: 07-JUL-25 | AD16: 28-JUL-25 | AE16: 01-AUG-25 | AH16: 01-AUG-25 | AT16: Burton, Kevin M. | AU16: =IF($AT16="","",IFERROR(INDEX(InstructorMap!$B:$B, MATCH($AT16, InstructorMap!$A:$A, 0)),"")) | AV16: =IF($AT16="","",IFERROR(INDEX(InstructorMap!$C:$C, MATCH($AT16, InstructorMap!$A:$A, 0)),"")) | AW16: 100 | BH16: CHIS | BI16: 24-APR-25 | BJ16: A | BK16: 2 | BL16: BL | BO16: MOODL | BT16: 70 | BU16: 0 | BV16: 0 | BW16: Y | CF16: Y | CS16: 4 | CT16: 202531 | CU16: Q
H17: 2220-04 | I17: 2220 | J17: CHIS | K17: 685 | L17: 040 | N17: Studies in Church History | Q17: 321 | R17: 0 | U17: TOUR | W17: 2,3 | X17: 2 | Y17: 45 | Z17: PRE | AA17: 07-JUL-25 | AD17: 07-JUL-25 | AE17: 19-JUL-25 | AH17: 01-AUG-25 | AT17: Burton, Kevin M. | AU17: =IF($AT17="","",IFERROR(INDEX(InstructorMap!$B:$B, MATCH($AT17, InstructorMap!$A:$A, 0)),"")) | AV17: =IF($AT17="","",IFERROR(INDEX(InstructorMap!$C:$C, MATCH($AT17, InstructorMap!$A:$A, 0)),"")) | AW17: 100 | BH17: CHIS | BI17: 24-APR-25 | BJ17: A | BK17: 2 | BL17: BL | BO17: MOODL | BT17: 70 | BU17: 0 | BV17: 0 | BW17: Y | CF17: Y | CS17: 4 | CT17: 202531 | CU17: Q
H18: 2220-06 | I18: 2220 | J18: CHIS | K18: 685 | L18: 040 | N18: Studies in Church History | Q18: 321 | R18: 0 | U18: TOUR | W18: 2,3 | X18: 2 | Y18: 45 | Z18: TOUR | AA18: 07-JUL-25 | AD18: 20-JUL-25 | AE18: 27-JUL-25 | AH18: 01-AUG-25 | AT18: Burton, Kevin M. | AU18: =IF($AT18="","",IFERROR(INDEX(InstructorMap!$B:$B, MATCH($AT18, InstructorMap!$A:$A, 0)),"")) | AV18: =IF($AT18="","",IFERROR(INDEX(InstructorMap!$C:$C, MATCH($AT18, InstructorMap!$A:$A, 0)),"")) | AW18: 100 | BH18: CHIS | BI18: 24-APR-25 | BJ18: A | BK18: 2 | BL18: BL | BO18: MOODL | BT18: 70 | BU18: 0 | BV18: 0 | BW18: Y | CF18: Y | CS18: 4 | CT18: 202531 | CU18: Q
H19: 3262-02 | I19: 3262 | J19: CHIS | K19: 507 | L19: 041 | N19: Church History 1500 to Present | R19: 0 | U19: TOUR | W19: 2,3 | X19: 2 | Y19: 25 | Z19: CLAS | AA19: 09-JUN-25 | AD19: 23-JUN-25 | AE19: 31-JUL-25 | AH19: 01-AUG-25 | AT19: O'Reggio, Trevor E. | AU19: =IF($AT19="","",IFERROR(INDEX(InstructorMap!$B:$B, MATCH($AT19, InstructorMap!$A:$A, 0)),"")) | AV19: =IF($AT19="","",IFERROR(INDEX(InstructorMap!$C:$C, MATCH($AT19, InstructorMap!$A:$A, 0)),"")) | AW19: 100 | BH19: CHIS | BI19: 28-APR-25 | BJ19: A | BK19: 2 | BL19: BL | BO19: MOODL | BQ19: TOUR | BT19: 70 | BU19: 4 | BV19: 0 | BW19: Y | CF19: Y | CS19: 8 | CT19: 202531 | CU19: W
H20: 3262-04 | I20: 3262 | J20: CHIS | K20: 507 | L20: 041 | N20: Church History 1500 to Present | R20: 0 | U20: TOUR | W20: 2,3 | X20: 2 | Y20: 25 | Z20: TOUR | AA20: 09-JUN-25 | AD20: 09-JUN-25 | AE20: 22-JUN-25 | AH20: 01-AUG-25 | AT20: O'Reggio, Trevor E. | AU20: =IF($AT20="","",IFERROR(INDEX(InstructorMap!$B:$B, MATCH($AT20, InstructorMap!$A:$A, 0)),"")) | AV20: =IF($AT20="","",IFERROR(INDEX(InstructorMap!$C:$C, MATCH($AT20, InstructorMap!$A:$A, 0)),"")) | AW20: 100 | BH20: CHIS | BI20: 28-APR-25 | BJ20: A | BK20: 2 | BL20: BL | BO20: MOODL | BQ20: TOUR | BT20: 70 | BU20: 4 | BV20: 0 | BW20: Y | CF20: Y | CS20: 8 | CT20: 202531 | CU20: W
H21: 3279-02 | I21: 3279 | J21: CHIS | K21: 880 | L21: 042 | N21: Topics in Church History: | O21: Topics CHIS: Martin Luther | Q21: 316 | R21: 0 | W21: 1-3 | X21: 3 | Y21: 25 | Z21: POST | AA21: 09-JUN-25 | AD21: 23-JUN-25 | AE21: 31-JUL-25 | AH21: 01-AUG-25 | AT21: O'Reggio, Trevor E. | AU21: =IF($AT21="","",IFERROR(INDEX(InstructorMap!$B:$B, MATCH($AT21, InstructorMap!$A:$A, 0)),"")) | AV21: =IF($AT21="","",IFERROR(INDEX(InstructorMap!$C:$C, MATCH($AT21, InstructorMap!$A:$A, 0)),"")) | AW21: 100 | BH21: CHIS | BI21: 30-APR-25 | BJ21: A | BK21: 3 | BL21: BL | BO21: MOODL | BT21: 70 | BU21: 1 | BV21: 0 | BW21: Y | CF21: Y | CS21: 8 | CT21: 202531 | CU21: W
H22: 3279-04 | I22: 3279 | J22: CHIS | K22: 880 | L22: 042 | N22: Topics in Church History: | O22: Topics CHIS: Martin Luther | Q22: 316 | R22: 0 | W22: 1-3 | X22: 3 | Y22: 25 | Z22: TOUR | AA22: 09-JUN-25 | AD22: 09-JUN-25 | AE22: 22-JUN-25 | AH22: 01-AUG-25 | AT22: O'Reggio, Trevor E. | AU22: =IF($AT22="","",IFERROR(INDEX(InstructorMap!$B:$B, MATCH($AT22, InstructorMap!$A:$A, 0)),"")) | AV22: =IF($AT22="","",IFERROR(INDEX(InstructorMap!$C:$C, MATCH($AT22, InstructorMap!$A:$A, 0)),"")) | AW22: 100 | BH22: CHIS | BI22: 30-APR-25 | BJ22: A | BK22: 3 | BL22: BL | BO22: MOODL | BT22: 70 | BU22: 1 | BV22: 0 | BW22: Y | CF22: Y | CS22: 8 | CT22: 202531 | CU22: W
H23: 3294-02 | I23: 3294 | J23: CHIS | K23: 880 | L23: 041 | N23: Topics in Church History: | O23: Top in CHIS: Reform Theology | Q23: 327 | R23: 0 | U23: TOUR | W23: 1-3 | X23: 3 | Y23: 25 | Z23: POST | AA23: 09-JUN-25 | AD23: 23-JUN-25 | AE23: 01-AUG-25 | AH23: 01-AUG-25 | AT23: Hernandez, Abner F. | AU23: =IF($AT23="","",IFERROR(INDEX(InstructorMap!$B:$B, MATCH($AT23, InstructorMap!$A:$A, 0)),"")) | AV23: =IF($AT23="","",IFERROR(INDEX(InstructorMap!$C:$C, MATCH($AT23, InstructorMap!$A:$A, 0)),"")) | AW23: 100 | BH23: CHIS | BI23: 01-MAY-25 | BJ23: A | BK23: 3 | BL23: BL | BO23: MOODL | BT23: 70 | BU23: 1 | BV23: 0 | BW23: Y | CF23: Y | CS23: 8 | CT23: 202531 | CU23: W
H24: 3294-04 | I24: 3294 | J24: CHIS | K24: 880 | L24: 041 | N24: Topics in Church History: | O24: Top in CHIS: Reform Theology | Q24: 327 | R24: 0 | U24: TOUR | W24: 1-3 | X24: 3 | Y24: 25 | Z24: TOUR | AA24: 09-JUN-25 | AD24: 09-JUN-25 | AE24: 22-JUN-25 | AH24: 01-AUG-25 | AT24: Hernandez, Abner F. | AU24: =IF($AT24="","",IFERROR(INDEX(InstructorMap!$B:$B, MATCH($AT24, InstructorMap!$A:$A, 0)),"")) | AV24: =IF($AT24="","",IFERROR(INDEX(InstructorMap!$C:$C, MATCH($AT24, InstructorMap!$A:$A, 0)),"")) | AW24: 100 | BH24: CHIS | BI24: 01-MAY-25 | BJ24: A | BK24: 3 | BL24: BL | BO24: MOODL | BT24: 70 | BU24: 1 | BV24: 0 | BW24: Y | CF24: Y | CS24: 8 | CT24: 202531 | CU24: W
H25: 3421-02 | I25: 3421 | J25: CHIS | K25: 890 | L25: 003 | N25: Directed Rdg in Church History | R25: 0 | W25: 1-6 | Y25: 999 | Z25: CLAS | AA25: 12-MAY-25 | AD25: 12-MAY-25 | AE25: 01-AUG-25 | AH25: 01-AUG-25 | AT25: Burton, Kevin M. | AU25: =IF($AT25="","",IFERROR(INDEX(InstructorMap!$B:$B, MATCH($AT25, InstructorMap!$A:$A, 0)),"")) | AV25: =IF($AT25="","",IFERROR(INDEX(InstructorMap!$C:$C, MATCH($AT25, InstructorMap!$A:$A, 0)),"")) | AW25: 100 | BH25: CHIS | BI25: 01-MAY-25 | BJ25: A | BL25: I | BO25: MOODL | BT25: 70 | BU25: 1 | BV25: 0 | BW25: Y | CF25: Y | CS25: 12 | CT25: 202531 | CU25: 1
H26: 3271-02 | I26: 3271 | J26: CHIS | K26: 640 | L26: 044 | N26: Reformation: | O26: Reformation:Reform Theology | Q26: 327 | R26: 0 | W26: 2,3 | X26: 3 | Y26: 25 | Z26: POST | AA26: 09-JUN-25 | AD26: 23-JUN-25 | AE26: 01-AUG-25 | AH26: 01-AUG-25 | AT26: Hernandez, Abner F. | AU26: =IF($AT26="","",IFERROR(INDEX(InstructorMap!$B:$B, MATCH($AT26, InstructorMap!$A:$A, 0)),"")) | AV26: =IF($AT26="","",IFERROR(INDEX(InstructorMap!$C:$C, MATCH($AT26, InstructorMap!$A:$A, 0)),"")) | AW26: 100 | BH26: CHIS | BI26: 09-MAY-25 | BJ26: A | BK26: 3 | BL26: BL | BO26: MOODL | BQ26: CH1,REFM | BT26: 70 | BU26: 1 | BV26: 0 | BW26: Y | CF26: Y | CS26: 8 | CT26: 202531 | CU26: W
H27: 3271-04 | I27: 3271 | J27: CHIS | K27: 640 | L27: 044 | N27: Reformation: | O27: Reformation:Reform Theology | Q27: 327 | R27: 0 | W27: 2,3 | X27: 3 | Y27: 25 | Z27: TOUR | AA27: 09-JUN-25 | AD27: 09-JUN-25 | AE27: 22-JUN-25 | AH27: 01-AUG-25 | AT27: Hernandez, Abner F. | AU27: =IF($AT27="","",IFERROR(INDEX(InstructorMap!$B:$B, MATCH($AT27, InstructorMap!$A:$A, 0)),"")) | AV27: =IF($AT27="","",IFERROR(INDEX(InstructorMap!$C:$C, MATCH($AT27, InstructorMap!$A:$A, 0)),"")) | AW27: 100 | BH27: CHIS | BI27: 09-MAY-25 | BJ27: A | BK27: 3 | BL27: BL | BO27: MOODL | BQ27: CH1,REFM | BT27: 70 | BU27: 1 | BV27: 0 | BW27: Y | CF27: Y | CS27: 8 | CT27: 202531 | CU27: W
H28: 3278-02 | I28: 3278 | J28: CHIS | K28: 685 | L28: 041 | N28: Studies in Church History | Q28: 321 | R28: 0 | W28: 2,3 | X28: 3 | Y28: 45 | Z28: POST | AA28: 07-JUL-25 | AD28: 28-JUL-25 | AE28: 01-AUG-25 | AH28: 01-AUG-25 | AT28: Burton, Kevin M. | AU28: =IF($AT28="","",IFERROR(INDEX(InstructorMap!$B:$B, MATCH($AT28, InstructorMap!$A:$A, 0)),"")) | AV28: =IF($AT28="","",IFERROR(INDEX(InstructorMap!$C:$C, MATCH($AT28, InstructorMap!$A:$A, 0)),"")) | AW28: 100 | BH28: CHIS | BI28: 11-MAY-25 | BJ28: A | BK28: 3 | BL28: BL | BO28: MOODL | BT28: 70 | BU28: 0 | BV28: 0 | BW28: Y | CF28: Y | CS28: 4 | CT28: 202531 | CU28: Q
H29: 3278-04 | I29: 3278 | J29: CHIS | K29: 685 | L29: 041 | N29: Studies in Church History | Q29: 321 | R29: 0 | W29: 2,3 | X29: 3 | Y29: 45 | Z29: PRE | AA29: 07-JUL-25 | AD29: 07-JUL-25 | AE29: 19-JUL-25 | AH29: 01-AUG-25 | AT29: Burton, Kevin M. | AU29: =IF($AT29="","",IFERROR(INDEX(InstructorMap!$B:$B, MATCH($AT29, InstructorMap!$A:$A, 0)),"")) | AV29: =IF($AT29="","",IFERROR(INDEX(InstructorMap!$C:$C, MATCH($AT29, InstructorMap!$A:$A, 0)),"")) | AW29: 100 | BH29: CHIS | BI29: 11-MAY-25 | BJ29: A | BK29: 3 | BL29: BL | BO29: MOODL | BT29: 70 | BU29: 0 | BV29: 0 | BW29: Y | CF29: Y | CS29: 4 | CT29: 202531 | CU29: Q
H30: 3278-06 | I30: 3278 | J30: CHIS | K30: 685 | L30: 041 | N30: Studies in Church History | Q30: 321 | R30: 0 | W30: 2,3 | X30: 3 | Y30: 45 | Z30: TOUR | AA30: 07-JUL-25 | AD30: 20-JUL-25 | AE30: 27-JUL-25 | AH30: 01-AUG-25 | AT30: Burton, Kevin M. | AU30: =IF($AT30="","",IFERROR(INDEX(InstructorMap!$B:$B, MATCH($AT30, InstructorMap!$A:$A, 0)),"")) | AV30: =IF($AT30="","",IFERROR(INDEX(InstructorMap!$C:$C, MATCH($AT30, InstructorMap!$A:$A, 0)),"")) | AW30: 100 | BH30: CHIS | BI30: 11-MAY-25 | BJ30: A | BK30: 3 | BL30: BL | BO30: MOODL | BT30: 70 | BU30: 0 | BV30: 0 | BW30: Y | CF30: Y | CS30: 4 | CT30: 202531 | CU30: Q
H31: 2022-02 | I31: 2022 | J31: CHIS | K31: 690 | L31: 102 | N31: Ind St: | O31: Ind St: Dev. of SDA Theology | R31: 0 | S31: 7 | W31: 1-3 | Y31: 999 | Z31: CLAS | AA31: 12-MAY-25 | AD31: 12-MAY-25 | AE31: 01-AUG-25 | AH31: 01-AUG-25 | AT31: Hernandez, Abner F. | AU31: =IF($AT31="","",IFERROR(INDEX(InstructorMap!$B:$B, MATCH($AT31, InstructorMap!$A:$A, 0)),"")) | AV31: =IF($AT31="","",IFERROR(INDEX(InstructorMap!$C:$C, MATCH($AT31, InstructorMap!$A:$A, 0)),"")) | AW31: 100 | BH31: CHIS | BI31: 12-MAY-25 | BJ31: A | BL31: I | BO31: MOODL | BT31: 70 | BU31: 0 | BV31: 0 | BW31: Y | CF31: Y | CR31: IT | CS31: 12 | CT31: 202531 | CU31: 1
H32: 3404-02 | I32: 3404 | J32: CHIS | K32: 690 | L32: 103 | N32: Ind St: | O32: Ind St: Dev. of SDA Theology | R32: 0 | W32: 1-3 | X32: 1 | Y32: 25 | Z32: CLAS | AA32: 12-MAY-25 | AD32: 12-MAY-25 | AE32: 01-AUG-25 | AH32: 01-AUG-25 | AT32: Kaiser, Denis | AU32: =IF($AT32="","",IFERROR(INDEX(InstructorMap!$B:$B, MATCH($AT32, InstructorMap!$A:$A, 0)),"")) | AV32: =IF($AT32="","",IFERROR(INDEX(InstructorMap!$C:$C, MATCH($AT32, InstructorMap!$A:$A, 0)),"")) | AW32: 100 | BH32: CHIS | BI32: 12-MAY-25 | BJ32: A | BK32: 1 | BL32: I | BO32: MOODL | BT32: 70 | BU32: 2 | BV32: 0 | BW32: Y | CF32: Y | CS32: 12 | CT32: 202531 | CU32: 1
H33: 3267-03 | I33: 3267 | J33: CHIS | K33: 624 | L33: 998 | N33: Issues in Ellen G White Stdies | Q33: 315 | R33: 7 | U33: SYNC | V33: FP | W33: 2,3 | X33: 2 | Y33: 25 | Z33: CLAS | AA33: 12-MAY-25 | AD33: 12-MAY-25 | AE33: 06-JUN-25 | AH33: 06-JUN-25 | AI33: 1330 | AJ33: 1520 | AL33: M | AM33: T | AN33: W | AO33: R | AT33: Garcia Zarate, Heber E. | AU33: =IF($AT33="","",IFERROR(INDEX(InstructorMap!$B:$B, MATCH($AT33, InstructorMap!$A:$A, 0)),"")) | AV33: =IF($AT33="","",IFERROR(INDEX(InstructorMap!$C:$C, MATCH($AT33, InstructorMap!$A:$A, 0)),"")) | AW33: 100 | BB33: 160 | BC33: ES12 | BD33: BILL | BE33: FP | BG33: 202531 | BH33: CHIS | BI33: 13-MAY-25 | BJ33: A | BK33: 2 | BL33: A | BM33: P-CHIS624 | BO33: MOODL | BT33: 70 | BU33: 7 | BV33: 0 | BW33: Y | BX33: O | CF33: Y | CS33: 4 | CT33: 202531 | CU33: 2 | CV33: 0
H34: 3267-04 | I34: 3267 | J34: CHIS | K34: 624 | L34: 998 | N34: Issues in Ellen G White Stdies | Q34: 315 | R34: 7 | U34: SYNC | V34: FP | W34: 2,3 | X34: 2 | Y34: 25 | Z34: CLAS | AA34: 12-MAY-25 | AD34: 12-MAY-25 | AE34: 06-JUN-25 | AH34: 06-JUN-25 | AI34: 1330 | AJ34: 1520 | AL34: M | AM34: T | AN34: W | AO34: R | AT34: Garcia Zarate, Heber E. | AU34: =IF($AT34="","",IFERROR(INDEX(InstructorMap!$B:$B, MATCH($AT34, InstructorMap!$A:$A, 0)),"")) | AV34: =IF($AT34="","",IFERROR(INDEX(InstructorMap!$C:$C, MATCH($AT34, InstructorMap!$A:$A, 0)),"")) | AW34: 100 | BB34: 160 | BC34: ES12 | BD34: BILL | BE34: FP | BG34: 202531 | BH34: CHIS | BI34: 13-MAY-25 | BJ34: A | BK34: 2 | BL34: A | BM34: P-CHIS624 | BO34: MOODL | BT34: 70 | BU34: 7 | BV34: 0 | BW34: Y | BX34: O | CF34: Y | CS34: 4 | CT34: 202531 | CU34: 2 | CV34: 7
H35: 3528-06 | I35: 3528 | J35: CHIS | K35: 690 | L35: 041 | N35: Ind St: | O35: Ind St:Devlmnt of SDA Theology | R35: 0 | U35: TOUR | V35: DO | W35: 1-3 | X35: 1 | Y35: 25 | Z35: POST | AA35: 09-JUN-25 | AD35: 23-JUN-25 | AE35: 31-JUL-25 | AH35: 31-JUL-25 | AT35: Hernandez, Abner F. | AU35: =IF($AT35="","",IFERROR(INDEX(InstructorMap!$B:$B, MATCH($AT35, InstructorMap!$A:$A, 0)),"")) | AV35: =IF($AT35="","",IFERROR(INDEX(InstructorMap!$C:$C, MATCH($AT35, InstructorMap!$A:$A, 0)),"")) | AW35: 100 | BB35: -922 | BC35: ESM1 | BD35: BILL | BE35: MA | BG35: 202531 | BH35: CHIS | BI35: 21-MAY-25 | BJ35: A | BK35: 1 | BL35: I | BO35: MOODL | BT35: 70 | BU35: 1 | BV35: 0 | BW35: Y | CF35: Y | CN35: 70 | CS35: 4 | CT35: 202531 | CU35: 3
H36: 3528-07 | I36: 3528 | J36: CHIS | K36: 690 | L36: 041 | N36: Ind St: | O36: Ind St:Devlmnt of SDA Theology | R36: 0 | U36: TOUR | V36: MA | W36: 1-3 | X36: 1 | Y36: 25 | Z36: POST | AA36: 09-JUN-25 | AD36: 23-JUN-25 | AE36: 31-JUL-25 | AH36: 31-JUL-25 | AT36: Hernandez, Abner F. | AU36: =IF($AT36="","",IFERROR(INDEX(InstructorMap!$B:$B, MATCH($AT36, InstructorMap!$A:$A, 0)),"")) | AV36: =IF($AT36="","",IFERROR(INDEX(InstructorMap!$C:$C, MATCH($AT36, InstructorMap!$A:$A, 0)),"")) | AW36: 100 | BB36: -633 | BC36: EAR2 | BD36: BILL | BE36: MA | BG36: 202531 | BH36: CHIS | BI36: 21-MAY-25 | BJ36: A | BK36: 1 | BL36: I | BO36: MOODL | BT36: 70 | BU36: 1 | BV36: 0 | BW36: Y | CF36: Y | CQ36: MAJOR | CS36: 4 | CT36: 202531 | CU36: 3
H37: 3528-08 | I37: 3528 | J37: CHIS | K37: 690 | L37: 041 | N37: Ind St: | O37: Ind St:Devlmnt of SDA Theology | R37: 0 | U37: TOUR | V37: MA | W37: 1-3 | X37: 1 | Y37: 25 | Z37: POST | AA37: 09-JUN-25 | AD37: 23-JUN-25 | AE37: 31-JUL-25 | AH37: 31-JUL-25 | AT37: Hernandez, Abner F. | AU37: =IF($AT37="","",IFERROR(INDEX(InstructorMap!$B:$B, MATCH($AT37, InstructorMap!$A:$A, 0)),"")) | AV37: =IF($AT37="","",IFERROR(INDEX(InstructorMap!$C:$C, MATCH($AT37, InstructorMap!$A:$A, 0)),"")) | AW37: 100 | BB37: -633 | BC37: ESM3 | BD37: BILL | BE37: MA | BG37: 202531 | BH37: CHIS | BI37: 21-MAY-25 | BJ37: A | BK37: 1 | BL37: I | BO37: MOODL | BT37: 70 | BU37: 1 | BV37: 0 | BW37: Y | CF37: Y | CO37: MSCID | CS37: 4 | CT37: 202531 | CU37: 3
H38: 3528-09 | I38: 3528 | J38: CHIS | K38: 690 | L38: 041 | N38: Ind St: | O38: Ind St:Devlmnt of SDA Theology | R38: 0 | U38: TOUR | V38: MA | W38: 1-3 | X38: 1 | Y38: 25 | Z38: POST | AA38: 09-JUN-25 | AD38: 23-JUN-25 | AE38: 31-JUL-25 | AH38: 31-JUL-25 | AT38: Hernandez, Abner F. | AU38: =IF($AT38="","",IFERROR(INDEX(InstructorMap!$B:$B, MATCH($AT38, InstructorMap!$A:$A, 0)),"")) | AV38: =IF($AT38="","",IFERROR(INDEX(InstructorMap!$C:$C, MATCH($AT38, InstructorMap!$A:$A, 0)),"")) | AW38: 100 | BB38: -633 | BC38: ESM4 | BD38: BILL | BE38: MA | BG38: 202531 | BH38: CHIS | BI38: 21-MAY-25 | BJ38: A | BK38: 1 | BL38: I | BO38: MOODL | BT38: 70 | BU38: 1 | BV38: 0 | BW38: Y | CF38: Y | CQ38: MAJOR | CS38: 4 | CT38: 202531 | CU38: 3
H39: 3528-10 | I39: 3528 | J39: CHIS | K39: 690 | L39: 041 | N39: Ind St: | O39: Ind St:Devlmnt of SDA Theology | R39: 0 | U39: TOUR | W39: 1-3 | X39: 1 | Y39: 25 | Z39: POST | AA39: 09-JUN-25 | AD39: 23-JUN-25 | AE39: 31-JUL-25 | AH39: 31-JUL-25 | AT39: Hernandez, Abner F. | AU39: =IF($AT39="","",IFERROR(INDEX(InstructorMap!$B:$B, MATCH($AT39, InstructorMap!$A:$A, 0)),"")) | AV39: =IF($AT39="","",IFERROR(INDEX(InstructorMap!$C:$C, MATCH($AT39, InstructorMap!$A:$A, 0)),"")) | AW39: 100 | BB39: 1267 | BC39: ESTM | BD39: BILL | BE39: MA | BG39: 202531 | BH39: CHIS | BI39: 21-MAY-25 | BJ39: A | BK39: 1 | BL39: I | BO39: MOODL | BT39: 70 | BU39: 1 | BV39: 0 | BW39: Y | CF39: Y | CS39: 4 | CT39: 202531 | CU39: 3
H40: 3528-16 | I40: 3528 | J40: CHIS | K40: 690 | L40: 041 | N40: Ind St: | O40: Ind St:Devlmnt of SDA Theology | R40: 0 | U40: TOUR | V40: DO | W40: 1-3 | X40: 1 | Y40: 25 | Z40: TOUR | AA40: 09-JUN-25 | AD40: 09-JUN-25 | AE40: 22-JUN-25 | AH40: 31-JUL-25 | AT40: Hernandez, Abner F. | AU40: =IF($AT40="","",IFERROR(INDEX(InstructorMap!$B:$B, MATCH($AT40, InstructorMap!$A:$A, 0)),"")) | AV40: =IF($AT40="","",IFERROR(INDEX(InstructorMap!$C:$C, MATCH($AT40, InstructorMap!$A:$A, 0)),"")) | AW40: 100 | BB40: -922 | BC40: ESM1 | BD40: BILL | BE40: MA | BG40: 202531 | BH40: CHIS | BI40: 21-MAY-25 | BJ40: A | BK40: 1 | BL40: I | BO40: MOODL | BT40: 70 | BU40: 1 | BV40: 0 | BW40: Y | CF40: Y | CN40: 70 | CS40: 4 | CT40: 202531 | CU40: 3
...

Sheet DSLE
A1: Don {not in Banner} | B1: Mismatching {not in Banner} | C1: Dept/Prog Admin {not in Banner} | D1: Mona {not in Banner} | E1: Karen {not in Banner} | F1: DONE {not in Banner} | G1: Notes {not in Banner} | H1: CRN sorted {not in Banner} | I1: CRN | J1: Subject | K1: Course Number {Crse Num} | L1: Course Section {Seq Crse Num} | M1: Program {not in Banner} | N1: Catalog Title | O1: Section Title | P1: Crosslist Details {not in Banner} | Q1: X Lst | R1: Campus {Ssasect Campus} | S1: Campus Restriction {Camp Restr CC} | T1: Schedule Type {not in Banner} | U1: Instruction Method {Inst Method} | V1: Level {Level SC} | W1: Credit Catalog {Cat Crs} | X1: Credits {Sect Crs} | Y1: Enrollment Cap {Max Enrl} | Z1: Meeting Type | AA1: Semester Start Date {Soaterm Start Date} | AB1: Pre-work Start Date {not in Banner} | AC1: Pre-work End Date {not in Banner} | AD1: Course Start Date {Meet Start Date} | AE1: Course End Date {Meet End Date} | AF1: Post-work Start Date {not in Banner} | AG1: Post-work End Date {not in Banner} | AH1: Semester End Date {Soaterm End Date} | AI1: Course Beginning Time {Meet Beg Time} | AJ1: Course Ending Time {Meet End Time} | AK1: SUN | AL1: MON | AM1: TUE | AN1: WED | AO1: THU | AP1: FRI | AQ1: SAT | AR1: Room {Meet Room} | AS1: Building {Meet Bldg} | AT1: Instructor Name {Instr Name} | AU1: Instructor Email {Instr Email} | AV1: Instructor ID {Instr ID} | AW1: % Responsibility | AX1: load/contract {not in Banner} | AY1: costs per credit {not in Banner} | AZ1: total costs {not in Banner} | BA1: account to be charged {not in Banner} | BB1: Fee Amount {Fees Amt} | BC1: Fee Code {Detl Code} | BD1: Fee Type | BE1: Fee Level | BF1: Fee Ind | BG1: Fee Term | BH1: SEM Department {Scacrse Dept} | BI1: Activity Date | BJ1: Status | BK1: Bill Hrs | BL1: Sect Sch Type | BM1: Prerequisites {Preq Areas} | BN1: Link Ind | BO1: Integration Code | BP1: Link Conn | BQ1: Crs Attr | BR1: Comments | BS1: Major Restr | BT1: Scacrse College | BU1: Enrolled | BV1: Waitlist Capacity | BW1: Primary Ind | BX1: Override | BY1: 1st Date Reg Opens | BZ1: Last Date Reg Opens | CA1: OL Range From Date | CB1: OL Range To Date | CC1: OL Numb Units | CD1: OL Duration Code | CE1: Grade Mode | CF1: Gradable Ind | CG1: Tuit Waiver | CH1: Course Override {Meet Override} | CI1: Lvl Res Ind | CJ1: Cmp Res Ind | CK1: Rate Code | CL1: Cohort Code | CM1: St Attr Code | CN1: Coll SC | CO1: DegC SC | CP1: Prog SC | CQ1: FOS Type | CR1: Special Approval {Special Apvl} | CS1: Weeks | CT1: Term Code | CU1: Part-Of-Term | CV1: Camp SC
H2: 849-02 | I2: 849 | J2: DSLE | K2: 680 | L2: 001 | N2: Field Practicum: | O2: Field Practicum:________ | R2: 0 | W2: 1-6 | Y2: 999 | Z2: CLAS | AA2: 12-MAY-25 | AD2: 12-MAY-25 | AE2: 01-AUG-25 | AH2: 01-AUG-25 | AT2: Paquini, Rogelio | AU2: =IF($AT2="","",IFERROR(INDEX(InstructorMap!$B:$B, MATCH($AT2, InstructorMap!$A:$A, 0)),"")) | AV2: =IF($AT2="","",IFERROR(INDEX(InstructorMap!$C:$C, MATCH($AT2, InstructorMap!$A:$A, 0)),"")) | AW2: 100 | BH2: DSLE | BI2: 27-JAN-25 | BJ2: A | BL2: P | BO2: MOODL | BT2: 70 | BU2: 0 | BV2: 0 | BW2: Y | CF2: Y | CS2: 12 | CT2: 202531 | CU2: 1
H3: 850-02 | I3: 850 | J3: DSLE | K3: 680 | L3: 002 | N3: Field Practicum: | O3: Field Practicum:________ | R3: 0 | W3: 1-6 | Y3: 999 | Z3: CLAS | AA3: 12-MAY-25 | AD3: 12-MAY-25 | AE3: 01-AUG-25 | AH3: 01-AUG-25 | AT3: Paquini, Rogelio | AU3: =IF($AT3="","",IFERROR(INDEX(InstructorMap!$B:$B, MATCH($AT3, InstructorMap!$A:$A, 0)),"")) | AV3: =IF($AT3="","",IFERROR(INDEX(InstructorMap!$C:$C, MATCH($AT3, InstructorMap!$A:$A, 0)),"")) | AW3: 100 | BH3: DSLE | BI3: 27-JAN-25 | BJ3: A | BL3: P | BO3: MOODL | BT3: 70 | BU3: 0 | BV3: 0 | BW3: Y | CF3: Y | CS3: 12 | CT3: 202531 | CU3: 1
H4: 851-02 | I4: 851 | J4: DSLE | K4: 870 | L4: 101 | N4: Adv Studies: | R4: 0 | W4: 1-4 | X4: 3 | Y4: 999 | Z4: CLAS | AA4: 12-MAY-25 | AD4: 12-MAY-25 | AE4: 01-AUG-25 | AH4: 01-AUG-25 | AT4: Fraser, Jasmine J. | AU4: =IF($AT4="","",IFERROR(INDEX(InstructorMap!$B:$B, MATCH($AT4, InstructorMap!$A:$A, 0)),"")) | AV4: =IF($AT4="","",IFERROR(INDEX(InstructorMap!$C:$C, MATCH($AT4, InstructorMap!$A:$A, 0)),"")) | AW4: 100 | BH4: DSLE | BI4: 27-JAN-25 | BJ4: A | BK4: 3 | BL4: I | BO4: MOODL | BT4: 70 | BU4: 0 | BV4: 0 | BW4: Y | CF4: Y | CR4: IT | CS4: 12 | CT4: 202531 | CU4: 1
H5: 853-02 | I5: 853 | J5: DSLE | K5: 880 | L5: 101 | N5: PhD (DSLE) Prog Cont | O5: PhD (Rel Education) Prog Cont | R5: 0 | W5: 0 | Y5: 999 | Z5: CLAS | AA5: 12-MAY-25 | AD5: 12-MAY-25 | AE5: 01-AUG-25 | AH5: 01-AUG-25 | AT5: Fraser, Jasmine J. | AU5: =IF($AT5="","",IFERROR(INDEX(InstructorMap!$B:$B, MATCH($AT5, InstructorMap!$A:$A, 0)),"")) | AV5: =IF($AT5="","",IFERROR(INDEX(InstructorMap!$C:$C, MATCH($AT5, InstructorMap!$A:$A, 0)),"")) | AW5: 100 | BH5: DSLE | BI5: 27-JAN-25 | BJ5: A | BL5: I | BO5: MOODL | BT5: 70 | BU5: 0 | BV5: 0 | BW5: Y | CF5: Y | CS5: 12 | CT5: 202531 | CU5: 1
H6: 854-02 | I6: 854 | J6: DSLE | K6: 885 | L6: 001 | N6: Field Practicum: | O6: Field Practicum: | R6: 0 | W6: 1-5 | Y6: 999 | Z6: CLAS | AA6: 12-MAY-25 | AD6: 12-MAY-25 | AE6: 01-AUG-25 | AH6: 01-AUG-25 | AT6: Fraser, Jasmine J. | AU6: =IF($AT6="","",IFERROR(INDEX(InstructorMap!$B:$B, MATCH($AT6, InstructorMap!$A:$A, 0)),"")) | AV6: =IF($AT6="","",IFERROR(INDEX(InstructorMap!$C:$C, MATCH($AT6, InstructorMap!$A:$A, 0)),"")) | AW6: 100 | BH6: DSLE | BI6: 27-JAN-25 | BJ6: A | BL6: P | BO6: MOODL | BT6: 70 | BU6: 0 | BV6: 0 | BW6: Y | CF6: Y | CS6: 12 | CT6: 202531 | CU6: 1
H7: 857-02 | I7: 857 | J7: DSLE | K7: 994 | L7: 101 | N7: Dissertation:Literature Review | R7: 0 | W7: 1-3 | X7: 3 | Y7: 999 | Z7: CLAS | AA7: 12-MAY-25 | AD7: 12-MAY-25 | AE7: 01-AUG-25 | AH7: 01-AUG-25 | AT7: Fraser, Jasmine J. | AU7: =IF($AT7="","",IFERROR(INDEX(InstructorMap!$B:$B, MATCH($AT7, InstructorMap!$A:$A, 0)),"")) | AV7: =IF($AT7="","",IFERROR(INDEX(InstructorMap!$C:$C, MATCH($AT7, InstructorMap!$A:$A, 0)),"")) | AW7: 100 | BH7: DSLE | BI7: 27-JAN-25 | BJ7: A | BK7: 3 | BL7: I | BO7: MOODL | BQ7: FT | BT7: 70 | BU7: 0 | BV7: 0 | BW7: Y | CF7: Y | CS7: 12 | CT7: 202531 | CU7: 1
H8: 1180-02 | I8: 1180 | J8: DSLE | K8: 699 | L8: 101 | N8: Thesis | R8: 0 | W8: 1-3 | Y8: 999 | Z8: CLAS | AA8: 12-MAY-25 | AD8: 12-MAY-25 | AE8: 01-AUG-25 | AH8: 01-AUG-25 | AT8: Paquini, Rogelio | AU8: =IF($AT8="","",IFERROR(INDEX(InstructorMap!$B:$B, MATCH($AT8, InstructorMap!$A:$A, 0)),"")) | AV8: =IF($AT8="","",IFERROR(INDEX(InstructorMap!$C:$C, MATCH($AT8, InstructorMap!$A:$A, 0)),"")) | AW8: 100 | BH8: DSLE | BI8: 27-JAN-25 | BJ8: A | BL8: I | BO8: MOODL | BT8: 70 | BU8: 0 | BV8: 0 | BW8: Y | CF8: Y | CS8: 12 | CT8: 202531 | CU8: 1
H9: 2841-02 | I9: 2841 | J9: DSLE | K9: 660 | L9: 101 | N9: Field Practicum: MAYYAM | R9: 0 | W9: 1-6 | Y9: 999 | Z9: CLAS | AA9: 12-MAY-25 | AD9: 12-MAY-25 | AE9: 01-AUG-25 | AH9: 01-AUG-25 | AT9: Ward, Scott R. | AU9: =IF($AT9="","",IFERROR(INDEX(InstructorMap!$B:$B, MATCH($AT9, InstructorMap!$A:$A, 0)),"")) | AV9: =IF($AT9="","",IFERROR(INDEX(InstructorMap!$C:$C, MATCH($AT9, InstructorMap!$A:$A, 0)),"")) | AW9: 100 | BH9: DSLE | BI9: 27-JAN-25 | BJ9: A | BL9: P | BO9: MOODL | BT9: 70 | BU9: 0 | BV9: 0 | BW9: Y | CF9: Y | CR9: I | CS9: 12 | CT9: 202531 | CU9: 1
H10: 2871-02 | I10: 2871 | J10: DSLE | K10: 660 | L10: 102 | N10: Field Practicum: MAYYAM | R10: 0 | W10: 1-6 | Y10: 999 | Z10: CLAS | AA10: 12-MAY-25 | AD10: 12-MAY-25 | AE10: 01-AUG-25 | AH10: 01-AUG-25 | AT10: Paquini, Rogelio | AU10: =IF($AT10="","",IFERROR(INDEX(InstructorMap!$B:$B, MATCH($AT10, InstructorMap!$A:$A, 0)),"")) | AV10: =IF($AT10="","",IFERROR(INDEX(InstructorMap!$C:$C, MATCH($AT10, InstructorMap!$A:$A, 0)),"")) | AW10: 100 | BH10: DSLE | BI10: 27-JAN-25 | BJ10: A | BL10: P | BO10: MOODL | BT10: 70 | BU10: 0 | BV10: 0 | BW10: Y | CF10: Y | CR10: I | CS10: 12 | CT10: 202531 | CU10: 1
H11: 852-02 | I11: 852 | J11: DSLE | K11: 878 | L11: 001 | N11: Adv Scholarly & Prof Dev | O11: Adv Scholarly & Prof Dev | R11: 0 | W11: 0 | Y11: 999 | Z11: CLAS | AA11: 12-MAY-25 | AD11: 12-MAY-25 | AE11: 01-AUG-25 | AH11: 01-AUG-25 | AT11: Fraser, Jasmine J. | AU11: =IF($AT11="","",IFERROR(INDEX(InstructorMap!$B:$B, MATCH($AT11, InstructorMap!$A:$A, 0)),"")) | AV11: =IF($AT11="","",IFERROR(INDEX(InstructorMap!$C:$C, MATCH($AT11, InstructorMap!$A:$A, 0)),"")) | AW11: 100 | BH11: DSLE | BI11: 28-APR-25 | BJ11: A | BL11: A | BO11: MOODL | BT11: 70 | BU11: 1 | BV11: 0 | BW11: Y | CF11: Y | CS11: 12 | CT11: 202531 | CU11: 1
H12: 3402-02 | I12: 3402 | J12: DSLE | K12: 690 | L12: 001 | N12: Ind St: | O12: Ind St:Sprtl Nurtr f Chldrn | R12: 0 | W12: 1-3 | X12: 1 | Y12: 10 | Z12: CLAS | AA12: 12-MAY-25 | AD12: 12-MAY-25 | AE12: 01-AUG-25 | AH12: 01-AUG-25 | AT12: Joseph, Ainsworth E. | AU12: =IF($AT12="","",IFERROR(INDEX(InstructorMap!$B:$B, MATCH($AT12, InstructorMap!$A:$A, 0)),"")) | AV12: =IF($AT12="","",IFERROR(INDEX(InstructorMap!$C:$C, MATCH($AT12, InstructorMap!$A:$A, 0)),"")) | AW12: 100 | BH12: DSLE | BI12: 29-APR-25 | BJ12: A | BK12: 1 | BL12: I | BO12: MOODL | BT12: 70 | BU12: 1 | BV12: 0 | BW12: Y | CF12: Y | CR12: I | CS12: 12 | CT12: 202531 | CU12: 1
H13: 3297-02 | I13: 3297 | J13: DSLE | K13: 541 | L13: 001 | N13: Fndtns of Biblicl Spirituality | Q13: 322 | R13: 0 | W13: 2,3 | X13: 3 | Y13: 25 | Z13: CLAS | AA13: 12-MAY-25 | AD13: 18-MAY-25 | AE13: 22-MAY-25 | AH13: 01-AUG-25 | AI13: 0800 | AJ13: 1200 | AL13: M | AM13: T | AN13: W | AO13: R | AR13: 153 | AS13: Buller Hall [BUL] | AT13: Kidder, S Joseph | AU13: =IF($AT13="","",IFERROR(INDEX(InstructorMap!$B:$B, MATCH($AT13, InstructorMap!$A:$A, 0)),"")) | AV13: =IF($AT13="","",IFERROR(INDEX(InstructorMap!$C:$C, MATCH($AT13, InstructorMap!$A:$A, 0)),"")) | AW13: 100 | BH13: DSLE | BI13: 06-MAY-25 | BJ13: A | BK13: 3 | BL13: A | BO13: MOODL | BT13: 70 | BU13: 0 | BV13: 0 | BW13: Y | CF13: Y | CS13: 12 | CT13: 202531 | CU13: 1
H14: 3297-04 | I14: 3297 | J14: DSLE | K14: 541 | L14: 001 | N14: Fndtns of Biblicl Spirituality | Q14: 322 | R14: 0 | W14: 2,3 | X14: 3 | Y14: 25 | Z14: CLAS | AA14: 12-MAY-25 | AD14: 18-MAY-25 | AE14: 22-MAY-25 | AH14: 01-AUG-25 | AI14: 1400 | AJ14: 1730 | AL14: M | AM14: T | AN14: W | AO14: R | AR14: 153 | AS14: Buller Hall [BUL] | AT14: Kidder, S Joseph | AU14: =IF($AT14="","",IFERROR(INDEX(InstructorMap!$B:$B, MATCH($AT14, InstructorMap!$A:$A, 0)),"")) | AV14: =IF($AT14="","",IFERROR(INDEX(InstructorMap!$C:$C, MATCH($AT14, InstructorMap!$A:$A, 0)),"")) | AW14: 100 | BH14: DSLE | BI14: 06-MAY-25 | BJ14: A | BK14: 3 | BL14: A | BO14: MOODL | BT14: 70 | BU14: 0 | BV14: 0 | BW14: Y | CF14: Y | CS14: 12 | CT14: 202531 | CU14: 1
H15: 3297-06 | I15: 3297 | J15: DSLE | K15: 541 | L15: 001 | N15: Fndtns of Biblicl Spirituality | Q15: 322 | R15: 0 | W15: 2,3 | X15: 3 | Y15: 25 | Z15: POST | AA15: 12-MAY-25 | AD15: 23-MAY-25 | AE15: 01-AUG-25 | AH15: 01-AUG-25 | AT15: Kidder, S Joseph | AU15: =IF($AT15="","",IFERROR(INDEX(InstructorMap!$B:$B, MATCH($AT15, InstructorMap!$A:$A, 0)),"")) | AV15: =IF($AT15="","",IFERROR(INDEX(InstructorMap!$C:$C, MATCH($AT15, InstructorMap!$A:$A, 0)),"")) | AW15: 100 | BH15: DSLE | BI15: 06-MAY-25 | BJ15: A | BK15: 3 | BL15: A | BO15: MOODL | BT15: 70 | BU15: 0 | BV15: 0 | BW15: Y | CF15: Y | CS15: 12 | CT15: 202531 | CU15: 1
H16: 3297-08 | I16: 3297 | J16: DSLE | K16: 541 | L16: 001 | N16: Fndtns of Biblicl Spirituality | Q16: 322 | R16: 0 | W16: 2,3 | X16: 3 | Y16: 25 | Z16: PRE | AA16: 12-MAY-25 | AD16: 12-MAY-25 | AE16: 17-MAY-25 | AH16: 01-AUG-25 | AT16: Kidder, S Joseph | AU16: =IF($AT16="","",IFERROR(INDEX(InstructorMap!$B:$B, MATCH($AT16, InstructorMap!$A:$A, 0)),"")) | AV16: =IF($AT16="","",IFERROR(INDEX(InstructorMap!$C:$C, MATCH($AT16, InstructorMap!$A:$A, 0)),"")) | AW16: 100 | BH16: DSLE | BI16: 06-MAY-25 | BJ16: A | BK16: 3 | BL16: A | BO16: MOODL | BT16: 70 | BU16: 0 | BV16: 0 | BW16: Y | CF16: Y | CS16: 12 | CT16: 202531 | CU16: 1
H17: 2492-02 | I17: 2492 | J17: DSLE | K17: 664 | L17: 001 | N17: Advanced Campus Ministry | R17: 0 | W17: 3 | Y17: 10 | Z17: CLAS | AA17: 12-MAY-25 | AD17: 12-MAY-25 | AE17: 01-AUG-25 | AH17: 01-AUG-25 | AT17: Ramos, Israel | AU17: =IF($AT17="","",IFERROR(INDEX(InstructorMap!$B:$B, MATCH($AT17, InstructorMap!$A:$A, 0)),"")) | AV17: =IF($AT17="","",IFERROR(INDEX(InstructorMap!$C:$C, MATCH($AT17, InstructorMap!$A:$A, 0)),"")) | AW17: 100 | BH17: DSLE | BI17: 09-MAY-25 | BJ17: A | BL17: A | BO17: MOODL | BT17: 70 | BU17: 2 | BV17: 0 | BW17: Y | CF17: Y | CR17: I | CS17: 12 | CT17: 202531 | CU17: 1
H18: 3451-06 | I18: 3451 | J18: DSLE | K18: 607 | L18: 101 | N18: Intergenerational Ministry | O18: IndepStud:Intergenerationl Min | R18: 0 | V18: DO | W18: 2 | Y18: 5 | Z18: CLAS | AA18: 12-MAY-25 | AD18: 12-MAY-25 | AE18: 01-AUG-25 | AH18: 01-AUG-25 | AT18: Paquini, Rogelio | AU18: =IF($AT18="","",IFERROR(INDEX(InstructorMap!$B:$B, MATCH($AT18, InstructorMap!$A:$A, 0)),"")) | AV18: =IF($AT18="","",IFERROR(INDEX(InstructorMap!$C:$C, MATCH($AT18, InstructorMap!$A:$A, 0)),"")) | AW18: 100 | BB18: -922 | BC18: ESM1 | BD18: BILL | BE18: MA | BG18: 202531 | BH18: DSLE | BI18: 13-MAY-25 | BJ18: A | BL18: I | BO18: MOODL | BT18: 70 | BU18: 0 | BV18: 0 | BW18: Y | CF18: Y | CN18: 70 | CS18: 12 | CT18: 202531 | CU18: 1
H19: 3451-07 | I19: 3451 | J19: DSLE | K19: 607 | L19: 101 | N19: Intergenerational Ministry | O19: IndepStud:Intergenerationl Min | R19: 0 | V19: MA | W19: 2 | Y19: 5 | Z19: CLAS | AA19: 12-MAY-25 | AD19: 12-MAY-25 | AE19: 01-AUG-25 | AH19: 01-AUG-25 | AT19: Paquini, Rogelio | AU19: =IF($AT19="","",IFERROR(INDEX(InstructorMap!$B:$B, MATCH($AT19, InstructorMap!$A:$A, 0)),"")) | AV19: =IF($AT19="","",IFERROR(INDEX(InstructorMap!$C:$C, MATCH($AT19, InstructorMap!$A:$A, 0)),"")) | AW19: 100 | BB19: -633 | BC19: EAR2 | BD19: BILL | BE19: MA | BG19: 202531 | BH19: DSLE | BI19: 13-MAY-25 | BJ19: A | BL19: I | BO19: MOODL | BT19: 70 | BU19: 0 | BV19: 0 | BW19: Y | CF19: Y | CQ19: MAJOR | CS19: 12 | CT19: 202531 | CU19: 1
H20: 3451-08 | I20: 3451 | J20: DSLE | K20: 607 | L20: 101 | N20: Intergenerational Ministry | O20: IndepStud:Intergenerationl Min | R20: 0 | V20: MA | W20: 2 | Y20: 5 | Z20: CLAS | AA20: 12-MAY-25 | AD20: 12-MAY-25 | AE20: 01-AUG-25 | AH20: 01-AUG-25 | AT20: Paquini, Rogelio | AU20: =IF($AT20="","",IFERROR(INDEX(InstructorMap!$B:$B, MATCH($AT20, InstructorMap!$A:$A, 0)),"")) | AV20: =IF($AT20="","",IFERROR(INDEX(InstructorMap!$C:$C, MATCH($AT20, InstructorMap!$A:$A, 0)),"")) | AW20: 100 | BB20: -633 | BC20: ESM3 | BD20: BILL | BE20: MA | BG20: 202531 | BH20: DSLE | BI20: 13-MAY-25 | BJ20: A | BL20: I | BO20: MOODL | BT20: 70 | BU20: 0 | BV20: 0 | BW20: Y | CF20: Y | CO20: MSCID | CS20: 12 | CT20: 202531 | CU20: 1
H21: 3451-09 | I21: 3451 | J21: DSLE | K21: 607 | L21: 101 | N21: Intergenerational Ministry | O21: IndepStud:Intergenerationl Min | R21: 0 | V21: MA | W21: 2 | Y21: 5 | Z21: CLAS | AA21: 12-MAY-25 | AD21: 12-MAY-25 | AE21: 01-AUG-25 | AH21: 01-AUG-25 | AT21: Paquini, Rogelio | AU21: =IF($AT21="","",IFERROR(INDEX(InstructorMap!$B:$B, MATCH($AT21, InstructorMap!$A:$A, 0)),"")) | AV21: =IF($AT21="","",IFERROR(INDEX(InstructorMap!$C:$C, MATCH($AT21, InstructorMap!$A:$A, 0)),"")) | AW21: 100 | BB21: -633 | BC21: ESM4 | BD21: BILL | BE21: MA | BG21: 202531 | BH21: DSLE | BI21: 13-MAY-25 | BJ21: A | BL21: I | BO21: MOODL | BT21: 70 | BU21: 0 | BV21: 0 | BW21: Y | CF21: Y | CQ21: MAJOR | CS21: 12 | CT21: 202531 | CU21: 1
H22: 3451-10 | I22: 3451 | J22: DSLE | K22: 607 | L22: 101 | N22: Intergenerational Ministry | O22: IndepStud:Intergenerationl Min | R22: 0 | W22: 2 | Y22: 5 | Z22: CLAS | AA22: 12-MAY-25 | AD22: 12-MAY-25 | AE22: 01-AUG-25 | AH22: 01-AUG-25 | AT22: Paquini, Rogelio | AU22: =IF($AT22="","",IFERROR(INDEX(InstructorMap!$B:$B, MATCH($AT22, InstructorMap!$A:$A, 0)),"")) | AV22: =IF($AT22="","",IFERROR(INDEX(InstructorMap!$C:$C, MATCH($AT22, InstructorMap!$A:$A, 0)),"")) | AW22: 100 | BB22: 1267 | BC22: ESTM | BD22: BILL | BE22: MA | BG22: 202531 | BH22: DSLE | BI22: 13-MAY-25 | BJ22: A | BL22: I | BO22: MOODL | BT22: 70 | BU22: 0 | BV22: 0 | BW22: Y | CF22: Y | CS22: 12 | CT22: 202531 | CU22: 1
H23: 3452-02 | I23: 3452 | J23: DSLE | K23: 656 | L23: 101 | N23: Counseling Youth & Young Adult | O23: Ind St:Counseling Youth & Y Ad | R23: 0 | W23: 2,3 | X23: 2 | Y23: 5 | Z23: CLAS | AA23: 12-MAY-25 | AD23: 12-MAY-25 | AE23: 01-AUG-25 | AH23: 01-AUG-25 | AT23: Joseph, Ainsworth E. | AU23: =IF($AT23="","",IFERROR(INDEX(InstructorMap!$B:$B, MATCH($AT23, InstructorMap!$A:$A, 0)),"")) | AV23: =IF($AT23="","",IFERROR(INDEX(InstructorMap!$C:$C, MATCH($AT23, InstructorMap!$A:$A, 0)),"")) | AW23: 100 | BH23: DSLE | BI23: 13-MAY-25 | BJ23: A | BK23: 2 | BL23: I | BO23: MOODL | BT23: 70 | BU23: 1 | BV23: 0 | BW23: Y | CF23: Y | CS23: 12 | CT23: 202531 | CU23: 1
H24: 3453-02 | I24: 3453 | J24: DSLE | K24: 652 | L24: 999 | N24: Personal & Fam Finance | R24: 7 | U24: ASYNC | V24: FP | W24: 3 | Y24: 0 | AA24: 12-MAY-25 | AH24: 01-AUG-25 | AT24: NAME NOT FOUND FOR PIDM: | AU24: =IF($AT24="","",IFERROR(INDEX(InstructorMap!$B:$B, MATCH($AT24, InstructorMap!$A:$A, 0)),"")) | AV24: =IF($AT24="","",IFERROR(INDEX(InstructorMap!$C:$C, MATCH($AT24, InstructorMap!$A:$A, 0)),"")) | BB24: 160 | BC24: ES12 | BD24: BILL | BE24: FP | BG24: 202531 | BH24: DSLE | BI24: 19-MAY-25 | BJ24: A | BL24: N | BO24: MOODL | BT24: 70 | BU24: 0 | BV24: 0 | CF24: Y | CS24: 12 | CT24: 202531 | CU24: 1
H25: 2008-02 | I25: 2008 | J25: DSLE | K25: 995 | L25: 101 | N25: Doctoral Dissertation | R25: 0 | W25: 1-13 | Y25: 999 | Z25: CLAS | AA25: 12-MAY-25 | AD25: 12-MAY-25 | AE25: 01-AUG-25 | AH25: 01-AUG-25 | AT25: Fraser, Jasmine J. | AU25: =IF($AT25="","",IFERROR(INDEX(InstructorMap!$B:$B, MATCH($AT25, InstructorMap!$A:$A, 0)),"")) | AV25: =IF($AT25="","",IFERROR(INDEX(InstructorMap!$C:$C, MATCH($AT25, InstructorMap!$A:$A, 0)),"")) | AW25: 100 | BH25: DSLE | BI25: 03-JUN-25 | BJ25: A | BL25: I | BO25: MOODL | BQ25: FT | BT25: 70 | BU25: 4 | BV25: 0 | BW25: Y | CF25: Y | CS25: 12 | CT25: 202531 | CU25: 1
H26: 2394-02 | I26: 2394 | J26: DSLE | K26: 503 | L26: 998 | N26: Marriage, Fam&Interprsnl Reltn | Q26: 086 | R26: 7 | U26: SYNC | W26: 2,3 | Y26: 10 | Z26: WEB | AA26: 09-JUN-25 | AD26: 09-JUN-25 | AE26: 03-JUL-25 | AH26: 03-JUL-25 | AI26: 1330 | AJ26: 1520 | AL26: M | AM26: T | AN26: W | AO26: R | AT26: Joseph, Ainsworth E. | AU26: =IF($AT26="","",IFERROR(INDEX(InstructorMap!$B:$B, MATCH($AT26, InstructorMap!$A:$A, 0)),"")) | AV26: =IF($AT26="","",IFERROR(INDEX(InstructorMap!$C:$C, MATCH($AT26, InstructorMap!$A:$A, 0)),"")) | AW26: 100 | BH26: DSLE | BI26: 10-JUN-25 | BJ26: A | BL26: N | BO26: MOODL | BT26: 70 | BU26: 6 | BV26: 0 | BW26: Y | CF26: Y | CS26: 4 | CT26: 202531 | CU26: 3
H27: 2252-02 | I27: 2252 | J27: DSLE | K27: 503 | L27: 001 | N27: Marriage, Fam&Interprsnl Reltn | Q27: 086 | R27: 0 | W27: 2,3 | Y27: 25 | Z27: CLAS | AA27: 09-JUN-25 | AD27: 09-JUN-25 | AE27: 03-JUL-25 | AH27: 03-JUL-25 | AI27: 1330 | AJ27: 1520 | AL27: M | AM27: T | AN27: W | AO27: R | AR27: 120 | AS27: Seminary Building [SEM] | AT27: Joseph, Ainsworth E. | AU27: =IF($AT27="","",IFERROR(INDEX(InstructorMap!$B:$B, MATCH($AT27, InstructorMap!$A:$A, 0)),"")) | AV27: =IF($AT27="","",IFERROR(INDEX(InstructorMap!$C:$C, MATCH($AT27, InstructorMap!$A:$A, 0)),"")) | AW27: 100 | BH27: DSLE | BI27: 25-JUN-25 | BJ27: A | BL27: A | BO27: MOODL | BT27: 70 | BU27: 11 | BV27: 0 | BW27: Y | BX27: O | CF27: Y | CS27: 4 | CT27: 202531 | CU27: 3

Sheet GSEM
A1: Don {not in Banner} | B1: Mismatching {not in Banner} | C1: Dept/Prog Admin {not in Banner} | D1: Mona {not in Banner} | E1: Karen {not in Banner} | F1: DONE {not in Banner} | G1: Notes {not in Banner} | H1: CRN sorted {not in Banner} | I1: CRN | J1: Subject | K1: Course Number {Crse Num} | L1: Course Section {Seq Crse Num} | M1: Program {not in Banner} | N1: Catalog Title | O1: Section Title | P1: Crosslist Details {not in Banner} | Q1: X Lst | R1: Campus {Ssasect Campus} | S1: Campus Restriction {Camp Restr CC} | T1: Schedule Type {not in Banner} | U1: Instruction Method {Inst Method} | V1: Level {Level SC} | W1: Credit Catalog {Cat Crs} | X1: Credits {Sect Crs} | Y1: Enrollment Cap {Max Enrl} | Z1: Meeting Type | AA1: Semester Start Date {Soaterm Start Date} | AB1: Pre-work Start Date {not in Banner} | AC1: Pre-work End Date {not in Banner} | AD1: Course Start Date {Meet Start Date} | AE1: Course End Date {Meet End Date} | AF1: Post-work Start Date {not in Banner} | AG1: Post-work End Date {not in Banner} | AH1: Semester End Date {Soaterm End Date} | AI1: Course Beginning Time {Meet Beg Time} | AJ1: Course Ending Time {Meet End Time} | AK1: SUN | AL1: MON | AM1: TUE | AN1: WED | AO1: THU | AP1: FRI | AQ1: SAT | AR1: Room {Meet Room} | AS1: Building {Meet Bldg} | AT1: Instructor Name {Instr Name} | AU1: Instructor Email {Instr Email} | AV1: Instructor ID {Instr ID} | AW1: % Responsibility | AX1: load/contract {not in Banner} | AY1: costs per credit {not in Banner} | AZ1: total costs {not in Banner} | BA1: account to be charged {not in Banner} | BB1: Fee Amount {Fees Amt} | BC1: Fee Code {Detl Code} | BD1: Fee Type | BE1: Fee Level | BF1: Fee Ind | BG1: Fee Term | BH1: SEM Department {Scacrse Dept} | BI1: Activity Date | BJ1: Status | BK1: Bill Hrs | BL1: Sect Sch Type | BM1: Prerequisites {Preq Areas} | BN1: Link Ind | BO1: Integration Code | BP1: Link Conn | BQ1: Crs Attr | BR1: Comments | BS1: Major Restr | BT1: Scacrse College | BU1: Enrolled | BV1: Waitlist Capacity | BW1: Primary Ind | BX1: Override | BY1: 1st Date Reg Opens | BZ1: Last Date Reg Opens | CA1: OL Range From Date | CB1: OL Range To Date | CC1: OL Numb Units | CD1: OL Duration Code | CE1: Grade Mode | CF1: Gradable Ind | CG1: Tuit Waiver | CH1: Course Override {Meet Override} | CI1: Lvl Res Ind | CJ1: Cmp Res Ind | CK1: Rate Code | CL1: Cohort Code | CM1: St Attr Code | CN1: Coll SC | CO1: DegC SC | CP1: Prog SC | CQ1: FOS Type | CR1: Special Approval {Special Apvl} | CS1: Weeks | CT1: Term Code | CU1: Part-Of-Term | CV1: Camp SC
H2: 663-02 | I2: 663 | J2: GSEM | K2: 844 | L2: 103 | N2: PhD-ThD Diss Prop Prep | O2: PhD-ThD Diss Prop Prep | R2: 0 | W2: 0 | Y2: 999 | Z2: CLAS | AA2: 12-MAY-25 | AD2: 12-MAY-25 | AE2: 01-AUG-25 | AH2: 01-AUG-25 | AT2: Fraser, Jasmine J. | AU2: =IF($AT2="","",IFERROR(INDEX(InstructorMap!$B:$B, MATCH($AT2, InstructorMap!$A:$A, 0)),"")) | AV2: =IF($AT2="","",IFERROR(INDEX(InstructorMap!$C:$C, MATCH($AT2, InstructorMap!$A:$A, 0)),"")) | AW2: 100 | BH2: GSEM | BI2: 27-JAN-25 | BJ2: A | BL2: I | BO2: MOODL | BQ2: FT | BT2: 70 | BU2: 0 | BV2: 0 | BW2: Y | CF2: Y | CS2: 12 | CT2: 202531 | CU2: 1
H3: 665-02 | I3: 665 | J3: GSEM | K3: 885 | L3: 103 | N3: PhD-ThD Comp Exams | O3: PhD-ThD Comp Exams | R3: 0 | W3: 0 | Y3: 30 | Z3: CLAS | AA3: 12-MAY-25 | AD3: 12-MAY-25 | AE3: 01-AUG-25 | AH3: 01-AUG-25 | AT3: Fraser, Jasmine J. | AU3: =IF($AT3="","",IFERROR(INDEX(InstructorMap!$B:$B, MATCH($AT3, InstructorMap!$A:$A, 0)),"")) | AV3: =IF($AT3="","",IFERROR(INDEX(InstructorMap!$C:$C, MATCH($AT3, InstructorMap!$A:$A, 0)),"")) | AW3: 100 | BH3: GSEM | BI3: 27-JAN-25 | BJ3: A | BL3: I | BO3: MOODL | BQ3: FT | BT3: 70 | BU3: 0 | BV3: 0 | BW3: Y | CF3: Y | CS3: 12 | CT3: 202531 | CU3: 1
H4: 666-02 | I4: 666 | J4: GSEM | K4: 888 | L4: 103 | N4: Doctoral Degr Continuation | O4: Doctoral Degr Continuation | R4: 0 | W4: 0 | Y4: 30 | Z4: CLAS | AA4: 12-MAY-25 | AD4: 12-MAY-25 | AE4: 01-AUG-25 | AH4: 01-AUG-25 | AT4: Fraser, Jasmine J. | AU4: =IF($AT4="","",IFERROR(INDEX(InstructorMap!$B:$B, MATCH($AT4, InstructorMap!$A:$A, 0)),"")) | AV4: =IF($AT4="","",IFERROR(INDEX(InstructorMap!$C:$C, MATCH($AT4, InstructorMap!$A:$A, 0)),"")) | AW4: 100 | BH4: GSEM | BI4: 27-JAN-25 | BJ4: A | BL4: I | BO4: MOODL | BQ4: FT | BT4: 70 | BU4: 0 | BV4: 0 | BW4: Y | CF4: Y | CS4: 12 | CT4: 202531 | CU4: 1
H5: 667-02 | I5: 667 | J5: GSEM | K5: 995 | L5: 103 | N5: PhD-ThD Dissertation | O5: PhD-ThD Dissertation | R5: 0 | W5: 1-12 | Y5: 30 | Z5: CLAS | AA5: 12-MAY-25 | AD5: 12-MAY-25 | AE5: 01-AUG-25 | AH5: 01-AUG-25 | AT5: Fraser, Jasmine J. | AU5: =IF($AT5="","",IFERROR(INDEX(InstructorMap!$B:$B, MATCH($AT5, InstructorMap!$A:$A, 0)),"")) | AV5: =IF($AT5="","",IFERROR(INDEX(InstructorMap!$C:$C, MATCH($AT5, InstructorMap!$A:$A, 0)),"")) | AW5: 100 | BH5: GSEM | BI5: 27-JAN-25 | BJ5: A | BL5: I | BO5: MOODL | BQ5: FT | BT5: 70 | BU5: 0 | BV5: 0 | BW5: Y | CF5: Y | CS5: 12 | CT5: 202531 | CU5: 1
H6: 668-02 | I6: 668 | J6: GSEM | K6: 898 | L6: 001 | N6: Postdoctoral Research Project | O6: Postdoctoral Research Project | R6: 0 | W6: 4,5 | Y6: 999 | Z6: CLAS | AA6: 12-MAY-25 | AD6: 12-MAY-25 | AE6: 01-AUG-25 | AH6: 01-AUG-25 | AT6: Kuhn, Wagner | AU6: =IF($AT6="","",IFERROR(INDEX(InstructorMap!$B:$B, MATCH($AT6, InstructorMap!$A:$A, 0)),"")) | AV6: =IF($AT6="","",IFERROR(INDEX(InstructorMap!$C:$C, MATCH($AT6, InstructorMap!$A:$A, 0)),"")) | AW6: 100 | BH6: GSEM | BI6: 27-JAN-25 | BJ6: A | BL6: I | BO6: MOODL | BT6: 70 | BU6: 0 | BV6: 0 | BW6: Y | CF6: Y | CS6: 12 | CT6: 202531 | CU6: 1
H7: 669-02 | I7: 669 | J7: GSEM | K7: 990 | L7: 101 | N7: Postdoctoral Seminar | R7: 0 | W7: 3,4 | Y7: 999 | Z7: CLAS | AA7: 12-MAY-25 | AD7: 12-MAY-25 | AE7: 01-AUG-25 | AH7: 01-AUG-25 | AT7: Kuhn, Wagner | AU7: =IF($AT7="","",IFERROR(INDEX(InstructorMap!$B:$B, MATCH($AT7, InstructorMap!$A:$A, 0)),"")) | AV7: =IF($AT7="","",IFERROR(INDEX(InstructorMap!$C:$C, MATCH($AT7, InstructorMap!$A:$A, 0)),"")) | AW7: 100 | BH7: GSEM | BI7: 27-JAN-25 | BJ7: A | BL7: M | BO7: MOODL | BT7: 70 | BU7: 0 | BV7: 0 | BW7: Y | CF7: Y | CS7: 12 | CT7: 202531 | CU7: 1
H8: 672-02 | I8: 672 | J8: GSEM | K8: 885 | L8: 101 | N8: PhD-ThD Comp Exams | O8: PhD-ThD Comp Exams | R8: 0 | W8: 0 | Y8: 30 | Z8: CLAS | AA8: 12-MAY-25 | AD8: 12-MAY-25 | AE8: 01-AUG-25 | AH8: 01-AUG-25 | AT8: Reeve, John W. | AU8: =IF($AT8="","",IFERROR(INDEX(InstructorMap!$B:$B, MATCH($AT8, InstructorMap!$A:$A, 0)),"")) | AV8: =IF($AT8="","",IFERROR(INDEX(InstructorMap!$C:$C, MATCH($AT8, InstructorMap!$A:$A, 0)),"")) | AW8: 100 | BH8: GSEM | BI8: 27-JAN-25 | BJ8: A | BL8: I | BO8: MOODL | BQ8: FT | BT8: 70 | BU8: 0 | BV8: 0 | BW8: Y | CF8: Y | CS8: 12 | CT8: 202531 | CU8: 1
H9: 676-02 | I9: 676 | J9: GSEM | K9: 695 | L9: 101 | N9: Research Project | O9: Research Project | R9: 0 | W9: 2,3 | Y9: 999 | Z9: CLAS | AA9: 12-MAY-25 | AD9: 12-MAY-25 | AE9: 01-AUG-25 | AH9: 01-AUG-25 | AT9: Vine, Cedric E. | AU9: =IF($AT9="","",IFERROR(INDEX(InstructorMap!$B:$B, MATCH($AT9, InstructorMap!$A:$A, 0)),"")) | AV9: =IF($AT9="","",IFERROR(INDEX(InstructorMap!$C:$C, MATCH($AT9, InstructorMap!$A:$A, 0)),"")) | AW9: 100 | BH9: GSEM | BI9: 27-JAN-25 | BJ9: A | BL9: I | BO9: MOODL | BT9: 70 | BU9: 0 | BV9: 0 | BW9: Y | CF9: Y | CS9: 12 | CT9: 202531 | CU9: 1
H10: 678-02 | I10: 678 | J10: GSEM | K10: 844 | L10: 102 | N10: PhD-ThD Diss Prop Prep | O10: PhD-ThD Diss Prop Prep | R10: 0 | W10: 0 | Y10: 20 | Z10: CLAS | AA10: 12-MAY-25 | AD10: 12-MAY-25 | AE10: 01-AUG-25 | AH10: 01-AUG-25 | AT10: Younker, Randall W. | AU10: =IF($AT10="","",IFERROR(INDEX(InstructorMap!$B:$B, MATCH($AT10, InstructorMap!$A:$A, 0)),"")) | AV10: =IF($AT10="","",IFERROR(INDEX(InstructorMap!$C:$C, MATCH($AT10, InstructorMap!$A:$A, 0)),"")) | AW10: 100 | BH10: GSEM | BI10: 27-JAN-25 | BJ10: A | BL10: I | BO10: MOODL | BQ10: FT | BT10: 70 | BU10: 0 | BV10: 0 | BW10: Y | CF10: Y | CS10: 12 | CT10: 202531 | CU10: 1
H11: 679-02 | I11: 679 | J11: GSEM | K11: 880 | L11: 102 | N11: Prep for Comprehensive Exams | O11: Prep for Comprehensive Exams | R11: 0 | W11: 0 | Y11: 999 | Z11: CLAS | AA11: 12-MAY-25 | AD11: 12-MAY-25 | AE11: 01-AUG-25 | AH11: 01-AUG-25 | AT11: Younker, Randall W. | AU11: =IF($AT11="","",IFERROR(INDEX(InstructorMap!$B:$B, MATCH($AT11, InstructorMap!$A:$A, 0)),"")) | AV11: =IF($AT11="","",IFERROR(INDEX(InstructorMap!$C:$C, MATCH($AT11, InstructorMap!$A:$A, 0)),"")) | AW11: 100 | BH11: GSEM | BI11: 27-JAN-25 | BJ11: A | BL11: I | BO11: MOODL | BQ11: FT | BT11: 70 | BU11: 0 | BV11: 0 | BW11: Y | CF11: Y | CS11: 12 | CT11: 202531 | CU11: 1
H12: 680-02 | I12: 680 | J12: GSEM | K12: 885 | L12: 102 | N12: PhD-ThD Comp Exams | O12: PhD-ThD Comp Exams | R12: 0 | W12: 0 | Y12: 30 | Z12: CLAS | AA12: 12-MAY-25 | AD12: 12-MAY-25 | AE12: 01-AUG-25 | AH12: 01-AUG-25 | AT12: Younker, Randall W. | AU12: =IF($AT12="","",IFERROR(INDEX(InstructorMap!$B:$B, MATCH($AT12, InstructorMap!$A:$A, 0)),"")) | AV12: =IF($AT12="","",IFERROR(INDEX(InstructorMap!$C:$C, MATCH($AT12, InstructorMap!$A:$A, 0)),"")) | AW12: 100 | BH12: GSEM | BI12: 27-JAN-25 | BJ12: A | BL12: I | BO12: MOODL | BQ12: FT | BT12: 70 | BU12: 0 | BV12: 0 | BW12: Y | CF12: Y | CS12: 12 | CT12: 202531 | CU12: 1
H13: 682-02 | I13: 682 | J13: GSEM | K13: 995 | L13: 102 | N13: PhD-ThD Dissertation | O13: PhD-ThD Dissertation | R13: 0 | W13: 1-12 | Y13: 30 | Z13: CLAS | AA13: 12-MAY-25 | AD13: 12-MAY-25 | AE13: 01-AUG-25 | AH13: 01-AUG-25 | AT13: Younker, Randall W. | AU13: =IF($AT13="","",IFERROR(INDEX(InstructorMap!$B:$B, MATCH($AT13, InstructorMap!$A:$A, 0)),"")) | AV13: =IF($AT13="","",IFERROR(INDEX(InstructorMap!$C:$C, MATCH($AT13, InstructorMap!$A:$A, 0)),"")) | AW13: 100 | BH13: GSEM | BI13: 27-JAN-25 | BJ13: A | BL13: I | BO13: MOODL | BQ13: FT | BT13: 70 | BU13: 0 | BV13: 0 | BW13: Y | CF13: Y | CS13: 12 | CT13: 202531 | CU13: 1
H14: 741-02 | I14: 741 | J14: GSEM | K14: 680 | L14: 999 | N14: Masters Comprehensive Exam | R14: 7 | V14: FP | W14: 0 | Y14: 999 | Z14: CLAS | AA14: 12-MAY-25 | AD14: 12-MAY-25 | AE14: 01-AUG-25 | AH14: 01-AUG-25 | AT14: Vine, Cedric E. | AU14: =IF($AT14="","",IFERROR(INDEX(InstructorMap!$B:$B, MATCH($AT14, InstructorMap!$A:$A, 0)),"")) | AV14: =IF($AT14="","",IFERROR(INDEX(InstructorMap!$C:$C, MATCH($AT14, InstructorMap!$A:$A, 0)),"")) | AW14: 100 | BB14: 160 | BC14: ES12 | BD14: BILL | BE14: MA | BG14: 202531 | BH14: GSEM | BI14: 27-JAN-25 | BJ14: A | BL14: I | BO14: MOODL | BQ14: FT | BT14: 70 | BU14: 0 | BV14: 0 | BW14: Y | CF14: Y | CS14: 12 | CT14: 202531 | CU14: 1
H15: 742-02 | I15: 742 | J15: GSEM | K15: 688 | L15: 999 | N15: Master's Degree Contin | R15: 7 | W15: 0 | Y15: 999 | Z15: CLAS | AA15: 12-MAY-25 | AD15: 12-MAY-25 | AE15: 01-AUG-25 | AH15: 01-AUG-25 | AT15: Vine, Cedric E. | AU15: =IF($AT15="","",IFERROR(INDEX(InstructorMap!$B:$B, MATCH($AT15, InstructorMap!$A:$A, 0)),"")) | AV15: =IF($AT15="","",IFERROR(INDEX(InstructorMap!$C:$C, MATCH($AT15, InstructorMap!$A:$A, 0)),"")) | AW15: 100 | BH15: GSEM | BI15: 27-JAN-25 | BJ15: A | BL15: I | BO15: MOODL | BQ15: FT | BT15: 70 | BU15: 0 | BV15: 0 | BW15: Y | CF15: Y | CS15: 12 | CT15: 202531 | CU15: 1
H16: 743-02 | I16: 743 | J16: GSEM | K16: 695 | L16: 999 | N16: Research Project | R16: 7 | W16: 2,3 | Y16: 999 | Z16: CLAS | AA16: 12-MAY-25 | AD16: 12-MAY-25 | AE16: 01-AUG-25 | AH16: 01-AUG-25 | AT16: Vine, Cedric E. | AU16: =IF($AT16="","",IFERROR(INDEX(InstructorMap!$B:$B, MATCH($AT16, InstructorMap!$A:$A, 0)),"")) | AV16: =IF($AT16="","",IFERROR(INDEX(InstructorMap!$C:$C, MATCH($AT16, InstructorMap!$A:$A, 0)),"")) | AW16: 100 | BH16: GSEM | BI16: 27-JAN-25 | BJ16: A | BL16: I | BO16: MOODL | BT16: 70 | BU16: 0 | BV16: 0 | BW16: Y | CF16: Y | CS16: 12 | CT16: 202531 | CU16: 1
H17: 744-02 | I17: 744 | J17: GSEM | K17: 697 | L17: 999 | N17: Thesis for MA Degree | R17: 7 | W17: 1-10 | Y17: 999 | Z17: CLAS | AA17: 12-MAY-25 | AD17: 12-MAY-25 | AE17: 01-AUG-25 | AH17: 01-AUG-25 | AT17: Vine, Cedric E. | AU17: =IF($AT17="","",IFERROR(INDEX(InstructorMap!$B:$B, MATCH($AT17, InstructorMap!$A:$A, 0)),"")) | AV17: =IF($AT17="","",IFERROR(INDEX(InstructorMap!$C:$C, MATCH($AT17, InstructorMap!$A:$A, 0)),"")) | AW17: 100 | BH17: GSEM | BI17: 21-APR-25 | BJ17: A | BL17: I | BO17: MOODL | BQ17: FT | BT17: 70 | BU17: 1 | BV17: 0 | BW17: Y | CF17: Y | CS17: 12 | CT17: 202531 | CU17: 1
