Workbook

Sheet CHIS
A1: Don {not in Banner} | B1: Mismatching {not in Banner} | C1: Dept/Prog Admin {not in Banner} | D1: Mona {not in Banner} | E1: Karen {not in Banner} | F1: DONE {not in Banner} | G1: Notes {not in Banner} | H1: CRN sorted {not in Banner} | I1: CRN | J1: Attribute {not in Banner} | K1: Subject | L1: Course Number {Crse Num} | M1: Course Section {Seq Crse Num} | N1: Program {not in Banner} | O1: Catalog Title | P1: Section Title | Q1: Crosslist Details {not in Banner} | R1: X Lst | S1: Campus {Ssasect Campus} | T1: Campus Restriction {Camp Restr CC} | U1: Schedule Type {not in Banner} | V1: Instruction Method {Inst Method} | W1: Level {Level SC} | X1: Part-Of-Term | Y1: Credit Catalog {Cat Crs} | Z1: Credits {Sect Crs} | AA1: Faculty Load / Contract Credits {not in Banner} | AB1: Enrollment Cap {Max Enrl} | AC1: Meeting Type | AD1: Semester Start Date {Soaterm Start Date} | AE1: Pre-work Start Date {not in Banner} | AF1: Pre-work End Date {not in Banner} | AG1: pre-work # of weeks {not in Banner} | AH1: pre-work hours/week {not in Banner} | AI1: pre-work hours/period {not in Banner} | AJ1: Intensive Period Start Date {Meet Start Date} | AK1: Intensive Period End Date {Meet End Date} | AL1: intensive # of weeks {not in Banner} | AM1: intensive hours/week {not in Banner} | AN1: intensive hours/period {not in Banner} | AO1: Post-work Start Date {not in Banner} | AP1: Post-work End Date {not in Banner} | AQ1: post-work # of weeks {not in Banner} | AR1: post-work hours/week {not in Banner} | AS1: post-work hours/period {not in Banner} | AT1: sum of weeks (for check) {not in Banner} | AU1: total contract hours {not in Banner} | AV1: Semester End Date {Soaterm End Date} | AW1: Course Beginning Time {Meet Beg Time} | AX1: Course Ending Time {Meet End Time} | AY1: SUN | AZ1: MON | BA1: TUE | BB1: WED | BC1: THU | BD1: FRI | BE1: SAT | BF1: Weeks | BG1: Fiscal Year {not in Banner} | BH1: Semester {not in Banner} | BI1: Room {Meet Room} | BJ1: Building {Meet Bldg} | BK1: Instructor Name {Instr Name} | BL1: Instructor Email {Instr Email} | BM1: Instructor ID {Instr ID} | BN1: Remote Employee {not in Banner} | BO1: % Responsibility | BP1: load/contract {not in Banner} | BQ1: Reason for Contract {not in Banner} | BR1: costs per credit {not in Banner} | BS1: total costs {not in Banner} | BT1: dept budget {not in Banner} | BU1: account to be charged {not in Banner} | BV1: SEM Department {Scacrse Dept} | BW1: dean email | BX1: VP finance email | BY1: HR email | BZ1: Fee Amount {Fees Amt} | CA1: Fee Code {Detl Code} | CB1: Fee Type | CC1: Fee Level | CD1: Fee Ind | CE1: Fee Term | CF1: Activity Date | CG1: Status | CH1: Bill Hrs | CI1: Sect Sch Type | CJ1: Prerequisites {Preq Areas} | CK1: Link Ind | CL1: Integration Code | CM1: Link Conn | CN1: Crs Attr | CO1: Comments | CP1: Major Restr | CQ1: Scacrse College | CR1: Enrolled | CS1: Waitlist Capacity | CT1: Primary Ind | CU1: Override | CV1: 1st Date Reg Opens | CW1: Last Date Reg Opens | CX1: OL Range From Date | CY1: OL Range To Date | CZ1: OL Numb Units | DA1: OL Duration Code | DB1: Grade Mode | DC1: Gradable Ind | DD1: Tuit Waiver | DE1: Course Override {Meet Override} | DF1: Lvl Res Ind | DG1: Cmp Res Ind | DH1: Rate Code | DI1: Cohort Code | DJ1: St Attr Code | DK1: Coll SC | DL1: DegC SC | DM1: Prog SC | DN1: FOS Type | DO1: Special Approval {Special Apvl} | DP1: Term Code | DQ1: Camp SC
A2: FALSE | B2: FALSE | C2: FALSE | D2: FALSE | E2: FALSE | F2: FALSE | H2: 2221-02 | I2: 2221 | K2: CHIS | L2: 885 | M2: 040 | O2: =IFERROR(INDEX(_courses_lookup!$C:$C,MATCH(K2&L2,_courses_lookup!$E:$E,0)),"") -> Topics in | P2: =IFERROR(INDEX(_courses_lookup!$D:$D,MATCH(K2&L2,_courses_lookup!$E:$E,0)),"") -> Topics: Dev of SDA Theology | S2: 0 | V2: TOUR | X2: Q | Y2: 1-3 | AB2: 45 | AC2: POST | AD2: 07-JUL-25 | AG2: =IF(AND(AE2<>"",AF2<>""),ROUNDUP((AF2-AE2)/7,0),"") | AI2: =IFERROR(IF(AG2*AH2=0,"",AG2*AH2),"") | AJ2: 28-JUL-25 | AK2: 01-AUG-25 | AL2: =IF(AND(AJ2<>"",AK2<>""),ROUNDUP((AK2-AJ2)/7,0),"") -> 1 | AN2: =IFERROR(IF(AL2*AM2=0,"",AL2*AM2),"") | AQ2: =IF(AND(AO2<>"",AP2<>""),ROUNDUP((AP2-AO2)/7,0),"") | AR2: =IFERROR(IF((AU2-(AI2+AN2))/AQ2=0,"",ROUNDUP((AU2-(AI2+AN2))/AQ2,0)),"") | AS2: =IFERROR(IF((AU2-(AI2+AN2))=0,"",(AU2-(AI2+AN2))),"") | AT2: =IF(AND(AG2="",AQ2=""),AL2,IF(SUM(AG2,AL2,AQ2)=0,"",SUM(AG2,AL2,AQ2))) -> 1 | AV2: 01-AUG-25 | BF2: 4 | BG2: =IF(AD2="","",YEAR(AD2)+IF(MONTH(AD2)>=5,1,0)) -> 2026 | BH2: =IF(AD2="","",IF(AND(MONTH(AD2)=8,DAY(AD2)>=15),"Fall",IF(MONTH(AD2)>8,"Fall",IF(MONTH(AD2)=5,"Summer",IF(MONTH(AD2)=1,"Spring",""))))) | BK2: Burton, Kevin M. | BL2: =IFERROR(INDEX(_names_lookup!$C:$C,MATCH(BK2,_names_lookup!$A:$A,0)),"") -> burtonk@andrews.edu | BM2: =IFERROR(INDEX(_names_lookup!$B:$B,MATCH(BK2,_names_lookup!$A:$A,0)),"") -> 000148286 | BO2: 100 | BS2: =IFERROR(IF(BR2*AA2=0,"",BR2*AA2),"") | BV2: CHIS | CF2: 27-MAR-25 | CG2: A | CI2: A | CL2: MOODL | CQ2: 70 | CR2: 0 | CS2: 0 | CT2: Y | DC2: Y | DP2: 202531
A3: FALSE | B3: FALSE | C3: FALSE | D3: FALSE | E3: FALSE | F3: FALSE | H3: 2221-04 | I3: 2221 | K3: CHIS | L3: 885 | M3: 040 | O3: =IFERROR(INDEX(_courses_lookup!$C:$C,MATCH(K3&L3,_courses_lookup!$E:$E,0)),"") -> Topics in | P3: =IFERROR(INDEX(_courses_lookup!$D:$D,MATCH(K3&L3,_courses_lookup!$E:$E,0)),"") -> Topics: Dev of SDA Theology | S3: 0 | V3: TOUR | X3: Q | Y3: 1-3 | AB3: 45 | AC3: PRE | AD3: 07-JUL-25 | AG3: =IF(AND(AE3<>"",AF3<>""),ROUNDUP((AF3-AE3)/7,0),"") | AI3: =IFERROR(IF(AG3*AH3=0,"",AG3*AH3),"") | AJ3: 07-JUL-25 | AK3: 19-JUL-25 | AL3: =IF(AND(AJ3<>"",AK3<>""),ROUNDUP((AK3-AJ3)/7,0),"") -> 2 | AN3: =IFERROR(IF(AL3*AM3=0,"",AL3*AM3),"") | AQ3: =IF(AND(AO3<>"",AP3<>""),ROUNDUP((AP3-AO3)/7,0),"") | AR3: =IFERROR(IF((AU3-(AI3+AN3))/AQ3=0,"",ROUNDUP((AU3-(AI3+AN3))/AQ3,0)),"") | AS3: =IFERROR(IF((AU3-(AI3+AN3))=0,"",(AU3-(AI3+AN3))),"") | AT3: =IF(AND(AG3="",AQ3=""),AL3,IF(SUM(AG3,AL3,AQ3)=0,"",SUM(AG3,AL3,AQ3))) -> 2 | AV3: 01-AUG-25 | BF3: 4 | BG3: =IF(AD3="","",YEAR(AD3)+IF(MONTH(AD3)>=5,1,0)) -> 2026 | BH3: =IF(AD3="","",IF(AND(MONTH(AD3)=8,DAY(AD3)>=15),"Fall",IF(MONTH(AD3)>8,"Fall",IF(MONTH(AD3)=5,"Summer",IF(MONTH(AD3)=1,"Spring",""))))) | BK3: Burton, Kevin M. | BL3: =IFERROR(INDEX(_names_lookup!$C:$C,MATCH(BK3,_names_lookup!$A:$A,0)),"") -> burtonk@andrews.edu | BM3: =IFERROR(INDEX(_names_lookup!$B:$B,MATCH(BK3,_names_lookup!$A:$A,0)),"") -> 000148286 | BO3: 100 | BS3: =IFERROR(IF(BR3*AA3=0,"",BR3*AA3),"") | BV3: CHIS | CF3: 27-MAR-25 | CG3: A | CI3: A | CL3: MOODL | CQ3: 70 | CR3: 0 | CS3: 0 | CT3: Y | DC3: Y | DP3: 202531
A4: FALSE | B4: FALSE | C4: FALSE | D4: FALSE | E4: FALSE | F4: FALSE | H4: 2221-06 | I4: 2221 | K4: CHIS | L4: 885 | M4: 040 | O4: =IFERROR(INDEX(_courses_lookup!$C:$C,MATCH(K4&L4,_courses_lookup!$E:$E,0)),"") -> Topics in | P4: =IFERROR(INDEX(_courses_lookup!$D:$D,MATCH(K4&L4,_courses_lookup!$E:$E,0)),"") -> Topics: Dev of SDA Theology | S4: 0 | V4: TOUR | X4: Q | Y4: 1-3 | AB4: 45 | AC4: TOUR | AD4: 07-JUL-25 | AG4: =IF(AND(AE4<>"",AF4<>""),ROUNDUP((AF4-AE4)/7,0),"") | AI4: =IFERROR(IF(AG4*AH4=0,"",AG4*AH4),"") | AJ4: 20-JUL-25 | AK4: 27-JUL-25 | AL4: =IF(AND(AJ4<>"",AK4<>""),ROUNDUP((AK4-AJ4)/7,0),"") -> 1 | AN4: =IFERROR(IF(AL4*AM4=0,"",AL4*AM4),"") | AQ4: =IF(AND(AO4<>"",AP4<>""),ROUNDUP((AP4-AO4)/7,0),"") | AR4: =IFERROR(IF((AU4-(AI4+AN4))/AQ4=0,"",ROUNDUP((AU4-(AI4+AN4))/AQ4,0)),"") | AS4: =IFERROR(IF((AU4-(AI4+AN4))=0,"",(AU4-(AI4+AN4))),"") | AT4: =IF(AND(AG4="",AQ4=""),AL4,IF(SUM(AG4,AL4,AQ4)=0,"",SUM(AG4,AL4,AQ4))) -> 1 | AV4: 01-AUG-25 | BF4: 4 | BG4: =IF(AD4="","",YEAR(AD4)+IF(MONTH(AD4)>=5,1,0)) -> 2026 | BH4: =IF(AD4="","",IF(AND(MONTH(AD4)=8,DAY(AD4)>=15),"Fall",IF(MONTH(AD4)>8,"Fall",IF(MONTH(AD4)=5,"Summer",IF(MONTH(AD4)=1,"Spring",""))))) | BK4: Burton, Kevin M. | BL4: =IFERROR(INDEX(_names_lookup!$C:$C,MATCH(BK4,_names_lookup!$A:$A,0)),"") -> burtonk@andrews.edu | BM4: =IFERROR(INDEX(_names_lookup!$B:$B,MATCH(BK4,_names_lookup!$A:$A,0)),"") -> 000148286 | BO4: 100 | BS4: =IFERROR(IF(BR4*AA4=0,"",BR4*AA4),"") | BV4: CHIS | CF4: 27-MAR-25 | CG4: A | CI4: A | CL4: MOODL | CQ4: 70 | CR4: 0 | CS4: 0 | CT4: Y | DC4: Y | DP4: 202531
A5: FALSE | B5: FALSE | C5: FALSE | D5: FALSE | E5: FALSE | F5: FALSE | H5: 2852-02 | I5: 2852 | K5: CHIS | L5: 890 | M5: 101 | O5: =IFERROR(INDEX(_courses_lookup!$C:$C,MATCH(K5&L5,_courses_lookup!$E:$E,0)),"") -> Directed Rdg in Church History | P5: =IFERROR(INDEX(_courses_lookup!$D:$D,MATCH(K5&L5,_courses_lookup!$E:$E,0)),"") -> 0 | S5: 0 | X5: 1 | Y5: 1-6 | AB5: 999 | AC5: CLAS | AD5: 12-MAY-25 | AG5: =IF(AND(AE5<>"",AF5<>""),ROUNDUP((AF5-AE5)/7,0),"") | AI5: =IFERROR(IF(AG5*AH5=0,"",AG5*AH5),"") | AJ5: 12-MAY-25 | AK5: 01-AUG-25 | AL5: =IF(AND(AJ5<>"",AK5<>""),ROUNDUP((AK5-AJ5)/7,0),"") -> 12 | AN5: =IFERROR(IF(AL5*AM5=0,"",AL5*AM5),"") | AQ5: =IF(AND(AO5<>"",AP5<>""),ROUNDUP((AP5-AO5)/7,0),"") | AR5: =IFERROR(IF((AU5-(AI5+AN5))/AQ5=0,"",ROUNDUP((AU5-(AI5+AN5))/AQ5,0)),"") | AS5: =IFERROR(IF((AU5-(AI5+AN5))=0,"",(AU5-(AI5+AN5))),"") | AT5: =IF(AND(AG5="",AQ5=""),AL5,IF(SUM(AG5,AL5,AQ5)=0,"",SUM(AG5,AL5,AQ5))) -> 12 | AV5: 01-AUG-25 | BF5: 12 | BG5: =IF(AD5="","",YEAR(AD5)+IF(MONTH(AD5)>=5,1,0)) -> 2026 | BH5: =IF(AD5="","",IF(AND(MONTH(AD5)=8,DAY(AD5)>=15),"Fall",IF(MONTH(AD5)>8,"Fall",IF(MONTH(AD5)=5,"Summer",IF(MONTH(AD5)=1,"Spring",""))))) -> Summer | BK5: Kaiser, Denis | BL5: =IFERROR(INDEX(_names_lookup!$C:$C,MATCH(BK5,_names_lookup!$A:$A,0)),"") -> denis@andrews.edu | BM5: =IFERROR(INDEX(_names_lookup!$B:$B,MATCH(BK5,_names_lookup!$A:$A,0)),"") -> 000134382 | BO5: 100 | BS5: =IFERROR(IF(BR5*AA5=0,"",BR5*AA5),"") | BV5: CHIS | CF5: 27-MAR-25 | CG5: A | CI5: I | CL5: MOODL | CQ5: 70 | CR5: 0 | CS5: 0 | CT5: Y | DC5: Y | DO5: IT | DP5: 202531
A6: FALSE | B6: FALSE | C6: FALSE | D6: FALSE | E6: FALSE | F6: FALSE | H6: 2879-02 | I6: 2879 | K6: CHIS | L6: 890 | M6: 102 | O6: =IFERROR(INDEX(_courses_lookup!$C:$C,MATCH(K6&L6,_courses_lookup!$E:$E,0)),"") -> Directed Rdg in Church History | P6: =IFERROR(INDEX(_courses_lookup!$D:$D,MATCH(K6&L6,_courses_lookup!$E:$E,0)),"") -> 0 | S6: 0 | X6: 1 | Y6: 1-6 | AB6: 999 | AC6: CLAS | AD6: 12-MAY-25 | AG6: =IF(AND(AE6<>"",AF6<>""),ROUNDUP((AF6-AE6)/7,0),"") | AI6: =IFERROR(IF(AG6*AH6=0,"",AG6*AH6),"") | AJ6: 12-MAY-25 | AK6: 01-AUG-25 | AL6: =IF(AND(AJ6<>"",AK6<>""),ROUNDUP((AK6-AJ6)/7,0),"") -> 12 | AN6: =IFERROR(IF(AL6*AM6=0,"",AL6*AM6),"") | AQ6: =IF(AND(AO6<>"",AP6<>""),ROUNDUP((AP6-AO6)/7,0),"") | AR6: =IFERROR(IF((AU6-(AI6+AN6))/AQ6=0,"",ROUNDUP((AU6-(AI6+AN6))/AQ6,0)),"") | AS6: =IFERROR(IF((AU6-(AI6+AN6))=0,"",(AU6-(AI6+AN6))),"") | AT6: =IF(AND(AG6="",AQ6=""),AL6,IF(SUM(AG6,AL6,AQ6)=0,"",SUM(AG6,AL6,AQ6))) -> 12 | AV6: 01-AUG-25 | BF6: 12 | BG6: =IF(AD6="","",YEAR(AD6)+IF(MONTH(AD6)>=5,1,0)) -> 2026 | BH6: =IF(AD6="","",IF(AND(MONTH(AD6)=8,DAY(AD6)>=15),"Fall",IF(MONTH(AD6)>8,"Fall",IF(MONTH(AD6)=5,"Summer",IF(MONTH(AD6)=1,"Spring",""))))) -> Summer | BK6: O'Reggio, Trevor E. | BL6: =IFERROR(INDEX(_names_lookup!$C:$C,MATCH(BK6,_names_lookup!$A:$A,0)),"") -> toreggio@andrews.edu | BM6: =IFERROR(INDEX(_names_lookup!$B:$B,MATCH(BK6,_names_lookup!$A:$A,0)),"") -> 000035762 | BO6: 100 | BS6: =IFERROR(IF(BR6*AA6=0,"",BR6*AA6),"") | BV6: CHIS | CF6: 27-MAR-25 | CG6: A | CI6: I | CL6: MOODL | CQ6: 70 | CR6: 0 | CS6: 0 | CT6: Y | DC6: Y | DO6: IT | DP6: 202531
A7: FALSE | B7: FALSE | C7: FALSE | D7: FALSE | E7: FALSE | F7: FALSE | H7: 2509-02 | I7: 2509 | K7: CHIS | L7: 891 | M7: 101 | O7: =IFERROR(INDEX(_courses_lookup!$C:$C,MATCH(K7&L7,_courses_lookup!$E:$E,0)),"") -> Ind St: | P7: =IFERROR(INDEX(_courses_lookup!$D:$D,MATCH(K7&L7,_courses_lookup!$E:$E,0)),"") -> Ind St:Church History | S7: 0 | X7: 1 | Y7: 1-3 | AB7: 999 | AC7: CLAS | AD7: 12-MAY-25 | AG7: =IF(AND(AE7<>"",AF7<>""),ROUNDUP((AF7-AE7)/7,0),"") | AI7: =IFERROR(IF(AG7*AH7=0,"",AG7*AH7),"") | AJ7: 13-MAY-25 | AK7: 01-AUG-25 | AL7: =IF(AND(AJ7<>"",AK7<>""),ROUNDUP((AK7-AJ7)/7,0),"") -> 12 | AN7: =IFERROR(IF(AL7*AM7=0,"",AL7*AM7),"") | AQ7: =IF(AND(AO7<>"",AP7<>""),ROUNDUP((AP7-AO7)/7,0),"") | AR7: =IFERROR(IF((AU7-(AI7+AN7))/AQ7=0,"",ROUNDUP((AU7-(AI7+AN7))/AQ7,0)),"") | AS7: =IFERROR(IF((AU7-(AI7+AN7))=0,"",(AU7-(AI7+AN7))),"") | AT7: =IF(AND(AG7="",AQ7=""),AL7,IF(SUM(AG7,AL7,AQ7)=0,"",SUM(AG7,AL7,AQ7))) -> 12 | AV7: 01-AUG-25 | BF7: 12 | BG7: =IF(AD7="","",YEAR(AD7)+IF(MONTH(AD7)>=5,1,0)) -> 2026 | BH7: =IF(AD7="","",IF(AND(MONTH(AD7)=8,DAY(AD7)>=15),"Fall",IF(MONTH(AD7)>8,"Fall",IF(MONTH(AD7)=5,"Summer",IF(MONTH(AD7)=1,"Spring",""))))) -> Summer | BK7: Reeve, John W. | BL7: =IFERROR(INDEX(_names_lookup!$C:$C,MATCH(BK7,_names_lookup!$A:$A,0)),"") -> jreeve@andrews.edu | BM7: =IFERROR(INDEX(_names_lookup!$B:$B,MATCH(BK7,_names_lookup!$A:$A,0)),"") -> 000049018 | BO7: 100 | BS7: =IFERROR(IF(BR7*AA7=0,"",BR7*AA7),"") | BV7: CHIS | CF7: 27-MAR-25 | CG7: A | CI7: I | CL7: MOODL | CQ7: 70 | CR7: 0 | CS7: 0 | CT7: Y | DC7: Y | DO7: IT | DP7: 202531
A8: FALSE | B8: FALSE | C8: FALSE | D8: FALSE | E8: FALSE | F8: FALSE | H8: 2580-02 | I8: 2580 | K8: CHIS | L8: 891 | M8: 102 | O8: =IFERROR(INDEX(_courses_lookup!$C:$C,MATCH(K8&L8,_courses_lookup!$E:$E,0)),"") -> Ind St: | P8: =IFERROR(INDEX(_courses_lookup!$D:$D,MATCH(K8&L8,_courses_lookup!$E:$E,0)),"") -> Ind St:Church History | S8: 0 | X8: 1 | Y8: 1-3 | AB8: 999 | AC8: CLAS | AD8: 12-MAY-25 | AG8: =IF(AND(AE8<>"",AF8<>""),ROUNDUP((AF8-AE8)/7,0),"") | AI8: =IFERROR(IF(AG8*AH8=0,"",AG8*AH8),"") | AJ8: 12-MAY-25 | AK8: 01-AUG-25 | AL8: =IF(AND(AJ8<>"",AK8<>""),ROUNDUP((AK8-AJ8)/7,0),"") -> 12 | AN8: =IFERROR(IF(AL8*AM8=0,"",AL8*AM8),"") | AQ8: =IF(AND(AO8<>"",AP8<>""),ROUNDUP((AP8-AO8)/7,0),"") | AR8: =IFERROR(IF((AU8-(AI8+AN8))/AQ8=0,"",ROUNDUP((AU8-(AI8+AN8))/AQ8,0)),"") | AS8: =IFERROR(IF((AU8-(AI8+AN8))=0,"",(AU8-(AI8+AN8))),"") | AT8: =IF(AND(AG8="",AQ8=""),AL8,IF(SUM(AG8,AL8,AQ8)=0,"",SUM(AG8,AL8,AQ8))) -> 12 | AV8: 01-AUG-25 | BF8: 12 | BG8: =IF(AD8="","",YEAR(AD8)+IF(MONTH(AD8)>=5,1,0)) -> 2026 | BH8: =IF(AD8="","",IF(AND(MONTH(AD8)=8,DAY(AD8)>=15),"Fall",IF(MONTH(AD8)>8,"Fall",IF(MONTH(AD8)=5,"Summer",IF(MONTH(AD8)=1,"Spring",""))))) -> Summer | BK8: Burton, Kevin M. | BL8: =IFERROR(INDEX(_names_lookup!$C:$C,MATCH(BK8,_names_lookup!$A:$A,0)),"") -> burtonk@andrews.edu | BM8: =IFERROR(INDEX(_names_lookup!$B:$B,MATCH(BK8,_names_lookup!$A:$A,0)),"") -> 000148286 | BO8: 100 | BS8: =IFERROR(IF(BR8*AA8=0,"",BR8*AA8),"") | BV8: CHIS | CF8: 27-MAR-25 | CG8: A | CI8: I | CL8: MOODL | CQ8: 70 | CR8: 0 | CS8: 0 | CT8: Y | DC8: Y | DO8: IT | DP8: 202531
A9: FALSE | B9: FALSE | C9: FALSE | D9: FALSE | E9: FALSE | F9: FALSE | H9: 2612-02 | I9: 2612 | K9: CHIS | L9: 891 | M9: 103 | O9: =IFERROR(INDEX(_courses_lookup!$C:$C,MATCH(K9&L9,_courses_lookup!$E:$E,0)),"") -> Ind St: | P9: =IFERROR(INDEX(_courses_lookup!$D:$D,MATCH(K9&L9,_courses_lookup!$E:$E,0)),"") -> Ind St:Church History | S9: 0 | X9: 1 | Y9: 1-3 | AB9: 5 | AC9: CLAS | AD9: 12-MAY-25 | AG9: =IF(AND(AE9<>"",AF9<>""),ROUNDUP((AF9-AE9)/7,0),"") | AI9: =IFERROR(IF(AG9*AH9=0,"",AG9*AH9),"") | AJ9: 12-MAY-25 | AK9: 01-AUG-25 | AL9: =IF(AND(AJ9<>"",AK9<>""),ROUNDUP((AK9-AJ9)/7,0),"") -> 12 | AN9: =IFERROR(IF(AL9*AM9=0,"",AL9*AM9),"") | AQ9: =IF(AND(AO9<>"",AP9<>""),ROUNDUP((AP9-AO9)/7,0),"") | AR9: =IFERROR(IF((AU9-(AI9+AN9))/AQ9=0,"",ROUNDUP((AU9-(AI9+AN9))/AQ9,0)),"") | AS9: =IFERROR(IF((AU9-(AI9+AN9))=0,"",(AU9-(AI9+AN9))),"") | AT9: =IF(AND(AG9="",AQ9=""),AL9,IF(SUM(AG9,AL9,AQ9)=0,"",SUM(AG9,AL9,AQ9))) -> 12 | AV9: 01-AUG-25 | BF9: 12 | BG9: =IF(AD9="","",YEAR(AD9)+IF(MONTH(AD9)>=5,1,0)) -> 2026 | BH9: =IF(AD9="","",IF(AND(MONTH(AD9)=8,DAY(AD9)>=15),"Fall",IF(MONTH(AD9)>8,"Fall",IF(MONTH(AD9)=5,"Summer",IF(MONTH(AD9)=1,"Spring",""))))) -> Summer | BK9: Burton, Kevin M. | BL9: =IFERROR(INDEX(_names_lookup!$C:$C,MATCH(BK9,_names_lookup!$A:$A,0)),"") -> burtonk@andrews.edu | BM9: =IFERROR(INDEX(_names_lookup!$B:$B,MATCH(BK9,_names_lookup!$A:$A,0)),"") -> 000148286 | BO9: 100 | BS9: =IFERROR(IF(BR9*AA9=0,"",BR9*AA9),"") | BV9: CHIS | CF9: 27-MAR-25 | CG9: A | CI9: I | CL9: MOODL | CQ9: 70 | CR9: 0 | CS9: 0 | CT9: Y | DC9: Y | DO9: IT | DP9: 202531
A10: FALSE | B10: FALSE | C10: FALSE | D10: FALSE | E10: FALSE | F10: FALSE | H10: 2220-02 | I10: 2220 | K10: CHIS | L10: 685 | M10: 040 | O10: =IFERROR(INDEX(_courses_lookup!$C:$C,MATCH(K10&L10,_courses_lookup!$E:$E,0)),"") -> Studies in Church History | P10: =IFERROR(INDEX(_courses_lookup!$D:$D,MATCH(K10&L10,_courses_lookup!$E:$E,0)),"") -> 0 | R10: 321 | S10: 0 | V10: TOUR | X10: Q | Y10: 2,3 | Z10: 2 | AB10: 45 | AC10: POST | AD10: 07-JUL-25 | AG10: =IF(AND(AE10<>"",AF10<>""),ROUNDUP((AF10-AE10)/7,0),"") | AI10: =IFERROR(IF(AG10*AH10=0,"",AG10*AH10),"") | AJ10: 28-JUL-25 | AK10: 01-AUG-25 | AL10: =IF(AND(AJ10<>"",AK10<>""),ROUNDUP((AK10-AJ10)/7,0),"") -> 1 | AN10: =IFERROR(IF(AL10*AM10=0,"",AL10*AM10),"") | AQ10: =IF(AND(AO10<>"",AP10<>""),ROUNDUP((AP10-AO10)/7,0),"") | AR10: =IFERROR(IF((AU10-(AI10+AN10))/AQ10=0,"",ROUNDUP((AU10-(AI10+AN10))/AQ10,0)),"") | AS10: =IFERROR(IF((AU10-(AI10+AN10))=0,"",(AU10-(AI10+AN10))),"") | AT10: =IF(AND(AG10="",AQ10=""),AL10,IF(SUM(AG10,AL10,AQ10)=0,"",SUM(AG10,AL10,AQ10))) -> 1 | AV10: 01-AUG-25 | BF10: 4 | BG10: =IF(AD10="","",YEAR(AD10)+IF(MONTH(AD10)>=5,1,0)) -> 2026 | BH10: =IF(AD10="","",IF(AND(MONTH(AD10)=8,DAY(AD10)>=15),"Fall",IF(MONTH(AD10)>8,"Fall",IF(MONTH(AD10)=5,"Summer",IF(MONTH(AD10)=1,"Spring",""))))) | BK10: Burton, Kevin M. | BL10: =IFERROR(INDEX(_names_lookup!$C:$C,MATCH(BK10,_names_lookup!$A:$A,0)),"") -> burtonk@andrews.edu | BM10: =IFERROR(INDEX(_names_lookup!$B:$B,MATCH(BK10,_names_lookup!$A:$A,0)),"") -> 000148286 | BO10: 100 | BS10: =IFERROR(IF(BR10*AA10=0,"",BR10*AA10),"") | BV10: CHIS | CF10: 24-APR-25 | CG10: A | CH10: 2 | CI10: BL | CL10: MOODL | CQ10: 70 | CR10: 0 | CS10: 0 | CT10: Y | DC10: Y | DP10: 202531
A11: FALSE | B11: FALSE | C11: FALSE | D11: FALSE | E11: FALSE | F11: FALSE | H11: 2220-04 | I11: 2220 | K11: CHIS | L11: 685 | M11: 040 | O11: =IFERROR(INDEX(_courses_lookup!$C:$C,MATCH(K11&L11,_courses_lookup!$E:$E,0)),"") -> Studies in Church History | P11: =IFERROR(INDEX(_courses_lookup!$D:$D,MATCH(K11&L11,_courses_lookup!$E:$E,0)),"") -> 0 | R11: 321 | S11: 0 | V11: TOUR | X11: Q | Y11: 2,3 | Z11: 2 | AB11: 45 | AC11: PRE | AD11: 07-JUL-25 | AG11: =IF(AND(AE11<>"",AF11<>""),ROUNDUP((AF11-AE11)/7,0),"") | AI11: =IFERROR(IF(AG11*AH11=0,"",AG11*AH11),"") | AJ11: 07-JUL-25 | AK11: 19-JUL-25 | AL11: =IF(AND(AJ11<>"",AK11<>""),ROUNDUP((AK11-AJ11)/7,0),"") -> 2 | AN11: =IFERROR(IF(AL11*AM11=0,"",AL11*AM11),"") | AQ11: =IF(AND(AO11<>"",AP11<>""),ROUNDUP((AP11-AO11)/7,0),"") | AR11: =IFERROR(IF((AU11-(AI11+AN11))/AQ11=0,"",ROUNDUP((AU11-(AI11+AN11))/AQ11,0)),"") | AS11: =IFERROR(IF((AU11-(AI11+AN11))=0,"",(AU11-(AI11+AN11))),"") | AT11: =IF(AND(AG11="",AQ11=""),AL11,IF(SUM(AG11,AL11,AQ11)=0,"",SUM(AG11,AL11,AQ11))) -> 2 | AV11: 01-AUG-25 | BF11: 4 | BG11: =IF(AD11="","",YEAR(AD11)+IF(MONTH(AD11)>=5,1,0)) -> 2026 | BH11: =IF(AD11="","",IF(AND(MONTH(AD11)=8,DAY(AD11)>=15),"Fall",IF(MONTH(AD11)>8,"Fall",IF(MONTH(AD11)=5,"Summer",IF(MONTH(AD11)=1,"Spring",""))))) | BK11: Burton, Kevin M. | BL11: =IFERROR(INDEX(_names_lookup!$C:$C,MATCH(BK11,_names_lookup!$A:$A,0)),"") -> burtonk@andrews.edu | BM11: =IFERROR(INDEX(_names_lookup!$B:$B,MATCH(BK11,_names_lookup!$A:$A,0)),"") -> 000148286 | BO11: 100 | BS11: =IFERROR(IF(BR11*AA11=0,"",BR11*AA11),"") | BV11: CHIS | CF11: 24-APR-25 | CG11: A | CH11: 2 | CI11: BL | CL11: MOODL | CQ11: 70 | CR11: 0 | CS11: 0 | CT11: Y | DC11: Y | DP11: 202531
A12: FALSE | B12: FALSE | C12: FALSE | D12: FALSE | E12: FALSE | F12: FALSE | H12: 2220-06 | I12: 2220 | K12: CHIS | L12: 685 | M12: 040 | O12: =IFERROR(INDEX(_courses_lookup!$C:$C,MATCH(K12&L12,_courses_lookup!$E:$E,0)),"") -> Studies in Church History | P12: =IFERROR(INDEX(_courses_lookup!$D:$D,MATCH(K12&L12,_courses_lookup!$E:$E,0)),"") -> 0 | R12: 321 | S12: 0 | V12: TOUR | X12: Q | Y12: 2,3 | Z12: 2 | AB12: 45 | AC12: TOUR | AD12: 07-JUL-25 | AG12: =IF(AND(AE12<>"",AF12<>""),ROUNDUP((AF12-AE12)/7,0),"") | AI12: =IFERROR(IF(AG12*AH12=0,"",AG12*AH12),"") | AJ12: 20-JUL-25 | AK12: 27-JUL-25 | AL12: =IF(AND(AJ12<>"",AK12<>""),ROUNDUP((AK12-AJ12)/7,0),"") -> 1 | AN12: =IFERROR(IF(AL12*AM12=0,"",AL12*AM12),"") | AQ12: =IF(AND(AO12<>"",AP12<>""),ROUNDUP((AP12-AO12)/7,0),"") | AR12: =IFERROR(IF((AU12-(AI12+AN12))/AQ12=0,"",ROUNDUP((AU12-(AI12+AN12))/AQ12,0)),"") | AS12: =IFERROR(IF((AU12-(AI12+AN12))=0,"",(AU12-(AI12+AN12))),"") | AT12: =IF(AND(AG12="",AQ12=""),AL12,IF(SUM(AG12,AL12,AQ12)=0,"",SUM(AG12,AL12,AQ12))) -> 1 | AV12: 01-AUG-25 | BF12: 4 | BG12: =IF(AD12="","",YEAR(AD12)+IF(MONTH(AD12)>=5,1,0)) -> 2026 | BH12: =IF(AD12="","",IF(AND(MONTH(AD12)=8,DAY(AD12)>=15),"Fall",IF(MONTH(AD12)>8,"Fall",IF(MONTH(AD12)=5,"Summer",IF(MONTH(AD12)=1,"Spring",""))))) | BK12: Burton, Kevin M. | BL12: =IFERROR(INDEX(_names_lookup!$C:$C,MATCH(BK12,_names_lookup!$A:$A,0)),"") -> burtonk@andrews.edu | BM12: =IFERROR(INDEX(_names_lookup!$B:$B,MATCH(BK12,_names_lookup!$A:$A,0)),"") -> 000148286 | BO12: 100 | BS12: =IFERROR(IF(BR12*AA12=0,"",BR12*AA12),"") | BV12: CHIS | CF12: 24-APR-25 | CG12: A | CH12: 2 | CI12: BL | CL12: MOODL | CQ12: 70 | CR12: 0 | CS12: 0 | CT12: Y | DC12: Y | DP12: 202531
A13: FALSE | B13: FALSE | C13: FALSE | D13: FALSE | E13: FALSE | F13: FALSE | H13: 3262-02 | I13: 3262 | K13: CHIS | L13: 507 | M13: 041 | O13: =IFERROR(INDEX(_courses_lookup!$C:$C,MATCH(K13&L13,_courses_lookup!$E:$E,0)),"") -> Church History 1500 to Present | P13: =IFERROR(INDEX(_courses_lookup!$D:$D,MATCH(K13&L13,_courses_lookup!$E:$E,0)),"") -> 0 | S13: 0 | V13: TOUR | X13: W | Y13: 2,3 | Z13: 2 | AB13: 25 | AC13: CLAS | AD13: 09-JUN-25 | AG13: =IF(AND(AE13<>"",AF13<>""),ROUNDUP((AF13-AE13)/7,0),"") | AI13: =IFERROR(IF(AG13*AH13=0,"",AG13*AH13),"") | AJ13: 23-JUN-25 | AK13: 31-JUL-25 | AL13: =IF(AND(AJ13<>"",AK13<>""),ROUNDUP((AK13-AJ13)/7,0),"") -> 6 | AN13: =IFERROR(IF(AL13*AM13=0,"",AL13*AM13),"") | AQ13: =IF(AND(AO13<>"",AP13<>""),ROUNDUP((AP13-AO13)/7,0),"") | AR13: =IFERROR(IF((AU13-(AI13+AN13))/AQ13=0,"",ROUNDUP((AU13-(AI13+AN13))/AQ13,0)),"") | AS13: =IFERROR(IF((AU13-(AI13+AN13))=0,"",(AU13-(AI13+AN13))),"") | AT13: =IF(AND(AG13="",AQ13=""),AL13,IF(SUM(AG13,AL13,AQ13)=0,"",SUM(AG13,AL13,AQ13))) -> 6 | AV13: 01-AUG-25 | BF13: 8 | BG13: =IF(AD13="","",YEAR(AD13)+IF(MONTH(AD13)>=5,1,0)) -> 2026 | BH13: =IF(AD13="","",IF(AND(MONTH(AD13)=8,DAY(AD13)>=15),"Fall",IF(MONTH(AD13)>8,"Fall",IF(MONTH(AD13)=5,"Summer",IF(MONTH(AD13)=1,"Spring",""))))) | BK13: O'Reggio, Trevor E. | BL13: =IFERROR(INDEX(_names_lookup!$C:$C,MATCH(BK13,_names_lookup!$A:$A,0)),"") -> toreggio@andrews.edu | BM13: =IFERROR(INDEX(_names_lookup!$B:$B,MATCH(BK13,_names_lookup!$A:$A,0)),"") -> 000035762 | BO13: 100 | BS13: =IFERROR(IF(BR13*AA13=0,"",BR13*AA13),"") | BV13: CHIS | CF13: 28-APR-25 | CG13: A | CH13: 2 | CI13: BL | CL13: MOODL | CN13: TOUR | CQ13: 70 | CR13: 4 | CS13: 0 | CT13: Y | DC13: Y | DP13: 202531
A14: FALSE | B14: FALSE | C14: FALSE | D14: FALSE | E14: FALSE | F14: FALSE | H14: 3262-04 | I14: 3262 | K14: CHIS | L14: 507 | M14: 041 | O14: =IFERROR(INDEX(_courses_lookup!$C:$C,MATCH(K14&L14,_courses_lookup!$E:$E,0)),"") -> Church History 1500 to Present | P14: =IFERROR(INDEX(_courses_lookup!$D:$D,MATCH(K14&L14,_courses_lookup!$E:$E,0)),"") -> 0 | S14: 0 | V14: TOUR | X14: W | Y14: 2,3 | Z14: 2 | AB14: 25 | AC14: TOUR | AD14: 09-JUN-25 | AG14: =IF(AND(AE14<>"",AF14<>""),ROUNDUP((AF14-AE14)/7,0),"") | AI14: =IFERROR(IF(AG14*AH14=0,"",AG14*AH14),"") | AJ14: 09-JUN-25 | AK14: 22-JUN-25 | AL14: =IF(AND(AJ14<>"",AK14<>""),ROUNDUP((AK14-AJ14)/7,0),"") -> 2 | AN14: =IFERROR(IF(AL14*AM14=0,"",AL14*AM14),"") | AQ14: =IF(AND(AO14<>"",AP14<>""),ROUNDUP((AP14-AO14)/7,0),"") | AR14: =IFERROR(IF((AU14-(AI14+AN14))/AQ14=0,"",ROUNDUP((AU14-(AI14+AN14))/AQ14,0)),"") | AS14: =IFERROR(IF((AU14-(AI14+AN14))=0,"",(AU14-(AI14+AN14))),"") | AT14: =IF(AND(AG14="",AQ14=""),AL14,IF(SUM(AG14,AL14,AQ14)=0,"",SUM(AG14,AL14,AQ14))) -> 2 | AV14: 01-AUG-25 | BF14: 8 | BG14: =IF(AD14="","",YEAR(AD14)+IF(MONTH(AD14)>=5,1,0)) -> 2026 | BH14: =IF(AD14="","",IF(AND(MONTH(AD14)=8,DAY(AD14)>=15),"Fall",IF(MONTH(AD14)>8,"Fall",IF(MONTH(AD14)=5,"Summer",IF(MONTH(AD14)=1,"Spring",""))))) | BK14: O'Reggio, Trevor E. | BL14: =IFERROR(INDEX(_names_lookup!$C:$C,MATCH(BK14,_names_lookup!$A:$A,0)),"") -> toreggio@andrews.edu | BM14: =IFERROR(INDEX(_names_lookup!$B:$B,MATCH(BK14,_names_lookup!$A:$A,0)),"") -> 000035762 | BO14: 100 | BS14: =IFERROR(IF(BR14*AA14=0,"",BR14*AA14),"") | BV14: CHIS | CF14: 28-APR-25 | CG14: A | CH14: 2 | CI14: BL | CL14: MOODL | CN14: TOUR | CQ14: 70 | CR14: 4 | CS14: 0 | CT14: Y | DC14: Y | DP14: 202531
A15: FALSE | B15: FALSE | C15: FALSE | D15: FALSE | E15: FALSE | F15: FALSE | H15: 3279-02 | I15: 3279 | K15: CHIS | L15: 880 | M15: 042 | O15: =IFERROR(INDEX(_courses_lookup!$C:$C,MATCH(K15&L15,_courses_lookup!$E:$E,0)),"") -> Topics in Church History: | P15: =IFERROR(INDEX(_courses_lookup!$D:$D,MATCH(K15&L15,_courses_lookup!$E:$E,0)),"") -> Top in Chrch Hist:Early Church | R15: 316 | S15: 0 | X15: W | Y15: 1-3 | Z15: 3 | AB15: 25 | AC15: POST | AD15: 09-JUN-25 | AG15: =IF(AND(AE15<>"",AF15<>""),ROUNDUP((AF15-AE15)/7,0),"") | AI15: =IFERROR(IF(AG15*AH15=0,"",AG15*AH15),"") | AJ15: 23-JUN-25 | AK15: 31-JUL-25 | AL15: =IF(AND(AJ15<>"",AK15<>""),ROUNDUP((AK15-AJ15)/7,0),"") -> 6 | AN15: =IFERROR(IF(AL15*AM15=0,"",AL15*AM15),"") | AQ15: =IF(AND(AO15<>"",AP15<>""),ROUNDUP((AP15-AO15)/7,0),"") | AR15: =IFERROR(IF((AU15-(AI15+AN15))/AQ15=0,"",ROUNDUP((AU15-(AI15+AN15))/AQ15,0)),"") | AS15: =IFERROR(IF((AU15-(AI15+AN15))=0,"",(AU15-(AI15+AN15))),"") | AT15: =IF(AND(AG15="",AQ15=""),AL15,IF(SUM(AG15,AL15,AQ15)=0,"",SUM(AG15,AL15,AQ15))) -> 6 | AV15: 01-AUG-25 | BF15: 8 | BG15: =IF(AD15="","",YEAR(AD15)+IF(MONTH(AD15)>=5,1,0)) -> 2026 | BH15: =IF(AD15="","",IF(AND(MONTH(AD15)=8,DAY(AD15)>=15),"Fall",IF(MONTH(AD15)>8,"Fall",IF(MONTH(AD15)=5,"Summer",IF(MONTH(AD15)=1,"Spring",""))))) | BK15: O'Reggio, Trevor E. | BL15: =IFERROR(INDEX(_names_lookup!$C:$C,MATCH(BK15,_names_lookup!$A:$A,0)),"") -> toreggio@andrews.edu | BM15: =IFERROR(INDEX(_names_lookup!$B:$B,MATCH(BK15,_names_lookup!$A:$A,0)),"") -> 000035762 | BO15: 100 | BS15: =IFERROR(IF(BR15*AA15=0,"",BR15*AA15),"") | BV15: CHIS | CF15: 30-APR-25 | CG15: A | CH15: 3 | CI15: BL | CL15: MOODL | CQ15: 70 | CR15: 1 | CS15: 0 | CT15: Y | DC15: Y | DP15: 202531
A16: FALSE | B16: FALSE | C16: FALSE | D16: FALSE | E16: FALSE | F16: FALSE | H16: 3279-04 | I16: 3279 | K16: CHIS | L16: 880 | M16: 042 | O16: =IFERROR(INDEX(_courses_lookup!$C:$C,MATCH(K16&L16,_courses_lookup!$E:$E,0)),"") -> Topics in Church History: | P16: =IFERROR(INDEX(_courses_lookup!$D:$D,MATCH(K16&L16,_courses_lookup!$E:$E,0)),"") -> Top in Chrch Hist:Early Church | R16: 316 | S16: 0 | X16: W | Y16: 1-3 | Z16: 3 | AB16: 25 | AC16: TOUR | AD16: 09-JUN-25 | AG16: =IF(AND(AE16<>"",AF16<>""),ROUNDUP((AF16-AE16)/7,0),"") | AI16: =IFERROR(IF(AG16*AH16=0,"",AG16*AH16),"") | AJ16: 09-JUN-25 | AK16: 22-JUN-25 | AL16: =IF(AND(AJ16<>"",AK16<>""),ROUNDUP((AK16-AJ16)/7,0),"") -> 2 | AN16: =IFERROR(IF(AL16*AM16=0,"",AL16*AM16),"") | AQ16: =IF(AND(AO16<>"",AP16<>""),ROUNDUP((AP16-AO16)/7,0),"") | AR16: =IFERROR(IF((AU16-(AI16+AN16))/AQ16=0,"",ROUNDUP((AU16-(AI16+AN16))/AQ16,0)),"") | AS16: =IFERROR(IF((AU16-(AI16+AN16))=0,"",(AU16-(AI16+AN16))),"") | AT16: =IF(AND(AG16="",AQ16=""),AL16,IF(SUM(AG16,AL16,AQ16)=0,"",SUM(AG16,AL16,AQ16))) -> 2 | AV16: 01-AUG-25 | BF16: 8 | BG16: =IF(AD16="","",YEAR(AD16)+IF(MONTH(AD16)>=5,1,0)) -> 2026 | BH16: =IF(AD16="","",IF(AND(MONTH(AD16)=8,DAY(AD16)>=15),"Fall",IF(MONTH(AD16)>8,"Fall",IF(MONTH(AD16)=5,"Summer",IF(MONTH(AD16)=1,"Spring",""))))) | BK16: O'Reggio, Trevor E. | BL16: =IFERROR(INDEX(_names_lookup!$C:$C,MATCH(BK16,_names_lookup!$A:$A,0)),"") -> toreggio@andrews.edu | BM16: =IFERROR(INDEX(_names_lookup!$B:$B,MATCH(BK16,_names_lookup!$A:$A,0)),"") -> 000035762 | BO16: 100 | BS16: =IFERROR(IF(BR16*AA16=0,"",BR16*AA16),"") | BV16: CHIS | CF16: 30-APR-25 | CG16: A | CH16: 3 | CI16: BL | CL16: MOODL | CQ16: 70 | CR16: 1 | CS16: 0 | CT16: Y | DC16: Y | DP16: 202531
A17: FALSE | B17: FALSE | C17: FALSE | D17: FALSE | E17: FALSE | F17: FALSE | H17: 3294-02 | I17: 3294 | K17: CHIS | L17: 880 | M17: 041 | O17: =IFERROR(INDEX(_courses_lookup!$C:$C,MATCH(K17&L17,_courses_lookup!$E:$E,0)),"") -> Topics in Church History: | P17: =IFERROR(INDEX(_courses_lookup!$D:$D,MATCH(K17&L17,_courses_lookup!$E:$E,0)),"") -> Top in Chrch Hist:Early Church | R17: 327 | S17: 0 | V17: TOUR | X17: W | Y17: 1-3 | Z17: 3 | AB17: 25 | AC17: POST | AD17: 09-JUN-25 | AG17: =IF(AND(AE17<>"",AF17<>""),ROUNDUP((AF17-AE17)/7,0),"") | AI17: =IFERROR(IF(AG17*AH17=0,"",AG17*AH17),"") | AJ17: 23-JUN-25 | AK17: 01-AUG-25 | AL17: =IF(AND(AJ17<>"",AK17<>""),ROUNDUP((AK17-AJ17)/7,0),"") -> 6 | AN17: =IFERROR(IF(AL17*AM17=0,"",AL17*AM17),"") | AQ17: =IF(AND(AO17<>"",AP17<>""),ROUNDUP((AP17-AO17)/7,0),"") | AR17: =IFERROR(IF((AU17-(AI17+AN17))/AQ17=0,"",ROUNDUP((AU17-(AI17+AN17))/AQ17,0)),"") | AS17: =IFERROR(IF((AU17-(AI17+AN17))=0,"",(AU17-(AI17+AN17))),"") | AT17: =IF(AND(AG17="",AQ17=""),AL17,IF(SUM(AG17,AL17,AQ17)=0,"",SUM(AG17,AL17,AQ17))) -> 6 | AV17: 01-AUG-25 | BF17: 8 | BG17: =IF(AD17="","",YEAR(AD17)+IF(MONTH(AD17)>=5,1,0)) -> 2026 | BH17: =IF(AD17="","",IF(AND(MONTH(AD17)=8,DAY(AD17)>=15),"Fall",IF(MONTH(AD17)>8,"Fall",IF(MONTH(AD17)=5,"Summer",IF(MONTH(AD17)=1,"Spring",""))))) | BK17: Hernandez, Abner F. | BL17: =IFERROR(INDEX(_names_lookup!$C:$C,MATCH(BK17,_names_lookup!$A:$A,0)),"") -> abnerh@andrews.edu | BM17: =IFERROR(INDEX(_names_lookup!$B:$B,MATCH(BK17,_names_lookup!$A:$A,0)),"") -> 000149024 | BO17: 100 | BS17: =IFERROR(IF(BR17*AA17=0,"",BR17*AA17),"") | BV17: CHIS | CF17: 01-MAY-25 | CG17: A | CH17: 3 | CI17: BL | CL17: MOODL | CQ17: 70 | CR17: 1 | CS17: 0 | CT17: Y | DC17: Y | DP17: 202531
A18: FALSE | B18: FALSE | C18: FALSE | D18: FALSE | E18: FALSE | F18: FALSE | H18: 3294-04 | I18: 3294 | K18: CHIS | L18: 880 | M18: 041 | O18: =IFERROR(INDEX(_courses_lookup!$C:$C,MATCH(K18&L18,_courses_lookup!$E:$E,0)),"") -> Topics in Church History: | P18: =IFERROR(INDEX(_courses_lookup!$D:$D,MATCH(K18&L18,_courses_lookup!$E:$E,0)),"") -> Top in Chrch Hist:Early Church | R18: 327 | S18: 0 | V18: TOUR | X18: W | Y18: 1-3 | Z18: 3 | AB18: 25 | AC18: TOUR | AD18: 09-JUN-25 | AG18: =IF(AND(AE18<>"",AF18<>""),ROUNDUP((AF18-AE18)/7,0),"") | AI18: =IFERROR(IF(AG18*AH18=0,"",AG18*AH18),"") | AJ18: 09-JUN-25 | AK18: 22-JUN-25 | AL18: =IF(AND(AJ18<>"",AK18<>""),ROUNDUP((AK18-AJ18)/7,0),"") -> 2 | AN18: =IFERROR(IF(AL18*AM18=0,"",AL18*AM18),"") | AQ18: =IF(AND(AO18<>"",AP18<>""),ROUNDUP((AP18-AO18)/7,0),"") | AR18: =IFERROR(IF((AU18-(AI18+AN18))/AQ18=0,"",ROUNDUP((AU18-(AI18+AN18))/AQ18,0)),"") | AS18: =IFERROR(IF((AU18-(AI18+AN18))=0,"",(AU18-(AI18+AN18))),"") | AT18: =IF(AND(AG18="",AQ18=""),AL18,IF(SUM(AG18,AL18,AQ18)=0,"",SUM(AG18,AL18,AQ18))) -> 2 | AV18: 01-AUG-25 | BF18: 8 | BG18: =IF(AD18="","",YEAR(AD18)+IF(MONTH(AD18)>=5,1,0)) -> 2026 | BH18: =IF(AD18="","",IF(AND(MONTH(AD18)=8,DAY(AD18)>=15),"Fall",IF(MONTH(AD18)>8,"Fall",IF(MONTH(AD18)=5,"Summer",IF(MONTH(AD18)=1,"Spring",""))))) | BK18: Hernandez, Abner F. | BL18: =IFERROR(INDEX(_names_lookup!$C:$C,MATCH(BK18,_names_lookup!$A:$A,0)),"") -> abnerh@andrews.edu | BM18: =IFERROR(INDEX(_names_lookup!$B:$B,MATCH(BK18,_names_lookup!$A:$A,0)),"") -> 000149024 | BO18: 100 | BS18: =IFERROR(IF(BR18*AA18=0,"",BR18*AA18),"") | BV18: CHIS | CF18: 01-MAY-25 | CG18: A | CH18: 3 | CI18: BL | CL18: MOODL | CQ18: 70 | CR18: 1 | CS18: 0 | CT18: Y | DC18: Y | DP18: 202531
A19: FALSE | B19: FALSE | C19: FALSE | D19: FALSE | E19: FALSE | F19: FALSE | H19: 3421-02 | I19: 3421 | K19: CHIS | L19: 890 | M19: 003 | O19: =IFERROR(INDEX(_courses_lookup!$C:$C,MATCH(K19&L19,_courses_lookup!$E:$E,0)),"") -> Directed Rdg in Church History | P19: =IFERROR(INDEX(_courses_lookup!$D:$D,MATCH(K19&L19,_courses_lookup!$E:$E,0)),"") -> 0 | S19: 0 | X19: 1 | Y19: 1-6 | AB19: 999 | AC19: CLAS | AD19: 12-MAY-25 | AG19: =IF(AND(AE19<>"",AF19<>""),ROUNDUP((AF19-AE19)/7,0),"") | AI19: =IFERROR(IF(AG19*AH19=0,"",AG19*AH19),"") | AJ19: 12-MAY-25 | AK19: 01-AUG-25 | AL19: =IF(AND(AJ19<>"",AK19<>""),ROUNDUP((AK19-AJ19)/7,0),"") -> 12 | AN19: =IFERROR(IF(AL19*AM19=0,"",AL19*AM19),"") | AQ19: =IF(AND(AO19<>"",AP19<>""),ROUNDUP((AP19-AO19)/7,0),"") | AR19: =IFERROR(IF((AU19-(AI19+AN19))/AQ19=0,"",ROUNDUP((AU19-(AI19+AN19))/AQ19,0)),"") | AS19: =IFERROR(IF((AU19-(AI19+AN19))=0,"",(AU19-(AI19+AN19))),"") | AT19: =IF(AND(AG19="",AQ19=""),AL19,IF(SUM(AG19,AL19,AQ19)=0,"",SUM(AG19,AL19,AQ19))) -> 12 | AV19: 01-AUG-25 | BF19: 12 | BG19: =IF(AD19="","",YEAR(AD19)+IF(MONTH(AD19)>=5,1,0)) -> 2026 | BH19: =IF(AD19="","",IF(AND(MONTH(AD19)=8,DAY(AD19)>=15),"Fall",IF(MONTH(AD19)>8,"Fall",IF(MONTH(AD19)=5,"Summer",IF(MONTH(AD19)=1,"Spring",""))))) -> Summer | BK19: Burton, Kevin M. | BL19: =IFERROR(INDEX(_names_lookup!$C:$C,MATCH(BK19,_names_lookup!$A:$A,0)),"") -> burtonk@andrews.edu | BM19: =IFERROR(INDEX(_names_lookup!$B:$B,MATCH(BK19,_names_lookup!$A:$A,0)),"") -> 000148286 | BO19: 100 | BS19: =IFERROR(IF(BR19*AA19=0,"",BR19*AA19),"") | BV19: CHIS | CF19: 01-MAY-25 | CG19: A | CI19: I | CL19: MOODL | CQ19: 70 | CR19: 1 | CS19: 0 | CT19: Y | DC19: Y | DP19: 202531
A20: FALSE | B20: FALSE | C20: FALSE | D20: FALSE | E20: FALSE | F20: FALSE | H20: 3271-02 | I20: 3271 | K20: CHIS | L20: 640 | M20: 044 | O20: =IFERROR(INDEX(_courses_lookup!$C:$C,MATCH(K20&L20,_courses_lookup!$E:$E,0)),"") -> Reformation: | P20: =IFERROR(INDEX(_courses_lookup!$D:$D,MATCH(K20&L20,_courses_lookup!$E:$E,0)),"") -> 0 | R20: 327 | S20: 0 | X20: W | Y20: 2,3 | Z20: 3 | AB20: 25 | AC20: POST | AD20: 09-JUN-25 | AG20: =IF(AND(AE20<>"",AF20<>""),ROUNDUP((AF20-AE20)/7,0),"") | AI20: =IFERROR(IF(AG20*AH20=0,"",AG20*AH20),"") | AJ20: 23-JUN-25 | AK20: 01-AUG-25 | AL20: =IF(AND(AJ20<>"",AK20<>""),ROUNDUP((AK20-AJ20)/7,0),"") -> 6 | AN20: =IFERROR(IF(AL20*AM20=0,"",AL20*AM20),"") | AQ20: =IF(AND(AO20<>"",AP20<>""),ROUNDUP((AP20-AO20)/7,0),"") | AR20: =IFERROR(IF((AU20-(AI20+AN20))/AQ20=0,"",ROUNDUP((AU20-(AI20+AN20))/AQ20,0)),"") | AS20: =IFERROR(IF((AU20-(AI20+AN20))=0,"",(AU20-(AI20+AN20))),"") | AT20: =IF(AND(AG20="",AQ20=""),AL20,IF(SUM(AG20,AL20,AQ20)=0,"",SUM(AG20,AL20,AQ20))) -> 6 | AV20: 01-AUG-25 | BF20: 8 | BG20: =IF(AD20="","",YEAR(AD20)+IF(MONTH(AD20)>=5,1,0)) -> 2026 | BH20: =IF(AD20="","",IF(AND(MONTH(AD20)=8,DAY(AD20)>=15),"Fall",IF(MONTH(AD20)>8,"Fall",IF(MONTH(AD20)=5,"Summer",IF(MONTH(AD20)=1,"Spring",""))))) | BK20: Hernandez, Abner F. | BL20: =IFERROR(INDEX(_names_lookup!$C:$C,MATCH(BK20,_names_lookup!$A:$A,0)),"") -> abnerh@andrews.edu | BM20: =IFERROR(INDEX(_names_lookup!$B:$B,MATCH(BK20,_names_lookup!$A:$A,0)),"") -> 000149024 | BO20: 100 | BS20: =IFERROR(IF(BR20*AA20=0,"",BR20*AA20),"") | BV20: CHIS | CF20: 09-MAY-25 | CG20: A | CH20: 3 | CI20: BL | CL20: MOODL | CN20: CH1,REFM | CQ20: 70 | CR20: 1 | CS20: 0 | CT20: Y | DC20: Y | DP20: 202531
A21: FALSE | B21: FALSE | C21: FALSE | D21: FALSE | E21: FALSE | F21: FALSE | H21: 3271-04 | I21: 3271 | K21: CHIS | L21: 640 | M21: 044 | O21: =IFERROR(INDEX(_courses_lookup!$C:$C,MATCH(K21&L21,_courses_lookup!$E:$E,0)),"") -> Reformation: | P21: =IFERROR(INDEX(_courses_lookup!$D:$D,MATCH(K21&L21,_courses_lookup!$E:$E,0)),"") -> 0 | R21: 327 | S21: 0 | X21: W | Y21: 2,3 | Z21: 3 | AB21: 25 | AC21: TOUR | AD21: 09-JUN-25 | AG21: =IF(AND(AE21<>"",AF21<>""),ROUNDUP((AF21-AE21)/7,0),"") | AI21: =IFERROR(IF(AG21*AH21=0,"",AG21*AH21),"") | AJ21: 09-JUN-25 | AK21: 22-JUN-25 | AL21: =IF(AND(AJ21<>"",AK21<>""),ROUNDUP((AK21-AJ21)/7,0),"") -> 2 | AN21: =IFERROR(IF(AL21*AM21=0,"",AL21*AM21),"") | AQ21: =IF(AND(AO21<>"",AP21<>""),ROUNDUP((AP21-AO21)/7,0),"") | AR21: =IFERROR(IF((AU21-(AI21+AN21))/AQ21=0,"",ROUNDUP((AU21-(AI21+AN21))/AQ21,0)),"") | AS21: =IFERROR(IF((AU21-(AI21+AN21))=0,"",(AU21-(AI21+AN21))),"") | AT21: =IF(AND(AG21="",AQ21=""),AL21,IF(SUM(AG21,AL21,AQ21)=0,"",SUM(AG21,AL21,AQ21))) -> 2 | AV21: 01-AUG-25 | BF21: 8 | BG21: =IF(AD21="","",YEAR(AD21)+IF(MONTH(AD21)>=5,1,0)) -> 2026 | BH21: =IF(AD21="","",IF(AND(MONTH(AD21)=8,DAY(AD21)>=15),"Fall",IF(MONTH(AD21)>8,"Fall",IF(MONTH(AD21)=5,"Summer",IF(MONTH(AD21)=1,"Spring",""))))) | BK21: Hernandez, Abner F. | BL21: =IFERROR(INDEX(_names_lookup!$C:$C,MATCH(BK21,_names_lookup!$A:$A,0)),"") -> abnerh@andrews.edu | BM21: =IFERROR(INDEX(_names_lookup!$B:$B,MATCH(BK21,_names_lookup!$A:$A,0)),"") -> 000149024 | BO21: 100 | BS21: =IFERROR(IF(BR21*AA21=0,"",BR21*AA21),"") | BV21: CHIS | CF21: 09-MAY-25 | CG21: A | CH21: 3 | CI21: BL | CL21: MOODL | CN21: CH1,REFM | CQ21: 70 | CR21: 1 | CS21: 0 | CT21: Y | DC21: Y | DP21: 202531
H22: 3278-02 | I22: 3278 | K22: CHIS | L22: 685 | M22: 041 | O22: =IFERROR(INDEX(_courses_lookup!$C:$C,MATCH(K22&L22,_courses_lookup!$E:$E,0)),"") -> Studies in Church History | P22: =IFERROR(INDEX(_courses_lookup!$D:$D,MATCH(K22&L22,_courses_lookup!$E:$E,0)),"") -> 0 | R22: 321 | S22: 0 | X22: Q | Y22: 2,3 | Z22: 3 | AB22: 45 | AC22: POST | AD22: 07-JUL-25 | AG22: =IF(AND(AE22<>"",AF22<>""),ROUNDUP((AF22-AE22)/7,0),"") | AI22: =IFERROR(IF(AG22*AH22=0,"",AG22*AH22),"") | AJ22: 28-JUL-25 | AK22: 01-AUG-25 | AL22: =IF(AND(AJ22<>"",AK22<>""),ROUNDUP((AK22-AJ22)/7,0),"") -> 1 | AN22: =IFERROR(IF(AL22*AM22=0,"",AL22*AM22),"") | AQ22: =IF(AND(AO22<>"",AP22<>""),ROUNDUP((AP22-AO22)/7,0),"") | AR22: =IFERROR(IF((AU22-(AI22+AN22))/AQ22=0,"",ROUNDUP((AU22-(AI22+AN22))/AQ22,0)),"") | AS22: =IFERROR(IF((AU22-(AI22+AN22))=0,"",(AU22-(AI22+AN22))),"") | AT22: =IF(AND(AG22="",AQ22=""),AL22,IF(SUM(AG22,AL22,AQ22)=0,"",SUM(AG22,AL22,AQ22))) -> 1 | AV22: 01-AUG-25 | BF22: 4 | BG22: =IF(AD22="","",YEAR(AD22)+IF(MONTH(AD22)>=5,1,0)) -> 2026 | BH22: =IF(AD22="","",IF(AND(MONTH(AD22)=8,DAY(AD22)>=15),"Fall",IF(MONTH(AD22)>8,"Fall",IF(MONTH(AD22)=5,"Summer",IF(MONTH(AD22)=1,"Spring",""))))) | BK22: Burton, Kevin M. | BL22: =IFERROR(INDEX(_names_lookup!$C:$C,MATCH(BK22,_names_lookup!$A:$A,0)),"") -> burtonk@andrews.edu | BM22: =IFERROR(INDEX(_names_lookup!$B:$B,MATCH(BK22,_names_lookup!$A:$A,0)),"") -> 000148286 | BO22: 100 | BS22: =IFERROR(IF(BR22*AA22=0,"",BR22*AA22),"") | BV22: CHIS | CF22: 11-MAY-25 | CG22: A | CH22: 3 | CI22: BL | CL22: MOODL | CQ22: 70 | CR22: 0 | CS22: 0 | CT22: Y | DC22: Y | DP22: 202531
H23: 3278-04 | I23: 3278 | K23: CHIS | L23: 685 | M23: 041 | O23: =IFERROR(INDEX(_courses_lookup!$C:$C,MATCH(K23&L23,_courses_lookup!$E:$E,0)),"") -> Studies in Church History | P23: =IFERROR(INDEX(_courses_lookup!$D:$D,MATCH(K23&L23,_courses_lookup!$E:$E,0)),"") -> 0 | R23: 321 | S23: 0 | X23: Q | Y23: 2,3 | Z23: 3 | AB23: 45 | AC23: PRE | AD23: 07-JUL-25 | AG23: =IF(AND(AE23<>"",AF23<>""),ROUNDUP((AF23-AE23)/7,0),"") | AI23: =IFERROR(IF(AG23*AH23=0,"",AG23*AH23),"") | AJ23: 07-JUL-25 | AK23: 19-JUL-25 | AL23: =IF(AND(AJ23<>"",AK23<>""),ROUNDUP((AK23-AJ23)/7,0),"") -> 2 | AN23: =IFERROR(IF(AL23*AM23=0,"",AL23*AM23),"") | AQ23: =IF(AND(AO23<>"",AP23<>""),ROUNDUP((AP23-AO23)/7,0),"") | AR23: =IFERROR(IF((AU23-(AI23+AN23))/AQ23=0,"",ROUNDUP((AU23-(AI23+AN23))/AQ23,0)),"") | AS23: =IFERROR(IF((AU23-(AI23+AN23))=0,"",(AU23-(AI23+AN23))),"") | AT23: =IF(AND(AG23="",AQ23=""),AL23,IF(SUM(AG23,AL23,AQ23)=0,"",SUM(AG23,AL23,AQ23))) -> 2 | AV23: 01-AUG-25 | BF23: 4 | BG23: =IF(AD23="","",YEAR(AD23)+IF(MONTH(AD23)>=5,1,0)) -> 2026 | BH23: =IF(AD23="","",IF(AND(MONTH(AD23)=8,DAY(AD23)>=15),"Fall",IF(MONTH(AD23)>8,"Fall",IF(MONTH(AD23)=5,"Summer",IF(MONTH(AD23)=1,"Spring",""))))) | BK23: Burton, Kevin M. | BL23: =IFERROR(INDEX(_names_lookup!$C:$C,MATCH(BK23,_names_lookup!$A:$A,0)),"") -> burtonk@andrews.edu | BM23: =IFERROR(INDEX(_names_lookup!$B:$B,MATCH(BK23,_names_lookup!$A:$A,0)),"") -> 000148286 | BO23: 100 | BS23: =IFERROR(IF(BR23*AA23=0,"",BR23*AA23),"") | BV23: CHIS | CF23: 11-MAY-25 | CG23: A | CH23: 3 | CI23: BL | CL23: MOODL | CQ23: 70 | CR23: 0 | CS23: 0 | CT23: Y | DC23: Y | DP23: 202531
H24: 3278-06 | I24: 3278 | K24: CHIS | L24: 685 | M24: 041 | O24: =IFERROR(INDEX(_courses_lookup!$C:$C,MATCH(K24&L24,_courses_lookup!$E:$E,0)),"") -> Studies in Church History | P24: =IFERROR(INDEX(_courses_lookup!$D:$D,MATCH(K24&L24,_courses_lookup!$E:$E,0)),"") -> 0 | R24: 321 | S24: 0 | X24: Q | Y24: 2,3 | Z24: 3 | AB24: 45 | AC24: TOUR | AD24: 07-JUL-25 | AG24: =IF(AND(AE24<>"",AF24<>""),ROUNDUP((AF24-AE24)/7,0),"") | AI24: =IFERROR(IF(AG24*AH24=0,"",AG24*AH24),"") | AJ24: 20-JUL-25 | AK24: 27-JUL-25 | AL24: =IF(AND(AJ24<>"",AK24<>""),ROUNDUP((AK24-AJ24)/7,0),"") -> 1 | AN24: =IFERROR(IF(AL24*AM24=0,"",AL24*AM24),"") | AQ24: =IF(AND(AO24<>"",AP24<>""),ROUNDUP((AP24-AO24)/7,0),"") | AR24: =IFERROR(IF((AU24-(AI24+AN24))/AQ24=0,"",ROUNDUP((AU24-(AI24+AN24))/AQ24,0)),"") | AS24: =IFERROR(IF((AU24-(AI24+AN24))=0,"",(AU24-(AI24+AN24))),"") | AT24: =IF(AND(AG24="",AQ24=""),AL24,IF(SUM(AG24,AL24,AQ24)=0,"",SUM(AG24,AL24,AQ24))) -> 1 | AV24: 01-AUG-25 | BF24: 4 | BG24: =IF(AD24="","",YEAR(AD24)+IF(MONTH(AD24)>=5,1,0)) -> 2026 | BH24: =IF(AD24="","",IF(AND(MONTH(AD24)=8,DAY(AD24)>=15),"Fall",IF(MONTH(AD24)>8,"Fall",IF(MONTH(AD24)=5,"Summer",IF(MONTH(AD24)=1,"Spring",""))))) | BK24: Burton, Kevin M. | BL24: =IFERROR(INDEX(_names_lookup!$C:$C,MATCH(BK24,_names_lookup!$A:$A,0)),"") -> burtonk@andrews.edu | BM24: =IFERROR(INDEX(_names_lookup!$B:$B,MATCH(BK24,_names_lookup!$A:$A,0)),"") -> 000148286 | BO24: 100 | BS24: =IFERROR(IF(BR24*AA24=0,"",BR24*AA24),"") | BV24: CHIS | CF24: 11-MAY-25 | CG24: A | CH24: 3 | CI24: BL | CL24: MOODL | CQ24: 70 | CR24: 0 | CS24: 0 | CT24: Y | DC24: Y | DP24: 202531
H25: 2022-02 | I25: 2022 | K25: CHIS | L25: 690 | M25: 102 | O25: =IFERROR(INDEX(_courses_lookup!$C:$C,MATCH(K25&L25,_courses_lookup!$E:$E,0)),"") -> Ind St: | P25: =IFERROR(INDEX(_courses_lookup!$D:$D,MATCH(K25&L25,_courses_lookup!$E:$E,0)),"") -> 0 | S25: 0 | T25: 7 | X25: 1 | Y25: 1-3 | AB25: 999 | AC25: CLAS | AD25: 12-MAY-25 | AG25: =IF(AND(AE25<>"",AF25<>""),ROUNDUP((AF25-AE25)/7,0),"") | AI25: =IFERROR(IF(AG25*AH25=0,"",AG25*AH25),"") | AJ25: 12-MAY-25 | AK25: 01-AUG-25 | AL25: =IF(AND(AJ25<>"",AK25<>""),ROUNDUP((AK25-AJ25)/7,0),"") -> 12 | AN25: =IFERROR(IF(AL25*AM25=0,"",AL25*AM25),"") | AQ25: =IF(AND(AO25<>"",AP25<>""),ROUNDUP((AP25-AO25)/7,0),"") | AR25: =IFERROR(IF((AU25-(AI25+AN25))/AQ25=0,"",ROUNDUP((AU25-(AI25+AN25))/AQ25,0)),"") | AS25: =IFERROR(IF((AU25-(AI25+AN25))=0,"",(AU25-(AI25+AN25))),"") | AT25: =IF(AND(AG25="",AQ25=""),AL25,IF(SUM(AG25,AL25,AQ25)=0,"",SUM(AG25,AL25,AQ25))) -> 12 | AV25: 01-AUG-25 | BF25: 12 | BG25: =IF(AD25="","",YEAR(AD25)+IF(MONTH(AD25)>=5,1,0)) -> 2026 | BH25: =IF(AD25="","",IF(AND(MONTH(AD25)=8,DAY(AD25)>=15),"Fall",IF(MONTH(AD25)>8,"Fall",IF(MONTH(AD25)=5,"Summer",IF(MONTH(AD25)=1,"Spring",""))))) -> Summer | BK25: Hernandez, Abner F. | BL25: =IFERROR(INDEX(_names_lookup!$C:$C,MATCH(BK25,_names_lookup!$A:$A,0)),"") -> abnerh@andrews.edu | BM25: =IFERROR(INDEX(_names_lookup!$B:$B,MATCH(BK25,_names_lookup!$A:$A,0)),"") -> 000149024 | BO25: 100 | BS25: =IFERROR(IF(BR25*AA25=0,"",BR25*AA25),"") | BV25: CHIS | CF25: 12-MAY-25 | CG25: A | CI25: I | CL25: MOODL | CQ25: 70 | CR25: 0 | CS25: 0 | CT25: Y | DC25: Y | DO25: IT | DP25: 202531
H26: 3404-02 | I26: 3404 | K26: CHIS | L26: 690 | M26: 103 | O26: =IFERROR(INDEX(_courses_lookup!$C:$C,MATCH(K26&L26,_courses_lookup!$E:$E,0)),"") -> Ind St: | P26: =IFERROR(INDEX(_courses_lookup!$D:$D,MATCH(K26&L26,_courses_lookup!$E:$E,0)),"") -> 0 | S26: 0 | X26: 1 | Y26: 1-3 | Z26: 1 | AB26: 25 | AC26: CLAS | AD26: 12-MAY-25 | AG26: =IF(AND(AE26<>"",AF26<>""),ROUNDUP((AF26-AE26)/7,0),"") | AI26: =IFERROR(IF(AG26*AH26=0,"",AG26*AH26),"") | AJ26: 12-MAY-25 | AK26: 01-AUG-25 | AL26: =IF(AND(AJ26<>"",AK26<>""),ROUNDUP((AK26-AJ26)/7,0),"") -> 12 | AN26: =IFERROR(IF(AL26*AM26=0,"",AL26*AM26),"") | AQ26: =IF(AND(AO26<>"",AP26<>""),ROUNDUP((AP26-AO26)/7,0),"") | AR26: =IFERROR(IF((AU26-(AI26+AN26))/AQ26=0,"",ROUNDUP((AU26-(AI26+AN26))/AQ26,0)),"") | AS26: =IFERROR(IF((AU26-(AI26+AN26))=0,"",(AU26-(AI26+AN26))),"") | AT26: =IF(AND(AG26="",AQ26=""),AL26,IF(SUM(AG26,AL26,AQ26)=0,"",SUM(AG26,AL26,AQ26))) -> 12 | AV26: 01-AUG-25 | BF26: 12 | BG26: =IF(AD26="","",YEAR(AD26)+IF(MONTH(AD26)>=5,1,0)) -> 2026 | BH26: =IF(AD26="","",IF(AND(MONTH(AD26)=8,DAY(AD26)>=15),"Fall",IF(MONTH(AD26)>8,"Fall",IF(MONTH(AD26)=5,"Summer",IF(MONTH(AD26)=1,"Spring",""))))) -> Summer | BK26: Kaiser, Denis | BL26: =IFERROR(INDEX(_names_lookup!$C:$C,MATCH(BK26,_names_lookup!$A:$A,0)),"") -> denis@andrews.edu | BM26: =IFERROR(INDEX(_names_lookup!$B:$B,MATCH(BK26,_names_lookup!$A:$A,0)),"") -> 000134382 | BO26: 100 | BS26: =IFERROR(IF(BR26*AA26=0,"",BR26*AA26),"") | BV26: CHIS | CF26: 12-MAY-25 | CG26: A | CH26: 1 | CI26: I | CL26: MOODL | CQ26: 70 | CR26: 2 | CS26: 0 | CT26: Y | DC26: Y | DP26: 202531
H27: 3267-03 | I27: 3267 | K27: CHIS | L27: 624 | M27: 998 | O27: =IFERROR(INDEX(_courses_lookup!$C:$C,MATCH(K27&L27,_courses_lookup!$E:$E,0)),"") -> Issues in Ellen G White Stdies | P27: =IFERROR(INDEX(_courses_lookup!$D:$D,MATCH(K27&L27,_courses_lookup!$E:$E,0)),"") -> 0 | R27: 315 | S27: 7 | V27: SYNC | W27: FP | X27: 2 | Y27: 2,3 | Z27: 2 | AB27: 25 | AC27: CLAS | AD27: 12-MAY-25 | AG27: =IF(AND(AE27<>"",AF27<>""),ROUNDUP((AF27-AE27)/7,0),"") | AI27: =IFERROR(IF(AG27*AH27=0,"",AG27*AH27),"") | AJ27: 12-MAY-25 | AK27: 06-JUN-25 | AL27: =IF(AND(AJ27<>"",AK27<>""),ROUNDUP((AK27-AJ27)/7,0),"") -> 4 | AN27: =IFERROR(IF(AL27*AM27=0,"",AL27*AM27),"") | AQ27: =IF(AND(AO27<>"",AP27<>""),ROUNDUP((AP27-AO27)/7,0),"") | AR27: =IFERROR(IF((AU27-(AI27+AN27))/AQ27=0,"",ROUNDUP((AU27-(AI27+AN27))/AQ27,0)),"") | AS27: =IFERROR(IF((AU27-(AI27+AN27))=0,"",(AU27-(AI27+AN27))),"") | AT27: =IF(AND(AG27="",AQ27=""),AL27,IF(SUM(AG27,AL27,AQ27)=0,"",SUM(AG27,AL27,AQ27))) -> 4 | AV27: 06-JUN-25 | AW27: 1330 | AX27: 1520 | AZ27: M | BA27: T | BB27: W | BC27: R | BF27: 4 | BG27: =IF(AD27="","",YEAR(AD27)+IF(MONTH(AD27)>=5,1,0)) -> 2026 | BH27: =IF(AD27="","",IF(AND(MONTH(AD27)=8,DAY(AD27)>=15),"Fall",IF(MONTH(AD27)>8,"Fall",IF(MONTH(AD27)=5,"Summer",IF(MONTH(AD27)=1,"Spring",""))))) -> Summer | BK27: Garcia Zarate, Heber E. | BL27: =IFERROR(INDEX(_names_lookup!$C:$C,MATCH(BK27,_names_lookup!$A:$A,0)),"") -> heber@andrews.edu | BM27: =IFERROR(INDEX(_names_lookup!$B:$B,MATCH(BK27,_names_lookup!$A:$A,0)),"") -> 000147941 | BO27: 100 | BS27: =IFERROR(IF(BR27*AA27=0,"",BR27*AA27),"") | BV27: CHIS | BZ27: 160 | CA27: ES12 | CB27: BILL | CC27: FP | CE27: 202531 | CF27: 13-MAY-25 | CG27: A | CH27: 2 | CI27: A | CJ27: P-CHIS624 | CL27: MOODL | CQ27: 70 | CR27: 7 | CS27: 0 | CT27: Y | CU27: O | DC27: Y | DP27: 202531 | DQ27: 0
H28: 3267-04 | I28: 3267 | K28: CHIS | L28: 624 | M28: 998 | O28: =IFERROR(INDEX(_courses_lookup!$C:$C,MATCH(K28&L28,_courses_lookup!$E:$E,0)),"") -> Issues in Ellen G White Stdies | P28: =IFERROR(INDEX(_courses_lookup!$D:$D,MATCH(K28&L28,_courses_lookup!$E:$E,0)),"") -> 0 | R28: 315 | S28: 7 | V28: SYNC | W28: FP | X28: 2 | Y28: 2,3 | Z28: 2 | AB28: 25 | AC28: CLAS | AD28: 12-MAY-25 | AG28: =IF(AND(AE28<>"",AF28<>""),ROUNDUP((AF28-AE28)/7,0),"") | AI28: =IFERROR(IF(AG28*AH28=0,"",AG28*AH28),"") | AJ28: 12-MAY-25 | AK28: 06-JUN-25 | AL28: =IF(AND(AJ28<>"",AK28<>""),ROUNDUP((AK28-AJ28)/7,0),"") -> 4 | AN28: =IFERROR(IF(AL28*AM28=0,"",AL28*AM28),"") | AQ28: =IF(AND(AO28<>"",AP28<>""),ROUNDUP((AP28-AO28)/7,0),"") | AR28: =IFERROR(IF((AU28-(AI28+AN28))/AQ28=0,"",ROUNDUP((AU28-(AI28+AN28))/AQ28,0)),"") | AS28: =IFERROR(IF((AU28-(AI28+AN28))=0,"",(AU28-(AI28+AN28))),"") | AT28: =IF(AND(AG28="",AQ28=""),AL28,IF(SUM(AG28,AL28,AQ28)=0,"",SUM(AG28,AL28,AQ28))) -> 4 | AV28: 06-JUN-25 | AW28: 1330 | AX28: 1520 | AZ28: M | BA28: T | BB28: W | BC28: R | BF28: 4 | BG28: =IF(AD28="","",YEAR(AD28)+IF(MONTH(AD28)>=5,1,0)) -> 2026 | BH28: =IF(AD28="","",IF(AND(MONTH(AD28)=8,DAY(AD28)>=15),"Fall",IF(MONTH(AD28)>8,"Fall",IF(MONTH(AD28)=5,"Summer",IF(MONTH(AD28)=1,"Spring",""))))) -> Summer | BK28: Garcia Zarate, Heber E. | BL28: =IFERROR(INDEX(_names_lookup!$C:$C,MATCH(BK28,_names_lookup!$A:$A,0)),"") -> heber@andrews.edu | BM28: =IFERROR(INDEX(_names_lookup!$B:$B,MATCH(BK28,_names_lookup!$A:$A,0)),"") -> 000147941 | BO28: 100 | BS28: =IFERROR(IF(BR28*AA28=0,"",BR28*AA28),"") | BV28: CHIS | BZ28: 160 | CA28: ES12 | CB28: BILL | CC28: FP | CE28: 202531 | CF28: 13-MAY-25 | CG28: A | CH28: 2 | CI28: A | CJ28: P-CHIS624 | CL28: MOODL | CQ28: 70 | CR28: 7 | CS28: 0 | CT28: Y | CU28: O | DC28: Y | DP28: 202531 | DQ28: 7
H29: 3528-06 | I29: 3528 | K29: CHIS | L29: 690 | M29: 041 | O29: =IFERROR(INDEX(_courses_lookup!$C:$C,MATCH(K29&L29,_courses_lookup!$E:$E,0)),"") -> Ind St: | P29: =IFERROR(INDEX(_courses_lookup!$D:$D,MATCH(K29&L29,_courses_lookup!$E:$E,0)),"") -> 0 | S29: 0 | V29: TOUR | W29: DO | X29: 3 | Y29: 1-3 | Z29: 1 | AB29: 25 | AC29: POST | AD29: 09-JUN-25 | AG29: =IF(AND(AE29<>"",AF29<>""),ROUNDUP((AF29-AE29)/7,0),"") | AI29: =IFERROR(IF(AG29*AH29=0,"",AG29*AH29),"") | AJ29: 23-JUN-25 | AK29: 31-JUL-25 | AL29: =IF(AND(AJ29<>"",AK29<>""),ROUNDUP((AK29-AJ29)/7,0),"") -> 6 | AN29: =IFERROR(IF(AL29*AM29=0,"",AL29*AM29),"") | AQ29: =IF(AND(AO29<>"",AP29<>""),ROUNDUP((AP29-AO29)/7,0),"") | AR29: =IFERROR(IF((AU29-(AI29+AN29))/AQ29=0,"",ROUNDUP((AU29-(AI29+AN29))/AQ29,0)),"") | AS29: =IFERROR(IF((AU29-(AI29+AN29))=0,"",(AU29-(AI29+AN29))),"") | AT29: =IF(AND(AG29="",AQ29=""),AL29,IF(SUM(AG29,AL29,AQ29)=0,"",SUM(AG29,AL29,AQ29))) -> 6 | AV29: 31-JUL-25 | BF29: 4 | BG29: =IF(AD29="","",YEAR(AD29)+IF(MONTH(AD29)>=5,1,0)) -> 2026 | BH29: =IF(AD29="","",IF(AND(MONTH(AD29)=8,DAY(AD29)>=15),"Fall",IF(MONTH(AD29)>8,"Fall",IF(MONTH(AD29)=5,"Summer",IF(MONTH(AD29)=1,"Spring",""))))) | BK29: Hernandez, Abner F. | BL29: =IFERROR(INDEX(_names_lookup!$C:$C,MATCH(BK29,_names_lookup!$A:$A,0)),"") -> abnerh@andrews.edu | BM29: =IFERROR(INDEX(_names_lookup!$B:$B,MATCH(BK29,_names_lookup!$A:$A,0)),"") -> 000149024 | BO29: 100 | BS29: =IFERROR(IF(BR29*AA29=0,"",BR29*AA29),"") | BV29: CHIS | BZ29: -922 | CA29: ESM1 | CB29: BILL | CC29: MA | CE29: 202531 | CF29: 21-MAY-25 | CG29: A | CH29: 1 | CI29: I | CL29: MOODL | CQ29: 70 | CR29: 1 | CS29: 0 | CT29: Y | DC29: Y | DK29: 70 | DP29: 202531
H30: 3528-07 | I30: 3528 | K30: CHIS | L30: 690 | M30: 041 | O30: =IFERROR(INDEX(_courses_lookup!$C:$C,MATCH(K30&L30,_courses_lookup!$E:$E,0)),"") -> Ind St: | P30: =IFERROR(INDEX(_courses_lookup!$D:$D,MATCH(K30&L30,_courses_lookup!$E:$E,0)),"") -> 0 | S30: 0 | V30: TOUR | W30: MA | X30: 3 | Y30: 1-3 | Z30: 1 | AB30: 25 | AC30: POST | AD30: 09-JUN-25 | AG30: =IF(AND(AE30<>"",AF30<>""),ROUNDUP((AF30-AE30)/7,0),"") | AI30: =IFERROR(IF(AG30*AH30=0,"",AG30*AH30),"") | AJ30: 23-JUN-25 | AK30: 31-JUL-25 | AL30: =IF(AND(AJ30<>"",AK30<>""),ROUNDUP((AK30-AJ30)/7,0),"") -> 6 | AN30: =IFERROR(IF(AL30*AM30=0,"",AL30*AM30),"") | AQ30: =IF(AND(AO30<>"",AP30<>""),ROUNDUP((AP30-AO30)/7,0),"") | AR30: =IFERROR(IF((AU30-(AI30+AN30))/AQ30=0,"",ROUNDUP((AU30-(AI30+AN30))/AQ30,0)),"") | AS30: =IFERROR(IF((AU30-(AI30+AN30))=0,"",(AU30-(AI30+AN30))),"") | AT30: =IF(AND(AG30="",AQ30=""),AL30,IF(SUM(AG30,AL30,AQ30)=0,"",SUM(AG30,AL30,AQ30))) -> 6 | AV30: 31-JUL-25 | BF30: 4 | BG30: =IF(AD30="","",YEAR(AD30)+IF(MONTH(AD30)>=5,1,0)) -> 2026 | BH30: =IF(AD30="","",IF(AND(MONTH(AD30)=8,DAY(AD30)>=15),"Fall",IF(MONTH(AD30)>8,"Fall",IF(MONTH(AD30)=5,"Summer",IF(MONTH(AD30)=1,"Spring",""))))) | BK30: Hernandez, Abner F. | BL30: =IFERROR(INDEX(_names_lookup!$C:$C,MATCH(BK30,_names_lookup!$A:$A,0)),"") -> abnerh@andrews.edu | BM30: =IFERROR(INDEX(_names_lookup!$B:$B,MATCH(BK30,_names_lookup!$A:$A,0)),"") -> 000149024 | BO30: 100 | BS30: =IFERROR(IF(BR30*AA30=0,"",BR30*AA30),"") | BV30: CHIS | BZ30: -633 | CA30: EAR2 | CB30: BILL | CC30: MA | CE30: 202531 | CF30: 21-MAY-25 | CG30: A | CH30: 1 | CI30: I | CL30: MOODL | CQ30: 70 | CR30: 1 | CS30: 0 | CT30: Y | DC30: Y | DN30: MAJOR | DP30: 202531
H31: 3528-08 | I31: 3528 | K31: CHIS | L31: 690 | M31: 041 | O31: =IFERROR(INDEX(_courses_lookup!$C:$C,MATCH(K31&L31,_courses_lookup!$E:$E,0)),"") -> Ind St: | P31: =IFERROR(INDEX(_courses_lookup!$D:$D,MATCH(K31&L31,_courses_lookup!$E:$E,0)),"") -> 0 | S31: 0 | V31: TOUR | W31: MA | X31: 3 | Y31: 1-3 | Z31: 1 | AB31: 25 | AC31: POST | AD31: 09-JUN-25 | AG31: =IF(AND(AE31<>"",AF31<>""),ROUNDUP((AF31-AE31)/7,0),"") | AI31: =IFERROR(IF(AG31*AH31=0,"",AG31*AH31),"") | AJ31: 23-JUN-25 | AK31: 31-JUL-25 | AL31: =IF(AND(AJ31<>"",AK31<>""),ROUNDUP((AK31-AJ31)/7,0),"") -> 6 | AN31: =IFERROR(IF(AL31*AM31=0,"",AL31*AM31),"") | AQ31: =IF(AND(AO31<>"",AP31<>""),ROUNDUP((AP31-AO31)/7,0),"") | AR31: =IFERROR(IF((AU31-(AI31+AN31))/AQ31=0,"",ROUNDUP((AU31-(AI31+AN31))/AQ31,0)),"") | AS31: =IFERROR(IF((AU31-(AI31+AN31))=0,"",(AU31-(AI31+AN31))),"") | AT31: =IF(AND(AG31="",AQ31=""),AL31,IF(SUM(AG31,AL31,AQ31)=0,"",SUM(AG31,AL31,AQ31))) -> 6 | AV31: 31-JUL-25 | BF31: 4 | BG31: =IF(AD31="","",YEAR(AD31)+IF(MONTH(AD31)>=5,1,0)) -> 2026 | BH31: =IF(AD31="","",IF(AND(MONTH(AD31)=8,DAY(AD31)>=15),"Fall",IF(MONTH(AD31)>8,"Fall",IF(MONTH(AD31)=5,"Summer",IF(MONTH(AD31)=1,"Spring",""))))) | BK31: Hernandez, Abner F. | BL31: =IFERROR(INDEX(_names_lookup!$C:$C,MATCH(BK31,_names_lookup!$A:$A,0)),"") -> abnerh@andrews.edu | BM31: =IFERROR(INDEX(_names_lookup!$B:$B,MATCH(BK31,_names_lookup!$A:$A,0)),"") -> 000149024 | BO31: 100 | BS31: =IFERROR(IF(BR31*AA31=0,"",BR31*AA31),"") | BV31: CHIS | BZ31: -633 | CA31: ESM3 | CB31: BILL | CC31: MA | CE31: 202531 | CF31: 21-MAY-25 | CG31: A | CH31: 1 | CI31: I | CL31: MOODL | CQ31: 70 | CR31: 1 | CS31: 0 | CT31: Y | DC31: Y | DL31: MSCID | DP31: 202531
H32: 3528-09 | I32: 3528 | K32: CHIS | L32: 690 | M32: 041 | O32: =IFERROR(INDEX(_courses_lookup!$C:$C,MATCH(K32&L32,_courses_lookup!$E:$E,0)),"") -> Ind St: | P32: =IFERROR(INDEX(_courses_lookup!$D:$D,MATCH(K32&L32,_courses_lookup!$E:$E,0)),"") -> 0 | S32: 0 | V32: TOUR | W32: MA | X32: 3 | Y32: 1-3 | Z32: 1 | AB32: 25 | AC32: POST | AD32: 09-JUN-25 | AG32: =IF(AND(AE32<>"",AF32<>""),ROUNDUP((AF32-AE32)/7,0),"") | AI32: =IFERROR(IF(AG32*AH32=0,"",AG32*AH32),"") | AJ32: 23-JUN-25 | AK32: 31-JUL-25 | AL32: =IF(AND(AJ32<>"",AK32<>""),ROUNDUP((AK32-AJ32)/7,0),"") -> 6 | AN32: =IFERROR(IF(AL32*AM32=0,"",AL32*AM32),"") | AQ32: =IF(AND(AO32<>"",AP32<>""),ROUNDUP((AP32-AO32)/7,0),"") | AR32: =IFERROR(IF((AU32-(AI32+AN32))/AQ32=0,"",ROUNDUP((AU32-(AI32+AN32))/AQ32,0)),"") | AS32: =IFERROR(IF((AU32-(AI32+AN32))=0,"",(AU32-(AI32+AN32))),"") | AT32: =IF(AND(AG32="",AQ32=""),AL32,IF(SUM(AG32,AL32,AQ32)=0,"",SUM(AG32,AL32,AQ32))) -> 6 | AV32: 31-JUL-25 | BF32: 4 | BG32: =IF(AD32="","",YEAR(AD32)+IF(MONTH(AD32)>=5,1,0)) -> 2026 | BH32: =IF(AD32="","",IF(AND(MONTH(AD32)=8,DAY(AD32)>=15),"Fall",IF(MONTH(AD32)>8,"Fall",IF(MONTH(AD32)=5,"Summer",IF(MONTH(AD32)=1,"Spring",""))))) | BK32: Hernandez, Abner F. | BL32: =IFERROR(INDEX(_names_lookup!$C:$C,MATCH(BK32,_names_lookup!$A:$A,0)),"") -> abnerh@andrews.edu | BM32: =IFERROR(INDEX(_names_lookup!$B:$B,MATCH(BK32,_names_lookup!$A:$A,0)),"") -> 000149024 | BO32: 100 | BS32: =IFERROR(IF(BR32*AA32=0,"",BR32*AA32),"") | BV32: CHIS | BZ32: -633 | CA32: ESM4 | CB32: BILL | CC32: MA | CE32: 202531 | CF32: 21-MAY-25 | CG32: A | CH32: 1 | CI32: I | CL32: MOODL | CQ32: 70 | CR32: 1 | CS32: 0 | CT32: Y | DC32: Y | DN32: MAJOR | DP32: 202531
H33: 3528-10 | I33: 3528 | K33: CHIS | L33: 690 | M33: 041 | O33: =IFERROR(INDEX(_courses_lookup!$C:$C,MATCH(K33&L33,_courses_lookup!$E:$E,0)),"") -> Ind St: | P33: =IFERROR(INDEX(_courses_lookup!$D:$D,MATCH(K33&L33,_courses_lookup!$E:$E,0)),"") -> 0 | S33: 0 | V33: TOUR | X33: 3 | Y33: 1-3 | Z33: 1 | AB33: 25 | AC33: POST | AD33: 09-JUN-25 | AG33: =IF(AND(AE33<>"",AF33<>""),ROUNDUP((AF33-AE33)/7,0),"") | AI33: =IFERROR(IF(AG33*AH33=0,"",AG33*AH33),"") | AJ33: 23-JUN-25 | AK33: 31-JUL-25 | AL33: =IF(AND(AJ33<>"",AK33<>""),ROUNDUP((AK33-AJ33)/7,0),"") -> 6 | AN33: =IFERROR(IF(AL33*AM33=0,"",AL33*AM33),"") | AQ33: =IF(AND(AO33<>"",AP33<>""),ROUNDUP((AP33-AO33)/7,0),"") | AR33: =IFERROR(IF((AU33-(AI33+AN33))/AQ33=0,"",ROUNDUP((AU33-(AI33+AN33))/AQ33,0)),"") | AS33: =IFERROR(IF((AU33-(AI33+AN33))=0,"",(AU33-(AI33+AN33))),"") | AT33: =IF(AND(AG33="",AQ33=""),AL33,IF(SUM(AG33,AL33,AQ33)=0,"",SUM(AG33,AL33,AQ33))) -> 6 | AV33: 31-JUL-25 | BF33: 4 | BG33: =IF(AD33="","",YEAR(AD33)+IF(MONTH(AD33)>=5,1,0)) -> 2026 | BH33: =IF(AD33="","",IF(AND(MONTH(AD33)=8,DAY(AD33)>=15),"Fall",IF(MONTH(AD33)>8,"Fall",IF(MONTH(AD33)=5,"Summer",IF(MONTH(AD33)=1,"Spring",""))))) | BK33: Hernandez, Abner F. | BL33: =IFERROR(INDEX(_names_lookup!$C:$C,MATCH(BK33,_names_lookup!$A:$A,0)),"") -> abnerh@andrews.edu | BM33: =IFERROR(INDEX(_names_lookup!$B:$B,MATCH(BK33,_names_lookup!$A:$A,0)),"") -> 000149024 | BO33: 100 | BS33: =IFERROR(IF(BR33*AA33=0,"",BR33*AA33),"") | BV33: CHIS | BZ33: 1267 | CA33: ESTM | CB33: BILL | CC33: MA | CE33: 202531 | CF33: 21-MAY-25 | CG33: A | CH33: 1 | CI33: I | CL33: MOODL | CQ33: 70 | CR33: 1 | CS33: 0 | CT33: Y | DC33: Y | DP33: 202531
H34: 3528-16 | I34: 3528 | K34: CHIS | L34: 690 | M34: 041 | O34: =IFERROR(INDEX(_courses_lookup!$C:$C,MATCH(K34&L34,_courses_lookup!$E:$E,0)),"") -> Ind St: | P34: =IFERROR(INDEX(_courses_lookup!$D:$D,MATCH(K34&L34,_courses_lookup!$E:$E,0)),"") -> 0 | S34: 0 | V34: TOUR | W34: DO | X34: 3 | Y34: 1-3 | Z34: 1 | AB34: 25 | AC34: TOUR | AD34: 09-JUN-25 | AG34: =IF(AND(AE34<>"",AF34<>""),ROUNDUP((AF34-AE34)/7,0),"") | AI34: =IFERROR(IF(AG34*AH34=0,"",AG34*AH34),"") | AJ34: 09-JUN-25 | AK34: 22-JUN-25 | AL34: =IF(AND(AJ34<>"",AK34<>""),ROUNDUP((AK34-AJ34)/7,0),"") -> 2 | AN34: =IFERROR(IF(AL34*AM34=0,"",AL34*AM34),"") | AQ34: =IF(AND(AO34<>"",AP34<>""),ROUNDUP((AP34-AO34)/7,0),"") | AR34: =IFERROR(IF((AU34-(AI34+AN34))/AQ34=0,"",ROUNDUP((AU34-(AI34+AN34))/AQ34,0)),"") | AS34: =IFERROR(IF((AU34-(AI34+AN34))=0,"",(AU34-(AI34+AN34))),"") | AT34: =IF(AND(AG34="",AQ34=""),AL34,IF(SUM(AG34,AL34,AQ34)=0,"",SUM(AG34,AL34,AQ34))) -> 2 | AV34: 31-JUL-25 | BF34: 4 | BG34: =IF(AD34="","",YEAR(AD34)+IF(MONTH(AD34)>=5,1,0)) -> 2026 | BH34: =IF(AD34="","",IF(AND(MONTH(AD34)=8,DAY(AD34)>=15),"Fall",IF(MONTH(AD34)>8,"Fall",IF(MONTH(AD34)=5,"Summer",IF(MONTH(AD34)=1,"Spring",""))))) | BK34: Hernandez, Abner F. | BL34: =IFERROR(INDEX(_names_lookup!$C:$C,MATCH(BK34,_names_lookup!$A:$A,0)),"") -> abnerh@andrews.edu | BM34: =IFERROR(INDEX(_names_lookup!$B:$B,MATCH(BK34,_names_lookup!$A:$A,0)),"") -> 000149024 | BO34: 100 | BS34: =IFERROR(IF(BR34*AA34=0,"",BR34*AA34),"") | BV34: CHIS | BZ34: -922 | CA34: ESM1 | CB34: BILL | CC34: MA | CE34: 202531 | CF34: 21-MAY-25 | CG34: A | CH34: 1 | CI34: I | CL34: MOODL | CQ34: 70 | CR34: 1 | CS34: 0 | CT34: Y | DC34: Y | DK34: 70 | DP34: 202531
